Workbook

Sheet COVER
A9: VALVE MARGIN | B9: N/A | C9: 밸브(조립&검사,PAINT 비용 제외) X FACTOR
A10: FACTOR | B10: 1.3 | C10: (밸브+사급비용) X FACTOR
A12: DESCRIPTION | B12: MATERIAL | C12: PRICE | D12: REMARK | G12: 구매 원가 | J12: FACTORY COST(0.7) -가공,도장,포장,인건비
A13: BODY(WAFER) | F13: SIZE | G13: BARE | H13: LEVER | I13: GEAR | J13: BARE | K13: LEVER | L13: GEAR
A14: BODY(LUG) | B14: A536 Gr65-45-12 | C14: 3500 | F14: 50A | G14: ='50A'!$K$33 -> 31245 | H14: ='50A'!$K$34 -> 47245 | I14: ='50A'!$K$35 -> 129245 | J14: ='50A'!$K$36 -> 44635.714 | K14: ='50A'!$K$37 -> 67492.857 | L14: ='50A'!$K$38 -> 184635.71
A15: BODY(FLANGE) | F15: 65A | G15: ='65A'!$K$33 -> 36390 | H15: ='65A'!$K$34 -> 52390 | I15: ='65A'!$K$35 -> 134390 | J15: ='65A'!$K$36 -> 51985.714 | K15: ='65A'!$K$37 -> 74842.857 | L15: ='65A'!$K$38 -> 191985.71
A16: DISC | B16: A351 CF8M | C16: 12000 | F16: 80A | G16: ='80A'!$K$33 -> 39370 | H16: ='80A'!$K$34 -> 55370 | I16: ='80A'!$K$35 -> 137370 | J16: ='80A'!$K$36 -> 56242.857 | K16: ='80A'!$K$37 -> 79100 | L16: ='80A'!$K$38 -> 196242.86
A17: STEM | B17: A564T630 | C17: 10000 | F17: 100A | G17: ='100A'!$K$33 -> 70370 | H17: ='100A'!$K$34 -> 86370 | I17: ='100A'!$K$35 -> 168370 | J17: ='100A'!$K$36 -> 100528.57 | K17: ='100A'!$K$37 -> 123385.71 | L17: ='100A'!$K$38 -> 240528.57
A18: SEAT | B18: EPDM | F18: 125A | G18: ='125A'!$K$33 -> 78270 | H18: ='125A'!$K$34 -> 95270 | I18: ='125A'!$K$35 -> 176270 | J18: ='125A'!$K$36 -> 111814.29 | K18: ='125A'!$K$37 -> 136100 | L18: ='125A'!$K$38 -> 251814.29
A19: PACKING(350A&below) | B19: NBR | D19: 350A 이하 | F19: 150A | G19: ='150A'!$K33 -> 99355 | H19: ='150A'!$K34 -> 116355 | I19: ='150A'!$K35 -> 197355 | J19: ='150A'!$K36 -> 141935.71 | K19: ='150A'!$K37 -> 166221.43 | L19: ='150A'!$K38 -> 281935.71
A20: PACKING(400A&above) | B20: ALBC2 | C20: 금액 변동 X | D20: 400A 이상 | F20: 200A | G20: ='200A'!$K$33 -> 146778 | H20: ='200A'!$K$34 -> 146778 | I20: ='200A'!$K$35 -> 244778 | J20: ='200A'!$K$36 -> 209682.86 | K20: ='200A'!$K$37 -> 209682.86 | L20: ='200A'!$K$38 -> 349682.86
A21: BUSH(Only 500A&above) | B21: SSPC | C21: 금액 변동 X | D21: 500A 이상 | F21: 250A | G21: ='250A'!$K$33 -> 226750 | H21: ='250A'!$K$34 -> 226750 | I21: ='250A'!$K$35 -> 349750 | J21: ='250A'!$K$36 -> 323928.57 | K21: ='250A'!$K$37 -> 323928.57 | L21: ='250A'!$K$38 -> 499642.86
A22: END COVER | B22: BODY MATERIAL | D22: 500A 이상 | F22: 300A | G22: ='300A'!$K$33 -> 337350 | H22: ='300A'!$K$34 -> 337350 | I22: ='300A'!$K$35 -> 460350 | J22: ='300A'!$K$36 -> 481928.57 | K22: ='300A'!$K$37 -> 481928.57 | L22: ='300A'!$K$38 -> 657642.86
A23: END COVER BOLT | B23: B8M | D23: 500A 이상 | F23: 350A | G23: ='350A'!$K$33 -> 404530 | H23: ='350A'!$K$34 -> 404530 | I23: ='350A'!$K$35 -> 527530 | J23: ='350A'!$K$36 -> 577900 | K23: ='350A'!$K$37 -> 577900 | L23: ='350A'!$K$38 -> 753614.29
A24: COLLAR | B24: ALBC2 | C24: 금액 변동 X | F24: 400A | G24: ='400A'!$K$33 -> 692580 | H24: ='400A'!$K$34 -> 692580 | I24: ='400A'!$K$35 -> 917580 | J24: ='400A'!$K$36 -> 989400 | K24: ='400A'!$K$37 -> 989400 | L24: ='400A'!$K$38 -> 1310828.6
A25: TOP RETAINER | B25: SS400 | C25: 금액 변동 X | D25: 450A 이하-T304 /500A 이상-SS400 | F25: 450A | G25: ='450A'!$K$33 -> 861080 | H25: ='450A'!$K$34 -> 861080 | I25: ='450A'!$K$35 -> 1086080 | J25: ='450A'!$K$36 -> 1230114.3 | K25: ='450A'!$K$37 -> 1230114.3 | L25: ='450A'!$K$38 -> 1551542.9
A26: TOP RETAINER BOLT | B26: B8M | C26: 금액 변동 X | F26: 500A | G26: ='500A'!$K$33 -> 1136610 | H26: ='500A'!$K$34 -> 1136610 | I26: ='500A'!$K$35 -> 1441610 | J26: ='500A'!$K$36 -> 1623728.6 | K26: ='500A'!$K$37 -> 1623728.6 | L26: ='500A'!$K$38 -> 2059442.9
A27: GEAR BOX BOLT | B27: B8M | F27: 550A | G27: ='550A'!$K$33 -> 1483485 | H27: ='550A'!$K$34 -> 1483485 | I27: ='550A'!$K$35 -> 1788485 | J27: ='550A'!$K$36 -> 2119264.3 | K27: ='550A'!$K$37 -> 2119264.3 | L27: ='550A'!$K$38 -> 2554978.6
A28: STEM CR PLATING | B28: REQUIRED | C28: BODY=STEM | D28: 450A 이하만 적용 | F28: 600A | G28: ='600A'!$K$33 -> 1881100 | H28: ='600A'!$K$34 -> 1881100 | I28: ='600A'!$K$35 -> 2236100 | J28: ='600A'!$K$36 -> 2687285.7 | K28: ='600A'!$K$37 -> 2687285.7 | L28: ='600A'!$K$38 -> 3194428.6
F29: 650A | G29: ='650A'!$K$33 -> 2270835 | H29: ='650A'!$K$34 -> 2270835 | I29: ='650A'!$K$35 -> 2625835 | J29: ='650A'!$K$36 -> 3244050 | K29: ='650A'!$K$37 -> 3244050 | L29: ='650A'!$K$38 -> 3751192.9
F30: 700A | G30: ='700A'!$K$33 -> 2746710 | H30: ='700A'!$K$34 -> 2746710 | I30: ='700A'!$K$35 -> 3335710 | J30: ='700A'!$K$36 -> 3923871.4 | K30: ='700A'!$K$37 -> 3923871.4 | L30: ='700A'!$K$38 -> 4765300
F31: 750A | G31: ='750A'!$K$33 -> 3621695 | H31: ='750A'!$K$34 -> 3621695 | I31: ='750A'!$K$35 -> 4210695 | J31: ='750A'!$K$36 -> 5173850 | K31: ='750A'!$K$37 -> 5173850 | L31: ='750A'!$K$38 -> 6015278.6
A32: PAINTING | B32: 기존 단가 | D32: 기존단가 /외주 2 COATING or 3 COATING | F32: 800A | G32: ='800A'!$K$33 -> 4457135 | H32: ='800A'!$K$34 -> 4457135 | I32: ='800A'!$K$35 -> 5046135 | J32: ='800A'!$K$36 -> 6367335.7 | K32: ='800A'!$K$37 -> 6367335.7 | L32: ='800A'!$K$38 -> 7208764.3
F33: 850A | G33: ='850A'!$K$33 -> 5143855 | H33: ='850A'!$K$34 -> 5143855 | I33: ='850A'!$K$35 -> 5732855 | J33: ='850A'!$K$36 -> 7348364.3 | K33: ='850A'!$K$37 -> 7348364.3 | L33: ='850A'!$K$38 -> 8189792.9
A34: PRESSURE | B34: 10 BAR | D34: 16BAR 기준(DISC 중량) | F34: 900A | G34: ='900A'!$K$33 -> 5517700 | H34: ='900A'!$K$34 -> 5517700 | I34: ='900A'!$K$35 -> 6265700 | J34: ='900A'!$K$36 -> 7882428.6 | K34: ='900A'!$K$37 -> 7882428.6 | L34: ='900A'!$K$38 -> 8951000
A35: OPERATION | B35: MOTOR | C35: SUS304 | D35: LEVER - SS400 or SUS | F35: 950A | G35: ='950A'!$K$33 -> 5970890 | H35: ='950A'!$K$34 -> 5970890 | I35: ='950A'!$K$35 -> 6718890 | J35: ='950A'!$K$36 -> 8529842.9 | K35: ='950A'!$K$37 -> 8529842.9 | L35: ='950A'!$K$38 -> 9598414.3
F36: 1000A | G36: ='1000A'!$K$33 -> 4656610 | H36: ='1000A'!$K$34 -> 4656610 | I36: ='1000A'!$K$35 -> 5404610 | J36: ='1000A'!$K$36 -> 6652300 | K36: ='1000A'!$K$37 -> 6652300 | L36: ='1000A'!$K$38 -> 7720871.4
F37: 1050A | G37: ='1050A'!$K$33 -> 4815230 | H37: ='1050A'!$K$34 -> 4815230 | I37: ='1050A'!$K$35 -> 5563230 | J37: ='1050A'!$K$36 -> 6878900 | K37: ='1050A'!$K$37 -> 6878900 | L37: ='1050A'!$K$38 -> 7947471.4
F38: 1100A | G38: ='1100A'!$K$33 -> 5571580 | H38: ='1100A'!$K$34 -> 5571580 | I38: ='1100A'!$K$35 -> 6319580 | J38: ='1100A'!$K$36 -> 7959400 | K38: ='1100A'!$K$37 -> 7959400 | L38: ='1100A'!K$38 -> 9027971.4
F39: 1200A | G39: ='1200A'!K$33 -> 7394810 | H39: ='1200A'!$K$34 -> 7394810 | I39: ='1200A'!$K$35 -> 8695810 | J39: ='1200A'!$K$36 -> 10564014 | K39: ='1200A'!$K$37 -> 10564014 | L39: ='1200A'!K$38 -> 12422586

Sheet 주조단가
A1: 업체/재질별 주조 단가 (2019-05-21)
AB2: 1 | AC2: 2 | AD2: 3 | AE2: 4 | AF2: 5 | AG2: 6 | AH2: 7 | AI2: 8 | AJ2: 9 | AK2: 10 | AL2: 11 | AM2: 12 | AN2: 13 | AO2: 14 | AP2: 15 | AR2: 17 | AS2: 18 | AU2: 19 | AW2: 20
A3: 업체 | B3: REV | C3: 관리CAPA. | D3: A216 WCB | E3: A217 WC9 | F3: A217 WC1 | G3: A352 LCC | H3: A217 WC6 | I3: A217 CA15 | J3: A351 CG8M | K3: A351 CG3M | L3: A351 CF8 | M3: A351 CF8M | N3: A351 CF3M | O3: A890 4A | P3: A890 5A | Q3: A890 6A | R3: A351 CF3 | S3: A351 CF8C | T3: CW6MC | U3: INCOLOY 25-6Mo | V3: A351 CN7M | W3: MONEL K500 | X3: ALBC3 | Y3: B148 | Z3: A536 | AB3: BODY MATERIAL | AC3: DISC MATERIAL | AD3: SEAT MATERIAL | AE3: STEM MATERIAL | AF3: PACKING (350A&Below) | AG3: PACKING (400A&Above) | AH3: BUSH (Only 500A&above) | AI3: END COVER | AJ3: END COVER BOLT | AK3: COLLAR | AL3: TOP RETAINER | AM3: TOP RETAINER BOLT | AN3: GEAR BOX BOLT | AO3: TOP COVER | AP3: TOP COVER BOLT | AQ3: STEM CR PLATING | AR3: PRESSURE | AS3: OPERATION | AU3: VALVE MARGIN | AW3: PAINTING/COATING
A4: 제흥금속 | B4: 폐업(2018년5월) | C4: 50KG이상 | D4: 2700 | E4: 4200 | G4: 2900 | H4: 3900 | L4: 6000 | M4: 7500 | N4: 8500 | AB4: A216 WCB | AC4: A351 CF8 | AD4: NBR | AE4: A276T304 | AF4: NBR | AG4: ALBC2 | AH4: SSPC | AI4: SS400 | AJ4: B8 | AK4: ALBC2 | AL4: SS400 | AM4: B8 | AN4: B8 | AO4: SS400 | AP4: B8 | AQ4: REQUIRED | AR4: 10 BAR | AS4: BARE | AU4: APPLICATION | AW4: 기존 단가
A5: HTF | B5: 품질문제로 품질부 거래 holding | C5: 101KG 이상 | D5: 2600 | L5: 5800 | M5: 7300 | N5: 8300 | AB5: A536 Gr65-45-12 | AC5: A351 CF8M | AD5: EPDM | AE5: A276T304L | AF5: EPDM | AI5: BODY MATERIAL | AJ5: B8M | AL5: A240T304 | AM5: B8M | AN5: B8M | AO5: A216 WCB | AP5: B8M | AQ5: N/A | AR5: 16 BAR | AS5: LEVER | AU5: N/A | AW5: 외주 2COATING
C6: 100KG 이하 | D6: 2800 | M6: 7300 | N6: 8300 | AB6: A395 Gr65-45-15 | AC6: A351 CF3 | AD6: VITON | AE6: A276T316 | AF6: VITON | AJ6: B7(다크로) | AL6: A240T316 | AN6: B7(다크로) | AO6: A351 CF8M | AP6: B7(다크로) | AR6: 20 BAR | AS6: GEAR | AW6: 외주 3COATING
A7: 영광스틸 | B7: 단가인상요청 미반영 거래 반납 | C7: 21KG 이상 | D7: 2700 | L7: 5800 | M7: 7700 | N7: 8700 | AC7: A351 CF3M | AE7: A276T316L | AS7: MOTOR
A8: 영광스틸 | C8: 20KG 이하 | D8: 2900 | I8: 5000 | L8: 6000 | M8: 8000 | N8: 9000 | AC8: B148 C95800 | AE8: A564T630 | AS8: PNEU
A9: 대림산업 | B9: 2018년 10월 rev. | C9: 200KG이상 | D9: 2600 | E9: 4200 | G9: 2800 | H9: 3600 | I9: 5000 | J9: 8300 | K9: 8500 | L9: 5800 | M9: 7000 | N9: 8000 | O9: 9000 | P9: 11000 | Q9: 12000 | R9: 6300 | T9: 35000 | V9: 17000 | W9: 35000 | AC9: A890 4A | AE9: A479T410 | AS9: SS400
A10: 대신금속 | B10: 2018년 11월 rev. | C10: 300KG미만 | D10: 2750 | AC10: A890 5A | AE10: UNS S31803 | AS10: SUS304
A11: 대신금속 | C11: 300KG이상 | D11: 2700 | E11: 4000 | F11: 3000 | G11: 2800 | H11: 3700 | I11: 4800 | J11: 7800 | K11: 8800 | L11: 6000 | M11: 7600 | N11: 8600 | O11: 10500 | P11: 11500 | Q11: 12500 | R11: 6500 | S11: 7000 | T11: 36000 | U11: 25000 | V11: 18000 | W11: 38000 | AE11: UNS S32750
A12: 주원특수강 | B12: 100kg 이하는 별도 견적 | C12: 100~300KG | D12: 2800 | AE12: MONEL K-400
A13: 주원특수강 | C13: 300KG이상 | D13: 2750 | E13: 4150 | G13: 2900 | H13: 3750 | I13: 4950 | L13: 6100 | M13: 7400 | N13: 8200 | O13: 9000 | P13: 11000 | Q13: 12000 | R13: 6600 | AE13: MONEL K-500
A14: 금화STEEL | B14: 2018년 6월 거래 개시 | D14: 3500 | L14: 6300 | M14: 8300 | N14: 9300 | P14: 18000 | R14: 7300 | AE14: INCONEL 625
A15: 광명금속 | B15: 신규 개발진행 업체 | C15: ~20KG | D15: 4000 | L15: 6900 | M15: 8600 | N15: 9600 | O15: 11500 | P15: 15000 | R15: 7900
C16: 21~50KG | D16: 3700 | L16: 6700 | M16: 8200 | N16: 9200 | O16: 11500 | P16: 15000 | R16: 7700
C17: 50KG~ | D17: 3300 | L17: 6500 | M17: 8000 | N17: 9000 | O17: 11500 | P17: 15000 | R17: 7500
A18: 디에스케스텍 | B18: 신규 개발진행 업체 | C18: ~20KG | D18: 3800 | L18: 6700 | M18: 8200 | N18: 8900 | O18: 11500 | P18: 16000 | R18: 7200
C19: 21~50KG | D19: 3300 | L19: 6400 | M19: 8200 | N19: 8900 | O19: 11500 | P19: 16000 | R19: 7200
C20: 50KG~ | D20: 3300 | L20: 6400 | M20: 8000 | N20: 8700 | O20: 11500 | P20: 16000 | R20: 7200
A21: 대원테크 | B21: 정밀주조업체 | L21: 12600 | M21: 16200 | N21: 18500
A22: SY메탈 | X22: 11300 | Y22: 11700
A23: 삼성금속 | X23: 11000 | Y23: 11300
A24: 진우 ENG | B24: REV.1(17-01-24) NEGO금액 ALBC,B148 -150원- | C24: DN350이하 | X24: 12150 | Y24: 12650
A25: 진우 ENG | C25: DN400이상 | X25: 11650 | Y25: 12250
A26: 진우 ENG | C26: 200KG이상 | X26: 10950 | Y26: 11350
A27: 마천캐스트 | B27: 2019-01-21 단가인상요청 (1950원->2100원) | C27: DN500~1000 | Z27: 2100
A28: 마천캐스트 | C28: DN2200 이하 | Z28: 1880
A29: 마천캐스트 | C29: DN2200 초과 | Z29: 1900
A30: 화성금속 | C30: 1500이상 | Z30: 2000
A31: 신우공업 | B31: 단가인상요청 미반영 거래 반납 | C31: 450A이하 | Z31: 2050
A32: 신우공업 | C32: 500A이상 | Z32: 1880
A33: 신우공업 | C33: 800KG이상 | Z33: 1880
A35: NOTE
A36: 주강 선급품 기존 단가에서 +100원/KG 추가됨
A37: 중공형 DISC는 용접비 +400원/KG 추가됨 (SY메탈 DN1000미만 +2000원/KG , DN1000이상 +1500원/KG)
A38: 영광 STEEL 주강 -100원 SUS -200원 NEGO(2017-01-12)
A39: 신우공업 - DN500이상 -70원, 800KG이상 -20원(2017-01-24)
A40: 진우 ENG - ALBC,B148 150원(2017-01-24)
A41: 신우공업 - DN450이하 -50원 NEGO(2017-10-10)
...

Sheet 50A
A1: CONCENTRIC BFV 원가 分析表
A3: SIZE | B3: 50A | C3: RATING | D3: #150 | F3: FLANGE DRILLING | I3: ASME B16.5 | J3: FACE TO FACE | K3: ISO575 SER'20(43MM)
J4: O.D(MM) | K4: 150 | L4: 외주가공비 / 단가표(EPC)
A5: NO. | B5: 부품명 | C5: 재질 | D5: 수량 | E5: 규격 | F5: 단중 | G5: 업체 | H5: 단가 | I5: 소계 | J5: 가공비 | K5: 합계 | L5: FC/FCD | M5: SC/WCB (ALBC) | N5: SUS | O5: A890 4A | P5: A890 5A | Q5: DISC 중량(일반) | R5: DISC 중량(고압) | T5: 이전 단가 Table 중량
A6: 1 | B6: BODY(WAFER) | C6: =COVER!B13 -> 0 | D6: 1 | F6: =(5+3.5)/2 -> 4.25 | H6: =COVER!C13 -> 0 | I6: =D6*F6*H6 -> 0 | K6: =I6+J6 -> 0 | L6: 10000 | M6: 15000 | N6: 30000 | T6: 3
A7: 1 | B7: BODY(LUG) | C7: =COVER!B14 -> A536 Gr65-45-12 | D7: 1 | F7: 5.5 | H7: =COVER!C14 -> 3500 | I7: =D7*F7*H7 -> 19250 | K7: =I7+J7 -> 19250 | L7: 14000 | M7: 21000 | T7: 5.5
A8: 1 | B8: BODY(FLANGE) | C8: =COVER!B15 -> 0 | D8: 1 | F8: 9 | H8: =COVER!C15 -> 0 | I8: =D8*F8*H8 -> 0 | K8: =I8+J8 -> 0 | L8: 17000 | M8: 25500 | T8: 7.5
A9: 2 | B9: DISC | C9: =COVER!B16 -> A351 CF8M | D9: 1 | F9: =IF(COVER!B34="10 BAR",Q9,IF(COVER!B34="16 BAR",R9,IF(COVER!B34="20 BAR",R9))) -> 0.3 | H9: =COVER!C16 -> 12000 | I9: =D9*F9*H9 -> 3600 | K9: =I9+J9 -> 3600 | L9: 3260 | M9: 3500 | N9: 3500 | O9: 9000 | P9: 12300 | Q9: 0.3 | R9: 0.3 | T9: 0.3 | V9: =P9/M9 -> 3.5142857
A10: 3 | B10: SEAT | C10: =COVER!B18 -> EPDM | D10: 1 | F10: 1 | H10: =IF(C10="NBR",L10,IF(C10="EPDM",L10,IF(C10="VITON",M10))) -> 805 | I10: =H10*F10*D10 -> 805 | K10: =I10+J10 -> 805 | L10: 805 | M10: 9500 | N10: 6000 | O10: N/A | P10: N/A
A11: 4 | B11: STEM(ONE STEM) | C11: =COVER!B17 -> A564T630 | D11: 1 | F11: 0.26 | H11: =COVER!C17 -> 10000 | I11: =D11*F11*H11 -> 2600 | K11: =I11+J11 -> 2600 | L11: Ø14X208L | M11: 3000 | N11: 1000 | Q11: 0.26 | T11: 0.3
A12: 5 | B12: PACKING+GLAND | C12: =COVER!B19 -> NBR | D12: 1 | F12: 1 | H12: =IF(C12="NBR",L12+N12,IF(C12="EPDM",L12+N12,IF(C12="VITON",M12+N12))) -> 290 | I12: =D12*F12*H12 -> 290 | K12: =I12+J12 -> 290 | L12: 120 | M12: 970 | N12: 170 | V12: =M9/L9 -> 1.0736196
A13: 6 | B13: BUSH | D13: 0 | L13: N/A
A14: 7 | B14: DISC BOLT(PIN) | C14: =C11 -> A564T630 | D14: 1 | F14: 1 | H14: =L14 -> 1400 | I14: =D14*F14*H14 -> 1400 | K14: =I14+J14 -> 1400 | L14: 1400
A15: 8 | B15: END COVER (WITH O-RING) | C15: =COVER!B22 -> BODY MATERIAL | D15: 0 | L15: N/A
A16: 9 | B16: END COVER BOLT | C16: =COVER!B23 -> B8M | D16: 0 | L16: N/A
A17: 10 | B17: COLLAR | C17: =COVER!B24 -> ALBC2 | D17: 0 | L17: N/A
A18: 11 | B18: TOP RETANIER | C18: A240T304 | D18: 1 | H18: =M18 -> 1300 | I18: =H18*D18 -> 1300 | K18: =I18+J18 -> 1300 | L18: Ø54X1.5T | M18: 1300 | Q18: 완가공
A19: 12 | B19: TOP RETANIER BOLT | C19: =COVER!B26 -> B8M | D19: 2 | H19: =IF(C19="B8",M19,IF(C19="B8M",N19)) -> 200 | I19: =H19*D19 -> 400 | K19: =I19+J19 -> 400 | M19: 200 | N19: 200 | Q19: WRENCH BOLT
A20: 13 | B20: GEAR BOX BOLT | C20: =COVER!B27 -> B8M | D20: 4 | H20: =IF(C20="B8",M20,IF(C20="B8M",N20,IF(C20="B7(다크로)",O20))) -> 400 | I20: =H20*D20 -> 1600 | K20: =I20+J20 -> 1600 | L20: M8X30L | M20: 350 | N20: 400 | O20: 300 | Q20: HEX BOLT
A21: 14 | B21: LEVER | C21: =COVER!C35 -> SUS304 | D21: 1 | H21: =IF(C21="SS400",L21,IF(C21="SUS304",M21)) -> 16000 | I21: =H21*D21 -> 16000 | K21: =I21+J21 -> 16000 | L21: 5400 | M21: 16000
A22: 15 | B22: GEAR BOX | C22: 10 BAR | D22: 1 | I22: =IF(C22="10 BAR",M22,IF(C22="16 BAR",N22,IF(C22="20 BAR",O22))) -> 98000 | K22: =I22+J22 -> 98000 | M22: 98000 | N22: 98000 | O22: 98000
A23: 16 | B23: PAINT | C23: =COVER!B32 -> 기존 단가 | D23: 1 | H23: =IF(COVER!B9="APPLICATION",0,IF(COVER!B32="기존 단가",L23,IF(COVER!B32="외주 2COATING",M23,IF(COVER!B32="외주 3COATING",N23)))) -> 5000 | I23: =H23 -> 5000 | L23: 5000 | M23: =IF(H6>0,F6*520,IF(H7>0,F7*520,IF(H8>0,F8*520))) -> 2860 | N23: =IF(H6>0,F6*620,IF(H7>0,F7*620,IF(H8>0,F8*620))) -> 3410
A24: 17 | B24: 조립.검사 | D24: 1 | H24: =IF(COVER!B9="APPLICATION",0,IF(COVER!B9="N/A",L24)) -> 5000 | I24: =H24 -> 5000 | L24: 5000
A25: 18 | B25: 밸브합산(BEAR) | K25: =SUM(K6:K20)+SUM(K23:K24) -> 31245 | L25: "A"
A26: 18 | B26: 밸브합산(LEVER) | K26: =SUM(K6:K21)+SUM(K23:K24) -> 47245 | L26: "A"
A27: 18 | B27: 밸브합산(GEAR) | K27: =SUM(K6:K20)+SUM(K22:K24) -> 129245 | L27: "A"
A28: 19 | B28: STEM CR PLATING | C28: =COVER!B28 -> REQUIRED | D28: 0 | H28: =IF(C28="REQUIRED",L28,IF(C28="N/A",0)) -> 2800 | I28: =H28 -> 2800 | L28: 2800
A29: 20 | B29: RUBBER LINING | D29: 0
A30: 21 | B30: 포장비용 | C30: =COVER!B35 -> MOTOR | D30: 1 | H30: =IF(COVER!B9="APPLICATION",0,IF(COVER!B35="BARE",M30,(IF(COVER!B35="LEVER",M30,IF(COVER!B35="GEAR",N30,IF(COVER!B35="MOTOR",O30)))))) -> 40000 | I30: =H30 -> 40000 | L30: 9500 | M30: 4500 | N30: 4500 | O30: 40000
A31: 22
A32: 23 | B32: 밸브외 사급품 비용 연산 | K32: =SUM(K28:K31) -> 0 | L32: "B"
A33: 24 | B33: VALVE 원가 - BEAR | K33: =K25+K32 -> 31245 | L33: (A+B)
A34: 24 | B34: VALVE 원가 - LEVER | K34: =K26+K32 -> 47245 | L34: (A+B)
A35: 24 | B35: VALVE 원가 - GEAR | K35: =K27+K32 -> 129245 | L35: (A+B)
A36: 25 | B36: FACTOR 금액 - BEAR | I36: FACTOR | J36: 0.7 | K36: =(K25+K32)/J36 -> 44635.714 | L36: (A+B)XFACTOR
A37: 25 | B37: FACTOR 금액 - LEVER | I37: FACTOR | J37: 0.7 | K37: =(K26+K32)/J37 -> 67492.857 | L37: (A+B)XFACTOR
A38: 25 | B38: FACTOR 금액 - GEAR | I38: FACTOR | J38: 0.7 | K38: =(K27+K32)/J38 -> 184635.71 | L38: (A+B)XFACTOR

Sheet 65A
A1: CONCENTRIC BFV 원가 分析表
A3: SIZE | B3: 65A | C3: RATING | D3: #150 | F3: FLANGE DRILLING | I3: ASME B16.5 | J3: FACE TO FACE | K3: ISO575 SER'20(46MM)
J4: O.D(MM) | K4: 180 | L4: 외주가공비 / 단가표(EPC)
A5: NO. | B5: 부품명 | C5: 재질 | D5: 수량 | E5: 규격 | F5: 단중 | G5: 업체 | H5: 단가 | I5: 소계 | J5: 가공비 | K5: 합계 | L5: FC/FCD | M5: SC/WCB (ALBC) | N5: SUS | O5: A890 4A | P5: A890 5A | Q5: DISC 중량(일반) | R5: DISC 중량(고압) | T5: 이전 단가 Table 중량
A6: 1 | B6: BODY(WAFER) | C6: =COVER!B13 -> 0 | D6: 1 | F6: 5 | H6: =COVER!C13 -> 0 | I6: =D6*F6*H6 -> 0 | K6: =I6+J6 -> 0 | L6: 10000 | M6: 15000 | N6: 30000 | T6: 4
A7: 1 | B7: BODY(LUG) | C7: =COVER!B14 -> A536 Gr65-45-12 | D7: 1 | F7: 6.5 | H7: =COVER!C14 -> 3500 | I7: =D7*F7*H7 -> 22750 | K7: =I7+J7 -> 22750 | L7: 14000 | M7: 21000 | T7: 5.5
A8: 1 | B8: BODY(FLANGE) | C8: =COVER!B15 -> 0 | D8: 1 | F8: 10 | H8: =COVER!C15 -> 0 | I8: =D8*F8*H8 -> 0 | K8: =I8+J8 -> 0 | L8: 18800 | M8: 28200 | T8: 10
A9: 2 | B9: DISC | C9: =COVER!B16 -> A351 CF8M | D9: 1 | F9: =IF(COVER!B34="10 BAR",Q9,IF(COVER!B34="16 BAR",R9,IF(COVER!B34="20 BAR",R9))) -> 0.4 | H9: =COVER!C16 -> 12000 | I9: =D9*F9*H9 -> 4800 | K9: =I9+J9 -> 4800 | L9: 3330 | M9: 3500 | N9: 3500 | O9: 9000 | P9: 12300 | Q9: 0.4 | R9: 0.4 | T9: 0.3 | V9: =P9/M9 -> 3.5142857
A10: 3 | B10: SEAT | C10: =COVER!B18 -> EPDM | D10: 1 | F10: 1 | H10: =IF(C10="NBR",L10,IF(C10="EPDM",L10,IF(C10="VITON",M10))) -> 1150 | I10: =H10*F10*D10 -> 1150 | K10: =I10+J10 -> 1150 | L10: 1150 | M10: 11000 | N10: 9000 | O10: N/A | P10: N/A
A11: 4 | B11: STEM(ONE STEM) | C11: =COVER!B17 -> A564T630 | D11: 1 | F11: 0.27 | H11: =COVER!C17 -> 10000 | I11: =D11*F11*H11 -> 2700 | K11: =I11+J11 -> 2700 | L11: Ø14X221L | M11: 3000 | N11: 1000 | Q11: 0.27 | T11: 0.3
A12: 5 | B12: PACKING+GLAND | C12: =COVER!B19 -> NBR | D12: 1 | F12: 1 | H12: =IF(C12="NBR",L12+N12,IF(C12="EPDM",L12+N12,IF(C12="VITON",M12+N12))) -> 290 | I12: =D12*F12*H12 -> 290 | K12: =I12+J12 -> 290 | L12: 120 | M12: 970 | N12: 170 | V12: =M9/L9 -> 1.0510511
A13: 6 | B13: BUSH | D13: 0 | L13: N/A
A14: 7 | B14: DISC BOLT(PIN) | C14: =C11 -> A564T630 | D14: 1 | F14: 1 | H14: =L14 -> 1400 | I14: =D14*F14*H14 -> 1400 | K14: =I14+J14 -> 1400 | L14: 1400
A15: 8 | B15: END COVER (WITH O-RING) | C15: =COVER!B22 -> BODY MATERIAL | D15: 0 | L15: N/A
A16: 9 | B16: END COVER BOLT | C16: =COVER!B23 -> B8M | D16: 0 | L16: N/A
A17: 10 | B17: COLLAR | C17: =COVER!B24 -> ALBC2 | D17: 0 | L17: N/A
A18: 11 | B18: TOP RETANIER | C18: A240T304 | D18: 1 | H18: =M18 -> 1300 | I18: =H18*D18 -> 1300 | K18: =I18+J18 -> 1300 | L18: Ø89X10T | M18: 1300 | Q18: 완가공 | S18: 400A 2500원 | U18: 450A 2700원
A19: 12 | B19: TOP RETANIER BOLT | C19: =COVER!B26 -> B8M | D19: 2 | H19: =IF(C19="B8",M19,IF(C19="B8M",N19)) -> 200 | I19: =H19*D19 -> 400 | K19: =I19+J19 -> 400 | M19: 200 | N19: 200 | Q19: WRENCH BOLT
A20: 13 | B20: GEAR BOX BOLT | C20: =COVER!B27 -> B8M | D20: 4 | H20: =IF(C20="B8",M20,IF(C20="B8M",N20,IF(C20="B7(다크로)",O20))) -> 400 | I20: =H20*D20 -> 1600 | K20: =I20+J20 -> 1600 | L20: M8X30L | M20: 350 | N20: 400 | O20: 300 | Q20: HEX BOLT
A21: 14 | B21: LEVER | C21: =COVER!C35 -> SUS304 | D21: 1 | H21: =IF(C21="SS400",L21,IF(C21="SUS304",M21)) -> 16000 | I21: =H21*D21 -> 16000 | K21: =I21+J21 -> 16000 | L21: 5400 | M21: 16000
A22: 15 | B22: GEAR BOX | C22: =COVER!B34 -> 10 BAR | D22: 1 | I22: =IF(C22="10 BAR",M22,IF(C22="16 BAR",N22,IF(C22="20 BAR",O22))) -> 98000 | K22: =I22+J22 -> 98000 | M22: 98000 | N22: 98000 | O22: 98000
A23: 16 | B23: PAINT | C23: =COVER!B32 -> 기존 단가 | D23: 1 | H23: =IF(COVER!B9="APPLICATION",0,IF(COVER!B32="기존 단가",L23,IF(COVER!B32="외주 2COATING",M23,IF(COVER!B32="외주 3COATING",N23)))) -> 5000 | I23: =H23 -> 5000 | L23: 5000 | M23: =IF(H6>0,F6*520,IF(H7>0,F7*520,IF(H8>0,F8*520))) -> 3380 | N23: =IF(H6>0,F6*620,IF(H7>0,F7*620,IF(H8>0,F8*620))) -> 4030 | V23: 338 | W23: 260 | X23: =V23/W23 -> 1.3
A24: 17 | B24: 조립.검사 | D24: 1 | H24: =IF(COVER!B9="APPLICATION",0,IF(COVER!B9="N/A",L24)) -> 5000 | I24: =H24 -> 5000 | L24: 5000 | V24: 429 | W24: 330 | X24: =V24/W24 -> 1.3
A25: 18 | B25: 밸브합산(BEAR) | K25: =SUM(K6:K20)+SUM(K23:K24) -> 36390 | L25: "A" | V25: 507 | W25: 390 | X25: =V25/W25 -> 1.3
A26: 18 | B26: 밸브합산(LEVER) | K26: =SUM(K6:K21)+SUM(K23:K24) -> 52390 | L26: "A" | V26: 676 | W26: 520 | X26: =V26/W26 -> 1.3
A27: 18 | B27: 밸브합산(GEAR) | K27: =SUM(K6:K20)+SUM(K22:K24) -> 134390 | L27: "A" | V27: 845 | W27: 650 | X27: =V27/W27 -> 1.3
A28: 19 | B28: STEM CR PLATING | C28: =COVER!B28 -> REQUIRED | D28: 0 | H28: =IF(C28="REQUIRED",L28,IF(C28="N/A",0)) -> 2900 | I28: =H28 -> 2900 | L28: 2900
A29: 20 | B29: RUBBER LINING | D29: 0
A30: 21 | B30: 포장비용 | C30: =COVER!B35 -> MOTOR | D30: 1 | H30: =IF(COVER!B9="APPLICATION",0,IF(COVER!B35="BARE",M30,(IF(COVER!B35="LEVER",M30,IF(COVER!B35="GEAR",N30,IF(COVER!B35="MOTOR",O30)))))) -> 40000 | I30: =H30 -> 40000 | L30: 9500 | M30: 4500 | N30: 4500 | O30: 40000
A31: 22
A32: 23 | B32: 밸브외 사급품 비용 연산 | K32: =SUM(K28:K31) -> 0 | L32: "B"
A33: 24 | B33: VALVE 원가 - BEAR | K33: =K25+K32 -> 36390 | L33: (A+B)
A34: 24 | B34: VALVE 원가 - LEVER | K34: =K26+K32 -> 52390 | L34: (A+B)
A35: 24 | B35: VALVE 원가 - GEAR | K35: =K27+K32 -> 134390 | L35: (A+B)
A36: 25 | B36: FACTOR 금액 - BEAR | I36: FACTOR | J36: 0.7 | K36: =(K25+K32)/J36 -> 51985.714 | L36: (A+B)XFACTOR
A37: 25 | B37: FACTOR 금액 - LEVER | I37: FACTOR | J37: 0.7 | K37: =(K26+K32)/J37 -> 74842.857 | L37: (A+B)XFACTOR
A38: 25 | B38: FACTOR 금액 - GEAR | I38: FACTOR | J38: 0.7 | K38: =(K27+K32)/J38 -> 191985.71 | L38: (A+B)XFACTOR

Sheet 80A
A1: CONCENTRIC BFV 원가 分析表
A3: SIZE | B3: 80A | C3: RATING | D3: #150 | F3: FLANGE DRILLING | I3: ASME B16.5 | J3: FACE TO FACE | K3: ISO575 SER'20(46MM)
J4: O.D(MM) | K4: 190 | L4: 외주가공비 / 단가표(EPC)
A5: NO. | B5: 부품명 | C5: 재질 | D5: 수량 | E5: 규격 | F5: 단중 | G5: 업체 | H5: 단가 | I5: 소계 | J5: 가공비 | K5: 합계 | L5: FC/FCD | M5: SC/WCB (ALBC) | N5: SUS | O5: A890 4A | P5: A890 5A | Q5: DISC 중량(일반) | R5: DISC 중량(고압) | T5: 이전 단가 Table 중량
A6: 1 | B6: BODY(WAFER) | C6: =COVER!B13 -> 0 | D6: 1 | F6: 6 | H6: =COVER!C13 -> 0 | I6: =D6*F6*H6 -> 0 | K6: =I6+J6 -> 0 | L6: 13000 | M6: 19500 | N6: 39000 | T6: 6
A7: 1 | B7: BODY(LUG) | C7: =COVER!B14 -> A536 Gr65-45-12 | D7: 1 | F7: 6 | H7: =COVER!C14 -> 3500 | I7: =D7*F7*H7 -> 21000 | K7: =I7+J7 -> 21000 | L7: 21000 | M7: 31500 | T7: 7.8
A8: 1 | B8: BODY(FLANGE) | C8: =COVER!B15 -> 0 | D8: 1 | F8: 13 | H8: =COVER!C15 -> 0 | I8: =D8*F8*H8 -> 0 | K8: =I8+J8 -> 0 | L8: 23500 | M8: 35250 | T8: 11
A9: 2 | B9: DISC | C9: =COVER!B16 -> A351 CF8M | D9: 1 | F9: =IF(COVER!B34="10 BAR",Q9,IF(COVER!B34="16 BAR",R9,IF(COVER!B34="20 BAR",R9))) -> 0.5 | H9: =COVER!C16 -> 12000 | I9: =D9*F9*H9 -> 6000 | K9: =I9+J9 -> 6000 | L9: 4390 | M9: 4600 | N9: 4600 | O9: 9000 | P9: 13000 | Q9: 0.5 | R9: 0.5 | T9: 0.5 | V9: =P9/M9 -> 2.826087
A10: 3 | B10: SEAT | C10: =COVER!B18 -> EPDM | D10: 1 | F10: 1 | H10: =IF(C10="NBR",L10,IF(C10="EPDM",L10,IF(C10="VITON",M10))) -> 1380 | I10: =H10*F10*D10 -> 1380 | K10: =I10+J10 -> 1380 | L10: 1380 | M10: 14000 | N10: 12000 | O10: N/A | P10: 4000
A11: 4 | B11: STEM(ONE STEM) | C11: =COVER!B17 -> A564T630 | D11: 1 | F11: 0.4 | H11: =COVER!C17 -> 10000 | I11: =D11*F11*H11 -> 4000 | K11: =I11+J11 -> 4000 | L11: Ø16X248L | M11: 3000 | N11: 1100 | Q11: 0.4 | T11: 0.4
A12: 5 | B12: PACKING+GLAND | C12: =COVER!B19 -> NBR | D12: 1 | F12: 1 | H12: =IF(C12="NBR",L12+N12,IF(C12="EPDM",L12+N12,IF(C12="VITON",M12+N12))) -> 290 | I12: =D12*F12*H12 -> 290 | K12: =I12+J12 -> 290 | L12: 120 | M12: 1020 | N12: 170 | V12: =M9/L9 -> 1.047836
A13: 6 | B13: BUSH | D13: 0 | L13: N/A
A14: 7 | B14: DISC BOLT(PIN) | C14: =C11 -> A564T630 | D14: 2 | F14: 1 | H14: =L14 -> 1700 | I14: =D14*F14*H14 -> 3400 | K14: =I14+J14 -> 3400 | L14: 1700
A15: 8 | B15: END COVER (WITH O-RING) | C15: =COVER!B22 -> BODY MATERIAL | D15: 0 | L15: N/A
A16: 9 | B16: END COVER BOLT | C16: =COVER!B23 -> B8M | D16: 0 | L16: N/A
A17: 10 | B17: COLLAR | C17: =COVER!B24 -> ALBC2 | D17: 0 | L17: N/A
A18: 11 | B18: TOP RETANIER | C18: A240T304 | D18: 1 | H18: =M18 -> 1300 | I18: =H18*D18 -> 1300 | K18: =I18+J18 -> 1300 | L18: Ø89X10T | M18: 1300 | Q18: 완가공 | S18: 65970 | T18: =S18/0.7 -> 94242.857 | U18: 450A 2700원
A19: 12 | B19: TOP RETANIER BOLT | C19: =COVER!B26 -> B8M | D19: 2 | H19: =IF(C19="B8",M19,IF(C19="B8M",N19)) -> 200 | I19: =H19*D19 -> 400 | K19: =I19+J19 -> 400 | M19: 200 | N19: 200 | Q19: WRENCH BOLT
A20: 13 | B20: GEAR BOX BOLT | C20: =COVER!B27 -> B8M | D20: 4 | H20: =IF(C20="B8",M20,IF(C20="B8M",N20,IF(C20="B7(다크로)",O20))) -> 400 | I20: =H20*D20 -> 1600 | K20: =I20+J20 -> 1600 | L20: M8X30L | M20: 350 | N20: 400 | O20: 300 | Q20: HEX BOLT
A21: 14 | B21: LEVER | C21: =COVER!C35 -> SUS304 | D21: 1 | H21: =IF(C21="SS400",L21,IF(C21="SUS304",M21)) -> 16000 | I21: =H21*D21 -> 16000 | K21: =I21+J21 -> 16000 | L21: 5400 | M21: 16000
A22: 15 | B22: GEAR BOX | C22: =COVER!B34 -> 10 BAR | D22: 1 | I22: =IF(C22="10 BAR",M22,IF(C22="16 BAR",N22,IF(C22="20 BAR",O22))) -> 98000 | K22: =I22+J22 -> 98000 | M22: 98000 | N22: 98000 | O22: 98000
A23: 16 | B23: PAINT | C23: =COVER!B32 -> 기존 단가 | D23: 1 | H23: =IF(COVER!B9="APPLICATION",0,IF(COVER!B32="기존 단가",L23,IF(COVER!B32="외주 2COATING",M23,IF(COVER!B32="외주 3COATING",N23)))) -> 5000 | I23: =H23 -> 5000 | L23: 5000 | M23: =IF(H6>0,F6*520,IF(H7>0,F7*520,IF(H8>0,F8*520))) -> 3120 | N23: =IF(H6>0,F6*620,IF(H7>0,F7*620,IF(H8>0,F8*620))) -> 3720
A24: 17 | B24: 조립.검사 | D24: 1 | H24: =IF(COVER!B9="APPLICATION",0,IF(COVER!B9="N/A",L24)) -> 5000 | I24: =H24 -> 5000 | L24: 5000
A25: 18 | B25: 밸브합산(BEAR) | K25: =SUM(K6:K20)+SUM(K23:K24) -> 39370 | L25: "A"
A26: 18 | B26: 밸브합산(LEVER) | K26: =SUM(K6:K21)+SUM(K23:K24) -> 55370 | L26: "A"
A27: 18 | B27: 밸브합산(GEAR) | K27: =SUM(K6:K20)+SUM(K22:K24) -> 137370 | L27: "A"
A28: 19 | B28: STEM CR PLATING | C28: =COVER!B28 -> REQUIRED | D28: 0 | H28: =IF(C28="REQUIRED",L28,IF(C28="N/A",0)) -> 3800 | I28: =H28 -> 3800 | L28: 3800
A29: 20 | B29: RUBBER LINING | D29: 0
A30: 21 | B30: 포장비용 | C30: =COVER!B35 -> MOTOR | D30: 1 | H30: =IF(COVER!B9="APPLICATION",0,IF(COVER!B35="BARE",M30,(IF(COVER!B35="LEVER",M30,IF(COVER!B35="GEAR",N30,IF(COVER!B35="MOTOR",O30)))))) -> 45000 | I30: =H30 -> 45000 | L30: 10000 | M30: 4500 | N30: 4500 | O30: 45000
A31: 22
A32: 23 | B32: 밸브외 사급품 비용 연산 | K32: =SUM(K28:K31) -> 0 | L32: "B"
A33: 24 | B33: VALVE 원가 - BEAR | K33: =K25+K32 -> 39370 | L33: (A+B)
A34: 24 | B34: VALVE 원가 - LEVER | K34: =K26+K32 -> 55370 | L34: (A+B)
A35: 24 | B35: VALVE 원가 - GEAR | K35: =K27+K32 -> 137370 | L35: (A+B)
A36: 25 | B36: FACTOR 금액 - BEAR | I36: FACTOR | J36: 0.7 | K36: =(K25+K32)/J36 -> 56242.857 | L36: (A+B)XFACTOR
A37: 25 | B37: FACTOR 금액 - LEVER | I37: FACTOR | J37: 0.7 | K37: =(K26+K32)/J37 -> 79100 | L37: (A+B)XFACTOR
A38: 25 | B38: FACTOR 금액 - GEAR | I38: FACTOR | J38: 0.7 | K38: =(K27+K32)/J38 -> 196242.86 | L38: (A+B)XFACTOR

Sheet 100A
A1: CONCENTRIC BFV 원가 分析表
A3: SIZE | B3: 100A | C3: RATING | D3: #150 | F3: FLANGE DRILLING | I3: ASME B16.5 | J3: FACE TO FACE | K3: ISO575 SER'20(46MM)
J4: O.D(MM) | K4: 190 | L4: 외주가공비 / 단가표(EPC)
A5: NO. | B5: 부품명 | C5: 재질 | D5: 수량 | E5: 규격 | F5: 단중 | G5: 업체 | H5: 단가 | I5: 소계 | J5: 가공비 | K5: 합계 | L5: FC/FCD | M5: SC/WCB (ALBC) | N5: SUS | O5: A890 4A | P5: A890 5A | Q5: DISC 중량(일반) | R5: DISC 중량(고압) | T5: 이전 단가 Table 중량
A6: 1 | B6: BODY(WAFER) | C6: =COVER!B13 -> 0 | D6: 1 | F6: 7.5 | H6: =COVER!C13 -> 0 | I6: =D6*F6*H6 -> 0 | K6: =I6+J6 -> 0 | L6: 13000 | M6: 19500 | N6: 39000 | T6: 6
A7: 1 | B7: BODY(LUG) | C7: =COVER!B14 -> A536 Gr65-45-12 | D7: 1 | F7: 13 | H7: =COVER!C14 -> 3500 | I7: =D7*F7*H7 -> 45500 | K7: =I7+J7 -> 45500 | L7: 21000 | M7: 31500 | T7: 7.8
A8: 1 | B8: BODY(FLANGE) | C8: =COVER!B15 -> 0 | D8: 1 | F8: 16 | H8: =COVER!C15 -> 0 | I8: =D8*F8*H8 -> 0 | K8: =I8+J8 -> 0 | L8: 23500 | M8: 35250 | T8: 11
A9: 2 | B9: DISC | C9: =COVER!B16 -> A351 CF8M | D9: 1 | F9: 1 | H9: =COVER!C16 -> 12000 | I9: =D9*F9*H9 -> 12000 | K9: =I9+J9 -> 12000 | L9: 4390 | M9: 4600 | N9: 4600 | O9: 9000 | P9: 13000 | Q9: 0.5 | R9: 0.5 | T9: 0.5 | V9: =P9/M9 -> 2.826087
A10: 3 | B10: SEAT | C10: =COVER!B18 -> EPDM | D10: 1 | F10: 1 | H10: =IF(C10="NBR",L10,IF(C10="EPDM",L10,IF(C10="VITON",M10))) -> 1380 | I10: =H10*F10*D10 -> 1380 | K10: =I10+J10 -> 1380 | L10: 1380 | M10: 14000 | N10: 12000 | O10: N/A | P10: 4000
A11: 4 | B11: STEM(ONE STEM) | C11: =COVER!B17 -> A564T630 | D11: 1 | F11: 0.45 | H11: =COVER!C17 -> 10000 | I11: =D11*F11*H11 -> 4500 | K11: =I11+J11 -> 4500 | L11: Ø16X248L | M11: 3000 | N11: 1100 | Q11: 0.4 | T11: 0.4
A12: 5 | B12: PACKING+GLAND | C12: =COVER!B19 -> NBR | D12: 1 | F12: 1 | H12: =IF(C12="NBR",L12+N12,IF(C12="EPDM",L12+N12,IF(C12="VITON",M12+N12))) -> 290 | I12: =D12*F12*H12 -> 290 | K12: =I12+J12 -> 290 | L12: 120 | M12: 1020 | N12: 170 | V12: =M9/L9 -> 1.047836
A13: 6 | B13: BUSH | D13: 0 | L13: N/A
A14: 7 | B14: DISC BOLT(PIN) | C14: =C11 -> A564T630 | D14: 2 | F14: 1 | H14: =L14 -> 1700 | I14: =D14*F14*H14 -> 3400 | K14: =I14+J14 -> 3400 | L14: 1700
A15: 8 | B15: END COVER (WITH O-RING) | C15: =COVER!B22 -> BODY MATERIAL | D15: 0 | L15: N/A
A16: 9 | B16: END COVER BOLT | C16: =COVER!B23 -> B8M | D16: 0 | L16: N/A
A17: 10 | B17: COLLAR | C17: =COVER!B24 -> ALBC2 | D17: 0 | L17: N/A
A18: 11 | B18: TOP RETANIER | C18: A240T304 | D18: 1 | H18: =M18 -> 1300 | I18: =H18*D18 -> 1300 | K18: =I18+J18 -> 1300 | L18: Ø89X10T | M18: 1300 | Q18: 완가공 | S18: 65970 | T18: =S18/0.7 -> 94242.857 | U18: 450A 2700원
A19: 12 | B19: TOP RETANIER BOLT | C19: =COVER!B26 -> B8M | D19: 2 | H19: =IF(C19="B8",M19,IF(C19="B8M",N19)) -> 200 | I19: =H19*D19 -> 400 | K19: =I19+J19 -> 400 | M19: 200 | N19: 200 | Q19: WRENCH BOLT
A20: 13 | B20: GEAR BOX BOLT | C20: =COVER!B27 -> B8M | D20: 4 | H20: =IF(C20="B8",M20,IF(C20="B8M",N20,IF(C20="B7(다크로)",O20))) -> 400 | I20: =H20*D20 -> 1600 | K20: =I20+J20 -> 1600 | L20: M8X30L | M20: 350 | N20: 400 | O20: 300 | Q20: HEX BOLT
A21: 14 | B21: LEVER | C21: =COVER!C35 -> SUS304 | D21: 1 | H21: =IF(C21="SS400",L21,IF(C21="SUS304",M21)) -> 16000 | I21: =H21*D21 -> 16000 | K21: =I21+J21 -> 16000 | L21: 5400 | M21: 16000
A22: 15 | B22: GEAR BOX | C22: =COVER!B34 -> 10 BAR | D22: 1 | I22: =IF(C22="10 BAR",M22,IF(C22="16 BAR",N22,IF(C22="20 BAR",O22))) -> 98000 | K22: =I22+J22 -> 98000 | M22: 98000 | N22: 98000 | O22: 98000
A23: 16 | B23: PAINT | C23: =COVER!B32 -> 기존 단가 | D23: 1 | H23: =IF(COVER!B9="APPLICATION",0,IF(COVER!B32="기존 단가",L23,IF(COVER!B32="외주 2COATING",M23,IF(COVER!B32="외주 3COATING",N23)))) -> 5000 | I23: =H23 -> 5000 | L23: 5000 | M23: =IF(H6>0,F6*520,IF(H7>0,F7*520,IF(H8>0,F8*520))) -> 6760 | N23: =IF(H6>0,F6*620,IF(H7>0,F7*620,IF(H8>0,F8*620))) -> 8060
A24: 17 | B24: 조립.검사 | D24: 1 | H24: =IF(COVER!B9="APPLICATION",0,IF(COVER!B9="N/A",L24)) -> 5000 | I24: =H24 -> 5000 | L24: 5000
A25: 18 | B25: 밸브합산(BEAR) | K25: =SUM(K6:K20)+SUM(K23:K24) -> 70370 | L25: "A"
A26: 18 | B26: 밸브합산(LEVER) | K26: =SUM(K6:K21)+SUM(K23:K24) -> 86370 | L26: "A"
A27: 18 | B27: 밸브합산(GEAR) | K27: =SUM(K6:K20)+SUM(K22:K24) -> 168370 | L27: "A"
A28: 19 | B28: STEM CR PLATING | C28: =COVER!B28 -> REQUIRED | D28: 0 | H28: =IF(C28="REQUIRED",L28,IF(C28="N/A",0)) -> 3800 | I28: =H28 -> 3800 | L28: 3800
A29: 20 | B29: RUBBER LINING | D29: 0
A30: 21 | B30: 포장비용 | C30: =COVER!B35 -> MOTOR | D30: 1 | H30: =IF(COVER!B9="APPLICATION",0,IF(COVER!B35="BARE",M30,(IF(COVER!B35="LEVER",M30,IF(COVER!B35="GEAR",N30,IF(COVER!B35="MOTOR",O30)))))) -> 45000 | I30: =H30 -> 45000 | L30: 10000 | M30: 4500 | N30: 4500 | O30: 45000
A31: 22
A32: 23 | B32: 밸브외 사급품 비용 연산 | K32: =SUM(K28:K31) -> 0 | L32: "B"
A33: 24 | B33: VALVE 원가 - BEAR | K33: =K25+K32 -> 70370 | L33: (A+B)
A34: 24 | B34: VALVE 원가 - LEVER | K34: =K26+K32 -> 86370 | L34: (A+B)
A35: 24 | B35: VALVE 원가 - GEAR | K35: =K27+K32 -> 168370 | L35: (A+B)
A36: 25 | B36: FACTOR 금액 - BEAR | I36: FACTOR | J36: 0.7 | K36: =(K25+K32)/J36 -> 100528.57 | L36: (A+B)XFACTOR
A37: 25 | B37: FACTOR 금액 - LEVER | I37: FACTOR | J37: 0.7 | K37: =(K26+K32)/J37 -> 123385.71 | L37: (A+B)XFACTOR
A38: 25 | B38: FACTOR 금액 - GEAR | I38: FACTOR | J38: 0.7 | K38: =(K27+K32)/J38 -> 240528.57 | L38: (A+B)XFACTOR

Sheet 125A
A1: CONCENTRIC BFV 원가 分析表
A3: SIZE | B3: 125A | C3: RATING | D3: #150 | F3: FLANGE DRILLING | I3: ASME B16.5 | J3: FACE TO FACE | K3: ISO575 SER'20(56MM)
J4: O.D(MM) | K4: 255 | L4: 외주가공비 / 단가표(EPC)
A5: NO. | B5: 부품명 | C5: 재질 | D5: 수량 | E5: 규격 | F5: 단중 | G5: 업체 | H5: 단가 | I5: 소계 | J5: 가공비 | K5: 합계 | L5: FC/FCD | M5: SC/WCB (ALBC) | N5: SUS | O5: A890 4A | P5: A890 5A | Q5: DISC 중량(일반) | R5: DISC 중량(고압) | T5: 이전 단가 Table 중량
A6: 1 | B6: BODY(WAFER) | C6: =COVER!B13 -> 0 | D6: 1 | F6: 9 | H6: =COVER!C13 -> 0 | I6: =D6*F6*H6 -> 0 | K6: =I6+J6 -> 0 | L6: 16000 | M6: 24000 | N6: 48000 | T6: 8
A7: 1 | B7: BODY(LUG) | C7: =COVER!B14 -> A536 Gr65-45-12 | D7: 1 | F7: 13 | H7: =COVER!C14 -> 3500 | I7: =D7*F7*H7 -> 45500 | K7: =I7+J7 -> 45500 | L7: 25000 | M7: 37500 | T7: 11
A8: 1 | B8: BODY(FLANGE) | C8: =COVER!B15 -> 0 | D8: 1 | F8: 22 | H8: =COVER!C15 -> 0 | I8: =D8*F8*H8 -> 0 | K8: =I8+J8 -> 0 | L8: 28100 | M8: 42150 | T8: 20.5
A9: 2 | B9: DISC | C9: =COVER!B16 -> A351 CF8M | D9: 1 | F9: =IF(COVER!B34="10 BAR",Q9,IF(COVER!B34="16 BAR",R9,IF(COVER!B34="20 BAR",R9))) -> 1.3 | H9: =COVER!C16 -> 12000 | I9: =D9*F9*H9 -> 15600 | K9: =I9+J9 -> 15600 | L9: 5450 | M9: 5500 | N9: 6000 | O9: =P9*0.8 -> 13600 | P9: 17000 | Q9: 1.3 | R9: 1.3 | T9: 1.3
A10: 3 | B10: SEAT | C10: =COVER!B18 -> EPDM | D10: 1 | F10: 1 | H10: =IF(C10="NBR",L10,IF(C10="EPDM",L10,IF(C10="VITON",M10))) -> 2760 | I10: =H10*F10*D10 -> 2760 | K10: =I10+J10 -> 2760 | L10: 2760 | M10: 28000 | N10: 20000 | O10: N/A | P10: N/A
A11: 4 | B11: STEM(ONE STEM) | C11: =COVER!B17 -> A564T630 | D11: 1 | F11: 0.7 | H11: =COVER!C17 -> 10000 | I11: =D11*F11*H11 -> 7000 | K11: =I11+J11 -> 7000 | L11: Ø19X308L | M11: 3000 | N11: 1350 | Q11: 0.7 | T11: 0.6
A12: 5 | B12: PACKING+GLAND | C12: =COVER!B19 -> NBR | D12: 1 | F12: 1 | H12: =IF(C12="NBR",L12+N12,IF(C12="EPDM",L12+N12,IF(C12="VITON",M12+N12))) -> 310 | I12: =D12*F12*H12 -> 310 | K12: =I12+J12 -> 310 | L12: 130 | M12: 1090 | N12: 180 | V12: =M9/L9 -> 1.0091743
A13: 6 | B13: BUSH | D13: 0 | L13: N/A
A14: 7 | B14: DISC BOLT(PIN) | C14: =C11 -> A564T630 | D14: 2 | F14: 1 | H14: =L14 -> 1900 | I14: =D14*F14*H14 -> 3800 | K14: =I14+J14 -> 3800 | L14: 1900
A15: 8 | B15: END COVER (WITH O-RING) | C15: =COVER!B22 -> BODY MATERIAL | D15: 0 | L15: N/A
A16: 9 | B16: END COVER BOLT | C16: =COVER!B23 -> B8M | D16: 0 | L16: N/A
A17: 10 | B17: COLLAR | C17: =COVER!B24 -> ALBC2 | D17: 0 | L17: N/A
A18: 11 | B18: TOP RETANIER | C18: A240T304 | D18: 1 | H18: =M18 -> 1300 | I18: =H18*D18 -> 1300 | K18: =I18+J18 -> 1300 | L18: Ø89X10T | M18: 1300 | Q18: 완가공
A19: 12 | B19: TOP RETANIER BOLT | C19: =COVER!B26 -> B8M | D19: 2 | H19: =IF(C19="B8",M19,IF(C19="B8M",N19)) -> 200 | I19: =H19*D19 -> 400 | K19: =I19+J19 -> 400 | M19: 200 | N19: 200 | Q19: WRENCH BOLT
A20: 13 | B20: GEAR BOX BOLT | C20: =COVER!B27 -> B8M | D20: 4 | H20: =IF(C20="B8",M20,IF(C20="B8M",N20,IF(C20="B7(다크로)",O20))) -> 400 | I20: =H20*D20 -> 1600 | K20: =I20+J20 -> 1600 | L20: M8X30L | M20: 350 | N20: 400 | O20: 300 | Q20: HEX BOLT
A21: 14 | B21: LEVER | C21: =COVER!C35 -> SUS304 | D21: 1 | H21: =IF(C21="SS400",L21,IF(C21="SUS304",M21)) -> 17000 | I21: =H21*D21 -> 17000 | K21: =I21+J21 -> 17000 | L21: 5800 | M21: 17000
A22: 15 | B22: GEAR BOX | C22: =COVER!B34 -> 10 BAR | D22: 1 | I22: =IF(C22="10 BAR",M22,IF(C22="16 BAR",N22,IF(C22="20 BAR",O22))) -> 98000 | K22: =I22+J22 -> 98000 | M22: 98000 | N22: 98000 | O22: 98000
A23: 16 | B23: PAINT | C23: =COVER!B32 -> 기존 단가 | D23: 1 | H23: =IF(COVER!B9="APPLICATION",0,IF(COVER!B32="기존 단가",L23,IF(COVER!B32="외주 2COATING",M23,IF(COVER!B32="외주 3COATING",N23)))) -> 7500 | I23: =H23 -> 7500 | L23: 7500 | M23: =IF(H6>0,F6*520,IF(H7>0,F7*520,IF(H8>0,F8*520))) -> 6760 | N23: =IF(H6>0,F6*620,IF(H7>0,F7*620,IF(H8>0,F8*620))) -> 8060
A24: 17 | B24: 조립.검사 | D24: 1 | H24: =IF(COVER!B9="APPLICATION",0,IF(COVER!B9="N/A",L24)) -> 7500 | I24: =H24 -> 7500 | L24: 7500
A25: 18 | B25: 밸브합산(BEAR) | K25: =SUM(K6:K20)+SUM(K23:K24) -> 78270 | L25: "A"
A26: 18 | B26: 밸브합산(LEVER) | K26: =SUM(K6:K21)+SUM(K23:K24) -> 95270 | L26: "A"
A27: 18 | B27: 밸브합산(GEAR) | K27: =SUM(K6:K20)+SUM(K22:K24) -> 176270 | L27: "A"
A28: 19 | B28: STEM CR PLATING | C28: =COVER!B28 -> REQUIRED | D28: 0 | H28: =IF(C28="REQUIRED",L28,IF(C28="N/A",0)) -> 5750 | I28: =H28 -> 5750 | L28: 5750
A29: 20 | B29: RUBBER LINING | D29: 0
A30: 21 | B30: 포장비용 | C30: =COVER!B35 -> MOTOR | D30: 1 | H30: =IF(COVER!B9="APPLICATION",0,IF(COVER!B35="BARE",M30,(IF(COVER!B35="LEVER",M30,IF(COVER!B35="GEAR",N30,IF(COVER!B35="MOTOR",O30)))))) -> 50000 | I30: =H30 -> 50000 | L30: 14000 | M30: 5000 | N30: 5000 | O30: 50000
A31: 22
A32: 23 | B32: 밸브외 사급품 비용 연산 | K32: =SUM(K28:K31) -> 0 | L32: "B"
A33: 24 | B33: VALVE 원가 - BEAR | K33: =K25+K32 -> 78270 | L33: (A+B)
A34: 24 | B34: VALVE 원가 - LEVER | K34: =K26+K32 -> 95270 | L34: (A+B)
A35: 24 | B35: VALVE 원가 - GEAR | K35: =K27+K32 -> 176270 | L35: (A+B)
A36: 25 | B36: FACTOR 금액 - BEAR | I36: FACTOR | J36: 0.7 | K36: =(K25+K32)/J36 -> 111814.29 | L36: (A+B)XFACTOR
A37: 25 | B37: FACTOR 금액 - LEVER | I37: FACTOR | J37: 0.7 | K37: =(K26+K32)/J37 -> 136100 | L37: (A+B)XFACTOR
A38: 25 | B38: FACTOR 금액 - GEAR | I38: FACTOR | J38: 0.7 | K38: =(K27+K32)/J38 -> 251814.29 | L38: (A+B)XFACTOR

Sheet 150A
A1: CONCENTRIC BFV 원가 分析表
A3: SIZE | B3: 150A | C3: RATING | D3: #150 | F3: FLANGE DRILLING | I3: ASME B16.5 | J3: FACE TO FACE | K3: ISO575 SER'20(56MM)
J4: O.D(MM) | K4: 280 | L4: 외주가공비 / 단가표(EPC)
A5: NO. | B5: 부품명 | C5: 재질 | D5: 수량 | E5: 규격 | F5: 단중 | G5: 업체 | H5: 단가 | I5: 소계 | J5: 가공비 | K5: 합계 | L5: FC/FCD | M5: SC/WCB (ALBC) | N5: SUS | O5: A890 4A | P5: A890 5A | Q5: DISC 중량(일반) | R5: DISC 중량(고압) | T5: 이전 단가 Table 중량
A6: 1 | B6: BODY(WAFER) | C6: =COVER!B13 -> 0 | D6: 1 | F6: 11 | H6: =COVER!C13 -> 0 | I6: =D6*F6*H6 -> 0 | K6: =I6+J6 -> 0 | L6: 16000 | M6: 24000 | N6: 48000 | T6: 9.5
A7: 1 | B7: BODY(LUG) | C7: =COVER!B14 -> A536 Gr65-45-12 | D7: 1 | F7: 17.5 | H7: =COVER!C14 -> 3500 | I7: =D7*F7*H7 -> 61250 | K7: =I7+J7 -> 61250 | L7: 25000 | M7: 37500 | T7: 13
A8: 1 | B8: BODY(FLANGE) | C8: =COVER!B15 -> 0 | D8: 1 | F8: 34 | H8: =COVER!C15 -> 0 | I8: =D8*F8*H8 -> 0 | K8: =I8+J8 -> 0 | L8: 30000 | M8: 45000 | T8: 23.5
A9: 2 | B9: DISC | C9: =COVER!B16 -> A351 CF8M | D9: 1 | F9: =IF(COVER!B34="10 BAR",Q9,IF(COVER!B34="16 BAR",R9,IF(COVER!B34="20 BAR",R9))) -> 1.6 | H9: =COVER!C16 -> 12000 | I9: =D9*F9*H9 -> 19200 | K9: =I9+J9 -> 19200 | L9: 5580 | M9: 5500 | N9: 6000 | O9: 13000 | P9: =O9*1.25 -> 16250 | Q9: 1.6 | R9: 3.2 | T9: 1.7 | V9: =P9/M9 -> 2.9545455
A10: 3 | B10: SEAT | C10: =COVER!B18 -> EPDM | D10: 1 | F10: 1 | H10: =IF(C10="NBR",L10,IF(C10="EPDM",L10,IF(C10="VITON",M10))) -> 3795 | I10: =H10*F10*D10 -> 3795 | K10: =I10+J10 -> 3795 | L10: 3795 | M10: 40000 | N10: 25000 | O10: 8800 | P10: 5200
A11: 4 | B11: STEM(ONE STEM) | C11: =COVER!B17 -> A564T630 | D11: 1 | F11: 0.77 | H11: =COVER!C17 -> 10000 | I11: =D11*F11*H11 -> 7700 | K11: =I11+J11 -> 7700 | L11: Ø19X340L | M11: 3000 | N11: 1350 | Q11: 0.77 | T11: 0.7
A12: 5 | B12: PACKING+GLAND | C12: =COVER!B19 -> NBR | D12: 1 | F12: 1 | H12: =IF(C12="NBR",L12+N12,IF(C12="EPDM",L12+N12,IF(C12="VITON",M12+N12))) -> 310 | I12: =D12*F12*H12 -> 310 | K12: =I12+J12 -> 310 | L12: 130 | M12: 1090 | N12: 180 | V12: =M9/L9 -> 0.98566308
A13: 6 | B13: BUSH | D13: 0 | L13: N/A
A14: 7 | B14: DISC BOLT(PIN) | C14: =C11 -> A564T630 | D14: 2 | F14: 1 | H14: =L14 -> 1900 | I14: =D14*F14*H14 -> 3800 | K14: =I14+J14 -> 3800 | L14: 1900
A15: 8 | B15: END COVER (WITH O-RING) | C15: =COVER!B22 -> BODY MATERIAL | D15: 0 | L15: N/A
A16: 9 | B16: END COVER BOLT | C16: =COVER!B23 -> B8M | D16: 0 | L16: N/A
A17: 10 | B17: COLLAR | C17: =COVER!B24 -> ALBC2 | D17: 0 | L17: N/A
A18: 11 | B18: TOP RETANIER | C18: A240T304 | D18: 1 | H18: =M18 -> 1300 | I18: =H18*D18 -> 1300 | K18: =I18+J18 -> 1300 | L18: Ø89X10T | M18: 1300 | Q18: 완가공
A19: 12 | B19: TOP RETANIER BOLT | C19: =COVER!B26 -> B8M | D19: 2 | H19: =IF(C19="B8",M19,IF(C19="B8M",N19)) -> 200 | I19: =H19*D19 -> 400 | K19: =I19+J19 -> 400 | M19: 200 | N19: 200 | Q19: WRENCH BOLT
A20: 13 | B20: GEAR BOX BOLT | C20: =COVER!B27 -> B8M | D20: 4 | H20: =IF(C20="B8",M20,IF(C20="B8M",N20,IF(C20="B7(다크로)",O20))) -> 400 | I20: =H20*D20 -> 1600 | K20: =I20+J20 -> 1600 | L20: M8X30L | M20: 350 | N20: 400 | O20: 300 | Q20: HEX BOLT | T20: 182420 | U20: =T20/0.7 -> 260600
A21: 14 | B21: LEVER | C21: =COVER!C35 -> SUS304 | D21: 1 | H21: =IF(C21="SS400",L21,IF(C21="SUS304",M21)) -> 17000 | I21: =H21*D21 -> 17000 | K21: =I21+J21 -> 17000 | L21: 5800 | M21: 17000
A22: 15 | B22: GEAR BOX | C22: =COVER!B34 -> 10 BAR | D22: 1 | I22: =IF(C22="10 BAR",M22,IF(C22="16 BAR",N22,IF(C22="20 BAR",O22))) -> 98000 | K22: =I22+J22 -> 98000 | M22: 98000 | N22: 98000 | O22: 98000
A23: 16 | B23: PAINT | C23: =COVER!B32 -> 기존 단가 | D23: 1 | H23: =IF(COVER!B9="APPLICATION",0,IF(COVER!B32="기존 단가",L23,IF(COVER!B32="외주 2COATING",M23,IF(COVER!B32="외주 3COATING",N23)))) -> 10500 | I23: =H23 -> 10500 | L23: 10500 | M23: =IF(H6>0,F6*520,IF(H7>0,F7*520,IF(H8>0,F8*520))) -> 9100 | N23: =IF(H6>0,F6*620,IF(H7>0,F7*620,IF(H8>0,F8*620))) -> 10850
A24: 17 | B24: 조립.검사 | D24: 1 | H24: =IF(COVER!B9="APPLICATION",0,IF(COVER!B9="N/A",L24)) -> 10500 | I24: =H24 -> 10500 | L24: 10500
A25: 18 | B25: 밸브합산(BEAR) | K25: =SUM(K6:K20)+SUM(K23:K24) -> 99355 | L25: "A"
A26: 18 | B26: 밸브합산(LEVER) | K26: =SUM(K6:K21)+SUM(K23:K24) -> 116355 | L26: "A"
A27: 18 | B27: 밸브합산(GEAR) | K27: =SUM(K6:K20)+SUM(K22:K24) -> 197355 | L27: "A"
A28: 19 | B28: STEM CR PLATING | C28: =COVER!B28 -> REQUIRED | D28: 0 | H28: =IF(C28="REQUIRED",L28,IF(C28="N/A",0)) -> 6000 | I28: =H28 -> 6000 | L28: 6000
A29: 20 | B29: RUBBER LINING | D29: 0
A30: 21 | B30: 포장비용 | C30: =COVER!B35 -> MOTOR | D30: 1 | H30: =IF(COVER!B9="APPLICATION",0,IF(COVER!B35="BARE",M30,(IF(COVER!B35="LEVER",M30,IF(COVER!B35="GEAR",N30,IF(COVER!B35="MOTOR",O30)))))) -> 50000 | I30: =H30 -> 50000 | L30: 15000 | M30: 5000 | N30: 5000 | O30: 50000
A31: 22
A32: 23 | B32: 밸브외 사급품 비용 연산 | K32: =SUM(K28:K31) -> 0 | L32: "B"
A33: 24 | B33: VALVE 원가 - BEAR | K33: =K25+K32 -> 99355 | L33: (A+B)
A34: 24 | B34: VALVE 원가 - LEVER | K34: =K26+K32 -> 116355 | L34: (A+B)
A35: 24 | B35: VALVE 원가 - GEAR | K35: =K27+K32 -> 197355 | L35: (A+B)
A36: 25 | B36: FACTOR 금액 - BEAR | I36: FACTOR | J36: 0.7 | K36: =(K25+K32)/J36 -> 141935.71 | L36: (A+B)XFACTOR
A37: 25 | B37: FACTOR 금액 - LEVER | I37: FACTOR | J37: 0.7 | K37: =(K26+K32)/J37 -> 166221.43 | L37: (A+B)XFACTOR
A38: 25 | B38: FACTOR 금액 - GEAR | I38: FACTOR | J38: 0.7 | K38: =(K27+K32)/J38 -> 281935.71 | L38: (A+B)XFACTOR

Sheet 200A
A1: CONCENTRIC BFV 원가 分析表
A3: SIZE | B3: 200A | C3: RATING | D3: #150 | F3: FLANGE DRILLING | I3: ASME B16.5 | J3: FACE TO FACE | K3: ISO575 SER'20(60MM)
J4: O.D(MM) | K4: 345 | L4: 외주가공비 / 단가표(EPC)
A5: NO. | B5: 부품명 | C5: 재질 | D5: 수량 | E5: 규격 | F5: 단중 | G5: 업체 | H5: 단가 | I5: 소계 | J5: 가공비 | K5: 합계 | L5: FC/FCD | M5: SC/WCB (ALBC) | N5: SUS | O5: A890 4A | P5: A890 5A | Q5: DISC 중량(일반) | R5: DISC 중량(고압) | T5: 이전 단가 Table 중량
A6: 1 | B6: BODY(WAFER) | C6: =COVER!B13 -> 0 | D6: 1 | F6: 15 | H6: =COVER!C13 -> 0 | I6: =D6*F6*H6 -> 0 | K6: =I6+J6 -> 0 | L6: 22000 | M6: 33000 | N6: 66000 | T6: 13
A7: 1 | B7: BODY(LUG) | C7: =COVER!B14 -> A536 Gr65-45-12 | D7: 1 | F7: 23 | H7: =COVER!C14 -> 3500 | I7: =D7*F7*H7 -> 80500 | K7: =I7+J7 -> 80500 | L7: 36000 | M7: 54000 | T7: 16.5
A8: 1 | B8: BODY(FLANGE) | C8: =COVER!B15 -> 0 | D8: 1 | F8: 34 | H8: =COVER!C15 -> 0 | I8: =D8*F8*H8 -> 0 | K8: =I8+J8 -> 0 | L8: 42100 | M8: 63150 | T8: 33
A9: 2 | B9: DISC | C9: =COVER!B16 -> A351 CF8M | D9: 1 | F9: =IF(COVER!B34="10 BAR",Q9,IF(COVER!B34="16 BAR",R9,IF(COVER!B34="20 BAR",R9))) -> 3.4 | H9: =COVER!C16 -> 12000 | I9: =D9*F9*H9 -> 40800 | K9: =I9+J9 -> 40800 | L9: 9700 | M9: 8000 | N9: 9000 | O9: 17000 | P9: 21000 | Q9: 3.4 | R9: 6 | T9: 4 | V9: =P9/M9 -> 2.625
A10: 3 | B10: SEAT | C10: =COVER!B18 -> EPDM | D10: 1 | F10: 1 | H10: =IF(C10="NBR",L10,IF(C10="EPDM",L10,IF(C10="VITON",M10))) -> 5348 | I10: =H10*F10*D10 -> 5348 | K10: =I10+J10 -> 5348 | L10: 5348 | M10: 80000 | N10: 30000 | O10: 9000 | P10: 8000
A11: 4 | B11: STEM(ONE STEM) | C11: =COVER!B17 -> A564T630 | D11: 1 | F11: 1.23 | H11: =COVER!C17 -> 10000 | I11: =D11*F11*H11 -> 12300 | K11: =I11+J11 -> 12300 | L11: Ø22X405L | M11: 3500 | N11: 1700 | Q11: 1.23 | T11: 0.9
A12: 5 | B12: PACKING+GLAND | C12: =COVER!B19 -> NBR | D12: 1 | F12: 1 | H12: =IF(C12="NBR",L12+N12,IF(C12="EPDM",L12+N12,IF(C12="VITON",M12+N12))) -> 330 | I12: =D12*F12*H12 -> 330 | K12: =I12+J12 -> 330 | L12: 140 | M12: 1140 | N12: 190 | V12: =M9/L9 -> 0.82474227
A13: 6 | B13: BUSH | D13: 0 | L13: N/A
A14: 7 | B14: DISC BOLT(PIN) | C14: =C11 -> A564T630 | D14: 2 | F14: 1 | H14: =L14 -> 2100 | I14: =D14*F14*H14 -> 4200 | K14: =I14+J14 -> 4200 | L14: 2100
A15: 8 | B15: END COVER (WITH O-RING) | C15: =COVER!B22 -> BODY MATERIAL | D15: 0 | L15: N/A
A16: 9 | B16: END COVER BOLT | C16: =COVER!B23 -> B8M | D16: 0 | L16: N/A
A17: 10 | B17: COLLAR | C17: =COVER!B24 -> ALBC2 | D17: 0 | L17: N/A
A18: 11 | B18: TOP RETANIER | C18: A240T304 | D18: 1 | H18: =M18 -> 1300 | I18: =H18*D18 -> 1300 | K18: =I18+J18 -> 1300 | L18: Ø57X1.5T | M18: 1300 | Q18: 완가공
A19: 12 | B19: TOP RETANIER BOLT | C19: =COVER!B26 -> B8M | D19: 2 | H19: =IF(C19="B8",M19,IF(C19="B8M",N19)) -> 200 | I19: =H19*D19 -> 400 | K19: =I19+J19 -> 400 | M19: 200 | N19: 200 | Q19: WRENCH BOLT
A20: 13 | B20: GEAR BOX BOLT | C20: =COVER!B27 -> B8M | D20: 4 | H20: =IF(C20="B8",M20,IF(C20="B8M",N20,IF(C20="B7(다크로)",O20))) -> 400 | I20: =H20*D20 -> 1600 | K20: =I20+J20 -> 1600 | L20: M8X30L | M20: 350 | N20: 400 | O20: 300 | Q20: HEX BOLT | U20: 390403 | V20: =U20/0.7 -> 557718.57
A21: 14 | B21: LEVER | C21: SUS | D21: 1 | L21: N/A
A22: 15 | B22: GEAR BOX | C22: =COVER!B34 -> 10 BAR | D22: 1 | I22: =IF(C22="10 BAR",M22,IF(C22="16 BAR",N22,IF(C22="20 BAR",O22))) -> 98000 | K22: =I22+J22 -> 98000 | M22: 98000 | N22: 98000 | O22: 98000
A23: 16 | B23: PAINT | C23: =COVER!B32 -> 기존 단가 | D23: 1 | H23: =IF(COVER!B9="APPLICATION",0,IF(COVER!B32="기존 단가",L23,IF(COVER!B32="외주 2COATING",M23,IF(COVER!B32="외주 3COATING",N23)))) -> 12500 | I23: =H23 -> 12500 | L23: 12500 | M23: =IF(H6>0,F6*520,IF(H7>0,F7*520,IF(H8>0,F8*520))) -> 11960 | N23: =IF(H6>0,F6*620,IF(H7>0,F7*620,IF(H8>0,F8*620))) -> 14260
A24: 17 | B24: 조립.검사 | D24: 1 | H24: =IF(COVER!B9="APPLICATION",0,IF(COVER!B9="N/A",L24)) -> 12500 | I24: =H24 -> 12500 | L24: 12500
A25: 18 | B25: 밸브합산(BEAR) | K25: =SUM(K6:K20)+SUM(K23:K24) -> 146778 | L25: "A"
A26: 18 | B26: 밸브합산(LEVER) | K26: =SUM(K6:K21)+SUM(K23:K24) -> 146778 | L26: "A"
A27: 18 | B27: 밸브합산(GEAR) | K27: =SUM(K6:K20)+SUM(K22:K24) -> 244778 | L27: "A"
A28: 19 | B28: STEM CR PLATING | C28: =COVER!B28 -> REQUIRED | D28: 0 | H28: =IF(C28="REQUIRED",L28,IF(C28="N/A",0)) -> 7300 | I28: =H28 -> 7300 | L28: 7300
A29: 20 | B29: RUBBER LINING | D29: 0
A30: 21 | B30: 포장비용 | C30: =COVER!B35 -> MOTOR | D30: 1 | H30: =IF(COVER!B9="APPLICATION",0,IF(COVER!B35="BARE",M30,(IF(COVER!B35="LEVER",M30,IF(COVER!B35="GEAR",N30,IF(COVER!B35="MOTOR",O30)))))) -> 55000 | I30: =H30 -> 55000 | L30: 17000 | M30: 10000 | N30: 12000 | O30: 55000
A31: 22
A32: 23 | B32: 밸브외 사급품 비용 연산 | K32: =SUM(K28:K31) -> 0 | L32: "B"
A33: 24 | B33: VALVE 원가 - BEAR | K33: =K25+K32 -> 146778 | L33: (A+B)
A34: 24 | B34: VALVE 원가 - LEVER | K34: =K26+K32 -> 146778 | L34: (A+B)
A35: 24 | B35: VALVE 원가 - GEAR | K35: =K27+K32 -> 244778 | L35: (A+B)
A36: 25 | B36: FACTOR 금액 - BEAR | I36: FACTOR | J36: 0.7 | K36: =(K25+K32)/J36 -> 209682.86 | L36: (A+B)XFACTOR
A37: 25 | B37: FACTOR 금액 - LEVER | I37: FACTOR | J37: 0.7 | K37: =(K26+K32)/J37 -> 209682.86 | L37: (A+B)XFACTOR
A38: 25 | B38: FACTOR 금액 - GEAR | I38: FACTOR | J38: 0.7 | K38: =(K27+K32)/J38 -> 349682.86 | L38: (A+B)XFACTOR

Sheet 250A
A1: CONCENTRIC BFV 원가 分析表
A3: SIZE | B3: 250A | C3: RATING | D3: #150 | F3: FLANGE DRILLING | I3: ASME B16.5 | J3: FACE TO FACE | K3: ISO575 SER'20(68MM) | O3: 318275 | P3: =O3/0.7 -> 454678.57
J4: O.D(MM) | K4: 405 | L4: 외주가공비 / 단가표(EPC)
A5: NO. | B5: 부품명 | C5: 재질 | D5: 수량 | E5: 규격 | F5: 단중 | G5: 업체 | H5: 단가 | I5: 소계 | J5: 가공비 | K5: 합계 | L5: FC/FCD | M5: SC/WCB (ALBC) | N5: SUS | O5: A890 4A | P5: A890 5A | Q5: DISC 중량(일반) | R5: DISC 중량(고압) | T5: 이전 단가 Table 중량
A6: 1 | B6: BODY(WAFER) | C6: =COVER!B13 -> 0 | D6: 1 | F6: 21 | H6: =COVER!C13 -> 0 | I6: =D6*F6*H6 -> 0 | K6: =I6+J6 -> 0 | L6: 27000 | M6: 37000 | T6: 18.6
A7: 1 | B7: BODY(LUG) | C7: =COVER!B14 -> A536 Gr65-45-12 | D7: 1 | F7: 33 | H7: =COVER!C14 -> 3500 | I7: =D7*F7*H7 -> 115500 | K7: =I7+J7 -> 115500 | L7: 53000 | M7: 55000 | T7: 27
A8: 1 | B8: BODY(FLANGE) | C8: =COVER!B15 -> 0 | D8: 1 | F8: 48 | H8: =COVER!C15 -> 0 | I8: =D8*F8*H8 -> 0 | K8: =I8+J8 -> 0 | L8: 70500 | M8: =L8*1.05 -> 74025 | T8: 48
A9: 2 | B9: DISC | C9: =COVER!B16 -> A351 CF8M | D9: 1 | F9: =IF(COVER!B34="10 BAR",Q9,IF(COVER!B34="16 BAR",R9,IF(COVER!B34="20 BAR",R9))) -> 6 | H9: =COVER!C16 -> 12000 | I9: =D9*F9*H9 -> 72000 | K9: =I9+J9 -> 72000 | L9: 13200 | M9: 11000 | N9: 12000 | O9: =P9*0.8 -> 19200 | P9: 24000 | Q9: 6 | R9: 10 | T9: 6.5 | V9: =P9/M9 -> 2.1818182
A10: 3 | B10: SEAT | C10: =COVER!B18 -> EPDM | D10: 1 | F10: 1 | H10: =IF(C10="NBR",L10,IF(C10="EPDM",L10,IF(C10="VITON",M10))) -> 7820 | I10: =H10*F10*D10 -> 7820 | K10: =I10+J10 -> 7820 | L10: 7820 | M10: 110000 | N10: 38000 | O10: 15000 | P10: 11000
A11: 4 | B11: STEM(ONE STEM) | C11: =COVER!B17 -> A564T630 | D11: 1 | F11: 1.99 | H11: =COVER!C17 -> 10000 | I11: =D11*F11*H11 -> 19900 | K11: =I11+J11 -> 19900 | L11: Ø25X507L | M11: 4500 | N11: 3000 | Q11: 1.99 | T11: 1.4
A12: 5 | B12: PACKING+GLAND | C12: =COVER!B19 -> NBR | D12: 1 | F12: 1 | H12: =IF(C12="NBR",L12+N12,IF(C12="EPDM",L12+N12,IF(C12="VITON",M12+N12))) -> 330 | I12: =D12*F12*H12 -> 330 | K12: =I12+J12 -> 330 | L12: 140 | M12: 1140 | N12: 190 | V12: =M9/L9 -> 0.83333333
A13: 6 | B13: BUSH | D13: 0 | L13: N/A
A14: 7 | B14: DISC BOLT(PIN) | C14: =C11 -> A564T630 | D14: 3 | F14: 1 | H14: =L14 -> 2100 | I14: =D14*F14*H14 -> 6300 | K14: =I14+J14 -> 6300 | L14: 2100
A15: 8 | B15: END COVER (WITH O-RING) | C15: =COVER!B22 -> BODY MATERIAL | D15: 0 | L15: N/A
A16: 9 | B16: END COVER BOLT | C16: =COVER!B23 -> B8M | D16: 0 | L16: N/A
A17: 10 | B17: COLLAR | C17: =COVER!B24 -> ALBC2 | D17: 0 | L17: N/A
A18: 11 | B18: TOP RETANIER | C18: A240T304 | D18: 1 | H18: =M18 -> 1300 | I18: =H18*D18 -> 1300 | K18: =I18+J18 -> 1300 | L18: Ø70.5X2T | M18: 1300 | Q18: 완가공
A19: 12 | B19: TOP RETANIER BOLT | C19: =COVER!B26 -> B8M | D19: 2 | H19: =IF(C19="B8",M19,IF(C19="B8M",N19)) -> 200 | I19: =H19*D19 -> 400 | K19: =I19+J19 -> 400 | M19: 200 | N19: 200 | Q19: WRENCH BOLT
A20: 13 | B20: GEAR BOX BOLT | C20: =COVER!B27 -> B8M | D20: 4 | H20: =IF(C20="B8",M20,IF(C20="B8M",N20,IF(C20="B7(다크로)",O20))) -> 800 | I20: =H20*D20 -> 3200 | K20: =I20+J20 -> 3200 | L20: M10X30L | M20: 500 | N20: 800 | O20: 500 | Q20: HEX BOLT
A21: 14 | B21: LEVER | C21: SUS | D21: 1 | K21: =I21+J21 -> 0 | L21: N/A
A22: 15 | B22: GEAR BOX | C22: =COVER!B34 -> 10 BAR | D22: 1 | I22: =IF(C22="10 BAR",M22,IF(C22="16 BAR",N22,IF(C22="20 BAR",O22))) -> 123000 | K22: =I22+J22 -> 123000 | M22: 123000 | N22: 203000 | O22: 203000
A23: 16 | B23: PAINT | C23: =COVER!B32 -> 기존 단가 | D23: 1 | H23: =IF(COVER!B9="APPLICATION",0,IF(COVER!B32="기존 단가",L23,IF(COVER!B32="외주 2COATING",M23,IF(COVER!B32="외주 3COATING",N23)))) -> 12500 | I23: =H23 -> 12500 | L23: 12500 | M23: =IF(H6>0,F6*520,IF(H7>0,F7*520,IF(H8>0,F8*520))) -> 17160 | N23: =IF(H6>0,F6*620,IF(H7>0,F7*620,IF(H8>0,F8*620))) -> 20460
A24: 17 | B24: 조립.검사 | D24: 1 | H24: =IF(COVER!B9="APPLICATION",0,IF(COVER!B9="N/A",L24)) -> 12500 | I24: =H24 -> 12500 | L24: 12500
A25: 18 | B25: 밸브합산(BEAR) | K25: =SUM(K6:K20)+SUM(K23:K24) -> 226750 | L25: "A"
A26: 18 | B26: 밸브합산(LEVER) | K26: =SUM(K6:K21)+SUM(K23:K24) -> 226750 | L26: "A"
A27: 18 | B27: 밸브합산(GEAR) | K27: =SUM(K6:K20)+SUM(K22:K24) -> 349750 | L27: "A"
A28: 19 | B28: STEM CR PLATING | C28: =COVER!B28 -> REQUIRED | D28: 0 | H28: =IF(C28="REQUIRED",L28,IF(C28="N/A",0)) -> 14000 | I28: =H28 -> 14000 | L28: 14000
A29: 20 | B29: RUBBER LINING | D29: 0
A30: 21 | B30: 포장비용 | C30: =COVER!B35 -> MOTOR | D30: 1 | H30: =IF(COVER!B9="APPLICATION",0,IF(COVER!B35="BARE",M30,(IF(COVER!B35="LEVER",M30,IF(COVER!B35="GEAR",N30,IF(COVER!B35="MOTOR",O30)))))) -> 60000 | I30: =H30 -> 60000 | L30: 24200 | M30: 16000 | N30: 16000 | O30: 60000
A31: 22
A32: 23 | B32: 밸브외 사급품 비용 연산 | K32: =SUM(K28:K31) -> 0 | L32: "B"
A33: 24 | B33: VALVE 원가 - BEAR | K33: =K25+K32 -> 226750 | L33: (A+B)
A34: 24 | B34: VALVE 원가 - LEVER | K34: =K26+K32 -> 226750 | L34: (A+B)
A35: 24 | B35: VALVE 원가 - GEAR | K35: =K27+K32 -> 349750 | L35: (A+B)
A36: 25 | B36: FACTOR 금액 - BEAR | I36: FACTOR | J36: 0.7 | K36: =(K25+K32)/J36 -> 323928.57 | L36: (A+B)XFACTOR
A37: 25 | B37: FACTOR 금액 - LEVER | I37: FACTOR | J37: 0.7 | K37: =(K26+K32)/J37 -> 323928.57 | L37: (A+B)XFACTOR
A38: 25 | B38: FACTOR 금액 - GEAR | I38: FACTOR | J38: 0.7 | K38: =(K27+K32)/J38 -> 499642.86 | L38: (A+B)XFACTOR

Sheet 300A
A1: CONCENTRIC BFV 원가 分析表
A3: SIZE | B3: 300A | C3: RATING | D3: #150 | F3: FLANGE DRILLING | I3: ASME B16.5 | J3: FACE TO FACE | K3: ISO575 SER'20(68MM) | O3: 318275 | P3: =O3/0.7 -> 454678.57
J4: O.D(MM) | K4: 405 | L4: 외주가공비 / 단가표(EPC)
A5: NO. | B5: 부품명 | C5: 재질 | D5: 수량 | E5: 규격 | F5: 단중 | G5: 업체 | H5: 단가 | I5: 소계 | J5: 가공비 | K5: 합계 | L5: FC/FCD | M5: SC/WCB (ALBC) | N5: SUS | O5: A890 4A | P5: A890 5A | Q5: DISC 중량(일반) | R5: DISC 중량(고압) | T5: 이전 단가 Table 중량
A6: 1 | B6: BODY(WAFER) | C6: =COVER!B13 -> 0 | D6: 1 | F6: 33 | H6: =COVER!C13 -> 0 | I6: =D6*F6*H6 -> 0 | K6: =I6+J6 -> 0 | L6: 27000 | M6: 37000 | T6: 18.6
A7: 1 | B7: BODY(LUG) | C7: =COVER!B14 -> A536 Gr65-45-12 | D7: 1 | F7: 48 | H7: =COVER!C14 -> 3500 | I7: =D7*F7*H7 -> 168000 | K7: =I7+J7 -> 168000 | L7: 53000 | M7: 55000 | T7: 27
A8: 1 | B8: BODY(FLANGE) | C8: =COVER!B15 -> 0 | D8: 1 | F8: 66 | H8: =COVER!C15 -> 0 | I8: =D8*F8*H8 -> 0 | K8: =I8+J8 -> 0 | L8: 70500 | M8: =L8*1.05 -> 74025 | T8: 48
A9: 2 | B9: DISC | C9: =COVER!B16 -> A351 CF8M | D9: 1 | F9: =IF([2]COVER!B34="10 BAR",Q9,IF([2]COVER!B34="16 BAR",R9,IF([2]COVER!B34="20 BAR",R9))) -> 10 | H9: =COVER!C16 -> 12000 | I9: =D9*F9*H9 -> 120000 | K9: =I9+J9 -> 120000 | L9: 13200 | M9: 11000 | N9: 12000 | O9: =P9*0.8 -> 19200 | P9: 24000 | Q9: 6 | R9: 10 | T9: 6.5 | V9: =P9/M9 -> 2.1818182
A10: 3 | B10: SEAT | C10: =COVER!B18 -> EPDM | D10: 1 | F10: 1 | H10: =IF(C10="NBR",L10,IF(C10="EPDM",L10,IF(C10="VITON",M10))) -> 7820 | I10: =H10*F10*D10 -> 7820 | K10: =I10+J10 -> 7820 | L10: 7820 | M10: 110000 | N10: 38000 | O10: 15000 | P10: 11000
A11: 4 | B11: STEM(ONE STEM) | C11: =COVER!B17 -> A564T630 | D11: 1 | F11: 3 | H11: =COVER!C17 -> 10000 | I11: =D11*F11*H11 -> 30000 | K11: =I11+J11 -> 30000 | L11: Ø25X507L | M11: 4500 | N11: 3000 | Q11: 1.99 | T11: 1.4
A12: 5 | B12: PACKING+GLAND | C12: =COVER!B19 -> NBR | D12: 1 | F12: 1 | H12: =IF(C12="NBR",L12+N12,IF(C12="EPDM",L12+N12,IF(C12="VITON",M12+N12))) -> 330 | I12: =D12*F12*H12 -> 330 | K12: =I12+J12 -> 330 | L12: 140 | M12: 1140 | N12: 190 | V12: =M9/L9 -> 0.83333333
A13: 6 | B13: BUSH | D13: 0 | L13: N/A
A14: 7 | B14: DISC BOLT(PIN) | C14: =C11 -> A564T630 | D14: 3 | F14: 1 | H14: =L14 -> 2100 | I14: =D14*F14*H14 -> 6300 | K14: =I14+J14 -> 6300 | L14: 2100
A15: 8 | B15: END COVER (WITH O-RING) | C15: =COVER!B22 -> BODY MATERIAL | D15: 0 | L15: N/A
A16: 9 | B16: END COVER BOLT | C16: =COVER!B23 -> B8M | D16: 0 | L16: N/A
A17: 10 | B17: COLLAR | C17: =COVER!B24 -> ALBC2 | D17: 0 | L17: N/A
A18: 11 | B18: TOP RETANIER | C18: A240T304 | D18: 1 | H18: =M18 -> 1300 | I18: =H18*D18 -> 1300 | K18: =I18+J18 -> 1300 | L18: Ø70.5X2T | M18: 1300 | Q18: 완가공
A19: 12 | B19: TOP RETANIER BOLT | C19: =COVER!B26 -> B8M | D19: 2 | H19: =IF(C19="B8",M19,IF(C19="B8M",N19)) -> 200 | I19: =H19*D19 -> 400 | K19: =I19+J19 -> 400 | M19: 200 | N19: 200 | Q19: WRENCH BOLT
A20: 13 | B20: GEAR BOX BOLT | C20: =COVER!B27 -> B8M | D20: 4 | H20: =IF(C20="B8",M20,IF(C20="B8M",N20,IF(C20="B7(다크로)",O20))) -> 800 | I20: =H20*D20 -> 3200 | K20: =I20+J20 -> 3200 | L20: M10X30L | M20: 500 | N20: 800 | O20: 500 | Q20: HEX BOLT
A21: 14 | B21: LEVER | C21: SUS | D21: 1 | K21: =I21+J21 -> 0 | L21: N/A
A22: 15 | B22: GEAR BOX | C22: =COVER!B34 -> 10 BAR | D22: 1 | I22: =IF(C22="10 BAR",M22,IF(C22="16 BAR",N22,IF(C22="20 BAR",O22))) -> 123000 | K22: =I22+J22 -> 123000 | M22: 123000 | N22: 203000 | O22: 225000
A23: 16 | B23: PAINT | C23: =COVER!B32 -> 기존 단가 | D23: 1 | H23: =IF(COVER!B9="APPLICATION",0,IF(COVER!B32="기존 단가",L23,IF(COVER!B32="외주 2COATING",M23,IF(COVER!B32="외주 3COATING",N23)))) -> 12500 | I23: =H23 -> 12500 | L23: 12500 | M23: =IF(H6>0,F6*520,IF(H7>0,F7*520,IF(H8>0,F8*520))) -> 24960 | N23: =IF(H6>0,F6*620,IF(H7>0,F7*620,IF(H8>0,F8*620))) -> 29760
A24: 17 | B24: 조립.검사 | D24: 1 | H24: =IF(COVER!B9="APPLICATION",0,IF(COVER!B9="N/A",L24)) -> 12500 | I24: =H24 -> 12500 | L24: 12500
A25: 18 | B25: 밸브합산(BEAR) | K25: =SUM(K6:K20)+SUM(K23:K24) -> 337350 | L25: "A"
A26: 18 | B26: 밸브합산(LEVER) | K26: =SUM(K6:K21)+SUM(K23:K24) -> 337350 | L26: "A"
A27: 18 | B27: 밸브합산(GEAR) | K27: =SUM(K6:K20)+SUM(K22:K24) -> 460350 | L27: "A"
A28: 19 | B28: STEM CR PLATING | C28: =COVER!B28 -> REQUIRED | D28: 0 | H28: =IF(C28="REQUIRED",L28,IF(C28="N/A",0)) -> 14000 | I28: =H28 -> 14000 | L28: 14000
A29: 20 | B29: RUBBER LINING | D29: 0
A30: 21 | B30: 포장비용 | C30: =COVER!B35 -> MOTOR | D30: 1 | H30: =IF(COVER!B9="APPLICATION",0,IF(COVER!B35="BARE",M30,(IF(COVER!B35="LEVER",M30,IF(COVER!B35="GEAR",N30,IF(COVER!B35="MOTOR",O30)))))) -> 60000 | I30: =H30 -> 60000 | L30: 24200 | M30: 16000 | N30: 16000 | O30: 60000
A31: 22
A32: 23 | B32: 밸브외 사급품 비용 연산 | K32: =SUM(K28:K31) -> 0 | L32: "B"
A33: 24 | B33: VALVE 원가 - BEAR | K33: =K25+K32 -> 337350 | L33: (A+B)
A34: 24 | B34: VALVE 원가 - LEVER | K34: =K26+K32 -> 337350 | L34: (A+B)
A35: 24 | B35: VALVE 원가 - GEAR | K35: =K27+K32 -> 460350 | L35: (A+B)
A36: 25 | B36: FACTOR 금액 - BEAR | I36: FACTOR | J36: 0.7 | K36: =(K25+K32)/J36 -> 481928.57 | L36: (A+B)XFACTOR
A37: 25 | B37: FACTOR 금액 - LEVER | I37: FACTOR | J37: 0.7 | K37: =(K26+K32)/J37 -> 481928.57 | L37: (A+B)XFACTOR
A38: 25 | B38: FACTOR 금액 - GEAR | I38: FACTOR | J38: 0.7 | K38: =(K27+K32)/J38 -> 657642.86 | L38: (A+B)XFACTOR

Sheet 350A
A1: CONCENTRIC BFV 원가 分析表
A3: SIZE | B3: 350A | C3: RATING | D3: #150 | F3: FLANGE DRILLING | I3: ASME B16.5 | J3: FACE TO FACE | K3: ISO575 SER'20(78MM)
J4: O.D(MM) | K4: 535 | L4: 외주가공비 / 단가표(EPC)
A5: NO. | B5: 부품명 | C5: 재질 | D5: 수량 | E5: 규격 | F5: 단중 | G5: 업체 | H5: 단가 | I5: 소계 | J5: 가공비 | K5: 합계 | L5: FC/FCD | M5: SC/WCB (ALBC) | N5: SUS | O5: A890 4A | P5: A890 5A | Q5: DISC 중량(일반) | R5: DISC 중량(고압) | T5: 이전 단가 Table 중량
A6: 1 | B6: BODY(WAFER) | C6: =COVER!B13 -> 0 | D6: 1 | F6: 35 | H6: =COVER!C13 -> 0 | I6: =D6*F6*H6 -> 0 | K6: =I6+J6 -> 0 | L6: 39000 | M6: =M7*0.72 -> 59400 | T6: 29.5
A7: 1 | B7: BODY(LUG) | C7: =COVER!B14 -> A536 Gr65-45-12 | D7: 1 | F7: 58 | H7: =COVER!C14 -> 3500 | I7: =D7*F7*H7 -> 203000 | K7: =I7+J7 -> 203000 | L7: 63000 | M7: 82500 | T7: 48
