Workbook
Name _____________SHT1: #REF!
Name _____________SHT2: #REF!
Name _____________SHT3: #REF!
Name ___________SHT1: #REF!
Name ___________SHT2: #REF!
Name ___________SHT3: #REF!
Name _________SHT1: #REF!
Name _________SHT2: #REF!
Name _________SHT3: #REF!
Name _______SHT1: #REF!
Name _______SHT2: #REF!
Name _______SHT3: #REF!
Name _____SHT1: #REF!
Name _____SHT2: #REF!
Name _____SHT3: #REF!
Name ____SHT1: #REF!
Name ____SHT2: #REF!
Name ____SHT3: #REF!
Name ___a5: #N/A
Name ___a6: #N/A
Name ___OPT8: #N/A
Name ___OPT9: #N/A
Name ___rev1: [1]Sheeta!$I$8
Name ___rev2: [1]Sheeta!$I$9
Name ___rev3: [1]Sheeta!$I$10
Name ___rev4: [1]Sheeta!$I$11
Name ___SHT1: #REF!
Name ___SHT2: #REF!
Name ___SHT3: #REF!
Name __a5: #N/A
Name __a6: #N/A
Name __OPT8: #N/A
Name __OPT9: #N/A
Name __plc1: [3]INSTR!$A$5:$M$208
Name __rev1: [1]Sheeta!$I$8
Name __rev2: [1]Sheeta!$I$9
Name __rev3: [1]Sheeta!$I$10
Name __rev4: [1]Sheeta!$I$11
Name _2NDFOUR: #REF!
Name _2NDONE: #REF!
Name _2NDTHREE: #REF!
Name _4: #REF!
Name _5: #REF!
Name _6: #REF!
Name _7: #REF!
Name _a5: [4]!Module1.UNITOK
Name _a6: [4]!UNITOK
Name _GFDS: '[5]Pag. 1'!$A$203:$S$256
Name _HKT: '[5]Pag. 1'!$A$611:$S$663
Name _KUIY: '[5]Pag. 1'!$A$319:$S$380
Name _LKOIU: '[5]Pag. 1'!$A$319:$S$380
Name _ooo: #REF!
Name _ooo: #REF!
Name _ooo: #REF!
Name _OPT8: [4]!_xlbgnm.OPT8
Name _OPT9: [4]!_xlbgnm.OPT9
Name _Order1: 255
Name _plc1: [3]INSTR!$A$5:$M$208
Name _pppp: '[5]Pag. 1'!$A$665:$S$717
Name _rev1: [1]Sheeta!$I$8

Sheet COVER
A9: END CONNECTION | B9: FLANGE
A10: VALVE MARGIN | B10: APPLICATION
A11: FACTOR | B11: 1.5 | C11: (표준원가 X Factor)
A13: DESCRIPTION | B13: MATERIAL | C13: PRICE | E13: SIZE | F13: 제조원가 | G13: 표준원가 | H13: FACTOR | I13: REMARK
A14: BODY(LUG) | C14: 0 | E14: 80 | F14: ='80-300LB'!$S$64 -> 768785 | G14: ='80-300LB'!$S$67 -> 930229.85 | H14: ='80-300LB'!$S$68 -> 1395344.8
A15: BODY(FLANGE) | B15: A216 WCB | C15: 4300 | E15: 100 | F15: ='100-300LB'!S64 -> 834925 | G15: ='100-300LB'!S67 -> 1010259.2 | H15: ='100-300LB'!S68 -> 1515388.9
A16: DISC | B16: A216 WCB | C16: 4300 | E16: 150 | F16: ='150-300LB'!S64 -> 1376770 | G16: ='150-300LB'!S67 -> 1665891.7 | H16: ='150-300LB'!S68 -> 2498837.5
A17: STEM | B17: A564T630 | C17: 8500 | E17: 200 | F17: ='200-300LB'!S64 -> 1711050 | G17: ='200-300LB'!S67 -> 2070370.5 | H17: ='200-300LB'!S68 -> 3105555.8
A18: SEAT | B18: A240T316L+GARPHITE | C18: SEAT 재질 동일 | E18: 250 | F18: ='250-300LB'!S64 -> 2571970 | G18: ='250-300LB'!S67 -> 3112083.7 | H18: ='250-300LB'!S68 -> 4668125.6
A19: STELLITE | B19: WCB+309+#6 | E19: 300 | F19: ='300-300LB'!S64 -> 2976715 | G19: ='300-300LB'!S67 -> 3601825.1 | H19: ='300-300LB'!S68 -> 5402737.7
A20: SEAT GLAND | B20: SS316L | E20: 350 | F20: ='350-300LB'!S64 -> 4199600 | G20: ='350-300LB'!S67 -> 5081516 | H20: ='350-300LB'!S68 -> 7622274
A21: SEAT GLAND BOLT | B21: B7(다크로) | E21: 400 | I21: N/A
A22: ASSEMBLY BOLT | B22: B7(다크로) | E22: 450 | I22: N/A
A23: BUSH | B23: 316+NICKEL | E23: 500 | I23: N/A
A24: PACKING GLAND | B24: A351 CF8M | E24: 550 | I24: N/A
A25: COLLAR | B25: 316+NICKEL | E25: 600 | F25: ='600-300LB'!S64 -> 11117185 | G25: ='600-300LB'!S67 -> 13451794 | H25: ='600-300LB'!S68 -> 20177691
A26: PACKING PLATE | B26: 316+NICKEL | E26: 650 | I26: N/A
A27: THRUST BEARING | B27: 316+NICKEL | E27: 700 | I27: N/A
A28: BEARING | B28: 316+NICKEL | E28: 750 | F28: ='750-300LB'!S64 -> 15436965 | G28: ='750-300LB'!S67 -> 18678728 | H28: ='750-300LB'!S68 -> 28018091
A29: END COVER | B29: SS400 | E29: 800 | F29: ='800-300LB '!S64 -> 14940950 | G29: ='800-300LB '!S67 -> 18078550 | H29: ='800-300LB '!S68 -> 27117824
A30: TOP COVER | B30: WCB | E30: 850 | I30: N/A
E31: 900 | F31: ='900-300LB'!S64 -> 22306825 | G31: ='900-300LB'!S67 -> 26991258 | H31: ='900-300LB'!S68 -> 40486887
A32: PAINTING | B32: 외주 2COATING | E32: 950 | I32: N/A
A33: 조립비용 | B33: 신규 | E33: 1000 | I33: N/A
E34: 1050 | F34: ='1050-300LB'!S64 -> 28298990 | G34: ='1050-300LB'!S67 -> 34241778 | H34: ='1050-300LB'!S68 -> 51362667
A35: OPERATION | B35: GEAR | E35: 1100 | I35: N/A
E36: 1150 | I36: N/A
E37: 1200 | F37: ='1200-300LB'!S64 -> 41922340 | G37: ='1200-300LB'!S67 -> 50726031 | H37: ='1200-300LB'!S68 -> 76089047
E38: 1250 | I38: N/A
E39: 1300 | I39: N/A
E40: 1350 | I40: N/A
E41: 1350 | I41: N/A

Sheet 주조단가
A1: 업체/재질별 주조 단가 (2019-05-21)
AB2: 0 | AC2: 1 | AD2: 2 | AE2: 3 | AF2: 4 | AG2: 5 | AH2: 6 | AI2: 7 | AJ2: 8 | AK2: 9 | AL2: 10 | AM2: 11 | AN2: 12 | AO2: 13 | AP2: 14 | AQ2: 15 | AR2: 16 | AS2: 17 | AU2: 18 | AW2: 19 | AX2: 20
A3: 업체 | B3: REV | C3: 관리CAPA. | D3: A216 WCB | E3: A217 WC9 | F3: A217 WC1 | G3: A352 LCC | H3: A217 WC6 | I3: A217 CA15 | J3: A351 CG8M | K3: A351 CG3M | L3: A351 CF8 | M3: A351 CF8M | N3: A351 CF3M | O3: A890 4A | P3: A890 5A | Q3: A890 6A | R3: A351 CF3 | S3: A351 CF8C | T3: CW6MC | U3: INCOLOY 25-6Mo | V3: A351 CN7M | W3: MONEL K500 | X3: ALBC3 | Y3: B148 | Z3: A536 | AB3: END CONNECTION | AC3: BODY MATERIAL | AD3: DISC MATERIAL | AE3: SEAT MATERIAL | AF3: STEM MATERIAL | AG3: STELLITE | AH3: SEAT GLAND | AI3: SEAT GLAND BOLT | AJ3: ASSEMBLY BOLT | AK3: BUSH | AL3: PACKING GLAND | AM3: COLLAR | AN3: PACKING PLATE | AO3: THRUST BEARING | AP3: BEARING | AQ3: END COVER | AR3: TOP COVER | AS3: OPERATION | AU3: VALVE MARGIN | AW3: PAINTING/COATING | AX3: 조립비용
A4: 제흥금속 | B4: 폐업(2018년5월) | C4: 50KG이상 | D4: 2700 | E4: 4200 | G4: 2900 | H4: 3900 | L4: 6000 | M4: 7500 | N4: 8500 | AB4: LUG | AC4: A216 WCB | AD4: A216 WCB | AE4: A240T316L | AF4: A276T304 | AG4: SUS+#6 | AH4: SS304 | AI4: B8 | AJ4: B8 | AK4: 316+NICKEL | AL4: A351 CF8M | AM4: 316+NICKEL | AN4: 316+NICKEL | AO4: 316+NICKEL | AP4: 316+NICKEL | AQ4: SS400 | AR4: WCB | AS4: GEAR | AU4: APPLICATION | AW4: 기존 단가 | AX4: 기존 단가
A5: HTF | B5: 품질문제로 품질부 거래 holding | C5: 101KG 이상 | D5: 2600 | L5: 5800 | M5: 7300 | N5: 8300 | AB5: FLANGE | AC5: A536 Gr65-45-12 | AD5: A536 Gr65-45-12 | AE5: A240T316L+GARPHITE | AF5: A276T304L | AG5: WCB+309+#6 | AH5: SS316L | AI5: B8M | AJ5: B8M | AK5: B148 C95400 | AL5: B148 C95400 | AM5: B148 C95400 | AN5: B148 C95400 | AO5: B148 C95400 | AP5: B148 C95400 | AQ5: SS304 | AR5: CF8M | AS5: MOTOR | AU5: N/A | AW5: 외주 2COATING | AX5: 신규
C6: 100KG 이하 | D6: 2800 | M6: 7300 | N6: 8300 | AC6: A351 CF8 | AD6: A351 CF8 | AE6: B443 N06625 | AF6: A276T316 | AI6: B7(다크로) | AJ6: B7(다크로) | AQ6: SS316 | AS6: PNEUMATIC | AW6: 외주 3COATING
A7: 영광스틸 | B7: 단가인상요청 미반영 거래 반납 | C7: 21KG 이상 | D7: 2700 | L7: 5800 | M7: 7700 | N7: 8700 | AC7: A351 CF8M | AD7: A351 CF8M | AE7: B443 N06625+GRAPHITE | AF7: A276T316L
A8: 영광스틸 | C8: 20KG 이하 | D8: 2900 | I8: 5000 | L8: 6000 | M8: 8000 | N8: 9000 | AC8: A351 CF3 | AD8: A351 CF3 | AF8: A564T630
A9: 대림산업 | B9: 2018년 10월 rev. | C9: 200KG이상 | D9: 2600 | E9: 4200 | G9: 2800 | H9: 3600 | I9: 5000 | J9: 8300 | K9: 8500 | L9: 5800 | M9: 7000 | N9: 8000 | O9: 9000 | P9: 11000 | Q9: 12000 | R9: 6300 | T9: 35000 | V9: 17000 | W9: 35000 | AC9: A351 CF3M | AD9: A351 CF3M | AF9: A479T410
A10: 대신금속 | B10: 2018년 11월 rev. | C10: 300KG미만 | D10: 2750 | AC10: A890 4A | AD10: A890 4A | AF10: UNS S31803
A11: 대신금속 | C11: 300KG이상 | D11: 2700 | E11: 4000 | F11: 3000 | G11: 2800 | H11: 3700 | I11: 4800 | J11: 7800 | K11: 8800 | L11: 6000 | M11: 7600 | N11: 8600 | O11: 10500 | P11: 11500 | Q11: 12500 | R11: 6500 | S11: 7000 | T11: 36000 | U11: 25000 | V11: 18000 | W11: 38000 | AC11: A890 5A | AD11: A890 5A | AF11: UNS S32750
A12: 주원특수강 | B12: 100kg 이하는 별도 견적 | C12: 100~300KG | D12: 2800 | AC12: A890 6A | AD12: A890 6A | AF12: MONEL K-400
A13: 주원특수강 | C13: 300KG이상 | D13: 2750 | E13: 4150 | G13: 2900 | H13: 3750 | I13: 4950 | L13: 6100 | M13: 7400 | N13: 8200 | O13: 9000 | P13: 11000 | Q13: 12000 | R13: 6600 | AC13: B148 C95800 | AD13: B148 C95800 | AF13: MONEL K-500
A14: 금화STEEL | B14: 2018년 6월 거래 개시 | D14: 3500 | L14: 6300 | M14: 8300 | N14: 9300 | P14: 18000 | R14: 7300 | AC14: A217 WC9 | AD14: A217 WC9 | AF14: INCONEL 625
A15: 광명금속 | B15: 신규 개발진행 업체 | C15: ~20KG | D15: 4000 | L15: 6900 | M15: 8600 | N15: 9600 | O15: 11500 | P15: 15000 | R15: 7900 | AC15: A217 WC1 | AD15: A217 WC1
C16: 21~50KG | D16: 3700 | L16: 6700 | M16: 8200 | N16: 9200 | O16: 11500 | P16: 15000 | R16: 7700 | AC16: A352 LCC | AD16: A352 LCC
C17: 50KG~ | D17: 3300 | L17: 6500 | M17: 8000 | N17: 9000 | O17: 11500 | P17: 15000 | R17: 7500 | AC17: A217 WC6 | AD17: A217 WC6
A18: 디에스케스텍 | B18: 신규 개발진행 업체 | C18: ~20KG | D18: 3800 | L18: 6700 | M18: 8200 | N18: 8900 | O18: 11500 | P18: 16000 | R18: 7200 | AC18: A217 CA15 | AD18: A217 CA15
C19: 21~50KG | D19: 3300 | L19: 6400 | M19: 8200 | N19: 8900 | O19: 11500 | P19: 16000 | R19: 7200 | AC19: MONEL K-400 | AD19: MONEL K-400
C20: 50KG~ | D20: 3300 | L20: 6400 | M20: 8000 | N20: 8700 | O20: 11500 | P20: 16000 | R20: 7200 | AC20: MONEL K-500 | AD20: MONEL K-500
A21: 대원테크 | B21: 정밀주조업체 | L21: 12600 | M21: 16200 | N21: 18500 | AC21: A351 CG8M | AD21: A351 CG8M
A22: SY메탈 | X22: 11300 | Y22: 11700 | AC22: A351 CG3M | AD22: A351 CG3M
A23: 삼성금속 | X23: 11000 | Y23: 11300 | AC23: A351 CF8C | AD23: A351 CF8C
A24: 진우 ENG | B24: REV.1(17-01-24) NEGO금액 ALBC,B148 -150원- | C24: DN350이하 | X24: 12150 | Y24: 12650 | AC24: CW6MC | AD24: CW6MC
A25: 진우 ENG | C25: DN400이상 | X25: 11650 | Y25: 12250 | AC25: INCOLOY 25-6Mo | AD25: INCOLOY 25-6Mo
A26: 진우 ENG | C26: 200KG이상 | X26: 10950 | Y26: 11350 | AC26: A351 CN7M | AD26: A351 CN7M
A27: 마천캐스트 | B27: 2019-01-21 단가인상요청 (1950원->2100원) | C27: DN500~1000 | Z27: 2100
A28: 마천캐스트 | C28: DN2200 이하 | Z28: 1880
A29: 마천캐스트 | C29: DN2200 초과 | Z29: 1900
A30: 화성금속 | C30: 1500이상 | Z30: 2000
A31: 신우공업 | B31: 단가인상요청 미반영 거래 반납 | C31: 450A이하 | Z31: 2050
A32: 신우공업 | C32: 500A이상 | Z32: 1880
A33: 신우공업 | C33: 800KG이상 | Z33: 1880
A35: NOTE
A36: 주강 선급품 기존 단가에서 +100원/KG 추가됨
A37: 중공형 DISC는 용접비 +400원/KG 추가됨 (SY메탈 DN1000미만 +2000원/KG , DN1000이상 +1500원/KG)
A38: 영광 STEEL 주강 -100원 SUS -200원 NEGO(2017-01-12)
A39: 신우공업 - DN500이상 -70원, 800KG이상 -20원(2017-01-24)
A40: 신우공업 - DN450이하 -50원 NEGO(2017-10-10)
A41: HTF,대원 - 단가적용(2017-10-10)
...

Sheet 80-300LB
A1: TREIPLE VALVE 원가분석 ( 300# FLANGE SHORT)
T2: 단위 : 원
A3: SIZE | C3: DN 80 | D3: CLASS | E3: 300LB | F3: TYPE | G3: =COVER!B9 -> FLANGE | H3: TRIPLE 가공공정 | R3: F TO F | S3: API 609 CAT'- B SHROT PATTERN | T3: REMARK
A5: NO. | C5: DESCRIPTION | D5: MATERIAL | E5: 재료비 | H5: ST | I5: 세부 가공비 | R5: 가공비 | S5: 소 계 ( 재료비 + 가공비 )
I6: A | J6: B | K6: C | L6: D | M6: E | N6: F | O6: G | P6: H | Q6: I
E7: 중량 | F7: 단가 | G7: 소재비 | I7: 터닝/선반 | J7: 레디알 | K7: 보링 | L7: 터닝/선반 | M7: 동시보링 | N7: 레이알 | O7: 선반 | P7: 밀링 | Q7: 기타
A8: S T A N D A R D | B8: 1 | C8: =COVER!A14 -> BODY(LUG) | D8: =COVER!B14 -> 0 | E8: 19 | F8: =COVER!C14 -> 0 | G8: =F8*E8 -> 0 | I8: =I10*I9 -> 3.6001489e+13 | J8: =J10*J9 -> 4.3341753e+13 | K8: =K10*K9 -> 1.6833509e+14 | L8: =L10*L9 -> 5.0670662e+14 | M8: =M10*M9 -> 6.3241734e+14 | N8: =N10*N9 -> 4.6528628e+13 | O8: =O10*O9 -> 0 | P8: =P10*P9 -> 0 | Q8: =Q10*Q9 -> 10000000000000 | R8: =IF(COVER!C14>0,79000*1.2,0) -> 0 | S8: =G8+R8 -> 0 | T8: LUG
B9: 1-1 | C9: =COVER!A15 -> BODY(FLANGE) | D9: =COVER!B15 -> A216 WCB | E9: 38 | F9: =COVER!C15 -> 4300 | G9: =F9*E9 -> 163400 | I9: =I11*I10 -> 2.3489854e+09 | J9: =J11*J10 -> 2.658302e+09 | K9: =K11*K10 -> 6.5682514e+09 | L9: =L11*L10 -> 1.3693182e+10 | M9: =M11*M10 -> 1.5873372e+10 | N9: =N11*N10 -> 2.7870633e+09 | O9: =O11*O10 -> 0 | P9: =P11*P10 -> 0 | Q9: =Q11*Q10 -> 1000000000 | R9: =IF(COVER!C15>0,80000*1.2,0) -> 96000 | S9: =G9+R9 -> 259400 | T9: FLANGE
H10: 기계임률 / H | I10: =I11/10 -> 15326.4 | J10: =J11/10 -> 16304.3 | K10: =K11/10 -> 25628.6 | L10: =L11/10 -> 37004.3 | M10: =M11/10 -> 39841.4 | N10: =N11/10 -> 16694.5 | O10: =O11/10 -> 0 | P10: =P11/10 -> 0 | Q10: =Q11/10 -> 10000 | S10: =G10+R10 -> 0
H11: 기계임률 / DAY (10시간) | I11: 153264 | J11: 163043 | K11: 256286 | L11: 370043 | M11: 398414 | N11: 166945 | O11: 0 | P11: 0 | Q11: 100000 | S11: =G11+R11 -> 0
B12: 2 | C12: DISC | D12: =COVER!B16 -> A216 WCB | E12: 1.7 | F12: =COVER!C16 -> 4300 | G12: =F12*E12 -> 7310 | I12: =I13*I14 -> 7663.2 | J12: =J13*J14 -> 0 | K12: =K13*K14 -> 4891.29 | L12: =L13*L14 -> 11485 | M12: =M13*M14 -> 0 | N12: =N13*N14 -> 0 | O12: =O13*O14 -> 0 | P12: =P13*P14 -> 0 | Q12: =Q13*Q14 -> 3000 | R12: 55200 | S12: =G12+R12 -> 62510
H13: 표준가공 ( S/T : EA/H) | I13: 0.5 | J13: 0 | K13: 0.3 | L13: 0.5 | M13: 0 | N13: 0 | Q13: 0.3 | S13: =G13+R13 -> 0
H14: 기계임률 / H | I14: =I15/10 -> 15326.4 | J14: =J15/10 -> 16304.3 | K14: =K15/10 -> 16304.3 | L14: =L15/10 -> 22970 | M14: =M15/10 -> 39841.4 | N14: =N15/10 -> 16694.5 | O14: =O15/10 -> 0 | P14: =P15/10 -> 0 | Q14: =Q15/10 -> 10000 | S14: =G14+R14 -> 0
H15: 기계임률 / DAY | I15: 153264 | J15: 163043 | K15: 163043 | L15: 229700 | M15: 398414 | N15: 166945 | O15: 0 | P15: 0 | Q15: 100000 | S15: =G15+R15 -> 0
B16: 3 | C16: STELLITE on BODY | D16: =COVER!B19 -> WCB+309+#6 | E16: 1 | F16: =IF(D16="SUS+#6",X76,IF(D16="WCB+309+#6",X77)) -> 35200 | G16: =F16*E16 -> 35200 | I16: 0 | J16: 0 | K16: 0 | L16: 0 | M16: 0 | N16: 0 | O16: 0 | P16: 0 | Q16: 0 | R16: 0 | S16: =G16+R16 -> 35200
B17: 4 | C17: DISC SEAT | D17: =COVER!B18 -> A240T316L+GARPHITE | E17: 1 | F17: =IF(D17="A240T316L+GARPHITE",Y84+Z84) -> 29200 | G17: =F17*E17 -> 29200 | I17: 0 | J17: 0 | K17: 0 | L17: 0 | M17: 0 | N17: 0 | O17: 0 | P17: 0 | Q17: 0 | R17: =Z84*1.3 -> 36400 | S17: =G17+R17 -> 65600
B18: 5 | C18: SEAT GLAND | D18: =COVER!B20 -> SS316L | E18: 1 | F18: =IF(D18="SS304",Y82,IF(D18="SS316L",Z82)) -> 4800 | G18: =E18*F18 -> 4800 | I18: =I19*I20 -> 4597.92 | J18: =J19*J20 -> 4891.29 | K18: =K19*K20 -> 0 | L18: =L19*L20 -> 0 | M18: =M19*M20 -> 0 | N18: =N19*N20 -> 0 | O18: =O19*O20 -> 0 | P18: =P19*P20 -> 0 | Q18: =Q19*Q20 -> 2000 | R18: =AA82*1.5 -> 33000 | S18: =G18+R18 -> 37800
G19: =E19*F19 -> 0 | H19: 표준가공 ( S/T : EA/H) | I19: 0.3 | J19: 0.3 | Q19: 0.2 | S19: =G19+R19 -> 0
G20: =E20*F20 -> 0 | H20: 표준가공 ( S/T : EA/H) | I20: =I21/10 -> 15326.4 | J20: =J21/10 -> 16304.3 | K20: =K21/10 -> 0 | L20: =L21/10 -> 0 | M20: =M21/10 -> 0 | N20: =N21/10 -> 0 | O20: =O21/10 -> 0 | P20: =P21/10 -> 0 | Q20: =Q21/10 -> 10000 | S20: =G20+R20 -> 0
G21: =E21*F21 -> 0 | H21: 표준가공 ( S/T : EA/H) | I21: 153264 | J21: 163043 | Q21: 100000 | S21: =G21+R21 -> 0
B22: 6 | C22: DISC SEAT Ret-Gasket | D22: 316L+G/P | E22: 1 | F22: =Y86 -> 2040 | G22: =F22*E22 -> 2040 | I22: 0 | J22: 0 | K22: 0 | L22: 0 | M22: 0 | N22: 0 | O22: 0 | P22: 0 | Q22: 0 | R22: 0 | S22: =G22+R22 -> 2040
B23: 7 | C23: SEAT GLAND BOLT | D23: =COVER!B21 -> B7(다크로) | E23: 6 | F23: =IF(D23="B8",Y91,IF(D23="B8M",Z91,IF(D23="B7(다크로)",AA91))) -> 300 | G23: =F23*E23 -> 1800 | I23: 0 | J23: 0 | K23: 0 | L23: 0 | M23: 0 | N23: 0 | O23: 0 | P23: 0 | Q23: 0 | R23: 0 | S23: =G23+R23 -> 1800
B24: 8 | C24: STEM | D24: =COVER!B17 -> A564T630 | E24: 1 | F24: =COVER!C17 -> 8500 | G24: =F24*E24 -> 8500 | I24: =I25*I26 -> 4597.92 | J24: =J25*J26 -> 0 | K24: =K25*K26 -> 0 | L24: =L25*L26 -> 0 | M24: =M25*M26 -> 0 | N24: =N25*N26 -> 0 | O24: =O25*O26 -> 0 | P24: =P25*P26 -> 0 | Q24: =Q25*Q26 -> 1000 | R24: =R12*0.3 -> 16560 | S24: =G24+R24 -> 25060
H25: 표준가공 ( S/T : EA/H) | I25: 0.3 | Q25: 0.1 | S25: =G25+R25 -> 0
H26: 표준가공 ( S/T : EA/H) | I26: =I27/10 -> 15326.4 | Q26: =Q27/10 -> 10000 | S26: =G26+R26 -> 0
H27: 표준가공 ( S/T : EA/H) | I27: 153264 | Q27: 100000 | S27: =G27+R27 -> 0
B28: 9 | C28: PACKING | D28: PILLAR | E28: 1 | F28: 5300 | G28: =E28*F28 -> 5300 | R28: 0 | S28: =G28+R28 -> 5300
B29: 10 | C29: PACKING GLAND | D29: =COVER!B24 -> A351 CF8M | E29: 1 | F29: =IF(D29="A351 CF8M",Y98,IF(D29="B148 C95400",Z98)) -> 18000 | G29: =F29*E29 -> 18000 | I29: =I30*I31 -> 1532.64 | J29: =J30*J31 -> 1630.43 | K29: =K30*K31 -> 0 | L29: =L30*L31 -> 0 | M29: =M30*M31 -> 0 | N29: =N30*N31 -> 0 | O29: =O30*O31 -> 0 | P29: =P30*P31 -> 0 | Q29: =Q30*Q31 -> 0 | R29: 0 | S29: =G29+R29 -> 18000
H30: 표준가공 ( S/T : EA/H) | I30: 0.1 | J30: 0.1 | S30: =G30+R30 -> 0
H31: 표준가공 ( S/T : EA/H) | I31: =I32/10 -> 15326.4 | J31: =J32/10 -> 16304.3 | S31: =G31+R31 -> 0
H32: 표준가공 ( S/T : EA/H) | I32: 153264 | J32: 163043 | S32: =G32+R32 -> 0
B33: 11 | C33: PACKING PLATE | D33: =COVER!B26 -> 316+NICKEL | E33: 1 | F33: =IF(D33="316+NICKEL",Y100,IF(D33="B148 C95400",Z100)) -> 6000 | G33: =F33*E33 -> 6000 | I33: =I34*I35 -> 1532.64 | J33: =J34*J35 -> 0 | K33: =K34*K35 -> 0 | L33: =L34*L35 -> 0 | M33: =M34*M35 -> 0 | N33: =N34*N35 -> 0 | O33: =O34*O35 -> 0 | P33: =P34*P35 -> 0 | Q33: =Q34*Q35 -> 0 | R33: 0 | S33: =G33+R33 -> 6000 | T33: SET 단가
H34: 표준가공 ( S/T : EA/H) | I34: 0.1 | S34: =G34+R34 -> 0
H35: 표준가공 ( S/T : EA/H) | I35: =I36/10 -> 15326.4 | S35: =G35+R35 -> 0
H36: 표준가공 ( S/T : EA/H) | I36: 153264 | S36: =G36+R36 -> 0
B37: 12 | C37: PACKING GLAND BOLT / NUT | D37: =COVER!B22 -> B7(다크로) | E37: 4 | F37: =IF(D37="B8",Y92,IF(D37="B8M",Z92,IF(D37="B7(다크로)",AA92))) -> 1000 | G37: =E37*F37 -> 4000 | I37: 0 | J37: 0 | K37: 0 | L37: 0 | M37: 0 | N37: 0 | O37: 0 | P37: 0 | Q37: 0 | R37: 0 | S37: =G37+R37 -> 4000
B38: 13 | C38: LIVE LOADING SPRING | E38: 1 | F38: 3000 | G38: =E38*F38 -> 3000 | I38: 0 | J38: 0 | K38: 0 | L38: 0 | M38: 0 | N38: 0 | O38: 0 | P38: 0 | Q38: 0 | R38: 0 | S38: =G38+R38 -> 3000
B39: 14 | C39: BUSH(MAIN) | D39: =COVER!B23 -> 316+NICKEL | E39: 2 | F39: =IF(D39="316+NICKEL",Y96,IF(D39="B148 C95400",Z96)) -> 21500 | G39: =F39*1 -> 21500 | I39: =I40*I41 -> 0 | J39: =J40*J41 -> 0 | K39: =K40*K41 -> 0 | L39: =L40*L41 -> 0 | M39: =M40*M41 -> 0 | N39: =N40*N41 -> 0 | O39: =O40*O41 -> 0 | P39: =P40*P41 -> 0 | Q39: =Q40*Q41 -> 0 | R39: 0 | S39: =G39+R39 -> 21500 | T39: SET 단가
B40: 15 | C40: BUSH(STUB) | D40: =COVER!B23 -> 316+NICKEL | E40: 2 | F40: =IF(D40="316+NICKEL",Y97,IF(D40="B148 C95400",Z97)) -> 20500 | G40: =F40*1 -> 20500 | I40: =I41*I42 -> 0 | J40: =J41*J42 -> 0 | K40: =K41*K42 -> 0 | L40: =L41*L42 -> 0 | M40: =M41*M42 -> 0 | N40: =N41*N42 -> 0 | O40: =O41*O42 -> 0 | P40: =P41*P42 -> 0 | Q40: =Q41*Q42 -> 0 | R40: 0 | S40: =G40+R40 -> 20500 | T40: SET 단가
H41: 표준가공 ( S/T : EA/H) | S41: =G41+R41 -> 0
...

Sheet 100-300LB
A1: TREIPLE VALVE 원가분석 ( 300# FLANGE SHORT)
T2: 단위 : 원
A3: SIZE | C3: DN 100 | D3: CLASS | E3: 300LB | F3: TYPE | G3: =COVER!B9 -> FLANGE | H3: TRIPLE 가공공정 | R3: F TO F | S3: API 609 CAT'- B SHROT PATTERN | T3: REMARK
A5: NO. | C5: DESCRIPTION | D5: MATERIAL | E5: 재료비 | H5: ST | I5: 세부 가공비 | R5: 가공비 | S5: 소 계 ( 재료비 + 가공비 )
I6: A | J6: B | K6: C | L6: D | M6: E | N6: F | O6: G | P6: H | Q6: I
E7: 중량 | F7: 단가 | G7: 소재비 | I7: 터닝/선반 | J7: 레디알 | K7: 보링 | L7: 터닝/선반 | M7: 동시보링 | N7: 레이알 | O7: 선반 | P7: 밀링 | Q7: 기타
A8: S T A N D A R D | B8: 1 | C8: =COVER!A14 -> BODY(LUG) | D8: =COVER!B14 -> 0 | E8: 21 | F8: =COVER!C14 -> 0 | G8: =F8*E8 -> 0 | I8: =I10*I9 -> 3.6001489e+13 | J8: =J10*J9 -> 4.3341753e+13 | K8: =K10*K9 -> 1.6833509e+14 | L8: =L10*L9 -> 5.0670662e+14 | M8: =M10*M9 -> 6.3241734e+14 | N8: =N10*N9 -> 4.6528628e+13 | O8: =O10*O9 -> 0 | P8: =P10*P9 -> 0 | Q8: =Q10*Q9 -> 10000000000000 | R8: =IF(COVER!C14>0,99000*1.2,0) -> 0 | S8: =G8+R8 -> 0 | T8: LUG
B9: 1-1 | C9: =COVER!A15 -> BODY(FLANGE) | D9: =COVER!B15 -> A216 WCB | E9: 41 | F9: =COVER!C15 -> 4300 | G9: =F9*E9 -> 176300 | I9: =I11*I10 -> 2.3489854e+09 | J9: =J11*J10 -> 2.658302e+09 | K9: =K11*K10 -> 6.5682514e+09 | L9: =L11*L10 -> 1.3693182e+10 | M9: =M11*M10 -> 1.5873372e+10 | N9: =N11*N10 -> 2.7870633e+09 | O9: =O11*O10 -> 0 | P9: =P11*P10 -> 0 | Q9: =Q11*Q10 -> 1000000000 | R9: =IF(COVER!C15>0,100000*1.2,0) -> 120000 | S9: =G9+R9 -> 296300 | T9: FLANGE
H10: 기계임률 / H | I10: =I11/10 -> 15326.4 | J10: =J11/10 -> 16304.3 | K10: =K11/10 -> 25628.6 | L10: =L11/10 -> 37004.3 | M10: =M11/10 -> 39841.4 | N10: =N11/10 -> 16694.5 | O10: =O11/10 -> 0 | P10: =P11/10 -> 0 | Q10: =Q11/10 -> 10000 | S10: =G10+R10 -> 0
H11: 기계임률 / DAY (10시간) | I11: 153264 | J11: 163043 | K11: 256286 | L11: 370043 | M11: 398414 | N11: 166945 | O11: 0 | P11: 0 | Q11: 100000 | S11: =G11+R11 -> 0
B12: 2 | C12: DISC | D12: =COVER!B16 -> A216 WCB | E12: 2 | F12: =COVER!C16 -> 4300 | G12: =F12*E12 -> 8600 | I12: =I13*I14 -> 7663.2 | J12: =J13*J14 -> 0 | K12: =K13*K14 -> 4891.29 | L12: =L13*L14 -> 11485 | M12: =M13*M14 -> 0 | N12: =N13*N14 -> 0 | O12: =O13*O14 -> 0 | P12: =P13*P14 -> 0 | Q12: =Q13*Q14 -> 3000 | R12: 69000 | S12: =G12+R12 -> 77600
H13: 표준가공 ( S/T : EA/H) | I13: 0.5 | J13: 0 | K13: 0.3 | L13: 0.5 | M13: 0 | N13: 0 | Q13: 0.3 | S13: =G13+R13 -> 0
H14: 기계임률 / H | I14: =I15/10 -> 15326.4 | J14: =J15/10 -> 16304.3 | K14: =K15/10 -> 16304.3 | L14: =L15/10 -> 22970 | M14: =M15/10 -> 39841.4 | N14: =N15/10 -> 16694.5 | O14: =O15/10 -> 0 | P14: =P15/10 -> 0 | Q14: =Q15/10 -> 10000 | S14: =G14+R14 -> 0
H15: 기계임률 / DAY | I15: 153264 | J15: 163043 | K15: 163043 | L15: 229700 | M15: 398414 | N15: 166945 | O15: 0 | P15: 0 | Q15: 100000 | S15: =G15+R15 -> 0
B16: 3 | C16: STELLITE on BODY | D16: =COVER!B19 -> WCB+309+#6 | E16: 1 | F16: =IF(D16="SUS+#6",X76,IF(D16="WCB+309+#6",X77)) -> 46200 | G16: =F16*E16 -> 46200 | I16: 0 | J16: 0 | K16: 0 | L16: 0 | M16: 0 | N16: 0 | O16: 0 | P16: 0 | Q16: 0 | R16: 0 | S16: =G16+R16 -> 46200
B17: 4 | C17: DISC SEAT | D17: =COVER!B18 -> A240T316L+GARPHITE | E17: 1 | F17: =IF(D17="A240T316L+GARPHITE",Y84+Z84) -> 31700 | G17: =F17*E17 -> 31700 | I17: 0 | J17: 0 | K17: 0 | L17: 0 | M17: 0 | N17: 0 | O17: 0 | P17: 0 | Q17: 0 | R17: =Z84*1.3 -> 39000 | S17: =G17+R17 -> 70700
B18: 5 | C18: SEAT GLAND | D18: =COVER!B20 -> SS316L | E18: 1 | F18: =IF(D18="SS304",Y82,IF(D18="SS316L",Z82)) -> 6240 | G18: =E18*F18 -> 6240 | I18: =I19*I20 -> 4597.92 | J18: =J19*J20 -> 4891.29 | K18: =K19*K20 -> 0 | L18: =L19*L20 -> 0 | M18: =M19*M20 -> 0 | N18: =N19*N20 -> 0 | O18: =O19*O20 -> 0 | P18: =P19*P20 -> 0 | Q18: =Q19*Q20 -> 2000 | R18: =AA82*1.5 -> 33000 | S18: =G18+R18 -> 39240
H19: 표준가공 ( S/T : EA/H) | I19: 0.3 | J19: 0.3 | Q19: 0.2 | S19: =G19+R19 -> 0
H20: 표준가공 ( S/T : EA/H) | I20: =I21/10 -> 15326.4 | J20: =J21/10 -> 16304.3 | K20: =K21/10 -> 0 | L20: =L21/10 -> 0 | M20: =M21/10 -> 0 | N20: =N21/10 -> 0 | O20: =O21/10 -> 0 | P20: =P21/10 -> 0 | Q20: =Q21/10 -> 10000 | S20: =G20+R20 -> 0
H21: 표준가공 ( S/T : EA/H) | I21: 153264 | J21: 163043 | Q21: 100000 | S21: =G21+R21 -> 0
B22: 6 | C22: DISC SEAT Ret-Gasket | D22: 316L+G/P | E22: 1 | F22: =Y86 -> 2520 | G22: =F22*E22 -> 2520 | I22: 0 | J22: 0 | K22: 0 | L22: 0 | M22: 0 | N22: 0 | O22: 0 | P22: 0 | Q22: 0 | R22: 0 | S22: =G22+R22 -> 2520
B23: 7 | C23: SEAT GLAND BOLT | D23: =COVER!B21 -> B7(다크로) | E23: 6 | F23: =IF(D23="B8",Y91,IF(D23="B8M",Z91,IF(D23="B7(다크로)",AA91))) -> 300 | G23: =F23*E23 -> 1800 | I23: 0 | J23: 0 | K23: 0 | L23: 0 | M23: 0 | N23: 0 | O23: 0 | P23: 0 | Q23: 0 | R23: 0 | S23: =G23+R23 -> 1800
B24: 8 | C24: STEM | D24: =COVER!B17 -> A564T630 | E24: 2 | F24: =COVER!C17 -> 8500 | G24: =F24*E24 -> 17000 | I24: =I25*I26 -> 4597.92 | J24: =J25*J26 -> 0 | K24: =K25*K26 -> 0 | L24: =L25*L26 -> 0 | M24: =M25*M26 -> 0 | N24: =N25*N26 -> 0 | O24: =O25*O26 -> 0 | P24: =P25*P26 -> 0 | Q24: =Q25*Q26 -> 1000 | R24: =R12*0.3 -> 20700 | S24: =G24+R24 -> 37700
H25: 표준가공 ( S/T : EA/H) | I25: 0.3 | Q25: 0.1 | S25: =G25+R25 -> 0
H26: 표준가공 ( S/T : EA/H) | I26: =I27/10 -> 15326.4 | Q26: =Q27/10 -> 10000 | S26: =G26+R26 -> 0
H27: 표준가공 ( S/T : EA/H) | I27: 153264 | Q27: 100000 | S27: =G27+R27 -> 0
B28: 9 | C28: PACKING | D28: PILLAR | E28: 1 | F28: 5500 | G28: =E28*F28 -> 5500 | R28: 0 | S28: =G28+R28 -> 5500
B29: 10 | C29: PACKING GLAND | D29: =COVER!B24 -> A351 CF8M | E29: 1 | F29: =IF(D29="A351 CF8M",Y99,IF(D29="B148 C95400",Z99)) -> 15000 | G29: =F29*E29 -> 15000 | I29: =I30*I31 -> 1532.64 | J29: =J30*J31 -> 1630.43 | K29: =K30*K31 -> 0 | L29: =L30*L31 -> 0 | M29: =M30*M31 -> 0 | N29: =N30*N31 -> 0 | O29: =O30*O31 -> 0 | P29: =P30*P31 -> 0 | Q29: =Q30*Q31 -> 0 | R29: 0 | S29: =G29+R29 -> 15000
H30: 표준가공 ( S/T : EA/H) | I30: 0.1 | J30: 0.1 | S30: =G30+R30 -> 0
H31: 표준가공 ( S/T : EA/H) | I31: =I32/10 -> 15326.4 | J31: =J32/10 -> 16304.3 | S31: =G31+R31 -> 0
H32: 표준가공 ( S/T : EA/H) | I32: 153264 | J32: 163043 | S32: =G32+R32 -> 0
B33: 11 | C33: PACKING PLATE | D33: =COVER!B26 -> 316+NICKEL | E33: 1 | F33: =IF(D33="316+NICKEL",Y101,IF(D33="B148 C95400",Z101)) -> 5000 | G33: =F33*E33 -> 5000 | I33: =I34*I35 -> 1532.64 | J33: =J34*J35 -> 0 | K33: =K34*K35 -> 0 | L33: =L34*L35 -> 0 | M33: =M34*M35 -> 0 | N33: =N34*N35 -> 0 | O33: =O34*O35 -> 0 | P33: =P34*P35 -> 0 | Q33: =Q34*Q35 -> 0 | R33: 0 | S33: =G33+R33 -> 5000 | T33: SET 단가
H34: 표준가공 ( S/T : EA/H) | I34: 0.1 | S34: =G34+R34 -> 0
H35: 표준가공 ( S/T : EA/H) | I35: =I36/10 -> 15326.4 | S35: =G35+R35 -> 0
H36: 표준가공 ( S/T : EA/H) | I36: 153264 | S36: =G36+R36 -> 0
B37: 12 | C37: PACKING GLAND BOLT / NUT | D37: =COVER!B22 -> B7(다크로) | E37: 4 | F37: =IF(D37="B8",Y93,IF(D37="B8M",Z93,IF(D37="B7(다크로)",AA93))) -> 1000 | G37: =E37*F37 -> 4000 | I37: 0 | J37: 0 | K37: 0 | L37: 0 | M37: 0 | N37: 0 | O37: 0 | P37: 0 | Q37: 0 | R37: 0 | S37: =G37+R37 -> 4000
B38: 13 | C38: LIVE LOADING SPRING | E38: 1 | F38: 3000 | G38: =E38*F38 -> 3000 | I38: 0 | J38: 0 | K38: 0 | L38: 0 | M38: 0 | N38: 0 | O38: 0 | P38: 0 | Q38: 0 | R38: 0 | S38: =G38+R38 -> 3000
B39: 14 | C39: BUSH(MAIN) | D39: =COVER!B23 -> 316+NICKEL | E39: 2 | F39: =IF(D39="316+NICKEL",Y97,IF(D39="B148 C95400",Z97)) -> 14500 | G39: =F39*1 -> 14500 | I39: =I40*I41 -> 0 | J39: =J40*J41 -> 0 | K39: =K40*K41 -> 0 | L39: =L40*L41 -> 0 | M39: =M40*M41 -> 0 | N39: =N40*N41 -> 0 | O39: =O40*O41 -> 0 | P39: =P40*P41 -> 0 | Q39: =Q40*Q41 -> 0 | R39: 0 | S39: =G39+R39 -> 14500 | T39: SET 단가
B40: 15 | C40: BUSH(STUB) | D40: =COVER!B23 -> 316+NICKEL | E40: 2 | F40: =IF(D40="316+NICKEL",Y98,IF(D40="B148 C95400",Z98)) -> 13500 | G40: =F40*1 -> 13500 | I40: =I41*I42 -> 0 | J40: =J41*J42 -> 0 | K40: =K41*K42 -> 0 | L40: =L41*L42 -> 0 | M40: =M41*M42 -> 0 | N40: =N41*N42 -> 0 | O40: =O41*O42 -> 0 | P40: =P41*P42 -> 0 | Q40: =Q41*Q42 -> 0 | R40: 0 | S40: =G40+R40 -> 13500 | T40: SET 단가
H41: 표준가공 ( S/T : EA/H) | S41: =G41+R41 -> 0
...

Sheet 150-300LB
A1: TREIPLE VALVE 원가분석 ( 300# FLANGE SHORT)
T2: 단위 : 원
A3: SIZE | C3: DN 150 | D3: CLASS | E3: 300LB | F3: TYPE | G3: =COVER!B9 -> FLANGE | H3: TRIPLE 가공공정 | R3: F TO F | S3: API 609 CAT'- B SHROT PATTERN | T3: REMARK
A5: NO. | C5: DESCRIPTION | D5: MATERIAL | E5: 재료비 | H5: ST | I5: 세부 가공비 | R5: 가공비 | S5: 소 계 ( 재료비 + 가공비 )
I6: A | J6: B | K6: C | L6: D | M6: E | N6: F | O6: G | P6: H | Q6: I
E7: 중량 | F7: 단가 | G7: 소재비 | I7: 터닝/선반 | J7: 레디알 | K7: 보링 | L7: 터닝/선반 | M7: 동시보링 | N7: 레이알 | O7: 선반 | P7: 밀링 | Q7: 기타
A8: S T A N D A R D | B8: 1 | C8: =COVER!A14 -> BODY(LUG) | D8: =COVER!B14 -> 0 | E8: 37 | F8: =COVER!C14 -> 0 | G8: =F8*E8 -> 0 | I8: =I10*I9 -> 3.6001489e+13 | J8: =J10*J9 -> 4.3341753e+13 | K8: =K10*K9 -> 1.6833509e+14 | L8: =L10*L9 -> 5.0670662e+14 | M8: =M10*M9 -> 6.3241734e+14 | N8: =N10*N9 -> 4.6528628e+13 | O8: =O10*O9 -> 0 | P8: =P10*P9 -> 0 | Q8: =Q10*Q9 -> 10000000000000 | R8: =IF(COVER!C14>0,140000*1.2,0) -> 0 | S8: =G8+R8 -> 0 | T8: LUG
B9: 1-1 | C9: =COVER!A15 -> BODY(FLANGE) | D9: =COVER!B15 -> A216 WCB | E9: 74 | F9: =COVER!C15 -> 4300 | G9: =F9*E9 -> 318200 | I9: =I11*I10 -> 2.3489854e+09 | J9: =J11*J10 -> 2.658302e+09 | K9: =K11*K10 -> 6.5682514e+09 | L9: =L11*L10 -> 1.3693182e+10 | M9: =M11*M10 -> 1.5873372e+10 | N9: =N11*N10 -> 2.7870633e+09 | O9: =O11*O10 -> 0 | P9: =P11*P10 -> 0 | Q9: =Q11*Q10 -> 1000000000 | R9: =IF(COVER!C15>0,150000*1.2,0) -> 180000 | S9: =G9+R9 -> 498200 | T9: FLANGE
H10: 기계임률 / H | I10: =I11/10 -> 15326.4 | J10: =J11/10 -> 16304.3 | K10: =K11/10 -> 25628.6 | L10: =L11/10 -> 37004.3 | M10: =M11/10 -> 39841.4 | N10: =N11/10 -> 16694.5 | O10: =O11/10 -> 0 | P10: =P11/10 -> 0 | Q10: =Q11/10 -> 10000 | S10: =G10+R10 -> 0
H11: 기계임률 / DAY (10시간) | I11: 153264 | J11: 163043 | K11: 256286 | L11: 370043 | M11: 398414 | N11: 166945 | O11: 0 | P11: 0 | Q11: 100000 | S11: =G11+R11 -> 0
B12: 2 | C12: DISC | D12: =COVER!B16 -> A216 WCB | E12: 5.5 | F12: =COVER!C16 -> 4300 | G12: =F12*E12 -> 23650 | I12: =I13*I14 -> 7663.2 | J12: =J13*J14 -> 0 | K12: =K13*K14 -> 4891.29 | L12: =L13*L14 -> 11485 | M12: =M13*M14 -> 0 | N12: =N13*N14 -> 0 | O12: =O13*O14 -> 0 | P12: =P13*P14 -> 0 | Q12: =Q13*Q14 -> 3000 | R12: 103500 | S12: =G12+R12 -> 127150
H13: 표준가공 ( S/T : EA/H) | I13: 0.5 | J13: 0 | K13: 0.3 | L13: 0.5 | M13: 0 | N13: 0 | Q13: 0.3 | S13: =G13+R13 -> 0
H14: 기계임률 / H | I14: =I15/10 -> 15326.4 | J14: =J15/10 -> 16304.3 | K14: =K15/10 -> 16304.3 | L14: =L15/10 -> 22970 | M14: =M15/10 -> 39841.4 | N14: =N15/10 -> 16694.5 | O14: =O15/10 -> 0 | P14: =P15/10 -> 0 | Q14: =Q15/10 -> 10000 | S14: =G14+R14 -> 0
H15: 기계임률 / DAY | I15: 153264 | J15: 163043 | K15: 163043 | L15: 229700 | M15: 398414 | N15: 166945 | O15: 0 | P15: 0 | Q15: 100000 | S15: =G15+R15 -> 0
B16: 3 | C16: STELLITE on BODY | D16: =COVER!B19 -> WCB+309+#6 | E16: 1 | F16: =IF(D16="SUS+#6",X76,IF(D16="WCB+309+#6",X77)) -> 72500 | G16: =F16*E16 -> 72500 | I16: 0 | J16: 0 | K16: 0 | L16: 0 | M16: 0 | N16: 0 | O16: 0 | P16: 0 | Q16: 0 | R16: 0 | S16: =G16+R16 -> 72500
B17: 4 | C17: DISC SEAT | D17: =COVER!B18 -> A240T316L+GARPHITE | E17: 1 | F17: =IF(D17="A240T316L+GARPHITE",Y84+Z84) -> 38400 | G17: =F17*E17 -> 38400 | I17: 0 | J17: 0 | K17: 0 | L17: 0 | M17: 0 | N17: 0 | O17: 0 | P17: 0 | Q17: 0 | R17: =Z84*1.3 -> 45500 | S17: =G17+R17 -> 83900
B18: 5 | C18: SEAT GLAND | D18: =COVER!B20 -> SS316L | E18: 1 | F18: =IF(D18="SS304",Y82,IF(D18="SS316L",Z82)) -> 12480 | G18: =E18*F18 -> 12480 | I18: =I19*I20 -> 4597.92 | J18: =J19*J20 -> 4891.29 | K18: =K19*K20 -> 0 | L18: =L19*L20 -> 0 | M18: =M19*M20 -> 0 | N18: =N19*N20 -> 0 | O18: =O19*O20 -> 0 | P18: =P19*P20 -> 0 | Q18: =Q19*Q20 -> 2000 | R18: =AA82*1.5 -> 45000 | S18: =G18+R18 -> 57480
H19: 표준가공 ( S/T : EA/H) | I19: 0.3 | J19: 0.3 | Q19: 0.2 | S19: =G19+R19 -> 0
H20: 표준가공 ( S/T : EA/H) | I20: =I21/10 -> 15326.4 | J20: =J21/10 -> 16304.3 | K20: =K21/10 -> 0 | L20: =L21/10 -> 0 | M20: =M21/10 -> 0 | N20: =N21/10 -> 0 | O20: =O21/10 -> 0 | P20: =P21/10 -> 0 | Q20: =Q21/10 -> 10000 | S20: =G20+R20 -> 0
H21: 표준가공 ( S/T : EA/H) | I21: 153264 | J21: 163043 | Q21: 100000 | S21: =G21+R21 -> 0
B22: 6 | C22: DISC SEAT Ret-Gasket | D22: 316L+G/P | E22: 1 | F22: =Y86 -> 4500 | G22: =F22*E22 -> 4500 | I22: 0 | J22: 0 | K22: 0 | L22: 0 | M22: 0 | N22: 0 | O22: 0 | P22: 0 | Q22: 0 | R22: 0 | S22: =G22+R22 -> 4500
B23: 7 | C23: SEAT GLAND BOLT | D23: =COVER!B21 -> B7(다크로) | E23: 16 | F23: =IF(D23="B8",Y91,IF(D23="B8M",Z91,IF(D23="B7(다크로)",AA91))) -> 300 | G23: =F23*E23 -> 4800 | I23: 0 | J23: 0 | K23: 0 | L23: 0 | M23: 0 | N23: 0 | O23: 0 | P23: 0 | Q23: 0 | R23: 0 | S23: =G23+R23 -> 4800
B24: 8 | C24: STEM | D24: =COVER!B17 -> A564T630 | E24: 4.5 | F24: =COVER!C17 -> 8500 | G24: =F24*E24 -> 38250 | I24: =I25*I26 -> 4597.92 | J24: =J25*J26 -> 0 | K24: =K25*K26 -> 0 | L24: =L25*L26 -> 0 | M24: =M25*M26 -> 0 | N24: =N25*N26 -> 0 | O24: =O25*O26 -> 0 | P24: =P25*P26 -> 0 | Q24: =Q25*Q26 -> 1000 | R24: =R12*0.3 -> 31050 | S24: =G24+R24 -> 69300
H25: 표준가공 ( S/T : EA/H) | I25: 0.3 | Q25: 0.1 | S25: =G25+R25 -> 0
H26: 표준가공 ( S/T : EA/H) | I26: =I27/10 -> 15326.4 | Q26: =Q27/10 -> 10000 | S26: =G26+R26 -> 0
H27: 표준가공 ( S/T : EA/H) | I27: 153264 | Q27: 100000 | S27: =G27+R27 -> 0
B28: 9 | C28: PACKING | D28: PILLAR | E28: 1 | F28: 11400 | G28: =E28*F28 -> 11400 | R28: 0 | S28: =G28+R28 -> 11400
B29: 10 | C29: PACKING GLAND | D29: =COVER!B24 -> A351 CF8M | E29: 1 | F29: =IF(D29="A351 CF8M",Y100,IF(D29="B148 C95400",Z100)) -> 23400 | G29: =F29*E29 -> 23400 | I29: =I30*I31 -> 1532.64 | J29: =J30*J31 -> 1630.43 | K29: =K30*K31 -> 0 | L29: =L30*L31 -> 0 | M29: =M30*M31 -> 0 | N29: =N30*N31 -> 0 | O29: =O30*O31 -> 0 | P29: =P30*P31 -> 0 | Q29: =Q30*Q31 -> 0 | R29: 0 | S29: =G29+R29 -> 23400
H30: 표준가공 ( S/T : EA/H) | I30: 0.1 | J30: 0.1 | S30: =G30+R30 -> 0
H31: 표준가공 ( S/T : EA/H) | I31: =I32/10 -> 15326.4 | J31: =J32/10 -> 16304.3 | S31: =G31+R31 -> 0
H32: 표준가공 ( S/T : EA/H) | I32: 153264 | J32: 163043 | S32: =G32+R32 -> 0
B33: 11 | C33: PACKING PLATE | D33: =COVER!B26 -> 316+NICKEL | E33: 1 | F33: =IF(D33="316+NICKEL",Y102,IF(D33="B148 C95400",Z102)) -> 9000 | G33: =F33*E33 -> 9000 | I33: =I34*I35 -> 1532.64 | J33: =J34*J35 -> 0 | K33: =K34*K35 -> 0 | L33: =L34*L35 -> 0 | M33: =M34*M35 -> 0 | N33: =N34*N35 -> 0 | O33: =O34*O35 -> 0 | P33: =P34*P35 -> 0 | Q33: =Q34*Q35 -> 0 | R33: 0 | S33: =G33+R33 -> 9000 | T33: SET 단가
H34: 표준가공 ( S/T : EA/H) | I34: 0.1 | S34: =G34+R34 -> 0
H35: 표준가공 ( S/T : EA/H) | I35: =I36/10 -> 15326.4 | S35: =G35+R35 -> 0
H36: 표준가공 ( S/T : EA/H) | I36: 153264 | S36: =G36+R36 -> 0
B37: 12 | C37: PACKING GLAND BOLT / NUT | D37: =COVER!B22 -> B7(다크로) | E37: 4 | F37: =IF(D37="B8",Y93,IF(D37="B8M",Z93,IF(D37="B7(다크로)",AA93))) -> 1000 | G37: =E37*F37 -> 4000 | I37: 0 | J37: 0 | K37: 0 | L37: 0 | M37: 0 | N37: 0 | O37: 0 | P37: 0 | Q37: 0 | R37: 0 | S37: =G37+R37 -> 4000
B38: 13 | C38: LIVE LOADING SPRING | E38: 1 | F38: 3000 | G38: =E38*F38 -> 3000 | I38: 0 | J38: 0 | K38: 0 | L38: 0 | M38: 0 | N38: 0 | O38: 0 | P38: 0 | Q38: 0 | R38: 0 | S38: =G38+R38 -> 3000
B39: 14 | C39: BUSH(MAIN) | D39: =COVER!B23 -> 316+NICKEL | E39: 3 | F39: =IF(D39="316+NICKEL",Y97+Y98,IF(D39="B148 C95400",Z97+Z98)) -> 54600 | G39: =F39*1 -> 54600 | I39: =I40*I41 -> 0 | J39: =J40*J41 -> 0 | K39: =K40*K41 -> 0 | L39: =L40*L41 -> 0 | M39: =M40*M41 -> 0 | N39: =N40*N41 -> 0 | O39: =O40*O41 -> 0 | P39: =P40*P41 -> 0 | Q39: =Q40*Q41 -> 0 | R39: 0 | S39: =G39+R39 -> 54600 | T39: SET 단가
B40: 15 | C40: BUSH(STUB) | D40: =COVER!B23 -> 316+NICKEL | E40: 2 | F40: =IF(D40="316+NICKEL",Y99,IF(D40="B148 C95400",Z99)) -> 36900 | G40: =F40*1 -> 36900 | I40: =I41*I42 -> 0 | J40: =J41*J42 -> 0 | K40: =K41*K42 -> 0 | L40: =L41*L42 -> 0 | M40: =M41*M42 -> 0 | N40: =N41*N42 -> 0 | O40: =O41*O42 -> 0 | P40: =P41*P42 -> 0 | Q40: =Q41*Q42 -> 0 | R40: 0 | S40: =G40+R40 -> 36900 | T40: SET 단가
H41: 표준가공 ( S/T : EA/H) | S41: =G41+R41 -> 0
...

Sheet 200-300LB
A1: TREIPLE VALVE 원가분석 ( 300# FLANGE SHORT)
T2: 단위 : 원
A3: SIZE | C3: DN 200 | D3: CLASS | E3: 300LB | F3: TYPE | G3: =COVER!B9 -> FLANGE | H3: TRIPLE 가공공정 | R3: F TO F | S3: API 609 CAT'- B SHROT PATTERN | T3: REMARK
A5: NO. | C5: DESCRIPTION | D5: MATERIAL | E5: 재료비 | H5: ST | I5: 세부 가공비 | R5: 가공비 | S5: 소 계 ( 재료비 + 가공비 )
I6: A | J6: B | K6: C | L6: D | M6: E | N6: F | O6: G | P6: H | Q6: I
E7: 중량 | F7: 단가 | G7: 소재비 | I7: 터닝/선반 | J7: 레디알 | K7: 보링 | L7: 터닝/선반 | M7: 동시보링 | N7: 레이알 | O7: 선반 | P7: 밀링 | Q7: 기타
A8: S T A N D A R D | B8: 1 | C8: =COVER!A14 -> BODY(LUG) | D8: =COVER!B14 -> 0 | E8: =43*1.2 -> 51.6 | F8: =COVER!C14 -> 0 | G8: =F8*E8 -> 0 | I8: =I10*I9 -> 3.6001489e+13 | J8: =J10*J9 -> 4.3341753e+13 | K8: =K10*K9 -> 1.6833509e+14 | L8: =L10*L9 -> 5.0670662e+14 | M8: =M10*M9 -> 6.3241734e+14 | N8: =N10*N9 -> 4.6528628e+13 | O8: =O10*O9 -> 0 | P8: =P10*P9 -> 0 | Q8: =Q10*Q9 -> 10000000000000 | R8: =IF(COVER!C14>0,150000*1.2,0) -> 0 | S8: =G8+R8 -> 0 | T8: LUG
B9: 1-1 | C9: =COVER!A15 -> BODY(FLANGE) | D9: =COVER!B15 -> A216 WCB | E9: 100 | F9: =COVER!C15 -> 4300 | G9: =F9*E9 -> 430000 | I9: =I11*I10 -> 2.3489854e+09 | J9: =J11*J10 -> 2.658302e+09 | K9: =K11*K10 -> 6.5682514e+09 | L9: =L11*L10 -> 1.3693182e+10 | M9: =M11*M10 -> 1.5873372e+10 | N9: =N11*N10 -> 2.7870633e+09 | O9: =O11*O10 -> 0 | P9: =P11*P10 -> 0 | Q9: =Q11*Q10 -> 1000000000 | R9: =IF(COVER!C15>0,200000*1.2,0) -> 240000 | S9: =G9+R9 -> 670000 | T9: FLANGE | V9: =R9 -> 240000
H10: 기계임률 / H | I10: =I11/10 -> 15326.4 | J10: =J11/10 -> 16304.3 | K10: =K11/10 -> 25628.6 | L10: =L11/10 -> 37004.3 | M10: =M11/10 -> 39841.4 | N10: =N11/10 -> 16694.5 | O10: =O11/10 -> 0 | P10: =P11/10 -> 0 | Q10: =Q11/10 -> 10000 | S10: =G10+R10 -> 0
H11: 기계임률 / DAY (10시간) | I11: 153264 | J11: 163043 | K11: 256286 | L11: 370043 | M11: 398414 | N11: 166945 | O11: 0 | P11: 0 | Q11: 100000 | S11: =G11+R11 -> 0
B12: 2 | C12: DISC | D12: =COVER!B16 -> A216 WCB | E12: 9 | F12: =COVER!C16 -> 4300 | G12: =F12*E12 -> 38700 | I12: =I13*I14 -> 10728.48 | J12: =J13*J14 -> 0 | K12: =K13*K14 -> 8152.15 | L12: =L13*L14 -> 11485 | M12: =M13*M14 -> 0 | N12: =N13*N14 -> 0 | O12: =O13*O14 -> 0 | P12: =P13*P14 -> 0 | Q12: =Q13*Q14 -> 3000 | R12: 138000 | S12: =G12+R12 -> 176700
H13: 표준가공 ( S/T : EA/H) | I13: 0.7 | J13: 0 | K13: 0.5 | L13: 0.5 | M13: 0 | N13: 0 | Q13: 0.3 | S13: =G13+R13 -> 0
H14: 기계임률 / H | I14: =I15/10 -> 15326.4 | J14: =J15/10 -> 16304.3 | K14: =K15/10 -> 16304.3 | L14: =L15/10 -> 22970 | M14: =M15/10 -> 39841.4 | N14: =N15/10 -> 16694.5 | O14: =O15/10 -> 0 | P14: =P15/10 -> 0 | Q14: =Q15/10 -> 10000 | S14: =G14+R14 -> 0
H15: 기계임률 / DAY | I15: 153264 | J15: 163043 | K15: 163043 | L15: 229700 | M15: 398414 | N15: 166945 | O15: 0 | P15: 0 | Q15: 100000 | S15: =G15+R15 -> 0
B16: 3 | C16: STELLITE on BODY | D16: =COVER!B19 -> WCB+309+#6 | E16: 1 | F16: =IF(D16="SUS+#6",X76,IF(D16="WCB+309+#6",X77)) -> 114300 | G16: =F16*E16 -> 114300 | I16: 0 | J16: 0 | K16: 0 | L16: 0 | M16: 0 | N16: 0 | O16: 0 | P16: 0 | Q16: 0 | R16: 0 | S16: =G16+R16 -> 114300
B17: 4 | C17: DISC SEAT | D17: =COVER!B18 -> A240T316L+GARPHITE | E17: 1 | F17: =IF(D17="A240T316L+GARPHITE",Y84+Z84) -> 59200 | G17: =F17*E17 -> 59200 | I17: 0 | J17: 0 | K17: 0 | L17: 0 | M17: 0 | N17: 0 | O17: 0 | P17: 0 | Q17: 0 | R17: =Z84*1.3 -> 65000 | S17: =G17+R17 -> 124200
B18: 5 | C18: SEAT GLAND | D18: =COVER!B20 -> SS316L | E18: 1 | F18: =IF(D18="SS304",Y82,IF(D18="SS316L",Z82)) -> 26000 | G18: =E18*F18 -> 26000 | I18: =I19*I20 -> 7663.2 | J18: =J19*J20 -> 8152.15 | K18: =K19*K20 -> 0 | L18: =L19*L20 -> 0 | M18: =M19*M20 -> 0 | N18: =N19*N20 -> 0 | O18: =O19*O20 -> 0 | P18: =P19*P20 -> 0 | Q18: =Q19*Q20 -> 2000 | R18: =AA82*1.5 -> 54000 | S18: =G18+R18 -> 80000
H19: 표준가공 ( S/T : EA/H) | I19: 0.5 | J19: 0.5 | Q19: 0.2 | S19: =G19+R19 -> 0
H20: 표준가공 ( S/T : EA/H) | I20: =I21/10 -> 15326.4 | J20: =J21/10 -> 16304.3 | K20: =K21/10 -> 0 | L20: =L21/10 -> 0 | M20: =M21/10 -> 0 | N20: =N21/10 -> 0 | O20: =O21/10 -> 0 | P20: =P21/10 -> 0 | Q20: =Q21/10 -> 10000 | S20: =G20+R20 -> 0
H21: 표준가공 ( S/T : EA/H) | I21: 153264 | J21: 163043 | Q21: 100000 | S21: =G21+R21 -> 0
B22: 6 | C22: DISC SEAT Ret-Gasket | D22: 316L+G/P | E22: 1 | F22: =Y86 -> 5830 | G22: =F22*E22 -> 5830 | I22: 0 | J22: 0 | K22: 0 | L22: 0 | M22: 0 | N22: 0 | O22: 0 | P22: 0 | Q22: 0 | R22: 0 | S22: =G22+R22 -> 5830
B23: 7 | C23: SEAT GLAND BOLT | D23: =COVER!B21 -> B7(다크로) | E23: 16 | F23: =IF(D23="B8",Y92,IF(D23="B8M",Z92,IF(D23="B7(다크로)",AA92))) -> 300 | G23: =F23*E23 -> 4800 | I23: 0 | J23: 0 | K23: 0 | L23: 0 | M23: 0 | N23: 0 | O23: 0 | P23: 0 | Q23: 0 | R23: 0 | S23: =G23+R23 -> 4800
B24: 8 | C24: STEM | D24: =COVER!B17 -> A564T630 | E24: 5 | F24: =COVER!C17 -> 8500 | G24: =F24*E24 -> 42500 | I24: =I25*I26 -> 6130.56 | J24: =J25*J26 -> 0 | K24: =K25*K26 -> 0 | L24: =L25*L26 -> 0 | M24: =M25*M26 -> 0 | N24: =N25*N26 -> 0 | O24: =O25*O26 -> 0 | P24: =P25*P26 -> 0 | Q24: =Q25*Q26 -> 1000 | R24: =R12*0.3 -> 41400 | S24: =G24+R24 -> 83900
H25: 표준가공 ( S/T : EA/H) | I25: 0.4 | Q25: 0.1 | S25: =G25+R25 -> 0
H26: 표준가공 ( S/T : EA/H) | I26: =I27/10 -> 15326.4 | Q26: =Q27/10 -> 10000 | S26: =G26+R26 -> 0
H27: 표준가공 ( S/T : EA/H) | I27: 153264 | Q27: 100000 | S27: =G27+R27 -> 0
B28: 9 | C28: PACKING | D28: PILLAR | E28: 1 | F28: 11400 | G28: =E28*F28 -> 11400 | R28: 0 | S28: =G28+R28 -> 11400
B29: 10 | C29: PACKING GLAND | D29: =COVER!B24 -> A351 CF8M | E29: 1 | F29: =IF(D29="A351 CF8M",Y98,IF(D29="B148 C95400",Z98)) -> 18200 | G29: =F29*E29 -> 18200 | I29: =I30*I31 -> 1532.64 | J29: =J30*J31 -> 1630.43 | K29: =K30*K31 -> 0 | L29: =L30*L31 -> 0 | M29: =M30*M31 -> 0 | N29: =N30*N31 -> 0 | O29: =O30*O31 -> 0 | P29: =P30*P31 -> 0 | Q29: =Q30*Q31 -> 0 | R29: 0 | S29: =G29+R29 -> 18200
H30: 표준가공 ( S/T : EA/H) | I30: 0.1 | J30: 0.1 | S30: =G30+R30 -> 0
H31: 표준가공 ( S/T : EA/H) | I31: =I32/10 -> 15326.4 | J31: =J32/10 -> 16304.3 | S31: =G31+R31 -> 0
H32: 표준가공 ( S/T : EA/H) | I32: 153264 | J32: 163043 | S32: =G32+R32 -> 0
B33: 11 | C33: PACKING PLATE | D33: =COVER!B26 -> 316+NICKEL | E33: 1 | F33: =IF(D33="316+NICKEL",Y101,IF(D33="B148 C95400",Z101)) -> 7000 | G33: =F33*E33 -> 7000 | I33: =I34*I35 -> 1532.64 | J33: =J34*J35 -> 0 | K33: =K34*K35 -> 0 | L33: =L34*L35 -> 0 | M33: =M34*M35 -> 0 | N33: =N34*N35 -> 0 | O33: =O34*O35 -> 0 | P33: =P34*P35 -> 0 | Q33: =Q34*Q35 -> 0 | R33: 0 | S33: =G33+R33 -> 7000 | T33: SET 단가
H34: 표준가공 ( S/T : EA/H) | I34: 0.1 | S34: =G34+R34 -> 0
H35: 표준가공 ( S/T : EA/H) | I35: =I36/10 -> 15326.4 | S35: =G35+R35 -> 0
H36: 표준가공 ( S/T : EA/H) | I36: 153264 | S36: =G36+R36 -> 0
B37: 12 | C37: PACKING GLAND BOLT / NUT | D37: =COVER!B22 -> B7(다크로) | E37: 4 | F37: =IF(D37="B8",Y93,IF(D37="B8M",Z93,IF(D37="B7(다크로)",AA93))) -> 1000 | G37: =E37*F37 -> 4000 | I37: 0 | J37: 0 | K37: 0 | L37: 0 | M37: 0 | N37: 0 | O37: 0 | P37: 0 | Q37: 0 | R37: 0 | S37: =G37+R37 -> 4000
B38: 13 | C38: LIVE LOADING SPRING | E38: 1 | F38: 3000 | G38: =E38*F38 -> 3000 | I38: 0 | J38: 0 | K38: 0 | L38: 0 | M38: 0 | N38: 0 | O38: 0 | P38: 0 | Q38: 0 | R38: 0 | S38: =G38+R38 -> 3000
B39: 14 | C39: BUSH(MAIN) | D39: =COVER!B23 -> 316+NICKEL | E39: 2 | F39: =IF(D39="316+NICKEL",Y97+Y98,IF(D39="B148 C95400",Z97+Z98)) -> 60730 | G39: =F39*1 -> 60730 | I39: =I40*I41 -> 0 | J39: =J40*J41 -> 0 | K39: =K40*K41 -> 0 | L39: =L40*L41 -> 0 | M39: =M40*M41 -> 0 | N39: =N40*N41 -> 0 | O39: =O40*O41 -> 0 | P39: =P40*P41 -> 0 | Q39: =Q40*Q41 -> 0 | R39: 0 | S39: =G39+R39 -> 60730 | T39: SET 단가
B40: 15 | C40: BUSH(STUB) | D40: =COVER!B23 -> 316+NICKEL | E40: 2 | F40: =IF(D40="316+NICKEL",Y99,IF(D40="B148 C95400",Z99)) -> 24700 | G40: =F40*1 -> 24700 | I40: =I41*I42 -> 0 | J40: =J41*J42 -> 0 | K40: =K41*K42 -> 0 | L40: =L41*L42 -> 0 | M40: =M41*M42 -> 0 | N40: =N41*N42 -> 0 | O40: =O41*O42 -> 0 | P40: =P41*P42 -> 0 | Q40: =Q41*Q42 -> 0 | R40: 0 | S40: =G40+R40 -> 24700 | T40: SET 단가
H41: 표준가공 ( S/T : EA/H) | S41: =G41+R41 -> 0
...

Sheet 250-300LB
A1: TREIPLE VALVE 원가분석 ( 300# FLANGE SHORT)
T2: 단위 : 원
A3: SIZE | C3: DN 250 | D3: CLASS | E3: 300LB | F3: TYPE | G3: =COVER!B9 -> FLANGE | H3: TRIPLE 가공공정 | R3: F TO F | S3: API 609 CAT'- B SHROT PATTERN | T3: REMARK
A5: NO. | C5: DESCRIPTION | D5: MATERIAL | E5: 재료비 | H5: ST | I5: 세부 가공비 | R5: 가공비 | S5: 소 계 ( 재료비 + 가공비 )
I6: A | J6: B | K6: C | L6: D | M6: E | N6: F | O6: G | P6: H | Q6: I
E7: 중량 | F7: 단가 | G7: 소재비 | I7: 터닝/선반 | J7: 레디알 | K7: 보링 | L7: 터닝/선반 | M7: 동시보링 | N7: 레이알 | O7: 선반 | P7: 밀링 | Q7: 기타
A8: S T A N D A R D | B8: 1 | C8: =COVER!A14 -> BODY(LUG) | D8: =COVER!B14 -> 0 | E8: =73*1.2 -> 87.6 | F8: =COVER!C14 -> 0 | G8: =F8*E8 -> 0 | I8: =I10*I9 -> 3.6001489e+13 | J8: =J10*J9 -> 4.3341753e+13 | K8: =K10*K9 -> 1.6833509e+14 | L8: =L10*L9 -> 5.0670662e+14 | M8: =M10*M9 -> 6.3241734e+14 | N8: =N10*N9 -> 4.6528628e+13 | O8: =O10*O9 -> 0 | P8: =P10*P9 -> 0 | Q8: =Q10*Q9 -> 10000000000000 | R8: =IF(COVER!C14>0,190000*1.2,0) -> 0 | S8: =G8+R8 -> 0 | T8: LUG
B9: 1-1 | C9: =COVER!A15 -> BODY(FLANGE) | D9: =COVER!B15 -> A216 WCB | E9: 150 | F9: =COVER!C15 -> 4300 | G9: =F9*E9 -> 645000 | I9: =I11*I10 -> 2.3489854e+09 | J9: =J11*J10 -> 2.658302e+09 | K9: =K11*K10 -> 6.5682514e+09 | L9: =L11*L10 -> 1.3693182e+10 | M9: =M11*M10 -> 1.5873372e+10 | N9: =N11*N10 -> 2.7870633e+09 | O9: =O11*O10 -> 0 | P9: =P11*P10 -> 0 | Q9: =Q11*Q10 -> 1000000000 | R9: =IF(COVER!C15>0,250000*1.2,0) -> 300000 | S9: =G9+R9 -> 945000 | T9: FLANGE | V9: =R9 -> 300000
H10: 기계임률 / H | I10: =I11/10 -> 15326.4 | J10: =J11/10 -> 16304.3 | K10: =K11/10 -> 25628.6 | L10: =L11/10 -> 37004.3 | M10: =M11/10 -> 39841.4 | N10: =N11/10 -> 16694.5 | O10: =O11/10 -> 0 | P10: =P11/10 -> 0 | Q10: =Q11/10 -> 10000 | S10: =G10+R10 -> 0
H11: 기계임률 / DAY (10시간) | I11: 153264 | J11: 163043 | K11: 256286 | L11: 370043 | M11: 398414 | N11: 166945 | O11: 0 | P11: 0 | Q11: 100000 | S11: =G11+R11 -> 0
B12: 2 | C12: DISC | D12: =COVER!B16 -> A216 WCB | E12: 19 | F12: =COVER!C16 -> 4300 | G12: =F12*E12 -> 81700 | I12: =I13*I14 -> 15326.4 | J12: =J13*J14 -> 0 | K12: =K13*K14 -> 16304.3 | L12: =L13*L14 -> 22970 | M12: =M13*M14 -> 0 | N12: =N13*N14 -> 0 | O12: =O13*O14 -> 0 | P12: =P13*P14 -> 0 | Q12: =Q13*Q14 -> 4000 | R12: 172500 | S12: =G12+R12 -> 254200
H13: 표준가공 ( S/T : EA/H) | I13: 1 | J13: 0 | K13: 1 | L13: 1 | M13: 0 | N13: 0 | Q13: 0.4 | S13: =G13+R13 -> 0
H14: 기계임률 / H | I14: =I15/10 -> 15326.4 | J14: =J15/10 -> 16304.3 | K14: =K15/10 -> 16304.3 | L14: =L15/10 -> 22970 | M14: =M15/10 -> 39841.4 | N14: =N15/10 -> 16694.5 | O14: =O15/10 -> 0 | P14: =P15/10 -> 0 | Q14: =Q15/10 -> 10000 | S14: =G14+R14 -> 0
H15: 기계임률 / DAY | I15: 153264 | J15: 163043 | K15: 163043 | L15: 229700 | M15: 398414 | N15: 166945 | O15: 0 | P15: 0 | Q15: 100000 | S15: =G15+R15 -> 0
B16: 3 | C16: STELLITE on BODY | D16: =COVER!B19 -> WCB+309+#6 | E16: 1 | F16: =IF(D16="SUS+#6",X76,IF(D16="WCB+309+#6",X77)) -> 218400 | G16: =F16*E16 -> 218400 | I16: 0 | J16: 0 | K16: 0 | L16: 0 | M16: 0 | N16: 0 | O16: 0 | P16: 0 | Q16: 0 | R16: 0 | S16: =G16+R16 -> 218400
B17: 4 | C17: DISC SEAT | D17: =COVER!B18 -> A240T316L+GARPHITE | E17: 1 | F17: =IF(D17="A240T316L+GARPHITE",Y84+Z84) -> 68200 | G17: =F17*E17 -> 68200 | I17: 0 | J17: 0 | K17: 0 | L17: 0 | M17: 0 | N17: 0 | O17: 0 | P17: 0 | Q17: 0 | R17: =Z84*1.3 -> 53300 | S17: =G17+R17 -> 121500
B18: 5 | C18: SEAT GLAND | D18: =COVER!B20 -> SS316L | E18: 1 | F18: =IF(D18="SS304",Y82,IF(D18="SS316L",Z82)) -> 38000 | G18: =E18*F18 -> 38000 | I18: =I19*I20 -> 7663.2 | J18: =J19*J20 -> 8152.15 | K18: =K19*K20 -> 0 | L18: =L19*L20 -> 0 | M18: =M19*M20 -> 0 | N18: =N19*N20 -> 0 | O18: =O19*O20 -> 0 | P18: =P19*P20 -> 0 | Q18: =Q19*Q20 -> 2000 | R18: =AA82*1.5 -> 63000 | S18: =G18+R18 -> 101000
H19: 표준가공 ( S/T : EA/H) | I19: 0.5 | J19: 0.5 | Q19: 0.2 | S19: =G19+R19 -> 0
H20: 표준가공 ( S/T : EA/H) | I20: =I21/10 -> 15326.4 | J20: =J21/10 -> 16304.3 | K20: =K21/10 -> 0 | L20: =L21/10 -> 0 | M20: =M21/10 -> 0 | N20: =N21/10 -> 0 | O20: =O21/10 -> 0 | P20: =P21/10 -> 0 | Q20: =Q21/10 -> 10000 | S20: =G20+R20 -> 0
H21: 표준가공 ( S/T : EA/H) | I21: 153264 | J21: 163043 | Q21: 100000 | S21: =G21+R21 -> 0
B22: 6 | C22: DISC SEAT Ret-Gasket | D22: 316L+G/P | E22: 1 | F22: =Y85 -> 9000 | G22: =F22*E22 -> 9000 | I22: 0 | J22: 0 | K22: 0 | L22: 0 | M22: 0 | N22: 0 | O22: 0 | P22: 0 | Q22: 0 | R22: 0 | S22: =G22+R22 -> 9000
B23: 7 | C23: SEAT GLAND BOLT | D23: =COVER!B21 -> B7(다크로) | E23: 16 | F23: =IF(D23="B8",Y91,IF(D23="B8M",Z91,IF(D23="B7(다크로)",AA91))) -> 300 | G23: =F23*E23 -> 4800 | I23: 0 | J23: 0 | K23: 0 | L23: 0 | M23: 0 | N23: 0 | O23: 0 | P23: 0 | Q23: 0 | R23: 0 | S23: =G23+R23 -> 4800
B24: 8 | C24: STEM | D24: =COVER!B17 -> A564T630 | E24: 15 | F24: =COVER!C17 -> 8500 | G24: =F24*E24 -> 127500 | I24: =I25*I26 -> 7663.2 | J24: =J25*J26 -> 0 | K24: =K25*K26 -> 0 | L24: =L25*L26 -> 0 | M24: =M25*M26 -> 0 | N24: =N25*N26 -> 0 | O24: =O25*O26 -> 0 | P24: =P25*P26 -> 0 | Q24: =Q25*Q26 -> 1000 | R24: =R12*0.3 -> 51750 | S24: =G24+R24 -> 179250
H25: 표준가공 ( S/T : EA/H) | I25: 0.5 | Q25: 0.1 | S25: =G25+R25 -> 0
H26: 표준가공 ( S/T : EA/H) | I26: =I27/10 -> 15326.4 | Q26: =Q27/10 -> 10000 | S26: =G26+R26 -> 0
H27: 표준가공 ( S/T : EA/H) | I27: 153264 | Q27: 100000 | S27: =G27+R27 -> 0
B28: 9 | C28: PACKING | D28: PILLAR | E28: 1 | F28: 24000 | G28: =E28*F28 -> 24000 | R28: 0 | S28: =G28+R28 -> 24000
B29: 10 | C29: PACKING GLAND | D29: =COVER!B24 -> A351 CF8M | E29: 1 | F29: =IF(D29="A351 CF8M",Y98,IF(D29="B148 C95400",Z98)) -> 25600 | G29: =F29*E29 -> 25600 | I29: =I30*I31 -> 3065.28 | J29: =J30*J31 -> 3260.86 | K29: =K30*K31 -> 0 | L29: =L30*L31 -> 0 | M29: =M30*M31 -> 0 | N29: =N30*N31 -> 0 | O29: =O30*O31 -> 0 | P29: =P30*P31 -> 0 | Q29: =Q30*Q31 -> 0 | R29: 0 | S29: =G29+R29 -> 25600
H30: 표준가공 ( S/T : EA/H) | I30: 0.2 | J30: 0.2 | S30: =G30+R30 -> 0
H31: 표준가공 ( S/T : EA/H) | I31: =I32/10 -> 15326.4 | J31: =J32/10 -> 16304.3 | S31: =G31+R31 -> 0
H32: 표준가공 ( S/T : EA/H) | I32: 153264 | J32: 163043 | S32: =G32+R32 -> 0
B33: 11 | C33: PACKING PLATE | D33: =COVER!B26 -> 316+NICKEL | E33: 1 | F33: =IF(D33="316+NICKEL",Y102,IF(D33="B148 C95400",Z102)) -> 9700 | G33: =F33*E33 -> 9700 | I33: =I34*I35 -> 4597.92 | J33: =J34*J35 -> 0 | K33: =K34*K35 -> 0 | L33: =L34*L35 -> 0 | M33: =M34*M35 -> 0 | N33: =N34*N35 -> 0 | O33: =O34*O35 -> 0 | P33: =P34*P35 -> 0 | Q33: =Q34*Q35 -> 0 | R33: 0 | S33: =G33+R33 -> 9700 | T33: SET 단가
H34: 표준가공 ( S/T : EA/H) | I34: 0.3 | S34: =G34+R34 -> 0
H35: 표준가공 ( S/T : EA/H) | I35: =I36/10 -> 15326.4 | S35: =G35+R35 -> 0
H36: 표준가공 ( S/T : EA/H) | I36: 153264 | S36: =G36+R36 -> 0
B37: 12 | C37: PACKING GLAND BOLT / NUT | D37: =COVER!B22 -> B7(다크로) | E37: 4 | F37: =IF(D37="B8",Y93,IF(D37="B8M",Z93,IF(D37="B7(다크로)",AA93))) -> 1500 | G37: =E37*F37 -> 6000 | I37: 0 | J37: 0 | K37: 0 | L37: 0 | M37: 0 | N37: 0 | O37: 0 | P37: 0 | Q37: 0 | R37: 0 | S37: =G37+R37 -> 6000
B38: 13 | C38: LIVE LOADING SPRING | E38: 1 | F38: 3000 | G38: =E38*F38 -> 3000 | I38: 0 | J38: 0 | K38: 0 | L38: 0 | M38: 0 | N38: 0 | O38: 0 | P38: 0 | Q38: 0 | R38: 0 | S38: =G38+R38 -> 3000
B39: 14 | C39: BUSH(MAIN) | D39: =COVER!B23 -> 316+NICKEL | E39: 3 | F39: =IF(D39="316+NICKEL",Y97+Y98,IF(D39="B148 C95400",Z97+Z98)) -> 106800 | G39: =F39*1 -> 106800 | I39: =I40*I41 -> 0 | J39: =J40*J41 -> 0 | K39: =K40*K41 -> 0 | L39: =L40*L41 -> 0 | M39: =M40*M41 -> 0 | N39: =N40*N41 -> 0 | O39: =O40*O41 -> 0 | P39: =P40*P41 -> 0 | Q39: =Q40*Q41 -> 0 | R39: 0 | S39: =G39+R39 -> 106800 | T39: SET 단가
B40: 15 | C40: BUSH(STUB) | D40: =COVER!B23 -> 316+NICKEL | E40: 2 | F40: =IF(D40="316+NICKEL",Y99+Y100,IF(D40="B148 C95400",Z99+Z100)) -> 79400 | G40: =F40*1 -> 79400 | I40: =I41*I42 -> 0 | J40: =J41*J42 -> 0 | K40: =K41*K42 -> 0 | L40: =L41*L42 -> 0 | M40: =M41*M42 -> 0 | N40: =N41*N42 -> 0 | O40: =O41*O42 -> 0 | P40: =P41*P42 -> 0 | Q40: =Q41*Q42 -> 0 | R40: 0 | S40: =G40+R40 -> 79400 | T40: SET 단가
H41: 표준가공 ( S/T : EA/H) | S41: =G41+R41 -> 0
...

Sheet 300-300LB
A1: TREIPLE VALVE 원가분석 ( 300# FLANGE SHORT)
T2: 단위 : 원
A3: SIZE | C3: DN 300 | D3: CLASS | E3: 300LB | F3: TYPE | G3: =COVER!B9 -> FLANGE | H3: TRIPLE 가공공정 | R3: F TO F | S3: API 609 CAT'- B SHROT PATTERN | T3: REMARK
A5: NO. | C5: DESCRIPTION | D5: MATERIAL | E5: 재료비 | H5: ST | I5: 세부 가공비 | R5: 가공비 | S5: 소 계 ( 재료비 + 가공비 )
I6: A | J6: B | K6: C | L6: D | M6: E | N6: F | O6: G | P6: H | Q6: I
E7: 중량 | F7: 단가 | G7: 소재비 | I7: 터닝/선반 | J7: 레디알 | K7: 보링 | L7: 터닝/선반 | M7: 동시보링 | N7: 레이알 | O7: 선반 | P7: 밀링 | Q7: 기타
A8: S T A N D A R D | B8: 1 | C8: =COVER!A14 -> BODY(LUG) | D8: =COVER!B14 -> 0 | E8: =102*1.2 -> 122.4 | F8: =COVER!C14 -> 0 | G8: =F8*E8 -> 0 | I8: =I10*I9 -> 3.6001489e+13 | J8: =J10*J9 -> 4.3341753e+13 | K8: =K10*K9 -> 1.6833509e+14 | L8: =L10*L9 -> 5.0670662e+14 | M8: =M10*M9 -> 6.3241734e+14 | N8: =N10*N9 -> 4.6528628e+13 | O8: =O10*O9 -> 0 | P8: =P10*P9 -> 0 | Q8: =Q10*Q9 -> 10000000000000 | R8: =IF(COVER!C14>0,290000*1.2,0) -> 0 | S8: =G8+R8 -> 0 | T8: LUG
B9: 1-1 | C9: =COVER!A15 -> BODY(FLANGE) | D9: =COVER!B15 -> A216 WCB | E9: 206 | F9: =COVER!C15 -> 4300 | G9: =F9*E9 -> 885800 | I9: =I11*I10 -> 2.3489854e+09 | J9: =J11*J10 -> 2.658302e+09 | K9: =K11*K10 -> 6.5682514e+09 | L9: =L11*L10 -> 1.3693182e+10 | M9: =M11*M10 -> 1.5873372e+10 | N9: =N11*N10 -> 2.7870633e+09 | O9: =O11*O10 -> 0 | P9: =P11*P10 -> 0 | Q9: =Q11*Q10 -> 1000000000 | R9: =IF(COVER!C15>0,300000*1.2,0) -> 360000 | S9: =G9+R9 -> 1245800 | T9: FLANGE | V9: =R9 -> 360000
H10: 기계임률 / H | I10: =I11/10 -> 15326.4 | J10: =J11/10 -> 16304.3 | K10: =K11/10 -> 25628.6 | L10: =L11/10 -> 37004.3 | M10: =M11/10 -> 39841.4 | N10: =N11/10 -> 16694.5 | O10: =O11/10 -> 0 | P10: =P11/10 -> 0 | Q10: =Q11/10 -> 10000 | S10: =G10+R10 -> 0
H11: 기계임률 / DAY (10시간) | I11: 153264 | J11: 163043 | K11: 256286 | L11: 370043 | M11: 398414 | N11: 166945 | O11: 0 | P11: 0 | Q11: 100000 | S11: =G11+R11 -> 0
B12: 2 | C12: DISC | D12: =COVER!B16 -> A216 WCB | E12: 33 | F12: =COVER!C16 -> 4300 | G12: =F12*E12 -> 141900 | I12: =I13*I14 -> 15326.4 | J12: =J13*J14 -> 0 | K12: =K13*K14 -> 16304.3 | L12: =L13*L14 -> 22970 | M12: =M13*M14 -> 0 | N12: =N13*N14 -> 0 | O12: =O13*O14 -> 0 | P12: =P13*P14 -> 0 | Q12: =Q13*Q14 -> 4000 | R12: 207000 | S12: =G12+R12 -> 348900
H13: 표준가공 ( S/T : EA/H) | I13: 1 | J13: 0 | K13: 1 | L13: 1 | M13: 0 | N13: 0 | Q13: 0.4 | S13: =G13+R13 -> 0
H14: 기계임률 / H | I14: =I15/10 -> 15326.4 | J14: =J15/10 -> 16304.3 | K14: =K15/10 -> 16304.3 | L14: =L15/10 -> 22970 | M14: =M15/10 -> 39841.4 | N14: =N15/10 -> 16694.5 | O14: =O15/10 -> 0 | P14: =P15/10 -> 0 | Q14: =Q15/10 -> 10000 | S14: =G14+R14 -> 0
H15: 기계임률 / DAY | I15: 153264 | J15: 163043 | K15: 163043 | L15: 229700 | M15: 398414 | N15: 166945 | O15: 0 | P15: 0 | Q15: 100000 | S15: =G15+R15 -> 0
B16: 3 | C16: STELLITE on BODY | D16: =COVER!B19 -> WCB+309+#6 | E16: 1 | F16: =IF(D16="SUS+#6",X76,IF(D16="WCB+309+#6",X77)) -> 224200 | G16: =F16*E16 -> 224200 | I16: 0 | J16: 0 | K16: 0 | L16: 0 | M16: 0 | N16: 0 | O16: 0 | P16: 0 | Q16: 0 | R16: 0 | S16: =G16+R16 -> 224200
B17: 4 | C17: DISC SEAT | D17: =COVER!B18 -> A240T316L+GARPHITE | E17: 1 | F17: =IF(D17="A240T316L+GARPHITE",Y84+Z84) -> 72100 | G17: =F17*E17 -> 72100 | I17: 0 | J17: 0 | K17: 0 | L17: 0 | M17: 0 | N17: 0 | O17: 0 | P17: 0 | Q17: 0 | R17: =Z84*1.3 -> 52000 | S17: =G17+R17 -> 124100
B18: 5 | C18: SEAT GLAND | D18: =COVER!B20 -> SS316L | E18: 1 | F18: =IF(D18="SS304",Y82,IF(D18="SS316L",Z82)) -> 76000 | G18: =E18*F18 -> 76000 | I18: =I19*I20 -> 7663.2 | J18: =J19*J20 -> 8152.15 | K18: =K19*K20 -> 0 | L18: =L19*L20 -> 0 | M18: =M19*M20 -> 0 | N18: =N19*N20 -> 0 | O18: =O19*O20 -> 0 | P18: =P19*P20 -> 0 | Q18: =Q19*Q20 -> 2000 | R18: =AA82*1.5 -> 72000 | S18: =G18+R18 -> 148000
G19: =E19*F19 -> 0 | H19: 표준가공 ( S/T : EA/H) | I19: 0.5 | J19: 0.5 | Q19: 0.2 | S19: =G19+R19 -> 0
G20: =E20*F20 -> 0 | H20: 표준가공 ( S/T : EA/H) | I20: =I21/10 -> 15326.4 | J20: =J21/10 -> 16304.3 | K20: =K21/10 -> 0 | L20: =L21/10 -> 0 | M20: =M21/10 -> 0 | N20: =N21/10 -> 0 | O20: =O21/10 -> 0 | P20: =P21/10 -> 0 | Q20: =Q21/10 -> 10000 | S20: =G20+R20 -> 0
G21: =E21*F21 -> 0 | H21: 표준가공 ( S/T : EA/H) | I21: 153264 | J21: 163043 | Q21: 100000 | S21: =G21+R21 -> 0
B22: 6 | C22: DISC SEAT Ret-Gasket | D22: 316L+G/P | E22: 1 | F22: =Y85 -> 12000 | G22: =F22*E22 -> 12000 | I22: 0 | J22: 0 | K22: 0 | L22: 0 | M22: 0 | N22: 0 | O22: 0 | P22: 0 | Q22: 0 | R22: 0 | S22: =G22+R22 -> 12000
B23: 7 | C23: SEAT GLAND BOLT | D23: =COVER!B21 -> B7(다크로) | E23: 20 | F23: =IF(D23="B8",Y92,IF(D23="B8M",Z92,IF(D23="B7(다크로)",AA92))) -> 300 | G23: =F23*E23 -> 6000 | I23: 0 | J23: 0 | K23: 0 | L23: 0 | M23: 0 | N23: 0 | O23: 0 | P23: 0 | Q23: 0 | R23: 0 | S23: =G23+R23 -> 6000
B24: 8 | C24: STEM | D24: =COVER!B17 -> A564T630 | E24: 12 | F24: =COVER!C17 -> 8500 | G24: =F24*E24 -> 102000 | I24: =I25*I26 -> 7663.2 | J24: =J25*J26 -> 0 | K24: =K25*K26 -> 0 | L24: =L25*L26 -> 0 | M24: =M25*M26 -> 0 | N24: =N25*N26 -> 0 | O24: =O25*O26 -> 0 | P24: =P25*P26 -> 0 | Q24: =Q25*Q26 -> 1000 | R24: =R12*0.3 -> 62100 | S24: =G24+R24 -> 164100
H25: 표준가공 ( S/T : EA/H) | I25: 0.5 | Q25: 0.1 | S25: =G25+R25 -> 0
H26: 표준가공 ( S/T : EA/H) | I26: =I27/10 -> 15326.4 | Q26: =Q27/10 -> 10000 | S26: =G26+R26 -> 0
H27: 표준가공 ( S/T : EA/H) | I27: 153264 | Q27: 100000 | S27: =G27+R27 -> 0
B28: 9 | C28: PACKING | D28: PILLAR | E28: 1 | F28: 21900 | G28: =E28*F28 -> 21900 | R28: 0 | S28: =G28+R28 -> 21900
B29: 10 | C29: PACKING GLAND | D29: =COVER!B24 -> A351 CF8M | E29: 1 | F29: =IF(D29="A351 CF8M",Y99,IF(D29="B148 C95400",Z99)) -> 39500 | G29: =F29*E29 -> 39500 | I29: =I30*I31 -> 3065.28 | J29: =J30*J31 -> 3260.86 | K29: =K30*K31 -> 0 | L29: =L30*L31 -> 0 | M29: =M30*M31 -> 0 | N29: =N30*N31 -> 0 | O29: =O30*O31 -> 0 | P29: =P30*P31 -> 0 | Q29: =Q30*Q31 -> 0 | R29: 0 | S29: =G29+R29 -> 39500
H30: 표준가공 ( S/T : EA/H) | I30: 0.2 | J30: 0.2 | S30: =G30+R30 -> 0
H31: 표준가공 ( S/T : EA/H) | I31: =I32/10 -> 15326.4 | J31: =J32/10 -> 16304.3 | S31: =G31+R31 -> 0
H32: 표준가공 ( S/T : EA/H) | I32: 153264 | J32: 163043 | S32: =G32+R32 -> 0
B33: 11 | C33: PACKING PLATE | D33: =COVER!B26 -> 316+NICKEL | E33: 1 | F33: =IF(D33="316+NICKEL",Y102,IF(D33="B148 C95400",Z102)) -> 19000 | G33: =F33*E33 -> 19000 | I33: =I34*I35 -> 4597.92 | J33: =J34*J35 -> 0 | K33: =K34*K35 -> 0 | L33: =L34*L35 -> 0 | M33: =M34*M35 -> 0 | N33: =N34*N35 -> 0 | O33: =O34*O35 -> 0 | P33: =P34*P35 -> 0 | Q33: =Q34*Q35 -> 0 | R33: 0 | S33: =G33+R33 -> 19000 | T33: SET 단가
H34: 표준가공 ( S/T : EA/H) | I34: 0.3 | S34: =G34+R34 -> 0
H35: 표준가공 ( S/T : EA/H) | I35: =I36/10 -> 15326.4 | S35: =G35+R35 -> 0
H36: 표준가공 ( S/T : EA/H) | I36: 153264 | S36: =G36+R36 -> 0
B37: 12 | C37: PACKING GLAND BOLT / NUT | D37: =COVER!B22 -> B7(다크로) | E37: 6 | F37: =IF(D37="B8",Y93,IF(D37="B8M",Z93,IF(D37="B7(다크로)",AA93))) -> 1500 | G37: =E37*F37 -> 9000 | I37: 0 | J37: 0 | K37: 0 | L37: 0 | M37: 0 | N37: 0 | O37: 0 | P37: 0 | Q37: 0 | R37: 0 | S37: =G37+R37 -> 9000
B38: 13 | C38: LIVE LOADING SPRING | E38: 1 | F38: 3000 | G38: =E38*F38 -> 3000 | I38: 0 | J38: 0 | K38: 0 | L38: 0 | M38: 0 | N38: 0 | O38: 0 | P38: 0 | Q38: 0 | R38: 0 | S38: =G38+R38 -> 3000
B39: 14 | C39: BUSH(MAIN) | D39: =COVER!B23 -> 316+NICKEL | E39: 2 | F39: =IF(D39="316+NICKEL",Y97,IF(D39="B148 C95400",Z97)) -> 66800 | G39: =F39*1 -> 66800 | I39: =I40*I41 -> 0 | J39: =J40*J41 -> 0 | K39: =K40*K41 -> 0 | L39: =L40*L41 -> 0 | M39: =M40*M41 -> 0 | N39: =N40*N41 -> 0 | O39: =O40*O41 -> 0 | P39: =P40*P41 -> 0 | Q39: =Q40*Q41 -> 0 | R39: 0 | S39: =G39+R39 -> 66800 | T39: SET 단가
B40: 15 | C40: BUSH(STUB) | D40: =COVER!B23 -> 316+NICKEL | E40: 2 | F40: =IF(D40="316+NICKEL",Y98,IF(D40="B148 C95400",Z98)) -> 56000 | G40: =F40*1 -> 56000 | I40: =I41*I42 -> 0 | J40: =J41*J42 -> 0 | K40: =K41*K42 -> 0 | L40: =L41*L42 -> 0 | M40: =M41*M42 -> 0 | N40: =N41*N42 -> 0 | O40: =O41*O42 -> 0 | P40: =P41*P42 -> 0 | Q40: =Q41*Q42 -> 0 | R40: 0 | S40: =G40+R40 -> 56000 | T40: SET 단가
H41: 표준가공 ( S/T : EA/H) | S41: =G41+R41 -> 0
...

Sheet 350-300LB
A1: TREIPLE VALVE 원가분석 ( 300# FLANGE SHORT)
T2: 단위 : 원
A3: SIZE | C3: DN 350 | D3: CLASS | E3: 300LB | F3: TYPE | G3: =COVER!B9 -> FLANGE | H3: TRIPLE 가공공정 | R3: F TO F | S3: API 609 CAT'- B SHROT PATTERN | T3: REMARK
A5: NO. | C5: DESCRIPTION | D5: MATERIAL | E5: 재료비 | H5: ST | I5: 세부 가공비 | R5: 가공비 | S5: 소 계 ( 재료비 + 가공비 )
I6: A | J6: B | K6: C | L6: D | M6: E | N6: F | O6: G | P6: H | Q6: I
E7: 중량 | F7: 단가 | G7: 소재비 | I7: 터닝/선반 | J7: 레디알 | K7: 보링 | L7: 터닝/선반 | M7: 동시보링 | N7: 레이알 | O7: 선반 | P7: 밀링 | Q7: 기타
A8: S T A N D A R D | B8: 1 | C8: =COVER!A14 -> BODY(LUG) | D8: =COVER!B14 -> 0 | E8: =160*1.2 -> 192 | F8: =COVER!C14 -> 0 | G8: =F8*E8 -> 0 | I8: =I10*I9 -> 3.6001489e+13 | J8: =J10*J9 -> 4.3341753e+13 | K8: =K10*K9 -> 1.6833509e+14 | L8: =L10*L9 -> 5.0670662e+14 | M8: =M10*M9 -> 6.3241734e+14 | N8: =N10*N9 -> 4.6528628e+13 | O8: =O10*O9 -> 0 | P8: =P10*P9 -> 0 | Q8: =Q10*Q9 -> 10000000000000 | R8: =IF(COVER!C14>0,340000*1.2,0) -> 0 | S8: =G8+R8 -> 0 | T8: LUG
B9: 1-1 | C9: =COVER!A15 -> BODY(FLANGE) | D9: =COVER!B15 -> A216 WCB | E9: 268 | F9: =COVER!C15 -> 4300 | G9: =F9*E9 -> 1152400 | I9: =I11*I10 -> 2.3489854e+09 | J9: =J11*J10 -> 2.658302e+09 | K9: =K11*K10 -> 6.5682514e+09 | L9: =L11*L10 -> 1.3693182e+10 | M9: =M11*M10 -> 1.5873372e+10 | N9: =N11*N10 -> 2.7870633e+09 | O9: =O11*O10 -> 0 | P9: =P11*P10 -> 0 | Q9: =Q11*Q10 -> 1000000000 | R9: =IF(COVER!C15>0,350000*1.2,0) -> 420000 | S9: =G9+R9 -> 1572400 | T9: FLANGE | V9: =R9 -> 420000
H10: 기계임률 / H | I10: =I11/10 -> 15326.4 | J10: =J11/10 -> 16304.3 | K10: =K11/10 -> 25628.6 | L10: =L11/10 -> 37004.3 | M10: =M11/10 -> 39841.4 | N10: =N11/10 -> 16694.5 | O10: =O11/10 -> 0 | P10: =P11/10 -> 0 | Q10: =Q11/10 -> 10000 | S10: =G10+R10 -> 0
H11: 기계임률 / DAY (10시간) | I11: 153264 | J11: 163043 | K11: 256286 | L11: 370043 | M11: 398414 | N11: 166945 | O11: 0 | P11: 0 | Q11: 100000 | S11: =G11+R11 -> 0
B12: 2 | C12: DISC | D12: =COVER!B16 -> A216 WCB | E12: 40 | F12: =COVER!C16 -> 4300 | G12: =F12*E12 -> 172000 | I12: =I13*I14 -> 15326.4 | J12: =J13*J14 -> 0 | K12: =K13*K14 -> 16304.3 | L12: =L13*L14 -> 45940 | M12: =M13*M14 -> 0 | N12: =N13*N14 -> 0 | O12: =O13*O14 -> 0 | P12: =P13*P14 -> 0 | Q12: =Q13*Q14 -> 4000 | R12: 241500 | S12: =G12+R12 -> 413500
H13: 표준가공 ( S/T : EA/H) | I13: 1 | J13: 0 | K13: 1 | L13: 2 | M13: 0 | N13: 0 | Q13: 0.4 | S13: =G13+R13 -> 0
H14: 기계임률 / H | I14: =I15/10 -> 15326.4 | J14: =J15/10 -> 16304.3 | K14: =K15/10 -> 16304.3 | L14: =L15/10 -> 22970 | M14: =M15/10 -> 39841.4 | N14: =N15/10 -> 16694.5 | O14: =O15/10 -> 0 | P14: =P15/10 -> 0 | Q14: =Q15/10 -> 10000 | S14: =G14+R14 -> 0
