Workbook
Name _1: #N/A
Name _11: #N/A
Name _2: #N/A
Name _22: #N/A
Name _AOC2: #REF!
Name _ELL45: #REF!
Name _ELL90: #REF!
Name _RE100: #REF!
Name _RE104: #REF!
Name _RE112: #REF!
Name _RE26: #REF!
Name _RE28: #REF!
Name _RE30: #REF!
Name _RE32: #REF!
Name _RE34: #REF!
Name _RE36: #REF!
Name _RE38: #REF!
Name _RE40: #REF!
Name _RE42: #REF!
Name _RE44: #REF!
Name _RE48: #REF!
Name _RE52: #REF!
Name _RE56: #REF!
Name _RE60: #REF!
Name _RE64: #REF!
Name _RE68: #REF!
Name _RE72: #REF!
Name _RE76: #REF!
Name _RE80: #REF!
Name _RE88: #REF!
Name _RE92: #REF!
Name _RE96: #REF!
Name \a: #N/A
Name \p: '[2]FWBS7000,8000'!#REF!
Name A7JB_WIRES: [3]A7!$S$68
Name air_trap: #REF!
Name angle: #REF!
Name B_FLG: #REF!
Name back_pressure: #REF!
Name ball: #REF!
Name BOLT: #REF!
Name BOSS: #REF!
Name butterfly: #REF!
Name CAP: #REF!
Name CCS: '[4]Product-part-a'!$R$11
Name check: #REF!
Name COM: #REF!
Name CPLG: #REF!
Name CS: #REF!
Name CS_DB: #REF!
Name data: #REF!
Name diameter: #REF!
Name diaphragm: #REF!
Name drain_trap: #REF!
Name dual_plate_check: #REF!
Name duplex_strainer: #REF!
Name EOL: #REF!
Name ex_joint: #REF!
Name FLG: #REF!
Name Flg_DB: #REF!

Sheet 원가
A2: 환율 | B2: 1 | E2: SIZE | F2: TOTAL COST | G2: MOTOR | H2: MOTOR | I2: M-factor | J2: Total | K2: 환율 | L2: motor factor
B3: Material | C3: 소재 단가 | E3: 100 | F3: ='100A'!K40 -> 448600 | K3: =B2 -> 1 | L3: =B16 -> 1
A4: BODY | B4: WCB | C4: 2600 | E4: 125 | F4: ='125A'!K40 -> 486350 | K4: =B2 -> 1 | L4: =B16 -> 1
A5: DISC | B5: WCB | C5: 2600 | E5: 150 | F5: ='150A'!K40 -> 573595 | K5: =B2 -> 1 | L5: =B16 -> 1
A6: SHAFT | B6: A276T316L | C6: 8500 | E6: 200 | F6: ='200A'!K40 -> 718242 | K6: =B2 -> 1 | L6: =B16 -> 1
A7: DISC Retainer Ring | B7: 316L | C7: 8500 | E7: 250 | F7: ='250A'!K40 -> 940349 | G7: 3740000 | H7: =ROUND(G7/K7,0) -> 3740000 | I7: =ROUND(H7*L7,0) -> 3740000 | J7: =I7+F7 -> 4680349 | K7: =B2 -> 1 | L7: =B16 -> 1
A8: BODY Retainer Ring | B8: 316L | C8: 8500 | E8: 300 | F8: ='300A'!K40 -> 1269525 | G8: 3740000 | H8: =ROUND(G8/K8,0) -> 3740000 | I8: =ROUND(H8*L8,0) -> 3740000 | J8: =I8+F8 -> 5009525 | K8: =B2 -> 1 | L8: =B16 -> 1
A9: Upper Bush | B9: B148 | C9: 12500 | E9: 350 | F9: ='350A'!K40 -> 1370020 | G9: 4370000 | H9: =ROUND(G9/K9,0) -> 4370000 | I9: =ROUND(H9*L9,0) -> 4370000 | J9: =I9+F9 -> 5740020 | K9: =B2 -> 1 | L9: =B16 -> 1
A10: Bottom Bush | B10: B148 | C10: 12500 | E10: 400 | F10: ='400A'!K40 -> 2191546 | G10: 4370000 | H10: =ROUND(G10/K10,0) -> 4370000 | I10: =ROUND(H10*L10,0) -> 4370000 | J10: =I10+F10 -> 6561546 | K10: =B2 -> 1 | L10: =B16 -> 1
A11: Packing Grand | B11: WCB | C11: 2600 | E11: 450 | F11: ='450A'!K40 -> 2655904 | G11: 4370000 | H11: =ROUND(G11/K11,0) -> 4370000 | I11: =ROUND(H11*L11,0) -> 4370000 | J11: =I11+F11 -> 7025904 | K11: =B2 -> 1 | L11: =B16 -> 1
A12: Bottom Cover | B12: WCB | C12: 2600 | E12: 500 | F12: ='500A'!K40 -> 2808900 | G12: 4910000 | H12: =ROUND(G12/K12,0) -> 4910000 | I12: =ROUND(H12*L12,0) -> 4910000 | J12: =I12+F12 -> 7718900 | K12: =B2 -> 1 | L12: =B16 -> 1
A13: Top Flange Cover | B13: WCB | C13: 2600 | E13: 550 | F13: ='550A'!K40 -> 3405895 | G13: 4910000 | H13: =ROUND(G13/K13,0) -> 4910000 | I13: =ROUND(H13*L13,0) -> 4910000 | J13: =I13+F13 -> 8315895 | K13: =B2 -> 1 | L13: =B16 -> 1
E14: 600 | F14: ='600A'!K40 -> 3993065.8 | G14: 4910000 | H14: =ROUND(G14/K14,0) -> 4910000 | I14: =ROUND(H14*L14,0) -> 4910000 | J14: =I14+F14 -> 8903065.8 | K14: =B2 -> 1 | L14: =B16 -> 1
A15: FACTOR | B15: 1 | E15: 650 | F15: ='650A'!K40 -> 4502730 | G15: 4910000 | H15: =ROUND(G15/K15,0) -> 4910000 | I15: =ROUND(H15*L15,0) -> 4910000 | J15: =I15+F15 -> 9412730 | K15: =B2 -> 1 | L15: =B16 -> 1
A16: MOTOR FACTOR | B16: 1 | E16: 700 | F16: ='700A'!K40 -> 4396130 | G16: 6310000 | H16: =ROUND(G16/K16,0) -> 6310000 | I16: =ROUND(H16*L16,0) -> 6310000 | J16: =I16+F16 -> 10706130 | K16: =B2 -> 1 | L16: =B16 -> 1
A17: PRESSURE | B17: 10 BAR | E17: 750 | F17: ='750A'!K40 -> 5273538 | G17: 6310000 | H17: =ROUND(G17/K17,0) -> 6310000 | I17: =ROUND(H17*L17,0) -> 6310000 | J17: =I17+F17 -> 11583538 | K17: =B2 -> 1 | L17: =B16 -> 1
A18: 목형관리대장 | E18: 800 | F18: ='800A'!K40 -> 6119997.5 | G18: 6310000 | H18: =ROUND(G18/K18,0) -> 6310000 | I18: =ROUND(H18*L18,0) -> 6310000 | J18: =I18+F18 -> 12429998 | K18: =B2 -> 1 | L18: =B16 -> 1
A19: DIMESION TABLE | E19: 850 | F19: ='850A'!K40 -> 7116000 | G19: 7670000 | H19: =ROUND(G19/K19,0) -> 7670000 | I19: =ROUND(H19*L19,0) -> 7670000 | J19: =I19+F19 -> 14786000 | K19: =B2 -> 1 | L19: =B16 -> 1
E20: 900 | F20: ='900A'!K40 -> 8542270 | G20: 10410000 | H20: =ROUND(G20/K20,0) -> 10410000 | I20: =ROUND(H20*L20,0) -> 10410000 | J20: =I20+F20 -> 18952270 | K20: =B2 -> 1 | L20: =B16 -> 1
E21: 950 | F21: ='950A'!K40 -> 8909085 | G21: 10410000 | H21: =ROUND(G21/K21,0) -> 10410000 | I21: =ROUND(H21*L21,0) -> 10410000 | J21: =I21+F21 -> 19319085 | K21: =B2 -> 1 | L21: =B16 -> 1
E22: 1000 | F22: ='1000A'!K40 -> 9878065 | G22: 10410000 | H22: =ROUND(G22/K22,0) -> 10410000 | I22: =ROUND(H22*L22,0) -> 10410000 | J22: =I22+F22 -> 20288065 | K22: =B2 -> 1 | L22: =B16 -> 1
E23: 1050 | F23: ='1050A'!K40 -> 10618765 | G23: 10410000 | H23: =ROUND(G23/K23,0) -> 10410000 | I23: =ROUND(H23*L23,0) -> 10410000 | J23: =I23+F23 -> 21028765 | K23: =B2 -> 1 | L23: =B16 -> 1
E24: 1100 | F24: ='1100A'!K40 -> 11399545 | G24: 10410000 | H24: =ROUND(G24/K24,0) -> 10410000 | I24: =ROUND(H24*L24,0) -> 10410000 | J24: =I24+F24 -> 21809545 | K24: =B2 -> 1 | L24: =B16 -> 1
E25: 1200 | F25: ='1200A'!K40 -> 13161824 | G25: 10410000 | H25: =ROUND(G25/K25,0) -> 10410000 | I25: =ROUND(H25*L25,0) -> 10410000 | J25: =I25+F25 -> 23571824 | K25: =B2 -> 1 | L25: =B16 -> 1
E26: 1300 | F26: ='1300A'!K40 -> 15186924 | G26: 10410000 | H26: =ROUND(G26/K26,0) -> 10410000 | I26: =ROUND(H26*L26,0) -> 10410000 | J26: =I26+F26 -> 25596924 | K26: =B2 -> 1 | L26: =B16 -> 1
E27: 1400 | F27: ='1400A'!K40 -> 17349960 | G27: 10410000 | H27: =ROUND(G27/K27,0) -> 10410000 | I27: =ROUND(H27*L27,0) -> 10410000 | J27: =I27+F27 -> 27759960 | K27: =B2 -> 1 | L27: =B16 -> 1
E28: 1500 | F28: ='1500A'!K40 -> 19665390 | G28: 14770000 | H28: =ROUND(G28/K28,0) -> 14770000 | I28: =ROUND(H28*L28,0) -> 14770000 | J28: =I28+F28 -> 34435390 | K28: =B2 -> 1 | L28: =B16 -> 1
E29: 1600 | F29: ='1600A'!K43 -> 23994125 | G29: 14770000 | H29: =ROUND(G29/K29,0) -> 14770000 | I29: =ROUND(H29*L29,0) -> 14770000 | J29: =I29+F29 -> 38764125 | K29: =B2 -> 1 | L29: =B16 -> 1
E30: 1650 | F30: ='1650A'!K43 -> 26006275 | G30: 14770000 | H30: =ROUND(G30/K30,0) -> 14770000 | I30: =ROUND(H30*L30,0) -> 14770000 | J30: =I30+F30 -> 40776275 | K30: =B2 -> 1 | L30: =B16 -> 1
E31: 1700 | F31: ='1700A'!K43 -> 28456225 | G31: 14770000 | H31: =ROUND(G31/K31,0) -> 14770000 | I31: =ROUND(H31*L31,0) -> 14770000 | J31: =I31+F31 -> 43226225 | K31: =B2 -> 1 | L31: =B16 -> 1
E32: 1800 | F32: ='1800A'!K43 -> 42404700 | G32: 23460000 | H32: =ROUND(G32/K32,0) -> 23460000 | I32: =ROUND(H32*L32,0) -> 23460000 | J32: =I32+F32 -> 65864700 | K32: =B2 -> 1 | L32: =B16 -> 1
E33: 1900 | F33: ='1900A'!K43 -> 30916780 | G33: 23460000 | H33: =ROUND(G33/K33,0) -> 23460000 | I33: =ROUND(H33*L33,0) -> 23460000 | J33: =I33+F33 -> 54376780 | K33: =B2 -> 1 | L33: =B16 -> 1
E34: 1950 | F34: ='1950A'!K43 -> 31548960 | G34: 23460000 | H34: =ROUND(G34/K34,0) -> 23460000 | I34: =ROUND(H34*L34,0) -> 23460000 | J34: =I34+F34 -> 55008960 | K34: =B2 -> 1 | L34: =B16 -> 1
E35: 2000 | F35: ='2000A'!K43 -> 34025642 | G35: 23460000 | H35: =ROUND(G35/K35,0) -> 23460000 | I35: =ROUND(H35*L35,0) -> 23460000 | J35: =I35+F35 -> 57485642 | K35: =B2 -> 1 | L35: =B16 -> 1
E36: 2100 | F36: ='2100A'!K43 -> 36414422 | G36: 23460000 | H36: =ROUND(G36/K36,0) -> 23460000 | I36: =ROUND(H36*L36,0) -> 23460000 | J36: =I36+F36 -> 59874422 | K36: =B2 -> 1 | L36: =B16 -> 1
E37: 2200 | F37: ='2250A'!K43 -> 40791752 | G37: 23460000 | H37: =ROUND(G37/K37,0) -> 23460000 | I37: =ROUND(H37*L37,0) -> 23460000 | J37: =I37+F37 -> 64251752 | K37: =B2 -> 1 | L37: =B16 -> 1
E38: 2400 | F38: ='2400A'!K43 -> 49212017 | G38: 23460000 | H38: =ROUND(G38/K38,0) -> 23460000 | I38: =ROUND(H38*L38,0) -> 23460000 | J38: =I38+F38 -> 72672017 | K38: =B2 -> 1 | L38: =B16 -> 1
E39: 2500 | F39: ='2500A'!K43 -> 55634142 | G39: 23460000 | H39: =ROUND(G39/K39,0) -> 23460000 | I39: =ROUND(H39*L39,0) -> 23460000 | J39: =I39+F39 -> 79094142 | K39: =B2 -> 1 | L39: =B16 -> 1
B41: PIYAKE
B42: 10 BAR
...

Sheet 100A
A1: 제수변 BFV 원가 分析表
A3: SIZE : 100A | C3: 압력 : 150#
A5: NO. | B5: 부품명 | C5: 재질 | D5: 수량 | E5: 규격 | F5: 단중 | G5: 업체 | H5: 단가 | I5: 소계 | J5: 가공비 | K5: 합계
A6: 1 | B6: BODY | C6: =원가!B4 -> WCB | D6: 1 | F6: 27.25 | H6: =원가!C4 -> 2600 | I6: =D6*F6*H6 -> 70850 | J6: 70000 | K6: =I6+J6 -> 140850
A7: 2 | B7: DISC | C7: =원가!B5 -> WCB | D7: 1 | F7: 2.3 | H7: =원가!C5 -> 2600 | I7: =D7*F7*H7 -> 5980 | J7: 10000 | K7: =I7+J7 -> 15980
A8: 3 | B8: SEAT | C8: EPDM | D8: 1 | F8: 1 | I8: 2500 | K8: =I8+J8 -> 2500
A9: 4 | B9: STEM(上,下) | C9: =원가!B6 -> A276T316L | D9: 1 | F9: 1.34 | H9: =원가!C6 -> 8500 | I9: =D9*F9*H9 -> 11390 | J9: 5000 | K9: =I9+J9 -> 16390
A10: 5 | B10: DISC RETAINER | C10: =원가!B7 -> 316L | D10: 1 | F10: 3.4 | H10: =원가!C7 -> 8500 | I10: =D10*F10*H10 -> 28900 | J10: 12000 | K10: =I10+J10 -> 40900
B11: BODY RETAINER | C11: =원가!B8 -> 316L | D11: 1 | F11: 1.2 | H11: =원가!C8 -> 8500 | I11: =D11*F11*H11 -> 10200 | J11: 10000 | K11: =I11+J11 -> 20200
A12: 6 | B12: BUSH(上) | C12: =원가!B9 -> B148 | D12: 1 | F12: 0.35 | H12: =원가!C9 -> 12500 | I12: =D12*F12*H12 -> 4375 | J12: 7000 | K12: =I12+J12 -> 11375
B13: BUSH(下) | C13: =원가!B10 -> B148 | D13: 1 | F13: 0.35 | H13: =원가!C10 -> 12500 | I13: =D13*F13*H13 -> 4375 | J13: 7000 | K13: =I13+J13 -> 11375
A14: 7 | B14: PACKING RING | C14: EPDM | D14: 3 | F14: 1 | H14: 750 | I14: =D14*F14*H14 -> 2250 | K14: =I14+J14 -> 2250
B15: PACKING BUSH | C15: C95800 | D15: 1 | F15: 1 | H15: 700 | I15: =D15*F15*H15 -> 700 | J15: 2000 | K15: =I15+J15 -> 2700
A16: 8 | B16: PACKING GLAND | C16: =원가!B11 -> WCB | D16: 1 | F16: 1.5 | H16: =원가!C11 -> 2600 | I16: =D16*F16*H16 -> 3900 | J16: 3500 | K16: =I16+J16 -> 7400
A17: 9 | B17: STAND BOLT/NUT | C17: B8M | D17: 2 | F17: 1 | H17: 800 | I17: =D17*F17*H17 -> 1600 | K17: =I17+J17 -> 1600
A18: 10 | B18: BOTTOM COVER | C18: =원가!B12 -> WCB | D18: 1 | F18: 1 | H18: =원가!C12 -> 2600 | I18: =D18*F18*H18 -> 2600 | J18: 5000 | K18: =I18+J18 -> 7600
A19: 11 | B19: SPLIT COLLAR | C19: C95800 | D19: 1 | F19: 0.8 | H19: 8000 | I19: =D19*F19*H19 -> 6400 | J19: 2500 | K19: =I19+J19 -> 8900
A20: 12 | B20: DISC BOLT/NUT | C20: 316L | D20: 3 | F20: 1 | I20: 200 | J20: 1200 | K20: =I20+J20 -> 1400
A21: 13 | B21: DISC RETAINER BOLT | C21: B8M | D21: 4 | F21: 1 | H21: 60 | I21: =D21*F21*H21 -> 240 | K21: =I21+J21 -> 240
A22: 14 | B22: BOTTOM COVER BOLT/WASHER | C22: B8M | D22: 4 | F22: 1 | H22: 1000 | I22: =D22*F22*H22 -> 4000 | K22: =I22+J22 -> 4000
A23: 15 | B23: TOP FLG COVER | C23: =원가!B13 -> WCB | D23: 1 | F23: 2 | H23: =원가!C13 -> 2600 | I23: =D23*F23*H23 -> 5200 | J23: 6000 | K23: =I23+J23 -> 11200
A24: 16 | B24: TOP COVER BOLT | C24: B8M | D24: 4 | F24: 1 | I24: 2100 | J24: 3000 | K24: =I24+J24 -> 5100
A25: 17 | B25: BOTTOM O-RING | C25: EPDM | D25: 4 | F25: 1 | H25: 30 | I25: =D25*F25*H25 -> 120 | K25: =I25+J25 -> 120
A26: 18 | B26: GEAR BOX | C26: =원가!B17 -> 10 BAR | D26: 1 | F26: 6.3 | J26: TMG | K26: =IF(C26="PIYAKE",L26,IF(C26="10 BAR",M26,IF(C26="20 BAR",N26))) -> 98000 | L26: 25320 | M26: 98000 | N26: 98000
B27: GEAR BOX BOLT/WASHER | D27: 4 | F27: 1 | H27: 2500 | I27: =D27*F27*H27 -> 10000 | K27: =I27+J27 -> 10000
A28: 19 | B28: KEY & TAG | C28: SUS | D28: 1 | F28: 1 | I28: 220 | J28: 3300 | K28: =I28+J28 -> 3520
A29: 20 | B29: 페인트 | D29: 1 | F29: 1 | I29: 10000 | K29: =I29+J29 -> 10000
A30: 21 | B30: 조립.검사 | D30: 1 | F30: 1 | I30: 10000 | K30: =I30+J30 -> 10000
A31: 22 | B31: 밸브합산 | K31: =SUM(K6:K30) -> 443600
A32: 23
A33: 24 | B33: ACTUATOR | D33: 1 | F33: 1 | K33: =I33+J33 -> 0
B34: ACTUATOR BOLT/WASHER | D34: 4 | F34: 1 | K34: =I34+J34 -> 0
A35: 25 | B35: 포장비용 | D35: 1 | F35: 1 | K35: 5000
A36: 26 | B36: RUBBER LINNING | D36: 1 | F36: 1
A37: 27 | B37: 밸브외 사급품 비용 연산 | I37: =SUM(K32:K36) -> 5000 | J37: 1 | K37: =J37*I37 -> 5000
A38: 28
A39: 29 | B39: FACTOR | E39: 1차견적가 | F39: =L40 -> 1310 | I39: =K31 -> 443600 | J39: =원가!B15 -> 1 | K39: =J39*I39 -> 443600 | L39: 1차견적가
A40: 30 | B40: 견적가격(TOTAL금액) | E40: 네고가능가 | F40: =K40 -> 448600 | H40: 환율 | I40: =원가!B2 -> 1 | K40: =SUM(K37:K39)/I40 -> 448600 | L40: 1310

Sheet 125A
A1: 제수변 BFV 원가 分析表
A3: SIZE : 100A | B3: 125A | C3: 압력 : 150#
A5: NO. | B5: 부품명 | C5: 재질 | D5: 수량 | E5: 규격 | F5: 단중 | G5: 업체 | H5: 단가 | I5: 소계 | J5: 가공비 | K5: 합계
A6: 1 | B6: BODY | C6: =원가!B4 -> WCB | D6: 1 | F6: 35 | H6: =원가!C4 -> 2600 | I6: =D6*F6*H6 -> 91000 | J6: 70000 | K6: =I6+J6 -> 161000
A7: 2 | B7: DISC | C7: =원가!B5 -> WCB | D7: 1 | F7: 3.6 | H7: =원가!C5 -> 2600 | I7: =D7*F7*H7 -> 9360 | J7: 10000 | K7: =I7+J7 -> 19360
A8: 3 | B8: SEAT | C8: EPDM | D8: 1 | F8: 1 | I8: =D8*F8*H8 -> 0 | K8: =I8+J8 -> 0
A9: 4 | B9: STEM(上,下) | C9: =원가!B6 -> A276T316L | D9: 1 | F9: 2.4 | H9: =원가!C6 -> 8500 | I9: =D9*F9*H9 -> 20400 | J9: 5000 | K9: =I9+J9 -> 25400
A10: 5 | B10: DISC RETAINER | C10: =원가!B7 -> 316L | D10: 1 | F10: 3.4 | H10: =원가!C7 -> 8500 | I10: =D10*F10*H10 -> 28900 | J10: 12000 | K10: =I10+J10 -> 40900
B11: BODY RETAINER | C11: =원가!B8 -> 316L | D11: 1 | F11: 2.1 | H11: =원가!C8 -> 8500 | I11: =D11*F11*H11 -> 17850 | J11: 10000 | K11: =I11+J11 -> 27850
A12: 6 | B12: BUSH(上) | C12: =원가!B9 -> B148 | D12: 1 | F12: 0.35 | H12: =원가!C9 -> 12500 | I12: =D12*F12*H12 -> 4375 | J12: 7000 | K12: =I12+J12 -> 11375
B13: BUSH(下) | C13: =원가!B10 -> B148 | D13: 1 | F13: 0.35 | H13: =원가!C10 -> 12500 | I13: =D13*F13*H13 -> 4375 | J13: 7000 | K13: =I13+J13 -> 11375
A14: 7 | B14: PACKING RING | C14: EPDM | D14: 3 | F14: 1 | H14: 750 | I14: =D14*F14*H14 -> 2250 | K14: =I14+J14 -> 2250
B15: PACKING BUSH | C15: C95800 | D15: 1 | F15: 1 | H15: 700 | I15: =D15*F15*H15 -> 700 | J15: 2000 | K15: =I15+J15 -> 2700
A16: 8 | B16: PACKING GLAND | C16: =원가!B11 -> WCB | D16: 1 | F16: 1.5 | H16: =원가!C11 -> 2600 | I16: =D16*F16*H16 -> 3900 | J16: 3500 | K16: =I16+J16 -> 7400
A17: 9 | B17: STAND BOLT/NUT | C17: B8M | D17: 2 | F17: 1 | H17: 800 | I17: =D17*F17*H17 -> 1600 | K17: =I17+J17 -> 1600
A18: 10 | B18: BOTTOM COVER | C18: =원가!B12 -> WCB | D18: 1 | F18: 1 | H18: =원가!C12 -> 2600 | I18: =D18*F18*H18 -> 2600 | J18: 5000 | K18: =I18+J18 -> 7600
A19: 11 | B19: SPLIT COLLAR | C19: C95800 | D19: 1 | F19: 0.8 | H19: 8000 | I19: =D19*F19*H19 -> 6400 | J19: 2500 | K19: =I19+J19 -> 8900
A20: 12 | B20: DISC BOLT/NUT | C20: 316L | D20: 3 | F20: 1 | I20: =D20*F20*H20 -> 0 | J20: 1200 | K20: =I20+J20 -> 1200
A21: 13 | B21: DISC RETAINER BOLT | C21: B8M | D21: 4 | F21: 1 | H21: 60 | I21: =D21*F21*H21 -> 240 | K21: =I21+J21 -> 240
A22: 14 | B22: BOTTOM COVER BOLT/WASHER | C22: B8M | D22: 4 | F22: 1 | H22: 1000 | I22: =D22*F22*H22 -> 4000 | K22: =I22+J22 -> 4000
A23: 15 | B23: TOP FLG COVER | C23: =원가!B13 -> WCB | D23: 1 | F23: 2.1 | H23: =원가!C13 -> 2600 | I23: =D23*F23*H23 -> 5460 | J23: 6000 | K23: =I23+J23 -> 11460
A24: 16 | B24: TOP COVER BOLT | C24: B8M | D24: 4 | F24: 1 | I24: 2100 | J24: 3000 | K24: =I24+J24 -> 5100
A25: 17 | B25: BOTTOM O-RING | C25: EPDM | D25: 4 | F25: 1 | H25: 30 | I25: =D25*F25*H25 -> 120 | K25: =I25+J25 -> 120
A26: 18 | B26: GEAR BOX | C26: =원가!B17 -> 10 BAR | D26: 1 | F26: 6.3 | J26: TMG | K26: =IF(C26="PIYAKE",L26,IF(C26="10 BAR",M26,IF(C26="20 BAR",N26))) -> 98000 | L26: 25230 | M26: 98000 | N26: 98000
B27: GEAR BOX BOLT/WASHER | D27: 4 | F27: 1 | H27: 2500 | I27: =D27*F27*H27 -> 10000 | K27: =I27+J27 -> 10000
A28: 19 | B28: KEY & TAG | C28: SUS | D28: 1 | F28: 1 | I28: 220 | J28: 3300 | K28: =I28+J28 -> 3520
A29: 20 | B29: 페인트 | D29: 1 | F29: 1 | I29: 10000 | K29: =I29+J29 -> 10000
A30: 21 | B30: 조립.검사 | D30: 1 | F30: 1 | I30: 10000 | K30: =I30+J30 -> 10000
A31: 22 | B31: 밸브합산 | K31: =SUM(K6:K30) -> 481350
A32: 23
A33: 24 | B33: ACTUATOR | D33: 1 | F33: 1 | K33: =I33+J33 -> 0
B34: ACTUATOR BOLT/WASHER | D34: 4 | F34: 1 | K34: =I34+J34 -> 0
A35: 25 | B35: 포장비용 | D35: 1 | F35: 1 | K35: 5000
A36: 26 | B36: RUBBER LINNING | D36: 1 | F36: 1
A37: 27 | B37: 밸브외 사급품 비용 연산 | I37: =SUM(K32:K36) -> 5000 | J37: 1 | K37: =J37*I37 -> 5000
A38: 28
A39: 29 | B39: FACTOR | E39: 1차견적가 | F39: =L40 -> 1310 | I39: =K31 -> 481350 | J39: =원가!B15 -> 1 | K39: =J39*I39 -> 481350 | L39: 1차견적가
A40: 30 | B40: 견적가격(TOTAL금액) | E40: 네고가능가 | F40: =K40 -> 486350 | H40: 환율 | I40: =원가!B2 -> 1 | K40: =SUM(K37:K39)/I40 -> 486350 | L40: 1310

Sheet 150A
A1: 제수변 BFV 원가 分析表
A3: SIZE : 100A | B3: 150A | C3: 압력 : 150#
A5: NO. | B5: 부품명 | C5: 재질 | D5: 수량 | E5: 규격 | F5: 단중 | G5: 업체 | H5: 단가 | I5: 소계 | J5: 가공비 | K5: 합계
A6: 1 | B6: BODY | C6: =원가!B4 -> WCB | D6: 1 | F6: 40 | H6: =원가!C4 -> 2600 | I6: =D6*F6*H6 -> 104000 | J6: 100000 | K6: =I6+J6 -> 204000
A7: 2 | B7: DISC | C7: =원가!B5 -> WCB | D7: 1 | F7: 4.6 | H7: =원가!C5 -> 2600 | I7: =D7*F7*H7 -> 11960 | J7: 15000 | K7: =I7+J7 -> 26960
A8: 3 | B8: SEAT | C8: EPDM | D8: 1 | F8: 1 | I8: =D8*F8*H8 -> 0 | K8: =I8+J8 -> 0
A9: 4 | B9: STEM(上,下) | C9: =원가!B6 -> A276T316L | D9: 1 | F9: 2.67 | H9: =원가!C6 -> 8500 | I9: =D9*F9*H9 -> 22695 | J9: 5000 | K9: =I9+J9 -> 27695
A10: 5 | B10: DISC RETAINER | C10: =원가!B7 -> 316L | D10: 1 | F10: 5 | H10: =원가!C7 -> 8500 | I10: =D10*F10*H10 -> 42500 | J10: 12000 | K10: =I10+J10 -> 54500
B11: BODY RETAINER | C11: =원가!B8 -> 316L | D11: 1 | F11: 2.1 | H11: =원가!C8 -> 8500 | I11: =D11*F11*H11 -> 17850 | J11: 10000 | K11: =I11+J11 -> 27850
A12: 6 | B12: BUSH(上) | C12: =원가!B9 -> B148 | D12: 1 | F12: 0.8 | H12: =원가!C9 -> 12500 | I12: =D12*F12*H12 -> 10000 | J12: 7000 | K12: =I12+J12 -> 17000
B13: BUSH(下) | C13: =원가!B10 -> B148 | D13: 1 | F13: 0.8 | H13: =원가!C10 -> 12500 | I13: =D13*F13*H13 -> 10000 | J13: 7000 | K13: =I13+J13 -> 17000
A14: 7 | B14: PACKING RING | C14: EPDM | D14: 3 | F14: 1 | H14: 750 | I14: =D14*F14*H14 -> 2250 | K14: =I14+J14 -> 2250
B15: PACKING BUSH | C15: C95800 | D15: 1 | F15: 1 | H15: 700 | I15: =D15*F15*H15 -> 700 | J15: 2000 | K15: =I15+J15 -> 2700
A16: 8 | B16: PACKING GLAND | C16: =원가!B11 -> WCB | D16: 1 | F16: 2.4 | H16: =원가!C11 -> 2600 | I16: =D16*F16*H16 -> 6240 | J16: 3500 | K16: =I16+J16 -> 9740
A17: 9 | B17: STAND BOLT/NUT | C17: B8M | D17: 2 | F17: 1 | H17: 800 | I17: =D17*F17*H17 -> 1600 | K17: =I17+J17 -> 1600
A18: 10 | B18: BOTTOM COVER | C18: =원가!B12 -> WCB | D18: 1 | F18: 1 | H18: =원가!C12 -> 2600 | I18: =D18*F18*H18 -> 2600 | J18: 5000 | K18: =I18+J18 -> 7600
A19: 11 | B19: SPLIT COLLAR | C19: C95800 | D19: 1 | F19: 0.8 | H19: 8000 | I19: =D19*F19*H19 -> 6400 | J19: 2500 | K19: =I19+J19 -> 8900
A20: 12 | B20: DISC BOLT/NUT | C20: 316L | D20: 3 | F20: 1 | I20: =D20*F20*H20 -> 0 | J20: 1200 | K20: =I20+J20 -> 1200
A21: 13 | B21: DISC RETAINER BOLT | C21: B8M | D21: 4 | F21: 1 | H21: 60 | I21: =D21*F21*H21 -> 240 | K21: =I21+J21 -> 240
A22: 14 | B22: BOTTOM COVER BOLT/WASHER | C22: B8M | D22: 4 | F22: 1 | H22: 1000 | I22: =D22*F22*H22 -> 4000 | K22: =I22+J22 -> 4000
A23: 15 | B23: TOP FLG COVER | C23: =원가!B13 -> WCB | D23: 1 | F23: 2.2 | H23: =원가!C13 -> 2600 | I23: =D23*F23*H23 -> 5720 | J23: 6000 | K23: =I23+J23 -> 11720
A24: 16 | B24: TOP COVER BOLT | C24: B8M | D24: 4 | F24: 1 | H24: 1500 | I24: =D24*F24*H24 -> 6000 | K24: =I24+J24 -> 6000
A25: 17 | B25: BOTTOM O-RING | C25: EPDM | D25: 4 | F25: 1 | H25: 30 | I25: =D25*F25*H25 -> 120 | K25: =I25+J25 -> 120
A26: 18 | B26: GEAR BOX | C26: =원가!B17 -> 10 BAR | D26: 1 | F26: 6.3 | J26: TMG | K26: =IF(C26="PIYAKE",L26,IF(C26="10 BAR",M26,IF(C26="20 BAR",N26))) -> 98000 | L26: 25230 | M26: 98000 | N26: 98000
B27: GEAR BOX BOLT/WASHER | D27: 4 | F27: 1 | H27: 2500 | I27: =D27*F27*H27 -> 10000 | K27: =I27+J27 -> 10000
A28: 19 | B28: KEY & TAG | C28: SUS | D28: 1 | F28: 1 | I28: 220 | J28: 3300 | K28: =I28+J28 -> 3520
A29: 20 | B29: 페인트 | D29: 1 | F29: 1 | I29: 11500 | K29: =I29+J29 -> 11500
A30: 21 | B30: 조립.검사 | D30: 1 | F30: 1 | I30: 11500 | K30: =I30+J30 -> 11500
A31: 22 | B31: 밸브합산 | K31: =SUM(K6:K30) -> 565595
A32: 23
A33: 24 | B33: ACTUATOR | D33: 1 | F33: 1 | K33: =I33+J33 -> 0
B34: ACTUATOR BOLT/WASHER | D34: 4 | F34: 1 | K34: =I34+J34 -> 0
A35: 25 | B35: 포장비용 | D35: 1 | F35: 1 | K35: 8000
A36: 26 | B36: RUBBER LINNING | D36: 1 | F36: 1
A37: 27 | B37: 밸브외 사급품 비용 연산 | I37: =SUM(K32:K36) -> 8000 | J37: 1 | K37: =J37*I37 -> 8000
A38: 28
A39: 29 | B39: FACTOR | E39: 1차견적가 | F39: =L40 -> 1310 | I39: =K31 -> 565595 | J39: =원가!B15 -> 1 | K39: =J39*I39 -> 565595 | L39: 1차견적가
A40: 30 | B40: 견적가격(TOTAL금액) | E40: 네고가능가 | F40: =K40 -> 573595 | H40: 환율 | I40: =원가!B2 -> 1 | K40: =SUM(K37:K39)/I40 -> 573595 | L40: 1310

Sheet 200A
A1: 제수변 BFV 원가 分析表
A3: SIZE : 200A | C3: 압력 : 150#
A5: NO. | B5: 부품명 | C5: 재질 | D5: 수량 | E5: 규격 | F5: 단중 | G5: 업체 | H5: 단가 | I5: 소계 | J5: 가공비 | K5: 합계
A6: 1 | B6: BODY | C6: =원가!B4 -> WCB | D6: 1 | F6: 66 | H6: =원가!C4 -> 2600 | I6: =D6*F6*H6 -> 171600 | J6: 130000 | K6: =I6+J6 -> 301600
A7: 2 | B7: DISC | C7: =원가!B5 -> WCB | D7: 1 | F7: 9.2 | H7: =원가!C5 -> 2600 | I7: =D7*F7*H7 -> 23920 | J7: 15000 | K7: =I7+J7 -> 38920
A8: 3 | B8: SEAT | C8: EPDM | D8: 1 | F8: 1 | I8: 2500 | K8: =I8+J8 -> 2500
A9: 4 | B9: STEM(上,下) | C9: =원가!B6 -> A276T316L | D9: 1 | F9: 3.82 | H9: =원가!C6 -> 8500 | I9: =D9*F9*H9 -> 32470 | J9: 8000 | K9: =I9+J9 -> 40470
A10: 5 | B10: DISC RETAINER | C10: =원가!B7 -> 316L | D10: 1 | F10: 5 | H10: =원가!C7 -> 8500 | I10: =D10*F10*H10 -> 42500 | J10: 12000 | K10: =I10+J10 -> 54500
B11: BODY RETAINER | C11: =원가!B8 -> 316L | D11: 1 | F11: 3.3 | H11: =원가!C8 -> 8500 | I11: =D11*F11*H11 -> 28050 | J11: 12000 | K11: =I11+J11 -> 40050
A12: 6 | B12: BUSH(上) | C12: =원가!B9 -> B148 | D12: 1 | F12: 0.8 | H12: =원가!C9 -> 12500 | I12: =D12*F12*H12 -> 10000 | J12: 9000 | K12: =I12+J12 -> 19000
B13: BUSH(下) | C13: =원가!B10 -> B148 | D13: 1 | F13: 0.8 | H13: =원가!C10 -> 12500 | I13: =D13*F13*H13 -> 10000 | J13: 9000 | K13: =I13+J13 -> 19000
A14: 7 | B14: PACKING RING | C14: EPDM | D14: 3 | F14: 1 | H14: 500 | I14: =D14*F14*H14 -> 1500 | K14: =I14+J14 -> 1500
B15: PACKING BUSH | C15: C95800 | D15: 2 | F15: 1 | H15: 1000 | I15: =D15*F15*H15 -> 2000 | J15: 2000 | K15: =I15+J15 -> 4000
A16: 8 | B16: PACKING GLAND | C16: =원가!B11 -> WCB | D16: 1 | F16: 1.5 | H16: =원가!C11 -> 2600 | I16: =D16*F16*H16 -> 3900 | J16: 4000 | K16: =I16+J16 -> 7900
A17: 9 | B17: STAND BOLT/NUT | C17: B8M | D17: 2 | F17: 1 | H17: 600 | I17: =D17*F17*H17 -> 1200 | K17: =I17+J17 -> 1200
A18: 10 | B18: BOTTOM COVER | C18: =원가!B12 -> WCB | D18: 1 | F18: 1.27 | H18: =원가!C12 -> 2600 | I18: =D18*F18*H18 -> 3302 | J18: 6000 | K18: =I18+J18 -> 9302
A19: 11 | B19: SPLIT COLLAR | C19: C95800 | D19: 1 | I19: 1000 | J19: 2500 | K19: =I19+J19 -> 3500
A20: 12 | B20: DISC BOLT/NUT | C20: 316L | D20: 3 | F20: 1 | H20: 300 | I20: =D20*F20*H20 -> 900 | J20: 1500 | K20: =I20+J20 -> 2400
A21: 13 | B21: DISC RETAINER BOLT | C21: B8M | D21: 8 | F21: 1 | H21: 60 | I21: =D21*F21*H21 -> 480 | K21: =I21+J21 -> 480
A22: 14 | B22: BOTTOM COVER BOLT/WASHER | C22: B8M | D22: 4 | F22: 1 | H22: 1500 | I22: =D22*F22*H22 -> 6000 | K22: =I22+J22 -> 6000
A23: 15 | B23: TOP FLG COVER | C23: =원가!B13 -> WCB | D23: 1 | F23: 2.5 | H23: =원가!C13 -> 2600 | I23: =D23*F23*H23 -> 6500 | J23: 6000 | K23: =I23+J23 -> 12500
A24: 16 | B24: TOP COVER BOLT | C24: B8M | D24: 4 | F24: 1 | H24: 1500 | I24: =D24*F24*H24 -> 6000 | K24: =I24+J24 -> 6000
A25: 17 | B25: BOTTOM O-RING | C25: EPDM | D25: 1 | F25: 1 | I25: 400 | K25: =I25+J25 -> 400
A26: 18 | B26: GEAR BOX | C26: =원가!B17 -> 10 BAR | D26: 1 | F26: 6.3 | J26: TMG | K26: =IF(C26="PIYAKE",L26,IF(C26="10 BAR",M26,IF(C26="20 BAR",N26))) -> 98000 | L26: 25230 | M26: 98000 | N26: 98000
B27: GEAR BOX BOLT/WASHER | D27: 4 | F27: 1 | H27: 3000 | I27: =D27*F27*H27 -> 12000 | K27: =I27+J27 -> 12000
A28: 19 | B28: KEY & TAG | C28: SUS | D28: 1 | F28: 1 | I28: 220 | J28: 3300 | K28: =I28+J28 -> 3520
A29: 20 | B29: 페인트 | D29: 1 | F29: 1 | I29: 12000 | K29: =I29+J29 -> 12000
A30: 21 | B30: 조립.검사 | D30: 1 | F30: 1 | I30: 12000 | K30: =I30+J30 -> 12000
A31: 22 | B31: 밸브합산 | K31: =SUM(K6:K30) -> 708742
A32: 23
A33: 24 | B33: ACTUATOR | D33: 1 | F33: 1 | K33: =I33+J33 -> 0
B34: ACTUATOR BOLT/WASHER | D34: 4 | F34: 1 | K34: =I34+J34 -> 0
A35: 25 | B35: 포장비용 | D35: 1 | F35: 1 | K35: 9500
A36: 26 | B36: RUBBER LINNING | D36: 1 | F36: 1
A37: 27 | B37: 밸브외 사급품 비용 연산 | I37: =SUM(K32:K36) -> 9500 | J37: 1 | K37: =J37*I37 -> 9500
A38: 28
A39: 29 | B39: FACTOR | E39: 1차견적가 | F39: =L40 -> 1580 | I39: =K31 -> 708742 | J39: =원가!B15 -> 1 | K39: =J39*I39 -> 708742 | L39: 1차견적가
A40: 30 | B40: 견적가격(TOTAL금액) | E40: 네고가능가 | F40: =K40 -> 718242 | H40: 환율 | I40: =원가!B2 -> 1 | K40: =SUM(K37:K39)/I40 -> 718242 | L40: 1580

Sheet 250A
A1: 제수변 BFV 원가 分析表
A3: SIZE : 250A | C3: 압력 : 150#
A5: NO. | B5: 부품명 | C5: 재질 | D5: 수량 | E5: 규격 | F5: 단중 | G5: 업체 | H5: 단가 | I5: 소계 | J5: 가공비 | K5: 합계
A6: 1 | B6: BODY | C6: =원가!B4 -> WCB | D6: 1 | F6: 80.1 | H6: =원가!C4 -> 2600 | I6: =D6*F6*H6 -> 208260 | J6: 150000 | K6: =I6+J6 -> 358260
A7: 2 | B7: DISC | C7: =원가!B5 -> WCB | D7: 1 | F7: 9.8 | H7: =원가!C5 -> 2600 | I7: =D7*F7*H7 -> 25480 | J7: 20000 | K7: =I7+J7 -> 45480
A8: 3 | B8: SEAT | C8: EPDM | D8: 1 | F8: 1 | I8: 2500 | K8: =I8+J8 -> 2500
A9: 4 | B9: STEM(上,下) | C9: =원가!B6 -> A276T316L | D9: 1 | F9: 4.75 | H9: =원가!C6 -> 8500 | I9: =D9*F9*H9 -> 40375 | J9: 10000 | K9: =I9+J9 -> 50375
A10: 5 | B10: DISC RETAINER | C10: =원가!B7 -> 316L | D10: 1 | F10: 5.4 | H10: =원가!C7 -> 8500 | I10: =D10*F10*H10 -> 45900 | J10: 15000 | K10: =I10+J10 -> 60900
B11: BODY RETAINER | C11: =원가!B8 -> 316L | D11: 1 | F11: 5.4 | H11: =원가!C8 -> 8500 | I11: =D11*F11*H11 -> 45900 | J11: 15000 | K11: =I11+J11 -> 60900
A12: 6 | B12: BUSH(上) | C12: =원가!B9 -> B148 | D12: 1 | F12: 0.863 | H12: =원가!C9 -> 12500 | I12: =D12*F12*H12 -> 10787.5 | J12: 10500 | K12: =I12+J12 -> 21287.5
B13: BUSH(下) | C13: =원가!B10 -> B148 | D13: 1 | F13: 0.863 | H13: =원가!C10 -> 12500 | I13: =D13*F13*H13 -> 10787.5 | J13: 10500 | K13: =I13+J13 -> 21287.5
A14: 7 | B14: PACKING RING | C14: EPDM | D14: 3 | F14: 1 | H14: 500 | I14: =D14*F14*H14 -> 1500 | K14: =I14+J14 -> 1500
B15: PACKING BUSH | C15: C95800 | D15: 2 | F15: 1 | H15: 1000 | I15: =D15*F15*H15 -> 2000 | J15: 2000 | K15: =I15+J15 -> 4000
A16: 8 | B16: PACKING GLAND | C16: =원가!B11 -> WCB | D16: 1 | F16: 1.5 | H16: =원가!C11 -> 2600 | I16: =D16*F16*H16 -> 3900 | J16: 4000 | K16: =I16+J16 -> 7900
A17: 9 | B17: STAND BOLT/NUT | C17: B8M | D17: 2 | F17: 1 | H17: 600 | I17: =D17*F17*H17 -> 1200 | K17: =I17+J17 -> 1200
A18: 10 | B18: BOTTOM COVER | C18: =원가!B12 -> WCB | D18: 1 | F18: 1.415 | H18: =원가!C12 -> 2600 | I18: =D18*F18*H18 -> 3679 | J18: 6000 | K18: =I18+J18 -> 9679
A19: 11 | B19: SPLIT COLLAR | C19: C95800 | D19: 1 | I19: 1000 | J19: 3000 | K19: =I19+J19 -> 4000
A20: 12 | B20: DISC BOLT/NUT | C20: 316L | D20: 3 | F20: 1 | H20: 300 | I20: =D20*F20*H20 -> 900 | J20: 1500 | K20: =I20+J20 -> 2400
A21: 13 | B21: DISC RETAINER BOLT | C21: B8M | D21: 8 | F21: 1 | H21: 60 | I21: =D21*F21*H21 -> 480 | K21: =I21+J21 -> 480
A22: 14 | B22: BOTTOM COVER BOLT/WASHER | C22: B8M | D22: 4 | F22: 1 | H22: 1500 | I22: =D22*F22*H22 -> 6000 | K22: =I22+J22 -> 6000
A23: 15 | B23: TOP FLG COVER | C23: =원가!B13 -> WCB | D23: 1 | F23: 2.8 | H23: =원가!C13 -> 2600 | I23: =D23*F23*H23 -> 7280 | J23: 7000 | K23: =I23+J23 -> 14280
A24: 16 | B24: TOP COVER BOLT | C24: B8M | D24: 4 | F24: 1 | H24: 2000 | I24: =D24*F24*H24 -> 8000 | K24: =I24+J24 -> 8000
A25: 17 | B25: BOTTOM O-RING | C25: EPDM | D25: 1 | F25: 1 | I25: 400 | K25: =I25+J25 -> 400
A26: 18 | B26: GEAR BOX | C26: =원가!B17 -> 10 BAR | D26: 1 | F26: 6.3 | J26: TMG | K26: =IF(C26="PIYAKE",L26,IF(C26="10 BAR",M26,IF(C26="20 BAR",N26))) -> 203000 | L26: 27860 | M26: 203000 | N26: 203000
B27: GEAR BOX BOLT/WASHER | D27: 4 | F27: 1 | H27: 3000 | I27: =D27*F27*H27 -> 12000 | K27: =I27+J27 -> 12000
A28: 19 | B28: KEY & TAG | C28: SUS | D28: 1 | F28: 1 | I28: 220 | J28: 3300 | K28: =I28+J28 -> 3520
A29: 20 | B29: 페인트 | D29: 1 | F29: 1 | I29: 15000 | K29: =I29+J29 -> 15000
A30: 21 | B30: 조립.검사 | D30: 1 | F30: 1 | I30: 15000 | K30: =I30+J30 -> 15000
A31: 22 | B31: 밸브합산 | K31: =SUM(K6:K30) -> 929349
A32: 23
A33: 24 | B33: ACTUATOR | D33: 1 | F33: 1 | K33: =I33+J33 -> 0
B34: ACTUATOR BOLT/WASHER | D34: 4 | F34: 1 | K34: =I34+J34 -> 0
A35: 25 | B35: 포장비용 | D35: 1 | F35: 1 | K35: 11000
A36: 26 | B36: RUBBER LINNING | D36: 1 | F36: 1
A37: 27 | B37: 밸브외 사급품 비용 연산 | I37: =SUM(K32:K36) -> 11000 | J37: 1 | K37: =J37*I37 -> 11000
A38: 28
A39: 29 | B39: FACTOR | E39: 1차견적가 | F39: =L40 -> 0 | I39: =K31 -> 929349 | J39: =원가!B15 -> 1 | K39: =J39*I39 -> 929349 | L39: 1차견적가
A40: 30 | B40: 견적가격(TOTAL금액) | E40: 네고가능가 | F40: =K40 -> 940349 | H40: 환율 | I40: =원가!B2 -> 1 | K40: =SUM(K37:K39)/I40 -> 940349

Sheet 300A
A1: 제수변 BFV 원가 分析表
A3: SIZE : 300A | C3: 압력 : 150#
A5: NO. | B5: 부품명 | C5: 재질 | D5: 수량 | E5: 규격 | F5: 단중 | G5: 업체 | H5: 단가 | I5: 소계 | J5: 가공비 | K5: 합계
A6: 1 | B6: BODY | C6: =원가!B4 -> WCB | D6: 1 | F6: 131 | H6: =원가!C4 -> 2600 | I6: =D6*F6*H6 -> 340600 | J6: 170000 | K6: =I6+J6 -> 510600
A7: 2 | B7: DISC | C7: =원가!B5 -> WCB | D7: 1 | F7: 23 | H7: =원가!C5 -> 2600 | I7: =D7*F7*H7 -> 59800 | J7: 20000 | K7: =I7+J7 -> 79800
A8: 3 | B8: SEAT | C8: EPDM | D8: 1 | F8: 1 | I8: 7700 | K8: =I8+J8 -> 7700
A9: 4 | B9: STEM(上,下) | C9: =원가!B6 -> A276T316L | D9: 1 | F9: 7.29 | H9: =원가!C6 -> 8500 | I9: =D9*F9*H9 -> 61965 | J9: 25000 | K9: =I9+J9 -> 86965
A10: 5 | B10: DISC RETAINER | C10: =원가!B7 -> 316L | D10: 1 | F10: 5 | H10: =원가!C7 -> 8500 | I10: =D10*F10*H10 -> 42500 | J10: 25000 | K10: =I10+J10 -> 67500
B11: BODY RETAINER | C11: =원가!B8 -> 316L | D11: 1 | F11: 5 | H11: =원가!C8 -> 8500 | I11: =D11*F11*H11 -> 42500 | J11: 25000 | K11: =I11+J11 -> 67500
A12: 6 | B12: BUSH(上) | C12: =원가!B9 -> B148 | D12: 1 | F12: 2 | H12: =원가!C9 -> 12500 | I12: =D12*F12*H12 -> 25000 | J12: 3000 | K12: =I12+J12 -> 28000
B13: BUSH(下) | C13: =원가!B10 -> B148 | D13: 1 | F13: 2 | H13: =원가!C10 -> 12500 | I13: =D13*F13*H13 -> 25000 | J13: 3000 | K13: =I13+J13 -> 28000
A14: 7 | B14: PACKING RING | C14: EPDM | D14: 4 | F14: 1 | H14: 550 | I14: =D14*F14*H14 -> 2200 | K14: =I14+J14 -> 2200
B15: PACKING BUSH | C15: C95800 | D15: 3 | F15: 1 | H15: 4200 | I15: =D15*F15*H15 -> 12600 | K15: =I15+J15 -> 12600
A16: 8 | B16: PACKING GLAND | C16: =원가!B11 -> WCB | D16: 1 | F16: 2 | H16: =원가!C11 -> 2600 | I16: =D16*F16*H16 -> 5200 | J16: 4000 | K16: =I16+J16 -> 9200
A17: 9 | B17: STAND BOLT/NUT | C17: B8M | D17: 4 | F17: 1 | H17: 3200 | I17: =D17*F17*H17 -> 12800 | K17: =I17+J17 -> 12800
A18: 10 | B18: BOTTOM COVER | C18: =원가!B12 -> WCB | D18: 1 | F18: 2.6 | H18: =원가!C12 -> 2600 | I18: =D18*F18*H18 -> 6760 | J18: 7000 | K18: =I18+J18 -> 13760
A19: 11 | B19: SPLIT COLLAR | C19: C95800 | D19: 1 | F19: 1.25 | H19: 8000 | I19: =D19*F19*H19 -> 10000 | J19: 4000 | K19: =I19+J19 -> 14000
A20: 12 | B20: DISC BOLT/NUT | C20: 316L | D20: 2 | F20: 0.4 | H20: 2400 | I20: =D20*F20*H20 -> 1920 | J20: 4000 | K20: =I20+J20 -> 5920
A21: 13 | B21: DISC RETAINER BOLT | C21: B8M | D21: 12 | F21: 1 | H21: 110 | I21: =D21*F21*H21 -> 1320 | K21: =I21+J21 -> 1320
A22: 14 | B22: BOTTOM COVER BOLT/WASHER | C22: B8M | D22: 6 | F22: 1 | H22: 1500 | I22: =D22*F22*H22 -> 9000 | K22: =I22+J22 -> 9000
A23: 15 | B23: TOP FLG COVER | C23: =원가!B13 -> WCB | D23: 1 | F23: 7 | H23: =원가!C13 -> 2600 | I23: =D23*F23*H23 -> 18200 | J23: 9000 | K23: =I23+J23 -> 27200
A24: 16 | B24: TOP COVER BOLT | C24: B8M | D24: 4 | F24: 1 | H24: 2000 | I24: =D24*F24*H24 -> 8000 | K24: =I24+J24 -> 8000
A25: 17 | B25: BOTTOM O-RING | C25: EPDM | D25: 1 | F25: 1 | I25: 900 | K25: =I25+J25 -> 900
A26: 18 | B26: GEAR BOX | C26: =원가!B17 -> 10 BAR | D26: 1 | F26: 52 | I26: 181032 | J26: TMG | K26: =IF(C26="PIYAKE",L26,IF(C26="10 BAR",M26,IF(C26="20 BAR",N26))) -> 203000 | M26: 203000 | N26: 225000
B27: GEAR BOX BOLT/WASHER | D27: 4 | F27: 1 | H27: 3000 | I27: =D27*F27*H27 -> 12000 | K27: =I27+J27 -> 12000
A28: 19 | B28: KEY & TAG | C28: SUS | D28: 1 | F28: 1 | I28: 2160 | J28: 4400 | K28: =I28+J28 -> 6560
A29: 20 | B29: 페인트 | D29: 1 | F29: 1 | I29: 20000 | K29: =I29+J29 -> 20000
A30: 21 | B30: 조립.검사 | D30: 1 | F30: 1 | I30: 20000 | K30: =I30+J30 -> 20000
A31: 22 | B31: 밸브합산 | K31: =SUM(K6:K30) -> 1254525
A32: 23
A33: 24 | B33: ACTUATOR | D33: 1 | F33: 1 | K33: =I33+J33 -> 0
B34: ACTUATOR BOLT/WASHER | D34: 4 | F34: 1 | K34: =I34+J34 -> 0
A35: 25 | B35: 포장비용 | D35: 1 | F35: 1 | K35: 15000
A36: 26 | B36: RUBBER LINNING | D36: 1 | F36: 1
A37: 27 | B37: 밸브외 사급품 비용 연산 | I37: =SUM(K32:K36) -> 15000 | J37: 1 | K37: =J37*I37 -> 15000
A38: 28
A39: 29 | B39: FACTOR | E39: 1차견적가 | F39: =L40 -> 0 | I39: =K31 -> 1254525 | J39: =원가!B15 -> 1 | K39: =J39*I39 -> 1254525 | L39: 1차견적가
A40: 30 | B40: 견적가격(TOTAL금액) | E40: 네고가능가 | F40: =K40 -> 1269525 | H40: 환율 | I40: =원가!B2 -> 1 | K40: =SUM(K37:K39)/I40 -> 1269525

Sheet 350A
A1: 제수변 BFV 원가 分析表
A3: SIZE : 350A | C3: 압력 : 150#
A5: NO. | B5: 부품명 | C5: 재질 | D5: 수량 | E5: 규격 | F5: 단중 | G5: 업체 | H5: 단가 | I5: 소계 | J5: 가공비 | K5: 합계
A6: 1 | B6: BODY | C6: =원가!B4 -> WCB | D6: 1 | F6: 134.7 | H6: =원가!C4 -> 2600 | I6: =D6*F6*H6 -> 350220 | J6: 190000 | K6: =I6+J6 -> 540220
A7: 2 | B7: DISC | C7: =원가!B5 -> WCB | D7: 1 | F7: 27 | H7: =원가!C5 -> 2600 | I7: =D7*F7*H7 -> 70200 | J7: 40000 | K7: =I7+J7 -> 110200
A8: 3 | B8: SEAT | C8: EPDM | D8: 1 | F8: 1 | I8: 7700 | K8: =I8+J8 -> 7700
A9: 4 | B9: STEM(上,下) | C9: =원가!B6 -> A276T316L | D9: 1 | F9: 11 | H9: =원가!C6 -> 8500 | I9: =D9*F9*H9 -> 93500 | J9: 25000 | K9: =I9+J9 -> 118500
A10: 5 | B10: DISC RETAINER | C10: =원가!B7 -> 316L | D10: 1 | F10: 6 | H10: =원가!C7 -> 8500 | I10: =D10*F10*H10 -> 51000 | J10: 25000 | K10: =I10+J10 -> 76000
B11: BODY RETAINER | C11: =원가!B8 -> 316L | D11: 1 | F11: 6 | H11: =원가!C8 -> 8500 | I11: =D11*F11*H11 -> 51000 | J11: 25000 | K11: =I11+J11 -> 76000
A12: 6 | B12: BUSH(上) | C12: =원가!B9 -> B148 | D12: 1 | F12: 1 | H12: =원가!C9 -> 12500 | I12: =D12*F12*H12 -> 12500 | J12: 3000 | K12: =I12+J12 -> 15500
B13: BUSH(下) | C13: =원가!B10 -> B148 | D13: 1 | F13: 1 | H13: =원가!C10 -> 12500 | I13: =D13*F13*H13 -> 12500 | J13: 3000 | K13: =I13+J13 -> 15500
A14: 7 | B14: PACKING RING | C14: EPDM | D14: 4 | F14: 1 | H14: 550 | I14: =D14*F14*H14 -> 2200 | K14: =I14+J14 -> 2200
B15: PACKING BUSH | C15: C95800 | D15: 3 | F15: 1 | H15: 4200 | I15: =D15*F15*H15 -> 12600 | K15: =I15+J15 -> 12600
A16: 8 | B16: PACKING GLAND | C16: =원가!B11 -> WCB | D16: 1 | F16: 2.5 | H16: =원가!C11 -> 2600 | I16: =D16*F16*H16 -> 6500 | J16: 4000 | K16: =I16+J16 -> 10500
A17: 9 | B17: STAND BOLT/NUT | C17: B8M | D17: 4 | F17: 1 | H17: 3200 | I17: =D17*F17*H17 -> 12800 | K17: =I17+J17 -> 12800
A18: 10 | B18: BOTTOM COVER | C18: =원가!B12 -> WCB | D18: 1 | F18: 2.6 | H18: =원가!C12 -> 2600 | I18: =D18*F18*H18 -> 6760 | J18: 7000 | K18: =I18+J18 -> 13760
A19: 11 | B19: SPLIT COLLAR | C19: C95800 | D19: 1 | F19: 0.432 | H19: 8000 | I19: =D19*F19*H19 -> 3456 | J19: 4000 | K19: =I19+J19 -> 7456
A20: 12 | B20: DISC BOLT/NUT | C20: 316L | D20: 2 | F20: 0.23 | H20: 2400 | I20: =D20*F20*H20 -> 1104 | J20: 4000 | K20: =I20+J20 -> 5104
A21: 13 | B21: DISC RETAINER BOLT | C21: B8M | D21: 12 | F21: 1 | H21: 110 | I21: =D21*F21*H21 -> 1320 | K21: =I21+J21 -> 1320
A22: 14 | B22: BOTTOM COVER BOLT/WASHER | C22: B8M | D22: 6 | F22: 1 | H22: 1500 | I22: =D22*F22*H22 -> 9000 | K22: =I22+J22 -> 9000
A23: 15 | B23: TOP FLG COVER | C23: =원가!B13 -> WCB | D23: 1 | F23: 7 | H23: =원가!C13 -> 2600 | I23: =D23*F23*H23 -> 18200 | J23: 9000 | K23: =I23+J23 -> 27200
A24: 16 | B24: TOP COVER BOLT | C24: B8M | D24: 4 | F24: 1 | H24: 2000 | I24: =D24*F24*H24 -> 8000 | K24: =I24+J24 -> 8000
A25: 17 | B25: BOTTOM O-RING | C25: EPDM | D25: 1 | F25: 1 | I25: 900 | K25: =I25+J25 -> 900
A26: 18 | B26: GEAR BOX | C26: =원가!B17 -> 10 BAR | D26: 1 | F26: 52 | I26: 181032 | J26: TMG | K26: =IF(C26="PIYAKE",L26,IF(C26="10 BAR",M26,IF(C26="20 BAR",N26))) -> 203000 | M26: 203000 | N26: 305000
B27: GEAR BOX BOLT/WASHER | D27: 4 | F27: 1 | H27: 3000 | I27: =D27*F27*H27 -> 12000 | K27: =I27+J27 -> 12000
A28: 19 | B28: KEY & TAG | C28: SUS | D28: 1 | F28: 1 | I28: 2160 | J28: 4400 | K28: =I28+J28 -> 6560
A29: 20 | B29: 페인트 | D29: 1 | F29: 1 | I29: 35000 | K29: =I29+J29 -> 35000
A30: 21 | B30: 조립.검사 | D30: 1 | F30: 1 | I30: 25000 | K30: =I30+J30 -> 25000
A31: 22 | B31: 밸브합산 | K31: =SUM(K6:K30) -> 1352020
A32: 23
A33: 24 | B33: ACTUATOR | D33: 1 | F33: 1 | K33: =I33+J33 -> 0
B34: ACTUATOR BOLT/WASHER | D34: 4 | F34: 1 | K34: =I34+J34 -> 0
A35: 25 | B35: 포장비용 | D35: 1 | F35: 1 | K35: 18000
A36: 26 | B36: RUBBER LINNING | D36: 1 | F36: 1
A37: 27 | B37: 밸브외 사급품 비용 연산 | I37: =SUM(K32:K36) -> 18000 | J37: 1 | K37: =J37*I37 -> 18000
A38: 28
A39: 29 | B39: FACTOR | E39: 1차견적가 | F39: =L40 -> 0 | I39: =K31 -> 1352020 | J39: =원가!B15 -> 1 | K39: =J39*I39 -> 1352020 | L39: 1차견적가
A40: 30 | B40: 견적가격(TOTAL금액) | E40: 네고가능가 | F40: =K40 -> 1370020 | H40: 환율 | I40: =원가!B2 -> 1 | K40: =SUM(K37:K39)/I40 -> 1370020

Sheet 400A
A1: 제수변 BFV 원가 分析表
A3: SIZE : 400A | C3: 압력 : 150#
A5: NO. | B5: 부품명 | C5: 재질 | D5: 수량 | E5: 규격 | F5: 단중 | G5: 업체 | H5: 단가 | I5: 소계 | J5: 가공비 | K5: 합계
A6: 1 | B6: BODY | C6: =원가!B4 -> WCB | D6: 1 | F6: 205 | H6: =원가!C4 -> 2600 | I6: =D6*F6*H6 -> 533000 | J6: 230000 | K6: =I6+J6 -> 763000
A7: 2 | B7: DISC | C7: =원가!B5 -> WCB | D7: 1 | F7: 41 | H7: =원가!C5 -> 2600 | I7: =D7*F7*H7 -> 106600 | J7: 160000 | K7: =I7+J7 -> 266600
A8: 3 | B8: SEAT | C8: EPDM | D8: 1 | F8: 1 | I8: 7700 | K8: =I8+J8 -> 7700
A9: 4 | B9: STEM(上,下) | C9: =원가!B6 -> A276T316L | D9: 1 | F9: 20.74 | H9: =원가!C6 -> 8500 | I9: =D9*F9*H9 -> 176290 | J9: 35000 | K9: =I9+J9 -> 211290
A10: 5 | B10: DISC RETAINER | C10: =원가!B7 -> 316L | D10: 1 | F10: 11 | H10: =원가!C7 -> 8500 | I10: =D10*F10*H10 -> 93500 | J10: 30000 | K10: =I10+J10 -> 123500
B11: BODY RETAINER | C11: =원가!B8 -> 316L | D11: 1 | F11: 22.34 | H11: =원가!C8 -> 8500 | I11: =D11*F11*H11 -> 189890 | J11: 33000 | K11: =I11+J11 -> 222890
A12: 6 | B12: BUSH(上) | C12: =원가!B9 -> B148 | D12: 1 | F12: 3 | H12: =원가!C9 -> 12500 | I12: =D12*F12*H12 -> 37500 | J12: 13000 | K12: =I12+J12 -> 50500
B13: BUSH(下) | C13: =원가!B10 -> B148 | D13: 1 | F13: 3 | H13: =원가!C10 -> 12500 | I13: =D13*F13*H13 -> 37500 | J13: 13000 | K13: =I13+J13 -> 50500
A14: 7 | B14: PACKING RING | C14: EPDM | D14: 4 | F14: 1 | H14: 550 | I14: =D14*F14*H14 -> 2200 | K14: =I14+J14 -> 2200
B15: PACKING BUSH | C15: C95800 | D15: 3 | F15: 1 | H15: 4200 | I15: =D15*F15*H15 -> 12600 | J15: 9000 | K15: =I15+J15 -> 21600
A16: 8 | B16: PACKING GLAND | C16: =원가!B11 -> WCB | D16: 1 | F16: 3 | H16: =원가!C11 -> 2600 | I16: =D16*F16*H16 -> 7800 | J16: 6000 | K16: =I16+J16 -> 13800
A17: 9 | B17: STAND BOLT/NUT | C17: B8M | D17: 4 | F17: 1 | H17: 3200 | I17: =D17*F17*H17 -> 12800 | K17: =I17+J17 -> 12800
A18: 10 | B18: BOTTOM COVER | C18: =원가!B12 -> WCB | D18: 1 | F18: 4.37 | H18: =원가!C12 -> 2600 | I18: =D18*F18*H18 -> 11362 | J18: 10000 | K18: =I18+J18 -> 21362
A19: 11 | B19: SPLIT COLLAR | C19: C95800 | D19: 1 | F19: 0.706 | H19: 8000 | I19: =D19*F19*H19 -> 5648 | J19: 4000 | K19: =I19+J19 -> 9648
A20: 12 | B20: DISC BOLT/NUT | C20: 316L | D20: 2 | F20: 0.37 | H20: 2400 | I20: =D20*F20*H20 -> 1776 | J20: 4000 | K20: =I20+J20 -> 5776
A21: 13 | B21: DISC RETAINER BOLT | C21: B8M | D21: 12 | F21: 1 | H21: 110 | I21: =D21*F21*H21 -> 1320 | K21: =I21+J21 -> 1320
A22: 14 | B22: BOTTOM COVER BOLT/WASHER | C22: B8M | D22: 6 | F22: 1 | H22: 2000 | I22: =D22*F22*H22 -> 12000 | K22: =I22+J22 -> 12000
A23: 15 | B23: TOP FLG COVER | C23: =원가!B13 -> WCB | D23: 1 | F23: 11 | H23: =원가!C13 -> 2600 | I23: =D23*F23*H23 -> 28600 | J23: 12000 | K23: =I23+J23 -> 40600
A24: 16 | B24: TOP COVER BOLT | C24: B8M | D24: 4 | F24: 1 | H24: 2500 | I24: =D24*F24*H24 -> 10000 | K24: =I24+J24 -> 10000
A25: 17 | B25: BOTTOM O-RING | C25: EPDM | D25: 1 | F25: 1 | I25: 900 | K25: =I25+J25 -> 900
A26: 18 | B26: GEAR BOX | C26: =원가!B17 -> 10 BAR | D26: 1 | F26: 52 | J26: TMG | K26: =IF(C26="PIYAKE",L26,IF(C26="10 BAR",M26,IF(C26="20 BAR",N26))) -> 225000 | L26: 258070 | M26: 225000 | N26: 305000
B27: GEAR BOX BOLT/WASHER | D27: 4 | F27: 1 | H27: 3000 | I27: =D27*F27*H27 -> 12000 | K27: =I27+J27 -> 12000
A28: 19 | B28: KEY & TAG | C28: SUS | D28: 1 | F28: 1 | I28: 2160 | J28: 4400 | K28: =I28+J28 -> 6560
A29: 20 | B29: 페인트 | D29: 1 | F29: 1 | I29: 40000 | K29: =I29+J29 -> 40000
A30: 21 | B30: 조립.검사 | D30: 1 | F30: 1 | I30: 35000 | K30: =I30+J30 -> 35000
A31: 22 | B31: 밸브합산 | K31: =SUM(K6:K30) -> 2166546
A32: 23
A33: 24 | B33: ACTUATOR | D33: 1 | F33: 1 | K33: =I33+J33 -> 0
B34: ACTUATOR BOLT/WASHER | D34: 4 | F34: 1 | K34: =I34+J34 -> 0
A35: 25 | B35: 포장비용 | D35: 1 | F35: 1 | K35: 25000
A36: 26 | B36: RUBBER LINNING | D36: 1 | F36: 1
A37: 27 | B37: 밸브외 사급품 비용 연산 | I37: =SUM(K32:K36) -> 25000 | J37: 1 | K37: =J37*I37 -> 25000
A38: 28
A39: 29 | B39: FACTOR | E39: 1차견적가 | F39: =L40 -> 6990 | I39: =K31 -> 2166546 | J39: =원가!B15 -> 1 | K39: =J39*I39 -> 2166546 | L39: 1차견적가
A40: 30 | B40: 견적가격(TOTAL금액) | E40: 네고가능가 | F40: =K40 -> 2191546 | H40: 환율 | I40: =원가!B2 -> 1 | K40: =SUM(K37:K39)/I40 -> 2191546 | L40: 6990

Sheet 450A
A1: 제수변 BFV 원가 分析表
A3: SIZE : 450A | C3: 압력 : 150#
A5: NO. | B5: 부품명 | C5: 재질 | D5: 수량 | E5: 규격 | F5: 단중 | G5: 업체 | H5: 단가 | I5: 소계 | J5: 가공비 | K5: 합계
A6: 1 | B6: BODY | C6: =원가!B4 -> WCB | D6: 1 | F6: 238 | H6: =원가!C4 -> 2600 | I6: =D6*F6*H6 -> 618800 | J6: 270000 | K6: =I6+J6 -> 888800
A7: 2 | B7: DISC | C7: =원가!B5 -> WCB | D7: 1 | F7: 52 | H7: =원가!C5 -> 2600 | I7: =D7*F7*H7 -> 135200 | J7: 160000 | K7: =I7+J7 -> 295200
A8: 3 | B8: SEAT | C8: EPDM | D8: 1 | F8: 1 | I8: 7700 | K8: =I8+J8 -> 7700
A9: 4 | B9: STEM(上,下) | C9: =원가!B6 -> A276T316L | D9: 1 | F9: 23 | H9: =원가!C6 -> 8500 | I9: =D9*F9*H9 -> 195500 | J9: 35000 | K9: =I9+J9 -> 230500
A10: 5 | B10: DISC RETAINER | C10: =원가!B7 -> 316L | D10: 1 | F10: 22.34 | H10: =원가!C7 -> 8500 | I10: =D10*F10*H10 -> 189890 | J10: 40000 | K10: =I10+J10 -> 229890
B11: BODY RETAINER | C11: =원가!B8 -> 316L | D11: 1 | F11: 22.34 | H11: =원가!C8 -> 8500 | I11: =D11*F11*H11 -> 189890 | J11: 33000 | K11: =I11+J11 -> 222890
A12: 6 | B12: BUSH(上) | C12: =원가!B9 -> B148 | D12: 1 | F12: 3.8 | H12: =원가!C9 -> 12500 | I12: =D12*F12*H12 -> 47500 | J12: 13000 | K12: =I12+J12 -> 60500
B13: BUSH(下) | C13: =원가!B10 -> B148 | D13: 1 | F13: 3.8 | H13: =원가!C10 -> 12500 | I13: =D13*F13*H13 -> 47500 | J13: 13000 | K13: =I13+J13 -> 60500
A14: 7 | B14: PACKING RING | C14: EPDM | D14: 4 | F14: 8 | H14: 550 | I14: =D14*F14*H14 -> 17600 | K14: =I14+J14 -> 17600
B15: PACKING BUSH | C15: C95800 | D15: 3 | F15: 1 | H15: 4200 | I15: =D15*F15*H15 -> 12600 | J15: 9000 | K15: =I15+J15 -> 21600
A16: 8 | B16: PACKING GLAND | C16: =원가!B11 -> WCB | D16: 1 | F16: 2.5 | H16: =원가!C11 -> 2600 | I16: =D16*F16*H16 -> 6500 | J16: 6000 | K16: =I16+J16 -> 12500
A17: 9 | B17: STAND BOLT/NUT | C17: B8M | D17: 4 | F17: 1 | H17: 3200 | I17: =D17*F17*H17 -> 12800 | K17: =I17+J17 -> 12800
A18: 10 | B18: BOTTOM COVER | C18: =원가!B12 -> WCB | D18: 1 | F18: 4.5 | H18: =원가!C12 -> 2600 | I18: =D18*F18*H18 -> 11700 | J18: 10000 | K18: =I18+J18 -> 21700
A19: 11 | B19: SPLIT COLLAR | C19: C95800 | D19: 1 | F19: 1 | H19: 8000 | I19: =D19*F19*H19 -> 8000 | J19: 4000 | K19: =I19+J19 -> 12000
A20: 12 | B20: DISC BOLT/NUT | C20: 316L | D20: 2 | F20: 0.43 | H20: 2400 | I20: =D20*F20*H20 -> 2064 | J20: 4000 | K20: =I20+J20 -> 6064
A21: 13 | B21: DISC RETAINER BOLT | C21: B8M | D21: 12 | F21: 1 | H21: 3000 | I21: =D21*F21*H21 -> 36000 | K21: =I21+J21 -> 36000
A22: 14 | B22: BOTTOM COVER BOLT/WASHER | C22: B8M | D22: 6 | F22: 1 | H22: 2000 | I22: =D22*F22*H22 -> 12000 | K22: =I22+J22 -> 12000
A23: 15 | B23: TOP FLG COVER | C23: =원가!B13 -> WCB | D23: 1 | F23: 17 | H23: =원가!C13 -> 2600 | I23: =D23*F23*H23 -> 44200 | J23: 12000 | K23: =I23+J23 -> 56200
A24: 16 | B24: TOP COVER BOLT | C24: B8M | D24: 4 | F24: 1 | H24: 2500 | I24: =D24*F24*H24 -> 10000 | K24: =I24+J24 -> 10000
A25: 17 | B25: BOTTOM O-RING | C25: EPDM | D25: 1 | F25: 1 | I25: 900 | K25: =I25+J25 -> 900
A26: 18 | B26: GEAR BOX | C26: =원가!B17 -> 10 BAR | D26: 1 | F26: 52 | J26: TMG | K26: =IF(C26="PIYAKE",L26,IF(C26="10 BAR",M26,IF(C26="20 BAR",N26))) -> 305000 | L26: 258070 | M26: 305000 | N26: 355000
B27: GEAR BOX BOLT/WASHER | D27: 4 | F27: 1 | H27: 3500 | I27: =D27*F27*H27 -> 14000 | K27: =I27+J27 -> 14000
A28: 19 | B28: KEY & TAG | C28: SUS | D28: 1 | F28: 1 | I28: 2160 | J28: 4400 | K28: =I28+J28 -> 6560
A29: 20 | B29: 페인트 | D29: 1 | F29: 1 | I29: 45000 | K29: =I29+J29 -> 45000
A30: 21 | B30: 조립.검사 | D30: 1 | F30: 1 | I30: 40000 | K30: =I30+J30 -> 40000
A31: 22 | B31: 밸브합산 | K31: =SUM(K6:K30) -> 2625904
A32: 23
A33: 24 | B33: ACTUATOR | D33: 1 | F33: 1 | K33: =I33+J33 -> 0
B34: ACTUATOR BOLT/WASHER | D34: 4 | F34: 1 | K34: =I34+J34 -> 0
A35: 25 | B35: 포장비용 | D35: 1 | F35: 1 | K35: 30000
A36: 26 | B36: RUBBER LINNING | D36: 1 | F36: 1
A37: 27 | B37: 밸브외 사급품 비용 연산 | I37: =SUM(K32:K36) -> 30000 | J37: 1 | K37: =J37*I37 -> 30000
A38: 28
A39: 29 | B39: FACTOR | E39: 1차견적가 | F39: =L40 -> 6990 | I39: =K31 -> 2625904 | J39: =원가!B15 -> 1 | K39: =J39*I39 -> 2625904 | L39: 1차견적가
A40: 30 | B40: 견적가격(TOTAL금액) | E40: 네고가능가 | F40: =K40 -> 2655904 | H40: 환율 | I40: =원가!B2 -> 1 | K40: =SUM(K37:K39)/I40 -> 2655904 | L40: 6990

Sheet 500A
A1: 제수변 BFV 원가 分析表
A3: SIZE : 500A | C3: 압력 : 150#
A5: NO. | B5: 부품명 | C5: 재질 | D5: 수량 | E5: 규격 | F5: 단중 | G5: 업체 | H5: 단가 | I5: 소계 | J5: 가공비 | K5: 합계
A6: 1 | B6: BODY | C6: =원가!B4 -> WCB | D6: 1 | F6: 290 | H6: =원가!C4 -> 2600 | I6: =D6*F6*H6 -> 754000 | J6: 290000 | K6: =I6+J6 -> 1044000
A7: 2 | B7: DISC | C7: =원가!B5 -> WCB | D7: 1 | F7: 81 | H7: =원가!C5 -> 2600 | I7: =D7*F7*H7 -> 210600 | J7: 180000 | K7: =I7+J7 -> 390600
A8: 3 | B8: SEAT | C8: EPDM | D8: 1 | F8: 1 | I8: 8400 | K8: =I8+J8 -> 8400
A9: 4 | B9: STEM(上,下) | C9: =원가!B6 -> A276T316L | D9: 1 | F9: 29 | H9: =원가!C6 -> 8500 | I9: =D9*F9*H9 -> 246500 | J9: 50000 | K9: =I9+J9 -> 296500
A10: 5 | B10: DISC RETAINER | C10: =원가!B7 -> 316L | D10: 1 | F10: 14.5 | H10: =원가!C7 -> 8500 | I10: =D10*F10*H10 -> 123250 | J10: 45000 | K10: =I10+J10 -> 168250
B11: BODY RETAINER | C11: =원가!B8 -> 316L | D11: 1 | F11: 14.5 | H11: =원가!C8 -> 8500 | I11: =D11*F11*H11 -> 123250 | J11: 45000 | K11: =I11+J11 -> 168250
A12: 6 | B12: BUSH(上) | C12: =원가!B9 -> B148 | D12: 1 | F12: 2 | H12: =원가!C9 -> 12500 | I12: =D12*F12*H12 -> 25000 | J12: 15000 | K12: =I12+J12 -> 40000
B13: BUSH(下) | C13: =원가!B10 -> B148 | D13: 1 | F13: 2 | H13: =원가!C10 -> 12500 | I13: =D13*F13*H13 -> 25000 | J13: 15000 | K13: =I13+J13 -> 40000
A14: 7 | B14: PACKING RING | C14: EPDM | D14: 4 | F14: 1 | H14: 550 | I14: =D14*F14*H14 -> 2200 | K14: =I14+J14 -> 2200
B15: PACKING BUSH | C15: C95800 | D15: 1 | F15: 0.7 | H15: 8000 | I15: =D15*F15*H15 -> 5600 | J15: 3500 | K15: =I15+J15 -> 9100
A16: 8 | B16: PACKING GLAND | C16: =원가!B11 -> WCB | D16: 1 | F16: 3.4 | H16: =원가!C11 -> 2600 | I16: =D16*F16*H16 -> 8840 | J16: 6000 | K16: =I16+J16 -> 14840
A17: 9 | B17: STAND BOLT/NUT | C17: B8M | D17: 4 | F17: 1 | H17: 2400 | I17: =D17*F17*H17 -> 9600 | K17: =I17+J17 -> 9600
A18: 10 | B18: BOTTOM COVER | C18: =원가!B12 -> WCB | D18: 1 | F18: 3.5 | H18: =원가!C12 -> 2600 | I18: =D18*F18*H18 -> 9100 | J18: 10000 | K18: =I18+J18 -> 19100
A19: 11 | B19: SPLIT COLLAR | C19: CF3M | D19: 1 | F19: 0.7 | H19: 7500 | I19: =D19*F19*H19 -> 5250 | J19: 4500 | K19: =I19+J19 -> 9750
A20: 12 | B20: DISC BOLT/NUT | C20: 316L | D20: 3 | F20: 0.5 | I20: 3500 | J20: 4770 | K20: =I20+J20 -> 8270
A21: 13 | B21: DISC RETAINER BOLT | C21: B8M | D21: 16 | F21: 1 | H21: 130 | I21: =D21*F21*H21 -> 2080 | K21: =I21+J21 -> 2080
A22: 14 | B22: BOTTOM COVER BOLT/WASHER | C22: B8M | D22: 6 | F22: 1 | H22: 2000 | I22: =D22*F22*H22 -> 12000 | K22: =I22+J22 -> 12000
A23: 15 | B23: TOP FLG COVER | C23: =원가!B13 -> WCB | D23: 1 | F23: 20 | H23: =원가!C13 -> 2600 | I23: =D23*F23*H23 -> 52000 | J23: 22000 | K23: =I23+J23 -> 74000
A24: 16 | B24: TOP COVER BOLT | C24: B8M | D24: 4 | F24: 1 | H24: 3500 | I24: =D24*F24*H24 -> 14000 | K24: =I24+J24 -> 14000
A25: 17 | B25: BOTTOM O-RING | C25: EPDM | D25: 1 | F25: 1 | H25: 560 | I25: =D25*F25*H25 -> 560 | J25: 1000 | K25: =I25+J25 -> 1560
A26: 18 | B26: GEAR BOX | C26: =원가!B17 -> 10 BAR | D26: 1 | F26: 52 | I26: 243432 | J26: TMG | K26: =IF(C26="PIYAKE",L26,IF(C26="10 BAR",M26,IF(C26="20 BAR",N26))) -> 305000 | M26: 305000 | N26: 355000
B27: GEAR BOX BOLT/WASHER | D27: 8 | F27: 1 | H27: 3500 | I27: =D27*F27*H27 -> 28000 | K27: =I27+J27 -> 28000
A28: 19 | B28: KEY & TAG | C28: SUS | D28: 1 | F28: 1 | I28: 4000 | J28: 4400 | K28: =I28+J28 -> 8400
A29: 20 | B29: 페인트 | D29: 1 | F29: 1 | I29: 50000 | K29: =I29+J29 -> 50000
A30: 21 | B30: 조립.검사 | D30: 1 | F30: 1 | I30: 45000 | K30: =I30+J30 -> 45000
A31: 22 | B31: 밸브합산 | K31: =SUM(K6:K30) -> 2768900
A32: 23 | B32: PNE.ACT | C32: SINGLE | D32: 1 | E32: FAIL TO CLOSE | G32: DW7 SR
A33: 24 | B33: LIMIT/SOL V/V | D33: 1 | F33: 1
B34: ACTUATOR BOLT/WASHER | D34: 4 | F34: 1 | H34: 630 | I34: =D34*F34*H34 -> 2520
A35: 25 | B35: 포장비용 | D35: 1 | F35: 1 | K35: 40000
A36: 26 | B36: RUBBER LINNING | D36: 1 | F36: 1
A37: 27 | B37: 밸브외 사급품 비용 연산 | I37: =SUM(K32:K36) -> 40000 | J37: 1 | K37: =J37*I37 -> 40000
A38: 28
A39: 29 | B39: FACTOR | E39: 1차견적가 | F39: =L40 -> 0 | I39: =K31 -> 2768900 | J39: =원가!B15 -> 1 | K39: =J39*I39 -> 2768900 | L39: 1차견적가
A40: 30 | B40: 견적가격(TOTAL금액) | E40: 네고가능가 | F40: =K40 -> 2808900 | H40: 환율 | I40: =원가!B2 -> 1 | K40: =SUM(K37:K39)/I40 -> 2808900
J41: 중량확인

Sheet 550A
A1: 제수변 BFV 원가 分析表
A3: SIZE : 550A | C3: 압력 : 150#
A5: NO. | B5: 부품명 | C5: 재질 | D5: 수량 | E5: 규격 | F5: 단중 | G5: 업체 | H5: 단가 | I5: 소계 | J5: 가공비 | K5: 합계
A6: 1 | B6: BODY | C6: =원가!B4 -> WCB | D6: 1 | F6: 380 | H6: =원가!C4 -> 2600 | I6: =D6*F6*H6 -> 988000 | J6: 310000 | K6: =I6+J6 -> 1298000
A7: 2 | B7: DISC | C7: =원가!B5 -> WCB | D7: 1 | F7: 100 | H7: =원가!C5 -> 2600 | I7: =D7*F7*H7 -> 260000 | J7: 200000 | K7: =I7+J7 -> 460000
A8: 3 | B8: SEAT | C8: EPDM | D8: 1 | F8: 1 | I8: 13000 | J8: 10000 | K8: =I8+J8 -> 23000
A9: 4 | B9: STEM(上,下) | C9: =원가!B6 -> A276T316L | D9: 1 | F9: 43 | H9: =원가!C6 -> 8500 | I9: =D9*F9*H9 -> 365500 | K9: =I9+J9 -> 365500
A10: 5 | B10: DISC RETAINER | C10: =원가!B7 -> 316L | D10: 1 | F10: 17 | H10: =원가!C7 -> 8500 | I10: =D10*F10*H10 -> 144500 | J10: 60000 | K10: =I10+J10 -> 204500
B11: BODY RETAINER | C11: =원가!B8 -> 316L | D11: 1 | F11: 17 | H11: =원가!C8 -> 8500 | I11: =D11*F11*H11 -> 144500 | J11: 60000 | K11: =I11+J11 -> 204500
A12: 6 | B12: BUSH(上) | C12: =원가!B9 -> B148 | D12: 1 | F12: 2.1 | H12: =원가!C9 -> 12500 | I12: =D12*F12*H12 -> 26250 | J12: 18000 | K12: =I12+J12 -> 44250
B13: BUSH(下) | C13: =원가!B10 -> B148 | D13: 1 | F13: 2.1 | H13: =원가!C10 -> 12500 | I13: =D13*F13*H13 -> 26250 | J13: 18000 | K13: =I13+J13 -> 44250
A14: 7 | B14: PACKING RING | C14: EPDM | D14: 4 | F14: 1 | H14: 550 | I14: =D14*F14*H14 -> 2200 | K14: =I14+J14 -> 2200
B15: PACKING BUSH | C15: C95800 | D15: 1 | F15: 3.75 | H15: 8000 | I15: =D15*F15*H15 -> 30000 | J15: 3500 | K15: =I15+J15 -> 33500
A16: 8 | B16: PACKING GLAND | C16: =원가!B11 -> WCB | D16: 1 | F16: 5 | H16: =원가!C11 -> 2600 | I16: =D16*F16*H16 -> 13000 | J16: 11000 | K16: =I16+J16 -> 24000
A17: 9 | B17: STAND BOLT/NUT | C17: B8M | D17: 4 | F17: 1 | H17: 2400 | I17: =D17*F17*H17 -> 9600 | K17: =I17+J17 -> 9600
A18: 10 | B18: BOTTOM COVER | C18: =원가!B12 -> WCB | D18: 1 | F18: 7.6 | H18: =원가!C12 -> 2600 | I18: =D18*F18*H18 -> 19760 | J18: 10000 | K18: =I18+J18 -> 29760
A19: 11 | B19: SPLIT COLLAR | C19: CF3M | D19: 1 | F19: 0.75 | H19: 7500 | I19: =D19*F19*H19 -> 5625 | J19: 4500 | K19: =I19+J19 -> 10125
A20: 12 | B20: DISC BOLT/NUT | C20: 316L | D20: 3 | F20: 1.71 | I20: 3500 | J20: 4770 | K20: =I20+J20 -> 8270
A21: 13 | B21: DISC RETAINER BOLT | C21: B8M | D21: 16 | F21: 1 | H21: 130 | I21: =D21*F21*H21 -> 2080 | K21: =I21+J21 -> 2080
A22: 14 | B22: BOTTOM COVER BOLT/WASHER | C22: B8M | D22: 6 | F22: 1 | H22: 2000 | I22: =D22*F22*H22 -> 12000 | K22: =I22+J22 -> 12000
A23: 15 | B23: TOP FLG COVER | C23: =원가!B13 -> WCB | D23: 1 | F23: 24 | H23: =원가!C13 -> 2600 | I23: =D23*F23*H23 -> 62400 | J23: 22000 | K23: =I23+J23 -> 84400
A24: 16 | B24: TOP COVER BOLT | C24: B8M | D24: 4 | F24: 1 | H24: 3500 | I24: =D24*F24*H24 -> 14000 | K24: =I24+J24 -> 14000
A25: 17 | B25: BOTTOM O-RING | C25: EPDM | D25: 1 | F25: 1 | H25: 560 | I25: =D25*F25*H25 -> 560 | J25: 1000 | K25: =I25+J25 -> 1560
A26: 18 | B26: GEAR BOX | C26: =원가!B17 -> 10 BAR | D26: 1 | F26: 65 | I26: 243432 | J26: TMG | K26: =IF(C26="PIYAKE",L26,IF(C26="10 BAR",M26,IF(C26="20 BAR",N26))) -> 355000 | M26: 355000 | N26: 589000
B27: GEAR BOX BOLT/WASHER | D27: 8 | F27: 1 | H27: 4000 | I27: =D27*F27*H27 -> 32000 | K27: =I27+J27 -> 32000
A28: 19 | B28: KEY & TAG | C28: SUS | D28: 1 | F28: 1 | I28: 4000 | J28: 4400 | K28: =I28+J28 -> 8400
A29: 20 | B29: 페인트 | D29: 1 | F29: 1 | I29: 50000 | K29: =I29+J29 -> 50000
A30: 21 | B30: 조립.검사 | D30: 1 | F30: 1 | I30: 45000 | K30: =I30+J30 -> 45000
A31: 22 | B31: 밸브합산 | K31: =SUM(K6:K30) -> 3365895
A32: 23 | B32: PNE.ACT | C32: SINGLE | D32: 1 | E32: FAIL TO CLOSE | G32: DW7 SR
A33: 24 | B33: LIMIT/SOL V/V | D33: 1 | F33: 1
B34: ACTUATOR BOLT/WASHER | D34: 4 | F34: 1 | H34: 630 | I34: =D34*F34*H34 -> 2520
A35: 25 | B35: 포장비용 | D35: 1 | F35: 1 | K35: 40000
A36: 26 | B36: RUBBER LINNING | D36: 1 | F36: 1
A37: 27 | B37: 밸브외 사급품 비용 연산 | I37: =SUM(K32:K36) -> 40000 | J37: 1 | K37: =J37*I37 -> 40000
A38: 28
A39: 29 | B39: FACTOR | E39: 1차견적가 | F39: =L40 -> 0 | I39: =K31 -> 3365895 | J39: =원가!B15 -> 1 | K39: =J39*I39 -> 3365895 | L39: 1차견적가
A40: 30 | B40: 견적가격(TOTAL금액) | E40: 네고가능가 | F40: =K40 -> 3405895 | H40: 환율 | I40: =원가!B2 -> 1 | K40: =SUM(K37:K39)/I40 -> 3405895
J41: 중량확인

Sheet 600A
A1: 제수변 BFV 원가 分析表
A3: SIZE : 600A | C3: 압력 : 150#
A5: NO. | B5: 부품명 | C5: 재질 | D5: 수량 | E5: 규격 | F5: 단중 | G5: 업체 | H5: 단가 | I5: 소계 | J5: 가공비 | K5: 합계
A6: 1 | B6: BODY | C6: =원가!B4 -> WCB | D6: 1 | F6: 460 | H6: =원가!C4 -> 2600 | I6: =D6*F6*H6 -> 1196000 | J6: 310000 | K6: =I6+J6 -> 1506000
A7: 2 | B7: DISC | C7: =원가!B5 -> WCB | D7: 1 | F7: 110 | H7: =원가!C5 -> 2600 | I7: =D7*F7*H7 -> 286000 | J7: 200000 | K7: =I7+J7 -> 486000
A8: 3 | B8: SEAT | C8: EPDM | D8: 1 | F8: 1 | I8: 9000 | J8: 5000 | K8: =I8+J8 -> 14000
A9: 4 | B9: STEM(上,下) | C9: =원가!B6 -> A276T316L | D9: 1 | F9: 44 | H9: =원가!C6 -> 8500 | I9: =D9*F9*H9 -> 374000 | K9: =I9+J9 -> 374000
A10: 5 | B10: DISC RETAINER | C10: =원가!B7 -> 316L | D10: 1 | F10: 20 | H10: 20000 | I10: =D10*F10*H10 -> 400000 | J10: 60000 | K10: =I10+J10 -> 460000
B11: BODY RETAINER | C11: =원가!B8 -> 316L | D11: 1 | F11: 20 | H11: =원가!C8 -> 8500 | I11: =D11*F11*H11 -> 170000 | J11: 60000 | K11: =I11+J11 -> 230000
A12: 6 | B12: BUSH(上) | C12: =원가!B9 -> B148 | D12: 1 | F12: 2.1 | H12: =원가!C9 -> 12500 | I12: =D12*F12*H12 -> 26250 | J12: 18000 | K12: =I12+J12 -> 44250
B13: BUSH(下) | C13: =원가!B10 -> B148 | D13: 1 | F13: 2.1 | H13: =원가!C10 -> 12500 | I13: =D13*F13*H13 -> 26250 | J13: 18000 | K13: =I13+J13 -> 44250
A14: 7 | B14: PACKING RING | C14: EPDM | D14: 4 | F14: 1 | H14: 550 | I14: =D14*F14*H14 -> 2200 | K14: =I14+J14 -> 2200
B15: PACKING BUSH | C15: C95800 | D15: 1 | F15: 3.75 | H15: 8000 | I15: =D15*F15*H15 -> 30000 | J15: 3500 | K15: =I15+J15 -> 33500
A16: 8 | B16: PACKING GLAND | C16: =원가!B11 -> WCB | D16: 1 | F16: 5 | H16: =원가!C11 -> 2600 | I16: =D16*F16*H16 -> 13000 | J16: 11000 | K16: =I16+J16 -> 24000
A17: 9 | B17: STAND BOLT/NUT | C17: B8M | D17: 4 | F17: 1 | H17: 2400 | I17: =D17*F17*H17 -> 9600 | K17: =I17+J17 -> 9600
A18: 10 | B18: BOTTOM COVER | C18: =원가!B12 -> WCB | D18: 1 | F18: 7.6 | H18: =원가!C12 -> 2600 | I18: =D18*F18*H18 -> 19760 | J18: 10000 | K18: =I18+J18 -> 29760
A19: 11 | B19: SPLIT COLLAR | C19: CF3M | D19: 1 | F19: 1.4 | H19: 7500 | I19: =D19*F19*H19 -> 10500 | J19: 4500 | K19: =I19+J19 -> 15000
A20: 12 | B20: DISC BOLT/NUT | C20: 316L | D20: 3 | F20: 1.71 | H20: 9352 | I20: =H20*F20*D20 -> 47975.76 | J20: 4770 | K20: =I20+J20 -> 52745.76
A21: 13 | B21: DISC RETAINER BOLT | C21: B8M | D21: 20 | F21: 1 | H21: 110 | I21: =D21*F21*H21 -> 2200 | K21: =I21+J21 -> 2200
A22: 14 | B22: BOTTOM COVER BOLT/WASHER | C22: B8M | D22: 6 | F22: 1 | H22: 2500 | I22: =D22*F22*H22 -> 15000 | K22: =I22+J22 -> 15000
A23: 15 | B23: TOP FLG COVER | C23: =원가!B13 -> WCB | D23: 1 | F23: 26 | H23: =원가!C13 -> 2600 | I23: =D23*F23*H23 -> 67600 | J23: 22000 | K23: =I23+J23 -> 89600
A24: 16 | B24: TOP COVER BOLT | C24: B8M | D24: 4 | F24: 1 | H24: 3500 | I24: =D24*F24*H24 -> 14000 | K24: =I24+J24 -> 14000
A25: 17 | B25: BOTTOM O-RING | C25: EPDM | D25: 1 | F25: 1 | H25: 560 | I25: =D25*F25*H25 -> 560 | J25: 1000 | K25: =I25+J25 -> 1560
A26: 18 | B26: GEAR BOX | C26: =원가!B17 -> 10 BAR | D26: 1 | F26: 78 | I26: 243432 | J26: TMG | K26: =IF(C26="PIYAKE",L26,IF(C26="10 BAR",M26,IF(C26="20 BAR",N26))) -> 355000 | M26: 355000 | N26: 589000
B27: GEAR BOX BOLT/WASHER | D27: 8 | F27: 1 | H27: 4000 | I27: =D27*F27*H27 -> 32000 | K27: =I27+J27 -> 32000
A28: 19 | B28: KEY & TAG | C28: SUS | D28: 1 | F28: 1 | I28: 4000 | J28: 4400 | K28: =I28+J28 -> 8400
A29: 20 | B29: 페인트 | D29: 1 | F29: 1 | I29: 55000 | K29: =I29+J29 -> 55000
A30: 21 | B30: 조립.검사 | D30: 1 | F30: 1 | I30: 45000 | K30: =I30+J30 -> 45000
A31: 22 | B31: 밸브합산 | K31: =SUM(K6:K30) -> 3943065.8
A32: 23 | B32: PNE.ACT | C32: SINGLE | D32: 1 | E32: FAIL TO CLOSE | G32: DW7 SR
A33: 24 | B33: LIMIT/SOL V/V | D33: 1 | F33: 1
B34: ACTUATOR BOLT/WASHER | D34: 4 | F34: 1 | H34: 630 | I34: =D34*F34*H34 -> 2520
A35: 25 | B35: 포장비용 | D35: 1 | F35: 1 | K35: 50000
A36: 26 | B36: RUBBER LINNING | D36: 1 | F36: 1
A37: 27 | B37: 밸브외 사급품 비용 연산 | I37: =SUM(K32:K36) -> 50000 | J37: 1 | K37: =J37*I37 -> 50000
A38: 28
A39: 29 | B39: FACTOR | E39: 1차견적가 | F39: =L40 -> 0 | I39: =K31 -> 3943065.8 | J39: =원가!B15 -> 1 | K39: =J39*I39 -> 3943065.8 | L39: 1차견적가
A40: 30 | B40: 견적가격(TOTAL금액) | E40: 네고가능가 | F40: =K40 -> 3993065.8 | H40: 환율 | I40: =원가!B2 -> 1 | K40: =SUM(K37:K39)/I40 -> 3993065.8
J41: 중량확인

Sheet 650A
A1: 제수변 BFV 원가 分析表
A3: SIZE : 650A | C3: 압력 : 150#
A5: NO. | B5: 부품명 | C5: 재질 | D5: 수량 | E5: 규격 | F5: 단중 | G5: 업체 | H5: 단가 | I5: 소계 | J5: 가공비 | K5: 합계
A6: 1 | B6: BODY | C6: =원가!B4 -> WCB | D6: 1 | F6: 420 | H6: =원가!C4 -> 2600 | I6: =D6*F6*H6 -> 1092000 | J6: 310000 | K6: =I6+J6 -> 1402000
A7: 2 | B7: DISC | C7: =원가!B5 -> WCB | D7: 1 | F7: 150 | H7: =원가!C5 -> 2600 | I7: =D7*F7*H7 -> 390000 | J7: 200000 | K7: =I7+J7 -> 590000
A8: 3 | B8: SEAT | C8: EPDM | D8: 1 | F8: 1 | I8: 13000 | J8: 10000 | K8: =I8+J8 -> 23000
A9: 4 | B9: STEM(上,下) | C9: =원가!B6 -> A276T316L | D9: 1 | F9: 60 | H9: =원가!C6 -> 8500 | I9: =D9*F9*H9 -> 510000 | K9: =I9+J9 -> 510000
A10: 5 | B10: DISC RETAINER | C10: =원가!B7 -> 316L | D10: 1 | F10: 25 | H10: 20000 | I10: =D10*F10*H10 -> 500000 | J10: 70000 | K10: =I10+J10 -> 570000
B11: BODY RETAINER | C11: =원가!B8 -> 316L | D11: 1 | F11: 19 | H11: =원가!C8 -> 8500 | I11: =D11*F11*H11 -> 161500 | J11: 70000 | K11: =I11+J11 -> 231500
A12: 6 | B12: BUSH(上) | C12: =원가!B9 -> B148 | D12: 1 | F12: 5 | H12: =원가!C9 -> 12500 | I12: =D12*F12*H12 -> 62500 | J12: 5000 | K12: =I12+J12 -> 67500
B13: BUSH(下) | C13: =원가!B10 -> B148 | D13: 1 | F13: 5 | H13: =원가!C10 -> 12500 | I13: =D13*F13*H13 -> 62500 | J13: 5000 | K13: =I13+J13 -> 67500
A14: 7 | B14: PACKING RING | C14: EPDM | D14: 4 | F14: 1 | H14: 550 | I14: =D14*F14*H14 -> 2200 | K14: =I14+J14 -> 2200
B15: PACKING BUSH | C15: C95800 | D15: 1 | F15: 2.5 | H15: 8000 | I15: =D15*F15*H15 -> 20000 | J15: 3500 | K15: =I15+J15 -> 23500
A16: 8 | B16: PACKING GLAND | C16: =원가!B11 -> WCB | D16: 1 | F16: 4.2 | H16: =원가!C11 -> 2600 | I16: =D16*F16*H16 -> 10920 | J16: 11000 | K16: =I16+J16 -> 21920
A17: 9 | B17: STAND BOLT/NUT | C17: B8M | D17: 4 | F17: 1 | H17: 2400 | I17: =D17*F17*H17 -> 9600 | K17: =I17+J17 -> 9600
A18: 10 | B18: BOTTOM COVER | C18: =원가!B12 -> WCB | D18: 1 | F18: 6 | H18: =원가!C12 -> 2600 | I18: =D18*F18*H18 -> 15600 | J18: 10000 | K18: =I18+J18 -> 25600
A19: 11 | B19: SPLIT COLLAR | C19: CF3M | D19: 1 | F19: 1.6 | H19: 7500 | I19: =D19*F19*H19 -> 12000 | J19: 4500 | K19: =I19+J19 -> 16500
A20: 12 | B20: DISC BOLT/NUT | C20: 316L | D20: 3 | F20: 0.95 | I20: 3500 | J20: 4770 | K20: =I20+J20 -> 8270
A21: 13 | B21: DISC RETAINER BOLT | C21: B8M | D21: 16 | F21: 1 | H21: 130 | I21: =D21*F21*H21 -> 2080 | K21: =I21+J21 -> 2080
