Workbook
Name _1: #N/A
Name _11: #N/A
Name _2: #N/A
Name _22: #N/A
Name _AOC2: #REF!
Name _ELL45: #REF!
Name _ELL90: #REF!
Name _RE100: #REF!
Name _RE104: #REF!
Name _RE112: #REF!
Name _RE26: #REF!
Name _RE28: #REF!
Name _RE30: #REF!
Name _RE32: #REF!
Name _RE34: #REF!
Name _RE36: #REF!
Name _RE38: #REF!
Name _RE40: #REF!
Name _RE42: #REF!
Name _RE44: #REF!
Name _RE48: #REF!
Name _RE52: #REF!
Name _RE56: #REF!
Name _RE60: #REF!
Name _RE64: #REF!
Name _RE68: #REF!
Name _RE72: #REF!
Name _RE76: #REF!
Name _RE80: #REF!
Name _RE88: #REF!
Name _RE92: #REF!
Name _RE96: #REF!
Name \a: #N/A
Name \p: '[2]FWBS7000,8000'!#REF!
Name A7JB_WIRES: [3]A7!$S$68
Name AAA: 5
Name AIR: #REF!
Name air_trap: #REF!
Name angle: #REF!
Name B_FLG: #REF!
Name back_pressure: #REF!
Name ball: #REF!
Name BOLT: #REF!
Name BOSS: #REF!
Name butterfly: #REF!
Name CAP: #REF!
Name CCS: '[4]Product-part-a'!$R$11
Name check: #REF!
Name COM: #REF!
Name CPLG: #REF!
Name CS: #REF!
Name CS_DB: #REF!
Name data: #REF!
Name DESCRIPTION: #REF!
Name diameter: #REF!
Name diaphragm: #REF!
Name drain_trap: #REF!
Name dual_plate_check: #REF!
Name duplex_strainer: #REF!
Name EOL: #REF!

Sheet BFLY
A11: 환 율 | B11: 1000 | E11: US $ | F11: BASIC COST | I11: TOTAL COST
B12: MATERIAL | C12: 소재 단가 | E12: SIZE | F12: BARE | G12: LEVER | H12: GEAR | I12: BARE | J12: LEVER | K12: GEAR
A13: BODY(WAFER) | B13: CF8 | C13: 4000 | E13: 50A | F13: ='50A'!$K$29/$B$11 -> 159.826 | G13: ='50A'!$K$30/$B$11 -> 182.826 | H13: ='50A'!$K$31/$B$11 -> 257.826 | I13: ='50A'!$K$41/$B$11 -> 169.326 | J13: ='50A'!$K$42/$B$11 -> 192.326 | K13: ='50A'!$K$43/$B$11 -> 267.326
A14: BODY(LUG) | E14: 65A | F14: ='65A'!$K$29/$B$11 -> 172.23 | G14: ='65A'!$K$30/$B$11 -> 195.23 | H14: ='65A'!$K$31/$B$11 -> 270.23 | I14: ='65A'!$K$41/$B$11 -> 181.73 | J14: ='65A'!$K$42/$B$11 -> 204.73 | K14: ='65A'!$K$43/$B$11 -> 279.73
A15: BODY(FLANGE) | B15: CF8 | E15: 80A | F15: ='80A'!$K$29/$B$11 -> 192.253 | G15: ='80A'!$K$30/$B$11 -> 215.253 | H15: ='80A'!$K$31/$B$11 -> 290.253 | I15: ='80A'!$K$41/$B$11 -> 202.253 | J15: ='80A'!$K$42/$B$11 -> 225.253 | K15: ='80A'!$K$43/$B$11 -> 300.253
A16: DISC | B16: CF8M | C16: 8000 | E16: 100A | F16: ='100A'!$K$29/$B$11 -> 228.912 | G16: ='100A'!$K$30/$B$11 -> 251.912 | H16: ='100A'!$K$31/$B$11 -> 326.912 | I16: ='100A'!$K$41/$B$11 -> 243.412 | J16: ='100A'!$K$42/$B$11 -> 266.412 | K16: ='100A'!$K$43/$B$11 -> 341.412
A17: STEM | B17: A564T630 | C17: 8000 | E17: 125A | F17: ='125A'!$K$29/$B$11 -> 258.03 | G17: ='125A'!$K$30/$B$11 -> 281.03 | H17: ='125A'!$K$31/$B$11 -> 356.03 | I17: ='125A'!$K$41/$B$11 -> 272.03 | J17: ='125A'!$K$42/$B$11 -> 295.03 | K17: ='125A'!$K$43/$B$11 -> 370.03
E18: 150A | F18: ='150A'!$K$29/$B$11 -> 338.76 | G18: ='150A'!$K$30/$B$11 -> 361.76 | H18: ='150A'!$K$31/$B$11 -> 436.76 | I18: ='150A'!$K$41/$B$11 -> 353.76 | J18: ='150A'!$K$42/$B$11 -> 376.76 | K18: ='150A'!$K$43/$B$11 -> 451.76
A19: SEAT | B19: RTFE | E19: 200A | F19: ='200A'!$K$29/$B$11 -> 448.532 | G19: ='200A'!$K$30/$B$11 -> 474.452 | H19: ='200A'!$K$31/$B$11 -> 546.532 | I19: ='200A'!$K$41/$B$11 -> 465.532 | J19: ='200A'!$K$42/$B$11 -> 491.452 | K19: ='200A'!$K$43/$B$11 -> 563.532
A20: PRESSURE | B20: 10 BAR | E20: 250A | F20: ='250A'!$K$29/$B$11 -> 628.025 | G20: ='250A'!$K$30/$B$11 -> 653.945 | H20: ='250A'!$K$31/$B$11 -> 726.025 | I20: ='250A'!$K$41/$B$11 -> 652.225 | J20: ='250A'!$K$42/$B$11 -> 678.145 | K20: ='250A'!$K$43/$B$11 -> 750.225
A21: FACTOR | B21: 1 | E21: 300A | F21: ='300A'!$K$29/$B$11 -> 808.605 | G21: ='300A'!$K$30/$B$11 -> 836.465 | H21: ='300A'!$K$31/$B$11 -> 1011.605 | I21: ='300A'!$K$41/$B$11 -> 842.605 | J21: ='300A'!$K$42/$B$11 -> 870.465 | K21: ='300A'!$K$43/$B$11 -> 1045.605
A22: 목형관리대장 | E22: 350A | F22: ='350A'!$K$37/$B$11 -> 1370.1 | H22: ='350A'!$K$38/$B$11 -> 1573.1 | I22: ='350A'!$K$39/$B$11 -> 1370.1 | K22: ='350A'!$K$40/$B$11 -> 1573.1
A23: DIMESION TABLE | E23: 400A | F23: ='400A'!$K$37/$B$11 -> 1900.32 | H23: ='400A'!$K$38/$B$11 -> 2205.32 | I23: ='400A'!$K$39/$B$11 -> 1900.32 | K23: ='400A'!$K$40/$B$11 -> 2205.32
E24: 450A | F24: ='450A'!$K$37/$B$11 -> 2198.81 | H24: ='450A'!$K$38/$B$11 -> 2503.81 | I24: ='450A'!$K$39/$B$11 -> 2198.81 | K24: ='450A'!$K$40/$B$11 -> 2503.81
E25: 500A | F25: ='500A'!$K$37/$B$11 -> 2678.8 | H25: ='500A'!$K$38/$B$11 -> 2983.8 | I25: ='500A'!$K$39/$B$11 -> 2678.8 | K25: ='500A'!$K$40/$B$11 -> 2983.8
A26: MATERIAL | B26: KG당 비용 | E26: 600A | F26: ='600A'!$K$37/$B$11 -> 3336.086 | H26: ='600A'!$K$38/$B$11 -> 3691.086 | I26: ='600A'!$K$39/$B$11 -> 3336.086 | K26: ='600A'!$K$40/$B$11 -> 3691.086
A27: A126 (FC250) GG25 | B27: 2500 | E27: 650A | F27: ='650A'!$K$37/$B$11 -> 4422.31 | H27: ='650A'!$K$38/$B$11 -> 4777.31 | I27: ='650A'!$K$39/$B$11 -> 4422.31 | K27: ='650A'!$K$40/$B$11 -> 4777.31
A28: A536 (FCD400) GGG40 | B28: 2500 | E28: 700A | F28: ='700A'!$K$37/$B$11 -> 5458.38 | H28: ='700A'!$K$38/$B$11 -> 6047.38 | I28: ='700A'!$K$39/$B$11 -> 5458.38 | K28: ='700A'!$K$40/$B$11 -> 6047.38
A29: A216 (WCB) | B29: 3100 | E29: 750A | F29: ='750A'!$K$37/$B$11 -> 5953.56 | H29: ='750A'!$K$38/$B$11 -> 6542.56 | I29: ='750A'!$K$39/$B$11 -> 5953.56 | K29: ='750A'!$K$40/$B$11 -> 6542.56
A30: 304 (CF8) SCS13 | B30: 7000 | E30: 800A | F30: ='800A'!$K$37/$B$11 -> 6533.99 | H30: ='800A'!$K$38/$B$11 -> 7122.99 | I30: ='800A'!$K$39/$B$11 -> 6533.99 | K30: ='800A'!$K$40/$B$11 -> 7122.99
A31: 316 (CF8M) SCS14 | B31: 9000 | E31: 900A | F31: ='900A'!$K$37/$B$11 -> 10098.38 | H31: ='900A'!$K$38/$B$11 -> 10846.38 | I31: ='900A'!$K$39/$B$11 -> 10098.38 | K31: ='900A'!$K$40/$B$11 -> 10846.38
A32: 316L (CF3M) SCS16 | B32: 11000 | E32: 1000A | F32: ='1000A'!$K$37/$B$11 -> 11403.15 | H32: ='1000A'!$K$38/$B$11 -> 12151.15 | I32: ='1000A'!$K$39/$B$11 -> 11403.15 | K32: ='1000A'!$K$40/$B$11 -> 12151.15
A33: B148 (ALBC3) | B33: 15000
A34: MONEL(K400) | B34: 55000
A35: MONEL(K500) | B35: 62000
A36: DUPLEX(CD4MCU) | B36: 23000
A37: A217 GR CA 15 | B37: 3000
A38: 317L | B38: 12500
A39: SS630 | B39: 10500
A40: T410 | B40: 6000
A41: A276 가공비 ≒ 316 가공비
A46: DISC | B46: SEAT | D46: BODY | F46: STEM | G46: GEAR
A47: CF8 | B47: RTFE | D47: WCB | F47: A564T630 | G47: PIYAKE | H47: SRS924
A48: CF8M | B48: RTFE-A | D48: CF8 | F48: A276T316 | G48: 10 BAR | H48: SRS925
A49: CF3M | B49: METAL-B | D49: CF8M | F49: A276T304 | G49: 20 BAR | H49: SRS926
A50: B148 | B50: RTFE + METAL

Sheet 50A
A1: HIGH PERFORMANCE BFV 원가 分析表
A3: SIZE : 50A | C3: 압력 : 150# | F3: PJT :
A5: NO. | B5: 부품명 | C5: 재질 | D5: 수량 | E5: 규격 | F5: 단중 | G5: 업체 | H5: 단가 | I5: 소계 | J5: 가공비 | K5: 합계 | Q5: 소재비 | R5: 가공비 | T5: 합
A6: 1 | B6: BODY(WAFER) | C6: =BFLY!B13 -> CF8 | D6: 1 | F6: =IF(C6="WCB",3,IF(C6="CF8",3,IF(C6="CF8M",3))) -> 3 | H6: =BFLY!C13 -> 4000 | I6: =D6*F6*H6 -> 12000 | J6: =IF(C6="WCB",30000,IF(C6="CF8",30000,IF(C6="CF8M",30000))) -> 30000 | K6: =I6+J6 -> 42000 | P6: 외주가공 WAFER | R6: 30000 | T6: =R6+Q6 -> 30000
B7: BODY(LUG) | C7: =BFLY!B14 -> 0 | D7: 1 | F7: =IF(C7="WCB",3.63,IF(C7="CF8",3.63,IF(C7="CF8M",4.4))) -> FALSE | H7: =BFLY!C14 -> 0 | I7: =D7*F7*H7 -> 0 | J7: =IF(C7="WCB",28000,IF(C7="CF8",28000,IF(C7="CF8M",28000))) -> FALSE | K7: =I7+J7 -> 0 | P7: 외주가공 LUG | R7: 35000 | T7: =R7+Q7 -> 35000
B8: BODY(FLANGE) | C8: =BFLY!B15 -> CF8 | D8: 1 | F8: =12*1.1 -> 13.2 | H8: =BFLY!C15 -> 0 | I8: =D8*F8*H8 -> 0 | J8: =IF(C8="WCB",40000,IF(C8="CF8",40000,IF(C8="CF8M",40000))) -> 40000 | K8: =I8+J8 -> 40000 | L8: TEFLON SEAT | M8: METAL TEFLON SEAT | P8: 외주가공 FLANGE | R8: 40000 | T8: =R8+Q8 -> 40000
A9: 2 | B9: DISC | C9: =BFLY!B16 -> CF8M | D9: 1 | F9: =IF(C9="CF8",0.12,IF(C9="CF8M",0.12,IF(C9="CF3M",0.12,IF(C9="B148",0.5)))) -> 0.12 | H9: =BFLY!C16 -> 8000 | I9: =D9*F9*H9 -> 960 | J9: =IF(C9="WCB",8000,IF(C9="CF8",8000,IF(C9="CF8M",8000))) -> 8000 | K9: =I9+J9 -> 8960 | L9: TEFLON | M9: TEFLON | N9: METAL | O9: 합계
A10: 3 | B10: SEAT | C10: =BFLY!B19 -> RTFE | D10: 1 | I10: =IF(C10="RTFE",4400,IF(C10="RTFE-A",4400,IF(C10="METAL-B",2000,IF(C10="RTFE + METAL",4200)))) -> 4400 | J10: =IF(C10="RTFE",1500,IF(C10="METAL-B",10000,IF(C10="RTFE + METAL",8000))) -> 1500 | K10: =I10+J10 -> 5900 | L10: 4400 | M10: 2700 | N10: 1500 | O10: =M10+N10 -> 4200
A11: 4 | B11: STEM(上,下) | C11: =BFLY!B17 -> A564T630 | D11: 1 | F11: 0.32 | H11: =BFLY!C17 -> 8000 | I11: =D11*F11*H11 -> 2560 | J11: 7000 | K11: =I11+J11 -> 9560 | P11: STEM | R11: 3500 | T11: =R11+Q11 -> 3500
A12: 5 | B12: RETAINER RING | C12: SS316 | D12: 1 | F12: 1 | H12: 4500 | I12: =D12*F12*H12 -> 4500 | J12: 7000 | K12: =I12+J12 -> 11500 | P12: RETAINER RING | Q12: =ROUND(3.67*1200,0) -> 4404 | R12: 7000 | T12: =R12+Q12 -> 11404
A13: 6 | B13: RETAINER BOLT | C13: B8M | D13: 4 | F13: 1 | H13: 600 | I13: =D13*F13*H13 -> 2400 | K13: =H13*D13 -> 2400 | T13: =R13+Q13 -> 0
A14: 7 | B14: BUSH | C14: SS316 | D14: 2 | F14: 1 | I14: 2170 | J14: 4980 | K14: =(I14+J14)*D14 -> 14300 | T14: =R14+Q14 -> 0
A15: 8 | B15: PACKING | C15: PTFE | D15: 1 | F15: 1 | H15: 3500 | I15: =D15*F15*H15 -> 3500 | K15: =I15+J15 -> 3500 | P15: PTFE PACKING (완제품) | T15: 2050
A16: 9 | B16: PACKING GLAND | C16: CF8/CF8M | D16: 1 | F16: 1 | H16: 956 | I16: =D16*F16*H16 -> 956 | J16: 300 | K16: =I16+J16 -> 1256 | P16: PACKING GLAND (소재+가공비) | R16: =ROUND(0.96*1200,-2) -> 1200
A17: 10 | B17: GLAND BOLT/NUT | C17: B8M | D17: 2 | F17: 1 | H17: 600 | I17: =D17*F17*H17 -> 1200 | K17: =I17+J17 -> 1200 | T17: =R17+Q17 -> 0
A18: 11 | B18: COLOR | C18: SS316 | D18: 1 | F18: 1 | H18: 80 | I18: =D18*F18*H18 -> 80 | J18: 100 | K18: =I18+J18 -> 180 | T18: =R18+Q18 -> 0
A19: 12 | B19: DISCK PIN | C19: =C11 -> A564T630 | D19: 1 | F19: 1 | H19: 150 | I19: =D19*F19*H19 -> 150 | J19: 160 | K19: =I19+J19 -> 310 | T19: =R19+Q19 -> 0
A20: 13 | B20: END COVER | C20: WCB | D20: 1 | F20: 1 | H20: 435 | I20: =D20*F20*H20 -> 435 | J20: 300 | K20: 2900 | P20: END COVER (소재+가공비) | R20: =ROUND(2.43*1200,-2) -> 2900 | T20: =R20+Q20 -> 2900
A21: 14 | B21: END COVER BOLT | C21: B8M | D21: 4 | F21: 1 | H21: 100 | I21: =D21*F21*H21 -> 400 | K21: =I21+J21 -> 400
A22: 15 | B22: GASKET | C22: N-ASBESTOS | D22: 1 | F22: 1 | H22: 920 | I22: =D22*F22*H22 -> 920 | K22: =I22+J22 -> 920
A23: 16 | B23: TAG | C23: SS316 | D23: 1 | F23: 1 | H23: 900 | I23: =D23*F23*H23 -> 900 | K23: =I23+J23 -> 900
A24: 17 | B24: INDICATOR | C24: SS304 | D24: 1 | F24: 1 | H24: 3000 | I24: =D24*F24*H24 -> 3000 | K24: =I24+J24 -> 3000
A25: 18 | B25: INDICATOR BOLT/NUT | C25: B8M | D25: 4 | F25: 1 | H25: 160 | I25: =D25*F25*H25 -> 640 | K25: =I25+J25 -> 640
A26: 19 | B26: LEVER | C26: SS304 | D26: 1 | F26: 1 | J26: SUS | K26: 23000 | L26: 11000
A27: 20 | B27: GEAR BOX | C27: =BFLY!B20 -> 10 BAR | D27: 1 | F27: 1 | J27: =C27 -> 10 BAR | K27: =IF(C27="PIYAKE",L27,IF(C27="10 BAR",M27,IF(C27="20 BAR",N27))) -> 98000 | L27: 16410 | M27: 98000 | N27: 98000
A28: 21 | B28: 페인트, 조립 | C28: CEPHAS | D28: 1 | F28: 1 | I28: 5000 | J28: 5000 | K28: =I28+J28 -> 10000
A29: 22 | B29: 밸브합산(BEAR) | K29: =SUM(K6:K25,K28) -> 159826
A30: 23 | B30: 밸브합산(LEVER) | K30: =SUM(K6:K26,K28) -> 182826
A31: 24 | B31: 밸브합산(GEAR) | K31: =SUM(K6:K25,K27:K28) -> 257826
A32: 25
A33: 26 | B33: ACTUATOR | D33: 1 | K33: =I33+J33 -> 0
A34: 27 | B34: ACTUATOR BOLT/WASHER | D34: 4 | K34: =I34+J34 -> 0
B35: 포장비용 | C35: CEPHAS | D35: 1 | K35: 9500
A36: 28 | B36: 밸브외 사급품 비용 연산 | I36: =SUM(K32:K35) -> 9500 | J36: 1 | K36: =J36*I36 -> 9500
A37: 29
A38: 30 | B38: FACTOR(BEAR) | I38: =K29 -> 159826 | J38: =BFLY!B21 -> 1 | K38: =J38*I38 -> 159826
A39: 31 | B39: FACTOR(LEVER) | I39: =K30 -> 182826 | J39: =BFLY!B21 -> 1 | K39: =J39*I39 -> 182826
A40: 32 | B40: FACTOR(GEAR) | I40: =K31 -> 257826 | J40: =BFLY!B21 -> 1 | K40: =J40*I40 -> 257826
A41: 33 | B41: 견적가격(TOTAL금액) - BEAR | K41: =SUM(K36,K38) -> 169326
A42: 34 | B42: 견적가격(TOTAL금액) - LEVER | K42: =SUM(K36,K39) -> 192326
...

Sheet 65A
A1: HIGH PERFORMANCE BFV 원가 分析表
A3: SIZE : 65A | C3: 압력 : 150# | F3: PJT :
A5: NO. | B5: 부품명 | C5: 재질 | D5: 수량 | E5: 규격 | F5: 단중 | G5: 업체 | H5: 단가 | I5: 소계 | J5: 가공비 | K5: 합계
A6: 1 | B6: BODY(WAFER) | C6: =BFLY!B13 -> CF8 | D6: 1 | F6: =IF(C6="WCB",3,IF(C6="CF8",3,IF(C6="CF8M",3))) -> 3 | H6: =BFLY!C13 -> 4000 | I6: =D6*F6*H6 -> 12000 | J6: =IF(C6="WCB",35000,IF(C6="CF8",35000,IF(C6="CF8M",35000))) -> 35000 | K6: =I6+J6 -> 47000 | Q6: 소재비 | R6: 가공비 | T6: 합
B7: BODY(LUG) | C7: =BFLY!B14 -> 0 | D7: 1 | F7: =IF(C7="WCB",4.44,IF(C7="CF8",4.44,IF(C7="CF8M",4.44))) -> FALSE | H7: =BFLY!C14 -> 0 | I7: =D7*F7*H7 -> 0 | J7: =IF(C7="WCB",40000,IF(C7="CF8",40000,IF(C7="CF8M",40000))) -> FALSE | K7: =I7+J7 -> 0 | P7: 외주가공 WAFER | R7: 35000 | T7: =R7+Q7 -> 35000
B8: BODY(FLANGE) | C8: =BFLY!B15 -> CF8 | D8: 1 | F8: =13*1.1 -> 14.3 | H8: =BFLY!C15 -> 0 | I8: =D8*F8*H8 -> 0 | J8: =IF(C8="WCB",45000,IF(C8="CF8",45000,IF(C8="CF8M",45000))) -> 45000 | K8: =I8+J8 -> 45000 | L8: TEFLON SEAT | M8: METAL TEFLON SEAT | P8: 외주가공 LUG | R8: 40000 | T8: =R8+Q8 -> 40000
A9: 2 | B9: DISC | C9: =BFLY!B16 -> CF8M | D9: 1 | F9: =IF(C9="CF8",0.21,IF(C9="CF8M",0.21,IF(C9="CF3M",0.21,IF(C9="B148",0.6)))) -> 0.21 | H9: =BFLY!C16 -> 8000 | I9: =D9*F9*H9 -> 1680 | J9: 8000 | K9: =I9+J9 -> 9680 | L9: TEFLON | M9: TEFLON | N9: METAL | O9: 합계 | P9: 외주가공 FLANGE | R9: 45000 | T9: =R9+Q9 -> 45000
A10: 3 | B10: SEAT | C10: =BFLY!B19 -> RTFE | D10: 1 | I10: =IF(C10="RTFE",5600,IF(C10="RTFE-A",3120,IF(C10="METAL-B",2260,IF(C10="RTFE + METAL",5200)))) -> 5600 | J10: =IF(C10="RTFE",1500,IF(C10="METAL-B",10000,IF(C10="RTFE + METAL",8000))) -> 1500 | K10: =I10+J10 -> 7100 | L10: 5600 | M10: 3200 | N10: 2000 | O10: =M10+N10 -> 5200
A11: 4 | B11: STEM(上,下) | C11: =BFLY!B17 -> A564T630 | D11: 1 | F11: 0.45 | H11: =BFLY!C17 -> 8000 | I11: =D11*F11*H11 -> 3600 | J11: 3500 | K11: =I11+J11 -> 7100 | P11: STEM | R11: 3500 | T11: =R11+Q11 -> 3500
A12: 5 | B12: RETAINER RING | C12: SS316 | D12: 1 | F12: 1 | H12: 5570 | I12: =D12*F12*H12 -> 5570 | J12: 7000 | K12: =I12+J12 -> 12570 | P12: RETAINER RING | Q12: =4.64*1200 -> 5568 | R12: 7000 | T12: =R12+Q12 -> 12568
A13: 6 | B13: RETAINER BOLT | C13: B8M | D13: 4 | F13: 1 | H13: 600 | I13: =D13*F13*H13 -> 2400 | K13: =H13*D13 -> 2400
A14: 7 | B14: BUSH | C14: SS316 | D14: 2 | F14: 1 | I14: 2800 | J14: 5950 | K14: =(I14+J14)*D14 -> 17500 | T14: =R14+Q14 -> 0
A15: 8 | B15: PACKING | C15: RTFE | D15: 1 | F15: 1 | H15: 3900 | I15: =D15*F15*H15 -> 3900 | K15: 2100 | P15: PACKING (완제품) | T15: 2100
A16: 9 | B16: PACKING GLAND | C16: CF8/CF8M | D16: 1 | F16: 1 | H16: 956 | I16: =D16*F16*H16 -> 956 | J16: 300 | K16: 1150 | P16: PACKING GLAND (소재+가공비) | T16: =0.96*1200 -> 1152
A17: 10 | B17: GLAND BOLT/NUT | C17: B8M | D17: 2 | F17: 1 | H17: 600 | I17: =D17*F17*H17 -> 1200 | K17: =I17+J17 -> 1200
A18: 11 | B18: COLOR | C18: SS316 | D18: 1 | F18: 1 | H18: 80 | I18: =D18*F18*H18 -> 80 | J18: 100 | K18: =I18+J18 -> 180 | T18: =R18+Q18 -> 0
A19: 12 | B19: DISCK PIN | C19: SS630 | D19: 1 | F19: 1 | H19: 150 | I19: =D19*F19*H19 -> 150 | J19: 160 | K19: =I19+J19 -> 310 | T19: =R19+Q19 -> 0
A20: 13 | B20: END COVER | C20: SS316 | D20: 1 | F20: 1 | H20: 435 | I20: =D20*F20*H20 -> 435 | J20: 300 | K20: 2900 | P20: END COVER (소재+가공비) | T20: =2.43*1200 -> 2916
A21: 14 | B21: END COVER BOLT | C21: B8M | D21: 4 | F21: 1 | H21: 100 | I21: =D21*F21*H21 -> 400 | K21: =I21+J21 -> 400
A22: 15 | B22: GASKET | C22: N-ASBESTOS | D22: 1 | F22: 1 | H22: 1100 | I22: =D22*F22*H22 -> 1100 | K22: =I22+J22 -> 1100
A23: 16 | B23: TAG | C23: SS316 | D23: 1 | F23: 1 | H23: 900 | I23: =D23*F23*H23 -> 900 | K23: =I23+J23 -> 900
A24: 17 | B24: INDICATOR | C24: SS304 | D24: 1 | F24: 1 | H24: 3000 | I24: =D24*F24*H24 -> 3000 | K24: =I24+J24 -> 3000
A25: 18 | B25: INDICATOR BOLT/NUT | C25: B8M | D25: 4 | F25: 1 | H25: 160 | I25: =D25*F25*H25 -> 640 | K25: =I25+J25 -> 640
A26: 19 | B26: LEVER | C26: SS304 | D26: 1 | F26: 1 | I26: 11000 | J26: SUS | K26: 23000 | L26: 11000
A27: 20 | B27: GEAR BOX | C27: =BFLY!B20 -> 10 BAR | D27: 1 | F27: 1 | J27: =C27 -> 10 BAR | K27: =IF(C27="PIYAKE",L27,IF(C27="10 BAR",M27,IF(C27="20 BAR",N27))) -> 98000 | L27: 16410 | M27: 98000 | N27: 98000
A28: 21 | B28: 페인트, 조립 | C28: CEPHAS | D28: 1 | F28: 1 | I28: 5000 | J28: 5000 | K28: =I28+J28 -> 10000
A29: 22 | B29: 밸브합산(BEAR) | K29: =SUM(K6:K25,K28) -> 172230
A30: 23 | B30: 밸브합산(LEVER) | K30: =SUM(K6:K26,K28) -> 195230
A31: 24 | B31: 밸브합산(GEAR) | K31: =SUM(K6:K25,K27:K28) -> 270230
A32: 25
A33: 26 | B33: ACTUATOR | D33: 1 | K33: =I33+J33 -> 0
A34: 27 | B34: ACTUATOR BOLT/WASHER | D34: 4 | K34: =I34+J34 -> 0
B35: 포장비용 | D35: 1 | K35: 9500
A36: 28 | B36: 밸브외 사급품 비용 연산 | I36: =SUM(K32:K35) -> 9500 | J36: 1 | K36: =J36*I36 -> 9500
A37: 29
A38: 30 | B38: FACTOR(BEAR) | I38: =K29 -> 172230 | J38: =BFLY!B21 -> 1 | K38: =J38*I38 -> 172230
A39: 31 | B39: FACTOR(LEVER) | I39: =K30 -> 195230 | J39: =BFLY!B21 -> 1 | K39: =J39*I39 -> 195230
A40: 32 | B40: FACTOR(GEAR) | I40: =K31 -> 270230 | J40: =BFLY!B21 -> 1 | K40: =J40*I40 -> 270230
A41: 33 | B41: 견적가격(TOTAL금액) - BEAR | K41: =SUM(K36,K38) -> 181730
A42: 34 | B42: 견적가격(TOTAL금액) - LEVER | K42: =SUM(K36,K39) -> 204730
...

Sheet 80A
A1: HIGH PERFORMANCE BFV 원가 分析表
A3: SIZE : 80A | C3: 압력 : 150# | F3: PJT :
A5: NO. | B5: 부품명 | C5: 재질 | D5: 수량 | E5: 규격 | F5: 단중 | G5: 업체 | H5: 단가 | I5: 소계 | J5: 가공비 | K5: 합계 | Q5: 소재비 | R5: 가공비 | T5: 합
A6: 1 | B6: BODY(WAFER) | C6: =BFLY!B13 -> CF8 | D6: 1 | F6: =IF(C6="WCB",3.44,IF(C6="CF8",3.44,IF(C6="CF8M",3.44))) -> 3.44 | H6: =BFLY!C13 -> 4000 | I6: =D6*F6*H6 -> 13760 | J6: =IF(C6="WCB",40000,IF(C6="CF8",40000,IF(C6="CF8M",40000))) -> 40000 | K6: =I6+J6 -> 53760 | P6: 외주가공 WAFER | R6: 40000 | T6: =R6+Q6 -> 40000
B7: BODY(LUG) | C7: =BFLY!B14 -> 0 | D7: 1 | F7: =IF(C7="WCB",7.4,IF(C7="CF8",7.4,IF(C7="CF8M",7.4))) -> FALSE | H7: =BFLY!C14 -> 0 | I7: =D7*F7*H7 -> 0 | J7: =IF(C7="WCB",45000,IF(C7="CF8",45000,IF(C7="CF8M",45000))) -> FALSE | K7: =I7+J7 -> 0 | P7: 외주가공 LUG | R7: 45000 | T7: =R7+Q7 -> 45000
B8: BODY(FLANGE) | C8: =BFLY!B15 -> CF8 | D8: 1 | F8: =16*1.1 -> 17.6 | H8: =BFLY!C15 -> 0 | I8: =D8*F8*H8 -> 0 | J8: =IF(C8="WCB",50000,IF(C8="CF8",50000,IF(C8="CF8M",50000))) -> 50000 | K8: =I8+J8 -> 50000 | L8: TEFLON SEAT | M8: METAL TEFLON SEAT | P8: 외주가공 FLANGE | R8: 50000 | T8: =R8+Q8 -> 50000
A9: 2 | B9: DISC | C9: =BFLY!B16 -> CF8M | D9: 1 | F9: =IF(C9="CF8",0.31,IF(C9="CF8M",0.31,IF(C9="CF3M",0.31,IF(C9="B148",0.7)))) -> 0.31 | H9: =BFLY!C16 -> 8000 | I9: =D9*F9*H9 -> 2480 | J9: 8000 | K9: =I9+J9 -> 10480 | L9: TEFLON | M9: TEFLON | N9: METAL | O9: 합계
A10: 3 | B10: SEAT | C10: =BFLY!B19 -> RTFE | D10: 1 | I10: =IF(C10="RTFE",7300,IF(C10="RTFE-A",4820,IF(C10="METAL-B",2440,IF(C10="RTFE + METAL",8370)))) -> 7300 | J10: =IF(C10="RTFE",1800,IF(C10="METAL-B",10000,IF(C10="RTFE + METAL",8000))) -> 1800 | K10: =I10+J10 -> 9100 | L10: 7300 | M10: 5870 | N10: 2500 | O10: =M10+N10 -> 8370
A11: 4 | B11: STEM(上,下) | C11: =BFLY!B17 -> A564T630 | D11: 1 | F11: 0.486 | H11: =BFLY!C17 -> 8000 | I11: =D11*F11*H11 -> 3888 | J11: 3500 | K11: =I11+J11 -> 7388 | P11: STEM | R11: 3500 | T11: =R11+Q11 -> 3500
A12: 5 | B12: RETAINER RING | C12: SS316 | D12: 1 | F12: 1 | H12: 7440 | I12: =D12*F12*H12 -> 7440 | J12: 8000 | K12: =I12+J12 -> 15440 | P12: RETAINER RING | Q12: =6.2*1200 -> 7440 | R12: 8000 | T12: =R12+Q12 -> 15440
A13: 6 | B13: RETAINER BOLT | C13: B8M | D13: 4 | F13: 1 | H13: 600 | I13: =D13*F13*H13 -> 2400 | K13: =H13*D13 -> 2400
A14: 7 | B14: BUSH | C14: SS316 | D14: 2 | F14: 1 | I14: 2870 | J14: 6040 | K14: =(I14+J14)*D14 -> 17820 | T14: =R14+Q14 -> 0
A15: 8 | B15: PACKING | C15: GRAPHITE | D15: 1 | F15: 1 | H15: 3900 | I15: =D15*F15*H15 -> 3900 | K15: =I15+J15 -> 3900 | P15: PACKING (완제품)
A16: 9 | B16: PACKING GLAND | C16: CF8/CF8M | D16: 1 | F16: 1 | H16: 960 | I16: =D16*F16*H16 -> 960 | J16: 300 | K16: =I16+J16 -> 1260 | P16: PACKING GLAND (소재+가공비) | T16: =0.96*1200 -> 1152
A17: 10 | B17: GLAND BOLT/NUT | C17: B8M | D17: 2 | F17: 1 | H17: 600 | I17: =D17*F17*H17 -> 1200 | K17: =I17+J17 -> 1200
A18: 11 | B18: COLOR | C18: SS316 | D18: 1 | F18: 1 | H18: 80 | I18: =D18*F18*H18 -> 80 | J18: 100 | K18: =I18+J18 -> 180 | T18: =R18+Q18 -> 0
A19: 12 | B19: DISCK PIN | C19: SS630 | D19: 1 | F19: 1 | H19: 225 | I19: =D19*F19*H19 -> 225 | J19: 160 | K19: =I19+J19 -> 385 | T19: =R19+Q19 -> 0
A20: 13 | B20: END COVER | C20: SS316 | D20: 1 | F20: 1 | H20: 435 | I20: =D20*F20*H20 -> 435 | J20: 300 | K20: 2900 | P20: END COVER (소재+가공비) | T20: =2.43*1200 -> 2916
A21: 14 | B21: END COVER BOLT | C21: B8M | D21: 4 | F21: 1 | H21: 100 | I21: =D21*F21*H21 -> 400 | K21: =I21+J21 -> 400
A22: 15 | B22: GASKET | C22: N-ASBESTOS | D22: 1 | F22: 1 | H22: 1100 | I22: =D22*F22*H22 -> 1100 | K22: =I22+J22 -> 1100
A23: 16 | B23: TAG | C23: SS316 | D23: 1 | F23: 1 | H23: 900 | I23: =D23*F23*H23 -> 900 | K23: =I23+J23 -> 900
A24: 17 | B24: INDICATOR | C24: SS304 | D24: 1 | F24: 1 | H24: 3000 | I24: =D24*F24*H24 -> 3000 | K24: =I24+J24 -> 3000
A25: 18 | B25: INDICATOR BOLT/NUT | C25: B8M | D25: 4 | F25: 1 | H25: 160 | I25: =D25*F25*H25 -> 640 | K25: =I25+J25 -> 640
A26: 19 | B26: LEVER | C26: SS304 | D26: 1 | F26: 1 | J26: SUS | K26: 23000 | L26: 11000
A27: 20 | B27: GEAR BOX | C27: =BFLY!B20 -> 10 BAR | D27: 1 | F27: 1 | J27: =C27 -> 10 BAR | K27: =IF(C27="PIYAKE",L27,IF(C27="10 BAR",M27,IF(C27="20 BAR",N27))) -> 98000 | L27: 16410 | M27: 98000 | N27: 98000
A28: 21 | B28: 페인트, 조립 | C28: CEPHAS | D28: 1 | F28: 1 | I28: 5000 | J28: 5000 | K28: =I28+J28 -> 10000
A29: 22 | B29: 밸브합산(BEAR) | K29: =SUM(K6:K25,K28) -> 192253
A30: 23 | B30: 밸브합산(LEVER) | K30: =SUM(K6:K26,K28) -> 215253
A31: 24 | B31: 밸브합산(GEAR) | K31: =SUM(K6:K25,K27:K28) -> 290253
A32: 25
A33: 26 | B33: ACTUATOR | D33: 1 | K33: =I33+J33 -> 0
A34: 27 | B34: ACTUATOR BOLT/WASHER | D34: 4 | K34: =I34+J34 -> 0
B35: 포장비용 | D35: 1 | K35: 10000
A36: 28 | B36: 밸브외 사급품 비용 연산 | I36: =SUM(K32:K35) -> 10000 | J36: 1 | K36: =J36*I36 -> 10000
A37: 29
A38: 30 | B38: FACTOR(BEAR) | I38: =K29 -> 192253 | J38: =BFLY!B21 -> 1 | K38: =J38*I38 -> 192253
A39: 31 | B39: FACTOR(LEVER) | I39: =K30 -> 215253 | J39: =BFLY!B21 -> 1 | K39: =J39*I39 -> 215253
A40: 32 | B40: FACTOR(GEAR) | I40: =K31 -> 290253 | J40: =BFLY!B21 -> 1 | K40: =J40*I40 -> 290253
A41: 33 | B41: 견적가격(TOTAL금액) - BEAR | K41: =SUM(K36,K38) -> 202253
A42: 34 | B42: 견적가격(TOTAL금액) - LEVER | K42: =SUM(K36,K39) -> 225253
...

Sheet 100A
A1: HIGH PERFORMANCE BFV 원가 分析表
A3: SIZE : 100A | C3: 압력 : 150# | F3: PJT :
A5: NO. | B5: 부품명 | C5: 재질 | D5: 수량 | E5: 규격 | F5: 단중 | G5: 업체 | H5: 단가 | I5: 소계 | J5: 가공비 | K5: 합계 | Q5: 소재비 | R5: 가공비 | T5: 합
A6: 1 | B6: BODY(WAFER) | C6: =BFLY!B13 -> CF8 | D6: 1 | F6: =IF(C6="WCB",5,IF(C6="CF8",5,IF(C6="CF8M",5))) -> 5 | H6: =BFLY!C13 -> 4000 | I6: =D6*F6*H6 -> 20000 | J6: =IF(C6="WCB",45000,IF(C6="CF8",45000,IF(C6="CF8M",45000))) -> 45000 | K6: =I6+J6 -> 65000 | P6: 외주가공 WAFER | R6: 45000 | T6: =R6+Q6 -> 45000
B7: BODY(LUG) | C7: =BFLY!B14 -> 0 | D7: 1 | F7: =IF(C7="WCB",13,IF(C7="CF8",13,IF(C7="CF8M",13))) -> FALSE | H7: =BFLY!C14 -> 0 | I7: =D7*F7*H7 -> 0 | J7: =IF(C7="WCB",50000,IF(C7="CF8",50000,IF(C7="CF8M",50000))) -> FALSE | K7: =I7+J7 -> 0 | P7: 외주가공 LUG | R7: 50000 | T7: =R7+Q7 -> 50000
B8: BODY(FLANGE) | C8: =BFLY!B15 -> CF8 | D8: 1 | F8: =26*1.1 -> 28.6 | H8: =BFLY!C15 -> 0 | I8: =D8*F8*H8 -> 0 | J8: =IF(C8="WCB",55000,IF(C8="CF8",55000,IF(C8="CF8M",55000))) -> 55000 | K8: =I8+J8 -> 55000 | L8: TEFLON SEAT | M8: METAL TEFLON SEAT | P8: 외주가공 FLANGE | R8: 55000 | T8: =R8+Q8 -> 55000
A9: 2 | B9: DISC | C9: =BFLY!B16 -> CF8M | D9: 1 | F9: =IF(C9="CF8",0.72,IF(C9="CF8M",0.72,IF(C9="CF3M",0.72,IF(C9="B148",1.3)))) -> 0.72 | H9: =BFLY!C16 -> 8000 | I9: =D9*F9*H9 -> 5760 | J9: 8000 | K9: =I9+J9 -> 13760 | L9: TEFLON | M9: TEFLON | N9: METAL | O9: 합계
A10: 3 | B10: SEAT | C10: =BFLY!B19 -> RTFE | D10: 1 | I10: =IF(C10="RTFE",8500,IF(C10="RTFE-A",6250,IF(C10="METAL-B",2830,IF(C10="RTFE + METAL",8800)))) -> 8500 | J10: =IF(C10="RTFE",2000,IF(C10="METAL-B",12500,IF(C10="RTFE + METAL",8000))) -> 2000 | K10: =I10+J10 -> 10500 | L10: 8500 | M10: 5800 | N10: 3000 | O10: =M10+N10 -> 8800
A11: 4 | B11: STEM(上,下) | C11: =BFLY!B17 -> A564T630 | D11: 1 | F11: 0.854 | H11: =BFLY!C17 -> 8000 | I11: =D11*F11*H11 -> 6832 | J11: 4000 | K11: =I11+J11 -> 10832 | P11: STEM | R11: 4000 | T11: =R11+Q11 -> 4000
A12: 5 | B12: RETAINER RING | C12: SS316 | D12: 1 | F12: 1 | H12: 10900 | I12: =D12*F12*H12 -> 10900 | J12: 8000 | K12: =I12+J12 -> 18900 | P12: RETAINER RING | Q12: =9.09*1200 -> 10908 | R12: 8000 | T12: =R12+Q12 -> 18908
A13: 6 | B13: RETAINER BOLT | C13: B8M | D13: 4 | F13: 1 | H13: 600 | I13: =D13*F13*H13 -> 2400 | K13: =H13*D13 -> 2400
A14: 7 | B14: BUSH | C14: SS316 | D14: 2 | F14: 1 | I14: 3420 | J14: 7530 | K14: =(I14+J14)*D14 -> 21900 | T14: =R14+Q14 -> 0
A15: 8 | B15: PACKING | C15: GRAPHITE | D15: 1 | F15: 1 | H15: 4500 | I15: =D15*F15*H15 -> 4500 | K15: =I15+J15 -> 4500 | P15: PACKING (완제품)
A16: 9 | B16: PACKING GLAND | C16: CF8/CF8M | D16: 1 | F16: 1 | H16: 1050 | I16: =D16*F16*H16 -> 1050 | J16: 300 | K16: =I16+J16 -> 1350 | P16: PACKING GLAND (소재+가공비) | T16: =0.96*1200 -> 1152
A17: 10 | B17: GLAND BOLT/NUT | C17: B8M | D17: 2 | F17: 1 | H17: 600 | I17: =D17*F17*H17 -> 1200 | K17: =I17+J17 -> 1200
A18: 11 | B18: COLOR | C18: SS316 | D18: 1 | F18: 1 | H18: 120 | I18: =D18*F18*H18 -> 120 | J18: 100 | K18: =I18+J18 -> 220 | T18: =R18+Q18 -> 0
A19: 12 | B19: DISCK PIN | C19: SS630 | D19: 2 | F19: 1 | H19: 225 | I19: =D19*F19*H19 -> 450 | J19: 160 | K19: =I19+J19 -> 610 | T19: =R19+Q19 -> 0
A20: 13 | B20: END COVER | C20: SS316 | D20: 1 | F20: 1 | H20: 611 | I20: =D20*F20*H20 -> 611 | J20: 300 | K20: 3350 | P20: END COVER (소재+가공비) | T20: =2.79*1200 -> 3348
A21: 14 | B21: END COVER BOLT | C21: B8M | D21: 4 | F21: 1 | H21: 100 | I21: =D21*F21*H21 -> 400 | K21: =I21+J21 -> 400
A22: 15 | B22: GASKET | C22: N-ASBESTOS | D22: 1 | F22: 1 | H22: 1250 | I22: =D22*F22*H22 -> 1250 | K22: =I22+J22 -> 1250
A23: 16 | B23: TAG | C23: SS316 | D23: 1 | F23: 1 | H23: 900 | I23: =D23*F23*H23 -> 900 | K23: =I23+J23 -> 900
A24: 17 | B24: INDICATOR | C24: SS304 | D24: 1 | F24: 1 | H24: 3000 | I24: =D24*F24*H24 -> 3000 | K24: =I24+J24 -> 3000
A25: 18 | B25: INDICATOR BOLT/NUT | C25: B8M | D25: 4 | F25: 1 | H25: 160 | I25: =D25*F25*H25 -> 640 | K25: =I25+J25 -> 640
A26: 19 | B26: LEVER | C26: SS304 | D26: 1 | F26: 1 | J26: SUS | K26: 23000 | L26: 11000
A27: 20 | B27: GEAR BOX | C27: =BFLY!B20 -> 10 BAR | D27: 1 | F27: 1 | J27: =C27 -> 10 BAR | K27: =IF(C27="PIYAKE",L27,IF(C27="10 BAR",M27,IF(C27="20 BAR",N27))) -> 98000 | L27: 16410 | M27: 98000 | N27: 98000
A28: 21 | B28: 페인트, 조립 | C28: CEPHAS | D28: 1 | F28: 1 | I28: 7200 | J28: 6000 | K28: =I28+J28 -> 13200
A29: 22 | B29: 밸브합산(BEAR) | K29: =SUM(K6:K25,K28) -> 228912
A30: 23 | B30: 밸브합산(LEVER) | K30: =SUM(K6:K26,K28) -> 251912
A31: 24 | B31: 밸브합산(GEAR) | K31: =SUM(K6:K25,K27:K28) -> 326912
A32: 25
A33: 26 | B33: ACTUATOR | D33: 1 | K33: =I33+J33 -> 0
A34: 27 | B34: ACTUATOR BOLT/WASHER | D34: 4 | K34: =I34+J34 -> 0
B35: 포장비용 | D35: 1 | K35: 14500
A36: 28 | B36: 밸브외 사급품 비용 연산 | I36: =SUM(K32:K35) -> 14500 | J36: 1 | K36: =J36*I36 -> 14500
A37: 29
A38: 30 | B38: FACTOR(BEAR) | I38: =K29 -> 228912 | J38: =BFLY!B21 -> 1 | K38: =J38*I38 -> 228912
A39: 31 | B39: FACTOR(LEVER) | I39: =K30 -> 251912 | J39: =BFLY!B21 -> 1 | K39: =J39*I39 -> 251912
A40: 32 | B40: FACTOR(GEAR) | I40: =K31 -> 326912 | J40: =BFLY!B21 -> 1 | K40: =J40*I40 -> 326912
A41: 33 | B41: 견적가격(TOTAL금액) - BEAR | K41: =SUM(K36,K38) -> 243412
A42: 34 | B42: 견적가격(TOTAL금액) - LEVER | K42: =SUM(K36,K39) -> 266412
...

Sheet 125A
A1: HIGH PERFORMANCE BFV 원가 分析表
A3: SIZE : 125A | C3: 압력 : 150# | F3: PJT : | M3: 주강 콘센트릭
A5: NO. | B5: 부품명 | C5: 재질 | D5: 수량 | E5: 규격 | F5: 단중 | G5: 업체 | H5: 단가 | I5: 소계 | J5: 가공비 | K5: 합계 | Q5: 소재비 | R5: 가공비 | T5: 합
A6: 1 | B6: BODY(WAFER) | C6: =BFLY!B13 -> CF8 | D6: 1 | F6: =IF(C6="WCB",6.7,IF(C6="CF8",6.7,IF(C6="CF8M",6.7))) -> 6.7 | H6: =BFLY!C13 -> 4000 | I6: =D6*F6*H6 -> 26800 | J6: =IF(C6="WCB",50000,IF(C6="CF8",50000,IF(C6="CF8M",50000))) -> 50000 | K6: =I6+J6 -> 76800 | P6: 외주가공 WAFER | R6: 50000 | T6: =R6+Q6 -> 50000
B7: BODY(LUG) | C7: =BFLY!B14 -> 0 | D7: 1 | F7: =IF(C7="WCB",16,IF(C7="CF8",16,IF(C7="CF8M",16))) -> FALSE | H7: =BFLY!C14 -> 0 | I7: =D7*F7*H7 -> 0 | J7: =IF(C7="WCB",53000,IF(C7="CF8",53000,IF(C7="CF8M",53000))) -> FALSE | K7: =I7+J7 -> 0 | P7: 외주가공 LUG | R7: 53000 | T7: =R7+Q7 -> 53000
B8: BODY(FLANGE) | C8: =BFLY!B15 -> CF8 | D8: 1 | F8: =29*1.1 -> 31.9 | H8: =BFLY!C15 -> 0 | I8: =D8*F8*H8 -> 0 | J8: =IF(C8="WCB",58000,IF(C8="CF8",58000,IF(C8="CF8M",58000))) -> 58000 | K8: =I8+J8 -> 58000 | L8: TEFLON SEAT | M8: METAL TEFLON SEAT | P8: 외주가공 FLANGE | R8: 58000 | T8: =R8+Q8 -> 58000
A9: 2 | B9: DISC | C9: =BFLY!B16 -> CF8M | D9: 1 | F9: =IF(C9="CF8",1.34,IF(C9="CF8M",1.34,IF(C9="CF3M",1.34,IF(C9="B148",2.7)))) -> 1.34 | H9: =BFLY!C16 -> 8000 | I9: =D9*F9*H9 -> 10720 | J9: 10000 | K9: =I9+J9 -> 20720 | L9: TEFLON | M9: TEFLON | N9: METAL | O9: 합계
A10: 3 | B10: SEAT | C10: =BFLY!B19 -> RTFE | D10: 1 | I10: =IF(C10="RTFE",8900,IF(C10="RTFE-A",8480,IF(C10="METAL-B",3510,IF(C10="RTFE + METAL",11800)))) -> 8900 | J10: =IF(C10="RTFE",2300,IF(C10="METAL-B",12500,IF(C10="RTFE + METAL",8000))) -> 2300 | K10: =I10+J10 -> 11200 | L10: 8900 | M10: 8300 | N10: 3500 | O10: =M10+N10 -> 11800
A11: 4 | B11: STEM(上,下) | C11: =BFLY!B17 -> A564T630 | D11: 1 | F11: 0.92 | H11: =BFLY!C17 -> 8000 | I11: =D11*F11*H11 -> 7360 | J11: 4000 | K11: =I11+J11 -> 11360 | P11: STEM | R11: 4000 | T11: =R11+Q11 -> 4000
A12: 5 | B12: RETAINER RING | C12: SS316 | D12: 1 | F12: 1 | H12: 14050 | I12: =D12*F12*H12 -> 14050 | J12: 9000 | K12: =I12+J12 -> 23050 | P12: RETAINER RING | Q12: =11.71*1200 -> 14052 | R12: 9000 | T12: =R12+Q12 -> 23052
A13: 6 | B13: RETAINER BOLT | C13: B8M | D13: 4 | F13: 1 | H13: 600 | I13: =D13*F13*H13 -> 2400 | K13: =H13*D13 -> 2400
A14: 7 | B14: BUSH | C14: SS316 | D14: 2 | F14: 1 | I14: 3510 | J14: 7530 | K14: =(I14+J14)*D14 -> 22080 | T14: =R14+Q14 -> 0
A15: 8 | B15: PACKING | C15: GRAPHITE | D15: 1 | F15: 1 | H15: 4500 | I15: =D15*F15*H15 -> 4500 | K15: =I15+J15 -> 4500 | P15: PACKING (완제품)
A16: 9 | B16: PACKING GLAND | C16: CF8/CF8M | D16: 1 | F16: 1 | H16: 1050 | I16: =D16*F16*H16 -> 1050 | J16: 300 | K16: =I16+J16 -> 1350 | P16: PACKING GLAND (소재+가공비) | T16: =0.96*1200 -> 1152
A17: 10 | B17: GLAND BOLT/NUT | C17: B8M | D17: 2 | F17: 1 | H17: 600 | I17: =D17*F17*H17 -> 1200 | K17: =I17+J17 -> 1200
A18: 11 | B18: COLOR | C18: SS316 | D18: 1 | F18: 1 | H18: 120 | I18: =D18*F18*H18 -> 120 | J18: 100 | K18: =I18+J18 -> 220 | T18: =R18+Q18 -> 0
A19: 12 | B19: DISCK PIN | C19: SS630 | D19: 2 | F19: 1 | H19: 225 | I19: =D19*F19*H19 -> 450 | J19: 160 | K19: =I19+J19 -> 610 | T19: =R19+Q19 -> 0
A20: 13 | B20: END COVER | C20: SS316 | D20: 1 | F20: 1 | H20: 610 | I20: =D20*F20*H20 -> 610 | J20: 300 | K20: 3350 | P20: END COVER (소재+가공비) | T20: =2.79*1200 -> 3348
A21: 14 | B21: END COVER BOLT | C21: B8M | D21: 4 | F21: 1 | H21: 100 | I21: =D21*F21*H21 -> 400 | K21: =I21+J21 -> 400
A22: 15 | B22: GASKET | C22: N-ASBESTOS | D22: 1 | F22: 1 | H22: 1250 | I22: =D22*F22*H22 -> 1250 | K22: =I22+J22 -> 1250
A23: 16 | B23: TAG | C23: SS316 | D23: 1 | F23: 1 | H23: 900 | I23: =D23*F23*H23 -> 900 | K23: =I23+J23 -> 900
A24: 17 | B24: INDICATOR | C24: SS304 | D24: 1 | F24: 1 | H24: 3000 | I24: =D24*F24*H24 -> 3000 | K24: =I24+J24 -> 3000
A25: 18 | B25: INDICATOR BOLT/NUT | C25: B8M | D25: 4 | F25: 1 | H25: 160 | I25: =D25*F25*H25 -> 640 | K25: =I25+J25 -> 640
A26: 19 | B26: LEVER | C26: SS304 | D26: 1 | F26: 1 | J26: SUS | K26: 23000 | L26: 11000
A27: 20 | B27: GEAR BOX | C27: =BFLY!B20 -> 10 BAR | D27: 1 | F27: 1 | J27: =C27 -> 10 BAR | K27: =IF(C27="PIYAKE",L27,IF(C27="10 BAR",M27,IF(C27="20 BAR",N27))) -> 98000 | L27: 17510 | M27: 98000 | N27: 98000
A28: 21 | B28: 페인트, 조립 | C28: CEPHAS | D28: 1 | F28: 1 | I28: 9000 | J28: 6000 | K28: =I28+J28 -> 15000
A29: 22 | B29: 밸브합산(BEAR) | K29: =SUM(K6:K25,K28) -> 258030
A30: 23 | B30: 밸브합산(LEVER) | K30: =SUM(K6:K26,K28) -> 281030
A31: 24 | B31: 밸브합산(GEAR) | K31: =SUM(K6:K25,K27:K28) -> 356030
A32: 25
A33: 26 | B33: ACTUATOR | D33: 1 | K33: =I33+J33 -> 0
A34: 27 | B34: ACTUATOR BOLT/WASHER | D34: 4 | K34: =I34+J34 -> 0
B35: 포장비용 | D35: 1 | K35: 14000
A36: 28 | B36: 밸브외 사급품 비용 연산 | I36: =SUM(K32:K35) -> 14000 | J36: 1 | K36: =J36*I36 -> 14000
A37: 29
A38: 30 | B38: FACTOR(BEAR) | I38: =K29 -> 258030 | J38: =BFLY!B21 -> 1 | K38: =J38*I38 -> 258030
A39: 31 | B39: FACTOR(LEVER) | I39: =K30 -> 281030 | J39: =BFLY!B21 -> 1 | K39: =J39*I39 -> 281030
A40: 32 | B40: FACTOR(GEAR) | I40: =K31 -> 356030 | J40: =BFLY!B21 -> 1 | K40: =J40*I40 -> 356030
A41: 33 | B41: 견적가격(TOTAL금액) - BEAR | K41: =SUM(K36,K38) -> 272030
A42: 34 | B42: 견적가격(TOTAL금액) - LEVER | K42: =SUM(K36,K39) -> 295030
...

Sheet 150A
A1: HIGH PERFORMANCE BFV 원가 分析表
A3: SIZE : 150A | C3: 압력 : 150# | F3: PJT :
A5: NO. | B5: 부품명 | C5: 재질 | D5: 수량 | E5: 규격 | F5: 단중 | G5: 업체 | H5: 단가 | I5: 소계 | J5: 가공비 | K5: 합계 | Q5: 소재비 | R5: 가공비 | T5: 합
A6: 1 | B6: BODY(WAFER) | C6: =BFLY!B13 -> CF8 | D6: 1 | F6: =IF(C6="WCB",11,IF(C6="CF8",11,IF(C6="CF8M",11))) -> 11 | H6: =BFLY!C13 -> 4000 | I6: =D6*F6*H6 -> 44000 | J6: =IF(C6="WCB",55000,IF(C6="CF8",55000,IF(C6="CF8M",55000))) -> 55000 | K6: =I6+J6 -> 99000 | P6: 외주가공 WAFER | R6: 55000 | T6: =R6+Q6 -> 55000
B7: BODY(LUG) | C7: =BFLY!B14 -> 0 | D7: 1 | F7: =IF(C7="WCB",16,IF(C7="CF8",16,IF(C7="CF8M",16))) -> FALSE | H7: =BFLY!C14 -> 0 | I7: =D7*F7*H7 -> 0 | J7: =IF(C7="WCB",63000,IF(C7="CF8",63000,IF(C7="CF8M",63000))) -> FALSE | K7: =I7+J7 -> 0 | P7: 외주가공 LUG | R7: 63000 | T7: =R7+Q7 -> 63000
B8: BODY(FLANGE) | C8: =BFLY!B15 -> CF8 | D8: 1 | F8: =32*1.1 -> 35.2 | H8: =BFLY!C15 -> 0 | I8: =D8*F8*H8 -> 0 | J8: =IF(C8="WCB",68000,IF(C8="CF8",68000,IF(C8="CF8M",68000))) -> 68000 | K8: =I8+J8 -> 68000 | L8: TEFLON SEAT | M8: METAL TEFLON SEAT | P8: 외주가공 FLANGE | R8: 68000 | T8: =R8+Q8 -> 68000
A9: 2 | B9: DISC | C9: =BFLY!B16 -> CF8M | D9: 1 | F9: =IF(C9="CF8",3.5,IF(C9="CF8M",3.5,IF(C9="CF3M",3.5,IF(C9="B148",3.5)))) -> 3.5 | H9: =BFLY!C16 -> 8000 | I9: =D9*F9*H9 -> 28000 | J9: 10000 | K9: =I9+J9 -> 38000 | L9: TEFLON | M9: TEFLON | N9: METAL | O9: 합계
A10: 3 | B10: SEAT | C10: =BFLY!B19 -> RTFE | D10: 1 | I10: =IF(C10="RTFE",18560,IF(C10="RTFE-A",13050,IF(C10="METAL-B",4800,IF(C10="RTFE + METAL",17100)))) -> 18560 | J10: =IF(C10="RTFE",2500,IF(C10="METAL-B",12500,IF(C10="RTFE + METAL",10000))) -> 2500 | K10: =I10+J10 -> 21060 | L10: 18560 | M10: 11900 | N10: 5200 | O10: =M10+N10 -> 17100
A11: 4 | B11: STEM(上,下) | C11: =BFLY!B17 -> A564T630 | D11: 1 | F11: 1 | H11: =BFLY!C17 -> 8000 | I11: =D11*F11*H11 -> 8000 | J11: 9000 | K11: =I11+J11 -> 17000 | P11: STEM | R11: 4000 | T11: =R11+Q11 -> 4000
A12: 5 | B12: RETAINER RING | C12: SS316 | D12: 1 | F12: 1 | H12: 19200 | I12: =D12*F12*H12 -> 19200 | J12: 10000 | K12: =I12+J12 -> 29200 | P12: RETAINER RING | Q12: =15.99*1200 -> 19188 | R12: 10000 | T12: =R12+Q12 -> 29188
A13: 6 | B13: RETAINER BOLT | C13: B8M | D13: 4 | F13: 1 | H13: 600 | I13: =D13*F13*H13 -> 2400 | K13: =H13*D13 -> 2400
A14: 7 | B14: BUSH | C14: SS316 | D14: 2 | F14: 1 | I14: 4050 | J14: 8790 | K14: =(I14+J14)*D14 -> 25680 | T14: =R14+Q14 -> 0
A15: 8 | B15: PACKING | C15: GRAPHITE | D15: 1 | F15: 1 | H15: 4500 | I15: =D15*F15*H15 -> 4500 | K15: =I15+J15 -> 4500 | P15: PACKING (완제품)
A16: 9 | B16: PACKING GLAND | C16: CF8/CF8M | D16: 1 | F16: 1 | H16: 1050 | I16: =D16*F16*H16 -> 1050 | J16: 300 | K16: =I16+J16 -> 1350 | P16: PACKING GLAND (소재+가공비) | T16: =0.96*1200 -> 1152
A17: 10 | B17: GLAND BOLT/NUT | C17: B8M | D17: 2 | F17: 1 | H17: 600 | I17: =D17*F17*H17 -> 1200 | K17: =I17+J17 -> 1200
A18: 11 | B18: COLOR | C18: SS316 | D18: 1 | F18: 1 | H18: 120 | I18: =D18*F18*H18 -> 120 | J18: 100 | K18: =I18+J18 -> 220 | T18: =R18+Q18 -> 0
A19: 12 | B19: DISCK PIN | C19: SS630 | D19: 2 | F19: 1 | H19: 225 | I19: =D19*F19*H19 -> 450 | J19: 160 | K19: =I19+J19 -> 610 | T19: =R19+Q19 -> 0
A20: 13 | B20: END COVER | C20: SS316 | D20: 1 | F20: 1 | H20: 611 | I20: =D20*F20*H20 -> 611 | J20: 300 | K20: 3350 | P20: END COVER (소재+가공비) | T20: =2.79*1200 -> 3348
A21: 14 | B21: END COVER BOLT | C21: B8M | D21: 4 | F21: 1 | H21: 100 | I21: =D21*F21*H21 -> 400 | K21: =I21+J21 -> 400
A22: 15 | B22: GASKET | C22: N-ASBESTOS | D22: 1 | F22: 1 | H22: 1250 | I22: =D22*F22*H22 -> 1250 | K22: =I22+J22 -> 1250
A23: 16 | B23: TAG | C23: SS316 | D23: 1 | F23: 1 | H23: 900 | I23: =D23*F23*H23 -> 900 | K23: =I23+J23 -> 900
A24: 17 | B24: INDICATOR | C24: SS304 | D24: 1 | F24: 1 | H24: 3000 | I24: =D24*F24*H24 -> 3000 | K24: =I24+J24 -> 3000
A25: 18 | B25: INDICATOR BOLT/NUT | C25: B8M | D25: 4 | F25: 1 | H25: 160 | I25: =D25*F25*H25 -> 640 | K25: =I25+J25 -> 640
A26: 19 | B26: LEVER | C26: SS304 | D26: 1 | F26: 1 | J26: SUS | K26: 23000 | L26: 11000
A27: 20 | B27: GEAR BOX | C27: =BFLY!B20 -> 10 BAR | D27: 1 | F27: 1 | J27: =C27 -> 10 BAR | K27: =IF(C27="PIYAKE",L27,IF(C27="10 BAR",M27,IF(C27="20 BAR",N27))) -> 98000 | L27: 17510 | M27: 98000 | N27: 98000
A28: 21 | B28: 페인트, 조립 | C28: CEPHAS | D28: 1 | F28: 1 | I28: 15000 | J28: 6000 | K28: =I28+J28 -> 21000
A29: 22 | B29: 밸브합산(BEAR) | K29: =SUM(K6:K25,K28) -> 338760
A30: 23 | B30: 밸브합산(LEVER) | K30: =SUM(K6:K26,K28) -> 361760
A31: 24 | B31: 밸브합산(GEAR) | K31: =SUM(K6:K25,K27:K28) -> 436760
A32: 25
A33: 26 | B33: ACTUATOR | D33: 1 | K33: =I33+J33 -> 0
A34: 27 | B34: ACTUATOR BOLT/WASHER | D34: 4 | K34: =I34+J34 -> 0
B35: 포장비용 | D35: 1 | K35: 15000
A36: 28 | B36: 밸브외 사급품 비용 연산 | I36: =SUM(K32:K35) -> 15000 | J36: 1 | K36: =J36*I36 -> 15000
A37: 29
A38: 30 | B38: FACTOR(BEAR) | I38: =K29 -> 338760 | J38: =BFLY!B21 -> 1 | K38: =J38*I38 -> 338760
A39: 31 | B39: FACTOR(LEVER) | I39: =K30 -> 361760 | J39: =BFLY!B21 -> 1 | K39: =J39*I39 -> 361760
A40: 32 | B40: FACTOR(GEAR) | I40: =K31 -> 436760 | J40: =BFLY!B21 -> 1 | K40: =J40*I40 -> 436760
A41: 33 | B41: 견적가격(TOTAL금액) - BEAR | K41: =SUM(K36,K38) -> 353760
A42: 34 | B42: 견적가격(TOTAL금액) - LEVER | K42: =SUM(K36,K39) -> 376760
...

Sheet 200A
A1: HIGH PERFORMANCE BFV 원가 分析表
A3: SIZE : 200A | C3: 압력 : 150# | F3: PJT :
A5: NO. | B5: 부품명 | C5: 재질 | D5: 수량 | E5: 규격 | F5: 단중 | G5: 업체 | H5: 단가 | I5: 소계 | J5: 가공비 | K5: 합계 | Q5: 소재비 | R5: 가공비 | T5: 합
A6: 1 | B6: BODY(WAFER) | C6: =BFLY!B13 -> CF8 | D6: 1 | F6: =IF(C6="WCB",15,IF(C6="CF8",15,IF(C6="CF8M",15))) -> 15 | H6: =BFLY!C13 -> 4000 | I6: =D6*F6*H6 -> 60000 | J6: =IF(C6="WCB",70000,IF(C6="CF8",70000,IF(C6="CF8M",70000))) -> 70000 | K6: =I6+J6 -> 130000 | P6: 외주가공 WAFER | R6: 70000 | T6: =R6+Q6 -> 70000
B7: BODY(LUG) | C7: =BFLY!B14 -> 0 | D7: 1 | F7: =IF(C7="WCB",19,IF(C7="CF8",19,IF(C7="CF8M",19))) -> FALSE | H7: =BFLY!C14 -> 0 | I7: =D7*F7*H7 -> 0 | J7: =IF(C7="WCB",85000,IF(C7="CF8",85000,IF(C7="CF8M",85000))) -> FALSE | K7: =I7+J7 -> 0 | P7: 외주가공 LUG | R7: 85000 | T7: =R7+Q7 -> 85000
B8: BODY(FLANGE) | C8: =BFLY!B15 -> CF8 | D8: 1 | F8: =52*1.1 -> 57.2 | H8: =BFLY!C15 -> 0 | I8: =D8*F8*H8 -> 0 | J8: =IF(C8="WCB",90000,IF(C8="CF8",90000,IF(C8="CF8M",90000))) -> 90000 | K8: =I8+J8 -> 90000 | L8: TEFLON SEAT | M8: METAL TEFLON SEAT | P8: 외주가공 FLANGE | R8: 90000 | T8: =R8+Q8 -> 90000
A9: 2 | B9: DISC | C9: =BFLY!B16 -> CF8M | D9: 1 | F9: =IF(C9="CF8",4.18,IF(C9="CF8M",4.18,IF(C9="CF3M",4.18,IF(C9="B148",5.5)))) -> 4.18 | H9: =BFLY!C16 -> 8000 | I9: =D9*F9*H9 -> 33440 | J9: =IF(C9="CF8",14000,IF(C9="CF8M",14000,IF(C9="CF3M",14000,IF(C9="B148",20000)))) -> 14000 | K9: =I9+J9 -> 47440 | L9: TEFLON | M9: TEFLON | N9: METAL | O9: 합계
A10: 3 | B10: SEAT | C10: =BFLY!B19 -> RTFE | D10: 1 | I10: =IF(C10="RTFE",20100,IF(C10="RTFE-A",16710,IF(C10="METAL-B",5850,IF(C10="RTFE + METAL",25100)))) -> 20100 | J10: =IF(C10="RTFE",2800,IF(C10="METAL-B",19500,IF(C10="RTFE + METAL",10000))) -> 2800 | K10: =I10+J10 -> 22900 | L10: 20100 | M10: 18800 | N10: 6300 | O10: =M10+N10 -> 25100
A11: 4 | B11: STEM(上,下) | C11: =BFLY!B17 -> A564T630 | D11: 1 | F11: 1.974 | H11: =BFLY!C17 -> 8000 | I11: =D11*F11*H11 -> 15792 | J11: 6000 | K11: =I11+J11 -> 21792 | P11: STEM | R11: 6000 | T11: =R11+Q11 -> 6000
A12: 5 | B12: RETAINER RING | C12: SS316 | D12: 1 | F12: 1 | H12: 33500 | I12: =D12*F12*H12 -> 33500 | J12: 13000 | K12: =I12+J12 -> 46500 | P12: RETAINER RING | Q12: =27.78*1200 -> 33336 | R12: 13000 | T12: =R12+Q12 -> 46336
A13: 6 | B13: RETAINER BOLT | C13: B8M | D13: 4 | F13: 1 | H13: 600 | I13: =D13*F13*H13 -> 2400 | K13: =H13*D13 -> 2400
A14: 7 | B14: BUSH | C14: SS316 | D14: 2 | F14: 1 | I14: 5670 | J14: 13060 | K14: =(I14+J14)*D14 -> 37460 | T14: =R14+Q14 -> 0
A15: 8 | B15: PACKING | C15: GRAPHITE | D15: 1 | F15: 1 | H15: 6500 | I15: =D15*F15*H15 -> 6500 | K15: =I15+J15 -> 6500 | P15: PACKING (완제품)
A16: 9 | B16: PACKING GLAND | C16: CF8/CF8M | D16: 1 | F16: 1 | H16: 1310 | I16: =D16*F16*H16 -> 1310 | J16: 300 | K16: =I16+J16 -> 1610 | P16: PACKING GLAND (소재+가공비) | T16: =1.22*1200 -> 1464
A17: 10 | B17: GLAND BOLT/NUT | C17: B8M | D17: 2 | F17: 1 | H17: 600 | I17: =D17*F17*H17 -> 1200 | K17: =I17+J17 -> 1200
A18: 11 | B18: COLOR | C18: SS316 | D18: 1 | F18: 1 | H18: 180 | I18: =D18*F18*H18 -> 180 | J18: 100 | K18: =I18+J18 -> 280 | T18: =R18+Q18 -> 0
A19: 12 | B19: DISCK PIN | C19: SS630 | D19: 2 | F19: 1 | H19: 350 | I19: =H19 -> 350 | J19: 180 | K19: =(I19+J19)*D19 -> 1060 | T19: =R19+Q19 -> 0
A20: 13 | B20: END COVER | C20: SS316 | D20: 1 | F20: 1 | H20: 950 | I20: =D20*F20*H20 -> 950 | J20: 300 | K20: 5200 | P20: END COVER (소재+가공비) | T20: =4.34*1200 -> 5208
A21: 14 | B21: END COVER BOLT | C21: B8M | D21: 4 | F21: 1 | H21: 100 | I21: =D21*F21*H21 -> 400 | K21: =I21+J21 -> 400
A22: 15 | B22: GASKET | C22: N-ASBESTOS | D22: 1 | F22: 1 | H22: 1500 | I22: =D22*F22*H22 -> 1500 | K22: =I22+J22 -> 1500
A23: 16 | B23: TAG | C23: SS316 | D23: 1 | F23: 1 | H23: 900 | I23: =D23*F23*H23 -> 900 | K23: =I23+J23 -> 900
A24: 17 | B24: INDICATOR | C24: SS304 | D24: 1 | F24: 1 | H24: 4950 | I24: =D24*F24*H24 -> 4950 | K24: =I24+J24 -> 4950
A25: 18 | B25: INDICATOR BOLT/NUT | C25: B8M | D25: 4 | F25: 1 | H25: 360 | I25: =D25*F25*H25 -> 1440 | K25: =I25+J25 -> 1440
A26: 19 | B26: LEVER | C26: SS304 | D26: 1 | F26: 1 | I26: 19420 | J26: 6500 | K26: =I26+J26 -> 25920
A27: 20 | B27: GEAR BOX | C27: =BFLY!B20 -> 10 BAR | D27: 1 | F27: 1 | J27: =C27 -> 10 BAR | K27: =IF(C27="PIYAKE",L27,IF(C27="10 BAR",M27,IF(C27="20 BAR",N27))) -> 98000 | L27: 50000 | M27: 98000 | N27: 98000
A28: 21 | B28: 페인트, 조립 | C28: CEPHAS | D28: 1 | F28: 1 | I28: 15000 | J28: 10000 | K28: =I28+J28 -> 25000
A29: 22 | B29: 밸브합산(BEAR) | K29: =SUM(K6:K25,K28) -> 448532
A30: 23 | B30: 밸브합산(LEVER) | K30: =SUM(K6:K26,K28) -> 474452
A31: 24 | B31: 밸브합산(GEAR) | K31: =SUM(K6:K25,K27:K28) -> 546532
A32: 25
A33: 26 | B33: ACTUATOR | D33: 1 | K33: =I33+J33 -> 0
A34: 27 | B34: ACTUATOR BOLT/WASHER | D34: 4 | K34: =I34+J34 -> 0
B35: 포장비용 | D35: 1 | K35: 17000
A36: 28 | B36: 밸브외 사급품 비용 연산 | I36: =SUM(K32:K35) -> 17000 | J36: 1 | K36: =J36*I36 -> 17000
A37: 29
A38: 30 | B38: FACTOR(BEAR) | I38: =K29 -> 448532 | J38: =BFLY!B21 -> 1 | K38: =J38*I38 -> 448532
A39: 31 | B39: FACTOR(LEVER) | I39: =K30 -> 474452 | J39: =BFLY!B21 -> 1 | K39: =J39*I39 -> 474452
A40: 32 | B40: FACTOR(GEAR) | I40: =K31 -> 546532 | J40: =BFLY!B21 -> 1 | K40: =J40*I40 -> 546532
A41: 33 | B41: 견적가격(TOTAL금액) - BEAR | K41: =SUM(K36,K38) -> 465532
A42: 34 | B42: 견적가격(TOTAL금액) - LEVER | K42: =SUM(K36,K39) -> 491452
...

Sheet 250A
A1: HIGH PERFORMANCE BFV 원가 分析表
A3: SIZE : 250A | C3: 압력 : 150# | F3: PJT :
A5: NO. | B5: 부품명 | C5: 재질 | D5: 수량 | E5: 규격 | F5: 단중 | G5: 업체 | H5: 단가 | I5: 소계 | J5: 가공비 | K5: 합계 | Q5: 소재비 | R5: 가공비 | T5: 합
A6: 1 | B6: BODY(WAFER) | C6: =BFLY!B13 -> CF8 | D6: 1 | F6: =IF(C6="WCB",26,IF(C6="CF8",26,IF(C6="CF8M",26))) -> 26 | H6: =BFLY!C13 -> 4000 | I6: =D6*F6*H6 -> 104000 | J6: =IF(C6="WCB",90000,IF(C6="CF8",90000,IF(C6="CF8M",90000))) -> 90000 | K6: =I6+J6 -> 194000 | P6: 외주가공 WAFER | R6: 90000 | T6: =R6+Q6 -> 90000
B7: BODY(LUG) | C7: =BFLY!B14 -> 0 | D7: 1 | F7: =IF(C7="WCB",36,IF(C7="CF8",36,IF(C7="CF8M",36))) -> FALSE | H7: =BFLY!C14 -> 0 | I7: =D7*F7*H7 -> 0 | J7: =IF(C7="WCB",110000,IF(C7="CF8",110000,IF(C7="CF8M",110000))) -> FALSE | K7: =I7+J7 -> 0 | P7: 외주가공 LUG | R7: 110000 | T7: =R7+Q7 -> 110000
B8: BODY(FLANGE) | C8: =BFLY!B15 -> CF8 | D8: 1 | F8: =70*1.1 -> 77 | H8: =BFLY!C15 -> 0 | I8: =D8*F8*H8 -> 0 | J8: =IF(C8="WCB",130000,IF(C8="CF8",130000,IF(C8="CF8M",130000))) -> 130000 | K8: =I8+J8 -> 130000 | L8: TEFLON SEAT | M8: METAL TEFLON SEAT | P8: 외주가공 FLANGE | R8: 130000 | T8: =R8+Q8 -> 130000
A9: 2 | B9: DISC | C9: =BFLY!B16 -> CF8M | D9: 1 | F9: =IF(C9="CF8",8,IF(C9="CF8M",8,IF(C9="CF3M",8,IF(C9="B148",10)))) -> 8 | H9: =BFLY!C16 -> 8000 | I9: =D9*F9*H9 -> 64000 | J9: =IF(C9="CF8",18000,IF(C9="CF8M",18000,IF(C9="CF3M",18000,IF(C9="B148",25000)))) -> 18000 | K9: =I9+J9 -> 82000 | L9: TEFLON | M9: TEFLON | N9: METAL | O9: 합계
A10: 3 | B10: SEAT | C10: =BFLY!B19 -> RTFE | D10: 1 | I10: =IF(C10="RTFE",30800,IF(C10="RTFE-A",25850,IF(C10="METAL-B",6450,IF(C10="RTFE + METAL",37900)))) -> 30800 | J10: =IF(C10="RTFE",3400,IF(C10="METAL-B",20000,IF(C10="RTFE + METAL",10000))) -> 3400 | K10: =I10+J10 -> 34200 | L10: 30800 | M10: 30800 | N10: 7100 | O10: =M10+N10 -> 37900
A11: 4 | B11: STEM(上,下) | C11: =BFLY!B17 -> A564T630 | D11: 1 | F11: 3.1 | H11: =BFLY!C17 -> 8000 | I11: =D11*F11*H11 -> 24800 | J11: 6000 | K11: =I11+J11 -> 30800 | P11: STEM | R11: 6000 | T11: =R11+Q11 -> 6000
A12: 5 | B12: RETAINER RING | C12: SS316 | D12: 1 | F12: 1 | H12: 41500 | I12: =D12*F12*H12 -> 41500 | J12: 15000 | K12: =I12+J12 -> 56500 | P12: RETAINER RING | Q12: =34.59*1200 -> 41508 | R12: 15000 | T12: =R12+Q12 -> 56508
A13: 6 | B13: RETAINER BOLT | C13: B8M | D13: 4 | F13: 1 | H13: 700 | I13: =D13*F13*H13 -> 2800 | K13: =H13*D13 -> 2800
A14: 7 | B14: BUSH | C14: SS316 | D14: 2 | F14: 1 | I14: 6080 | J14: 15200 | K14: =(I14+J14)*D14 -> 42560 | T14: =R14+Q14 -> 0
A15: 8 | B15: PACKING | C15: GRAPHITE | D15: 1 | F15: 1 | H15: 7000 | I15: =D15*F15*H15 -> 7000 | K15: =I15+J15 -> 7000 | P15: PACKING (완제품)
A16: 9 | B16: PACKING GLAND | C16: CF8/CF8M | D16: 1 | F16: 1 | H16: 2445 | I16: =D16*F16*H16 -> 2445 | J16: 500 | K16: =I16+J16 -> 2945 | P16: PACKING GLAND (소재+가공비) | T16: =2.45*1200 -> 2940
A17: 10 | B17: GLAND BOLT/NUT | C17: B8M | D17: 2 | F17: 1 | H17: 600 | I17: =D17*F17*H17 -> 1200 | K17: =I17+J17 -> 1200
A18: 11 | B18: COLOR | C18: SS316 | D18: 1 | F18: 1 | H18: 400 | I18: =D18*F18*H18 -> 400 | J18: 500 | K18: =I18+J18 -> 900 | T18: =R18+Q18 -> 0
A19: 12 | B19: DISCK PIN | C19: SS630 | D19: 2 | F19: 1 | H19: 450 | I19: =H19 -> 450 | J19: 480 | K19: =(I19+J19)*D19 -> 1860 | T19: =R19+Q19 -> 0
A20: 13 | B20: END COVER | C20: SS316 | D20: 1 | F20: 1 | H20: 2270 | I20: =D20*F20*H20 -> 2270 | J20: 1000 | K20: 6670 | P20: END COVER (소재+가공비) | T20: =5.56*1200 -> 6672
A21: 14 | B21: END COVER BOLT | C21: B8M | D21: 4 | F21: 1 | H21: 100 | I21: =D21*F21*H21 -> 400 | K21: =I21+J21 -> 400
A22: 15 | B22: GASKET | C22: N-ASBESTOS | D22: 1 | F22: 1 | H22: 1900 | I22: =D22*F22*H22 -> 1900 | K22: =I22+J22 -> 1900
A23: 16 | B23: TAG | C23: SS316 | D23: 1 | F23: 1 | H23: 900 | I23: =D23*F23*H23 -> 900 | K23: =I23+J23 -> 900
A24: 17 | B24: INDICATOR | C24: SS304 | D24: 1 | F24: 1 | H24: 4950 | I24: =D24*F24*H24 -> 4950 | K24: =I24+J24 -> 4950
A25: 18 | B25: INDICATOR BOLT/NUT | C25: B8M | D25: 4 | F25: 1 | H25: 360 | I25: =D25*F25*H25 -> 1440 | K25: =I25+J25 -> 1440
A26: 19 | B26: LEVER | C26: SS304 | D26: 1 | F26: 1 | I26: 19420 | J26: 6500 | K26: =I26+J26 -> 25920
A27: 20 | B27: GEAR BOX | C27: =BFLY!B20 -> 10 BAR | D27: 1 | F27: 1 | J27: =C27 -> 10 BAR | K27: =IF(C27="PIYAKE",L27,IF(C27="10 BAR",M27,IF(C27="20 BAR",N27))) -> 98000 | M27: 98000 | N27: 203000
A28: 21 | B28: 페인트, 조립 | C28: CEPHAS | D28: 1 | F28: 1 | I28: 15000 | J28: 10000 | K28: =I28+J28 -> 25000
A29: 22 | B29: 밸브합산(BEAR) | K29: =SUM(K6:K25,K28) -> 628025
A30: 23 | B30: 밸브합산(LEVER) | K30: =SUM(K6:K26,K28) -> 653945
A31: 24 | B31: 밸브합산(GEAR) | K31: =SUM(K6:K25,K27:K28) -> 726025
A32: 25
A33: 26 | B33: ACTUATOR | D33: 1 | K33: =I33+J33 -> 0
A34: 27 | B34: ACTUATOR BOLT/WASHER | D34: 4 | K34: =I34+J34 -> 0
B35: 포장비용 | D35: 1 | K35: 24200
A36: 28 | B36: 밸브외 사급품 비용 연산 | I36: =SUM(K32:K35) -> 24200 | J36: 1 | K36: =J36*I36 -> 24200
A37: 29
A38: 30 | B38: FACTOR(BEAR) | I38: =K29 -> 628025 | J38: =BFLY!B21 -> 1 | K38: =J38*I38 -> 628025
A39: 31 | B39: FACTOR(LEVER) | I39: =K30 -> 653945 | J39: =BFLY!B21 -> 1 | K39: =J39*I39 -> 653945
A40: 32 | B40: FACTOR(GEAR) | I40: =K31 -> 726025 | J40: =BFLY!B21 -> 1 | K40: =J40*I40 -> 726025
A41: 33 | B41: 견적가격(TOTAL금액) - BEAR | K41: =SUM(K36,K38) -> 652225
A42: 34 | B42: 견적가격(TOTAL금액) - LEVER | K42: =SUM(K36,K39) -> 678145
...

Sheet 300A
A1: HIGH PERFORMANCE BFV 원가 分析表
A3: SIZE : 300A | C3: 압력 : 150# | F3: PJT :
A5: NO. | B5: 부품명 | C5: 재질 | D5: 수량 | E5: 규격 | F5: 단중 | G5: 업체 | H5: 단가 | I5: 소계 | J5: 가공비 | K5: 합계 | Q5: 소재비 | R5: 가공비 | T5: 합
A6: 1 | B6: BODY(WAFER) | C6: =BFLY!B13 -> CF8 | D6: 1 | F6: =IF(C6="WCB",36,IF(C6="CF8",36,IF(C6="CF8M",36))) -> 36 | H6: =BFLY!C13 -> 4000 | I6: =D6*F6*H6 -> 144000 | J6: =IF(C6="WCB",60000,IF(C6="CF8",60000,IF(C6="CF8M",60000))) -> 60000 | K6: =I6+J6 -> 204000 | P6: 외주가공 WAFER | R6: 110000 | T6: =R6+Q6 -> 110000
B7: BODY(LUG) | C7: =BFLY!B14 -> 0 | D7: 1 | F7: =IF(C7="WCB",56,IF(C7="CF8",56,IF(C7="CF8M",56))) -> FALSE | H7: =BFLY!C14 -> 0 | I7: =D7*F7*H7 -> 0 | J7: =IF(C7="WCB",130000,IF(C7="CF8",130000,IF(C7="CF8M",130000))) -> FALSE | K7: =I7+J7 -> 0 | P7: 외주가공 LUG | R7: 130000 | T7: =R7+Q7 -> 130000
B8: BODY(FLANGE) | C8: =BFLY!B15 -> CF8 | D8: 1 | F8: =106*1.1 -> 116.6 | H8: =BFLY!C15 -> 0 | I8: =D8*F8*H8 -> 0 | J8: =IF(C8="WCB",160000,IF(C8="CF8",160000,IF(C8="CF8M",160000))) -> 160000 | K8: =I8+J8 -> 160000 | L8: TEFLON SEAT | M8: METAL TEFLON SEAT | P8: 외주가공 FLANGE | R8: 160000 | T8: =R8+Q8 -> 160000
A9: 2 | B9: DISC | C9: =BFLY!B16 -> CF8M | D9: 1 | F9: =IF(C9="CF8",12.6,IF(C9="CF8M",12.6,IF(C9="CF3M",12.6,IF(C9="B148",14)))) -> 12.6 | H9: =BFLY!C16 -> 8000 | I9: =D9*F9*H9 -> 100800 | J9: =IF(C9="CF8",20000,IF(C9="CF8M",20000,IF(C9="CF3M",20000,IF(C9="B148",27000)))) -> 20000 | K9: =I9+J9 -> 120800 | L9: TEFLON | M9: TEFLON | N9: METAL | O9: 합계
A10: 3 | B10: SEAT | C10: =BFLY!B19 -> RTFE | D10: 1 | I10: =IF(C10="RTFE",48100,IF(C10="RTFE-A",32820,IF(C10="METAL-B",11700,IF(C10="RTFE + METAL",47700)))) -> 48100 | J10: =IF(C10="RTFE",4000,IF(C10="METAL-B",20000,IF(C10="RTFE + METAL",10000))) -> 4000 | K10: =I10+J10 -> 52100 | L10: 48100 | M10: 35200 | N10: 12500 | O10: =M10+N10 -> 47700
A11: 4 | B11: STEM(上,下) | C11: =BFLY!B17 -> A564T630 | D11: 1 | F11: 4.5 | H11: =BFLY!C17 -> 8000 | I11: =D11*F11*H11 -> 36000 | J11: 17000 | K11: =I11+J11 -> 53000 | P11: STEM | R11: 6000 | T11: =R11+Q11 -> 6000
A12: 5 | B12: RETAINER RING | C12: SS316 | D12: 1 | F12: 1 | H12: 61200 | I12: =D12*F12*H12 -> 61200 | J12: 20000 | K12: =I12+J12 -> 81200 | P12: RETAINER RING | Q12: =50.93*1200 -> 61116 | R12: 20000 | T12: =R12+Q12 -> 81116
A13: 6 | B13: RETAINER BOLT | C13: B8M | D13: 4 | F13: 1 | H13: 700 | I13: =D13*F13*H13 -> 2800 | K13: =H13*D13 -> 2800
A14: 7 | B14: BUSH | C14: SS316 | D14: 2 | F14: 1 | I14: 8030 | J14: 23760 | K14: =(I14+J14)*D14 -> 63580 | T14: =R14+Q14 -> 0
A15: 8 | B15: PACKING | C15: GRAPHITE | D15: 1 | F15: 1 | H15: 7900 | I15: =D15*F15*H15 -> 7900 | K15: =I15+J15 -> 7900 | P15: PACKING (완제품)
A16: 9 | B16: PACKING GLAND | C16: CF8/CF8M | D16: 1 | F16: 1 | H16: 2445 | I16: =D16*F16*H16 -> 2445 | J16: 500 | K16: =I16+J16 -> 2945 | P16: PACKING GLAND (소재+가공비) | T16: =0.96*1200 -> 1152
A17: 10 | B17: GLAND BOLT/NUT | C17: B8M | D17: 2 | F17: 1 | H17: 700 | I17: =D17*F17*H17 -> 1400 | K17: =I17+J17 -> 1400
A18: 11 | B18: COLOR | C18: SS316 | D18: 1 | F18: 1 | H18: 450 | I18: =D18*F18*H18 -> 450 | J18: 500 | K18: =I18+J18 -> 950 | T18: =R18+Q18 -> 0
A19: 12 | B19: DISCK PIN | C19: SS630 | D19: 3 | F19: 1 | H19: 600 | I19: =H19 -> 600 | J19: 480 | K19: =(I19+J19)*D19 -> 3240 | T19: =R19+Q19 -> 0
A20: 13 | B20: END COVER | C20: SS316 | D20: 1 | F20: 1 | H20: 2795 | I20: =D20*F20*H20 -> 2795 | J20: 1000 | K20: 7100 | P20: END COVER (소재+가공비) | T20: =5.91*1200 -> 7092
A21: 14 | B21: END COVER BOLT | C21: B8M | D21: 4 | F21: 1 | H21: 100 | I21: =D21*F21*H21 -> 400 | K21: =I21+J21 -> 400
A22: 15 | B22: GASKET | C22: N-ASBESTOS | D22: 1 | F22: 1 | H22: 1900 | I22: =D22*F22*H22 -> 1900 | K22: =I22+J22 -> 1900
A23: 16 | B23: TAG | C23: SS316 | D23: 1 | F23: 1 | H23: 900 | I23: =D23*F23*H23 -> 900 | K23: =I23+J23 -> 900
A24: 17 | B24: INDICATOR | C24: SS304 | D24: 1 | F24: 1 | H24: 4950 | I24: =D24*F24*H24 -> 4950 | K24: =I24+J24 -> 4950
A25: 18 | B25: INDICATOR BOLT/NUT | C25: B8M | D25: 4 | F25: 1 | H25: 360 | I25: =D25*F25*H25 -> 1440 | K25: =I25+J25 -> 1440
A26: 19 | B26: LEVER | C26: SS304 | D26: 1 | F26: 1 | I26: 21360 | J26: 6500 | K26: =I26+J26 -> 27860
A27: 20 | B27: GEAR BOX | C27: =BFLY!B20 -> 10 BAR | D27: 1 | F27: 1 | J27: =C27 -> 10 BAR | K27: =IF(C27="PIYAKE",L27,IF(C27="10 BAR",M27,IF(C27="20 BAR",N27))) -> 203000 | L27: 50000 | M27: 203000 | N27: 225000
A28: 21 | B28: 페인트, 조립 | C28: CEPHAS | D28: 1 | F28: 1 | I28: 28000 | J28: 10000 | K28: =I28+J28 -> 38000
A29: 22 | B29: 밸브합산(BEAR) | K29: =SUM(K6:K25,K28) -> 808605
A30: 23 | B30: 밸브합산(LEVER) | K30: =SUM(K6:K26,K28) -> 836465
A31: 24 | B31: 밸브합산(GEAR) | K31: =SUM(K6:K25,K27:K28) -> 1011605
A32: 25
A33: 26 | B33: ACTUATOR | D33: 1 | K33: =I33+J33 -> 0
A34: 27 | B34: ACTUATOR BOLT/WASHER | D34: 4 | K34: =I34+J34 -> 0
B35: 포장비용 | D35: 1 | K35: 34000
A36: 28 | B36: 밸브외 사급품 비용 연산 | I36: =SUM(K32:K35) -> 34000 | J36: 1 | K36: =J36*I36 -> 34000
A37: 29
A38: 30 | B38: FACTOR(BEAR) | I38: =K29 -> 808605 | J38: =BFLY!B21 -> 1 | K38: =J38*I38 -> 808605
A39: 31 | B39: FACTOR(LEVER) | I39: =K30 -> 836465 | J39: =BFLY!B21 -> 1 | K39: =J39*I39 -> 836465
A40: 32 | B40: FACTOR(GEAR) | I40: =K31 -> 1011605 | J40: =BFLY!B21 -> 1 | K40: =J40*I40 -> 1011605
A41: 33 | B41: 견적가격(TOTAL금액) - BEAR | K41: =SUM(K36,K38) -> 842605
A42: 34 | B42: 견적가격(TOTAL금액) - LEVER | K42: =SUM(K36,K39) -> 870465
...

Sheet 350A
A1: HIGH PERFORMANCE BFV 원가 分析表
A3: SIZE : 350A | C3: 압력 : 150# | F3: PJT :
Q4: 소재비 | R4: 가공비 | T4: 합
A5: NO. | B5: 부품명 | C5: 재질 | D5: 수량 | E5: 규격 | F5: 단중 | G5: 업체 | H5: 단가 | I5: 소계 | J5: 가공비 | K5: 합계
A6: 1 | B6: BODY(WAFER) | C6: =BFLY!B13 -> CF8 | D6: 1 | F6: =IF(C6="WCB",51,IF(C6="CF8",51,IF(C6="CF8M",51))) -> 51 | H6: =BFLY!C13 -> 4000 | I6: =D6*F6*H6 -> 204000 | J6: =IF(C6="WCB",100000,IF(C6="CF8",124800,IF(C6="CF8M",124800))) -> 124800 | K6: =I6+J6 -> 328800
B7: BODY(LUG) | C7: =BFLY!B14 -> 0 | D7: 1 | F7: =IF(C7="WCB",78,IF(C7="CF8",78,IF(C7="CF8M",78))) -> FALSE | H7: =BFLY!C14 -> 0 | I7: =D7*F7*H7 -> 0 | J7: =IF(C7="WCB",125000,IF(C7="CF8",150000,IF(C7="CF8M",150000))) -> FALSE | K7: =I7+J7 -> 0
B8: BODY(FLANGE) | C8: =BFLY!B15 -> CF8 | D8: 1 | F8: =130*1.1 -> 143 | H8: =BFLY!C15 -> 0 | I8: =D8*F8*H8 -> 0 | J8: =IF(C8="WCB",180000,IF(C8="CF8",180000,IF(C8="CF8M",180000))) -> 180000 | K8: =I8+J8 -> 180000 | L8: TEFLON SEAT | M8: METAL TEFLON SEAT
A9: 2 | B9: DISC | C9: =BFLY!B16 -> CF8M | D9: 1 | F9: =IF(C9="CF8",22.5,IF(C9="CF8M",22.5,IF(C9="CF3M",22.5,IF(C9="B148",24.5)))) -> 22.5 | H9: =BFLY!C16 -> 8000 | I9: =D9*F9*H9 -> 180000 | J9: =IF(C9="CF8",48000,IF(C9="CF8M",48000,IF(C9="CF3M",48000,IF(C9="B148",50000)))) -> 48000 | K9: =I9+J9 -> 228000 | L9: TEFLON | M9: TEFLON | N9: METAL | O9: 합계
A10: 3 | B10: SEAT | C10: =BFLY!B19 -> RTFE | D10: 1 | I10: =IF(C10="RTFE",60620,IF(C10="RTFE-A",50000,IF(C10="METAL-B",13750,IF(C10="RTFE + METAL",70750)))) -> 60620 | J10: =IF(C10="RTFE",4800,IF(C10="METAL-B",20000,IF(C10="RTFE + METAL",10000))) -> 4800 | K10: =I10+J10 -> 65420 | L10: 60620 | M10: 54750 | N10: 16000 | O10: =M10+N10 -> 70750
A11: 4 | B11: STEM(上,下) | C11: =BFLY!B17 -> A564T630 | D11: 1 | F11: 7.55 | H11: =BFLY!C17 -> 8000 | I11: =D11*F11*H11 -> 60400 | J11: 15000 | K11: =I11+J11 -> 75400
A12: 5 | B12: RETAINER RING | C12: SS316 | D12: 1 | F12: 1 | H12: 161250 | I12: =D12*F12*H12 -> 161250 | J12: 40000 | K12: =I12+J12 -> 201250 | P12: RETAINER RING | R12: 40000 | T12: =R12+Q12 -> 40000
A13: 6 | B13: RETAINER BOLT | C13: B8M | D13: 8 | F13: 1 | H13: 800 | I13: =D13*F13*H13 -> 6400 | K13: =H13*D13 -> 6400
A14: 7 | B14: BUSH | C14: SS316 | D14: 2 | F14: 1 | I14: 19540 | J14: 22290 | K14: =I14+J14 -> 41830
A15: 8 | B15: PACKING | C15: GRAPHITE | D15: 1 | F15: 1 | H15: 8600 | I15: =D15*F15*H15 -> 8600 | K15: =I15+J15 -> 8600
A16: 9 | B16: PACKING GLAND | C16: CF8/CF8M | D16: 1 | F16: 1 | H16: 9150 | I16: =D16*F16*H16 -> 9150 | J16: 5000 | K16: =I16+J16 -> 14150
A17: 10 | B17: GLAND BOLT/NUT | C17: B8M | D17: 2 | F17: 1 | H17: 700 | I17: =D17*F17*H17 -> 1400 | K17: =I17+J17 -> 1400
A18: 11 | B18: COLOR | C18: SS316 | D18: 1 | F18: 1 | H18: 650 | I18: =D18*F18*H18 -> 650 | J18: 3000 | K18: =I18+J18 -> 3650
A19: 12 | B19: DISCK PIN | C19: SS630 | D19: 4 | F19: 1 | H19: 400 | I19: =H19 -> 400 | J19: 500 | K19: =(I19+J19)*D19 -> 3600
A20: 13 | B20: END COVER | C20: SS316 | D20: 1 | F20: 1 | H20: 10370 | I20: =D20*F20*H20 -> 10370 | J20: 6000 | K20: =I20+J20 -> 16370
A21: 14 | B21: END COVER BOLT | C21: B8M | D21: 4 | F21: 1 | H21: 180 | I21: =D21*F21*H21 -> 720 | K21: =I21+J21 -> 720
A22: 15 | B22: GASKET | C22: N-ASBESTOS | D22: 1 | F22: 1 | H22: 2250 | I22: =D22*F22*H22 -> 2250 | K22: =I22+J22 -> 2250
A23: 16 | B23: TOP COVER BOLT | C23: B8 | D23: 4 | F23: 1 | H23: 1150 | I23: 1150 | K23: =(I23+J23)*D23 -> 4600
A24: 17 | B24: G/BOX BOLT | C24: B8 | D24: 4 | F24: 1 | H24: 900 | I24: 900 | K24: =(I24+J24)*D24 -> 3600
A25: 18 | B25: TAG | C25: SS304 | D25: 1 | F25: 1 | H25: 1200 | I25: =D25*F25*H25 -> 1200 | K25: =I25+J25 -> 1200
A26: 19 | B26: TOP COVER | C26: CF8/CF8M | D26: 1 | F26: 1 | H26: 40260 | I26: =D26*F26*H26 -> 40260 | J26: 9000 | K26: =I26+J26 -> 49260
A27: 20 | B27: GEAR BOX | C27: =BFLY!B20 -> 10 BAR | D27: 1 | F27: 1 | J27: =C27 -> 10 BAR | K27: =IF(C27="PIYAKE",L27,IF(C27="10 BAR",M27,IF(C27="20 BAR",N27))) -> 203000 | L27: 49520 | M27: 203000 | N27: 225000
A28: 21 | B28: 페인트, 조립 | C28: CEPHAS | D28: 1 | F28: 1 | I28: 38400 | J28: 38400 | K28: =I28+J28 -> 76800
A29: 22 | B29: 밸브합산(BEAR) | K29: =SUM(K6:K26,K28) -> 1313300
A30: 24 | B30: 밸브합산(GEAR) | K30: =SUM(K6:K28) -> 1516300
A31: 25
A32: 26 | B32: ACTUATOR | D32: 1 | K32: =I32+J32 -> 0
A33: 27 | B33: ACTUATOR BOLT/WASHER | D33: 4 | K33: =I33+J33 -> 0
B34: 포장비용 | D34: 1 | K34: 56800
A35: 28 | B35: 밸브외 사급품 비용 연산 | I35: =SUM(K31:K34) -> 56800 | J35: 1 | K35: =J35*I35 -> 56800
A36: 29
A37: 30 | B37: FACTOR(BEAR) | I37: =K29 -> 1313300 | K37: =I37+K35 -> 1370100
A38: 32 | B38: FACTOR(GEAR) | I38: =K30 -> 1516300 | K38: =I38+K35 -> 1573100
A39: 33 | B39: 견적가격(TOTAL금액) - BEAR | J39: =BFLY!B21 -> 1 | K39: =K37*J39 -> 1370100
A40: 35 | B40: 견적가격(TOTAL금액) - GEAR | J40: =BFLY!B21 -> 1 | K40: =K38*J40 -> 1573100

Sheet 400A
A1: HIGH PERFORMANCE BFV 원가 分析表
A3: SIZE : 400A | C3: 압력 : 150# | F3: PJT :
Q4: 소재비 | R4: 가공비 | T4: 합
A5: NO. | B5: 부품명 | C5: 재질 | D5: 수량 | E5: 규격 | F5: 단중 | G5: 업체 | H5: 단가 | I5: 소계 | J5: 가공비 | K5: 합계
A6: 1 | B6: BODY(WAFER) | C6: =BFLY!B13 -> CF8 | D6: 1 | F6: =IF(C6="WCB",77,IF(C6="CF8",77,IF(C6="CF8M",77))) -> 77 | H6: =BFLY!C13 -> 4000 | I6: =D6*F6*H6 -> 308000 | J6: =IF(C6="WCB",135000,IF(C6="CF8",168000,IF(C6="CF8M",168000))) -> 168000 | K6: =I6+J6 -> 476000
B7: BODY(LUG) | C7: =BFLY!B14 -> 0 | D7: 1 | F7: =IF(C7="WCB",114,IF(C7="CF8",114,IF(C7="CF8M",114))) -> FALSE | H7: =BFLY!C14 -> 0 | I7: =D7*F7*H7 -> 0 | J7: =IF(C7="WCB",168000,IF(C7="CF8",210000,IF(C7="CF8M",210000))) -> FALSE | K7: =I7+J7 -> 0
B8: BODY(FLANGE) | C8: =BFLY!B15 -> CF8 | D8: 1 | F8: =192*1.1 -> 211.2 | H8: =BFLY!C15 -> 0 | I8: =D8*F8*H8 -> 0 | J8: =IF(C8="WCB",240000,IF(C8="CF8",240000,IF(C8="CF8M",240000))) -> 240000 | K8: =I8+J8 -> 240000 | L8: TEFLON SEAT | M8: METAL TEFLON SEAT
A9: 2 | B9: DISC | C9: =BFLY!B16 -> CF8M | D9: 1 | F9: =IF(C9="CF8",34,IF(C9="CF8M",34,IF(C9="CF3M",34,IF(C9="B148",34.5)))) -> 34 | H9: =BFLY!C16 -> 8000 | I9: =D9*F9*H9 -> 272000 | J9: =IF(C9="CF8",60000,IF(C9="CF8M",60000,IF(C9="CF3M",60000,IF(C9="B148",60000)))) -> 60000 | K9: =I9+J9 -> 332000 | L9: TEFLON | M9: TEFLON | N9: METAL | O9: 합계
